Workbook

Sheet MOP_Mes_Corriente
C1: 1.620347 | D1: 1.620347 | E1: 1.620347 | F1: 1.620347 | G1: 1.620347 | H1: 1.620347 | I1: 1.620347 | J1: 1.620347 | K1: 1.620347 | L1: 1.620347 | M1: 1.620347 | N1: 1.620347 | P1: 1.5522091 | Q1: 1.5522091 | R1: 1.5522091 | S1: 1.5522091 | T1: 1.5522091 | U1: 1.5522091 | V1: 1.5522091 | W1: 1.5522091 | X1: 1.5522091 | Y1: 1.5522091 | Z1: 1.5522091 | AA1: 1.5522091 | AC1: 1.5114124 | AD1: 1.5114124 | AE1: 1.5114124 | AF1: 1.5114124 | AG1: 1.5114124 | AH1: 1.5114124 | AI1: 1.5114124 | AJ1: 1.5114124 | AK1: 1.5114124 | AL1: 1.5114124 | AM1: 1.5114124 | AN1: 1.5114124 | AP1: 1.4778845 | AQ1: 1.4778845 | AR1: 1.4778845 | AS1: 1.4778845 | AT1: 1.4778845 | AU1: 1.4778845 | AV1: 1.4778845 | AW1: 1.4778845 | AX1: 1.4778845 | AY1: 1.4778845 | AZ1: 1.4778845 | BA1: 1.4778845 | BC1: 1.4408545 | BD1: 1.4408545 | BE1: 1.4408545 | BF1: 1.4408545 | BG1: 1.4408545 | BH1: 1.4408545 | BI1: 1.4408545 | BJ1: 1.4408545 | BK1: 1.4408545 | BL1: 1.4408545 | BM1: 1.4408545 | BN1: 1.4408545 | BP1: 1.3989757 | BQ1: 1.3989757 | BR1: 1.3989757 | BS1: 1.3989757 | BT1: 1.3989757 | BU1: 1.3989757 | BV1: 1.3989757 | BW1: 1.3989757 | BX1: 1.3989757 | BY1: 1.3989757 | BZ1: 1.3989757 | CA1: 1.3989757 | CC1: 1.3584483 | CD1: 1.3584483 | CE1: 1.3584483 | CF1: 1.3584483 | CG1: 1.3584483 | CH1: 1.3584483 | CI1: 1.3584483 | CJ1: 1.3584483 | CK1: 1.3584483 | CL1: 1.3584483 | CM1: 1.3584483 | CN1: 1.3584483 | CP1: 1.2675174 | CQ1: 1.2675174 | CR1: 1.2675174 | CS1: 1.2675174 | CT1: 1.2675174 | CU1: 1.2675174 | CV1: 1.2675174 | CW1: 1.2675174 | CX1: 1.2675174 | CY1: 1.2675174 | CZ1: 1.2675174 | DA1: 1.2675174 | DC1: 1.1239584 | DD1: 1.1239584 | DE1: 1.1239584 | DF1: 1.1239584 | DG1: 1.1239584 | DH1: 1.1239584 | DI1: 1.1239584 | DJ1: 1.1239584 | DK1: 1.1239584 | DL1: 1.1239584 | DM1: 1.1239584 | DN1: 1.1239584 | DP1: 1.0813539 | DQ1: 1.0813539 | DR1: 1.0813539 | DS1: 1.0813539 | DT1: 1.0813539 | DU1: 1.0813539 | DV1: 1.0813539 | DW1: 1.0813539 | DX1: 1.0813539 | DY1: 1.0813539 | DZ1: 1.0813539 | EA1: 1.0813539 | EC1: 1.0344632 | ED1: 1.0344632 | EE1: 1.0344632 | EF1: 1.0344632 | EG1: 1.0344632 | EH1: 1.0344632 | EI1: 1.0344632 | EJ1: 1.0344632 | EK1: 1.0344632 | EL1: 1.0344632 | EM1: 1.0344632 | EN1: 1.0344632 | EP1: 1 | EQ1: 1 | ER1: 1 | ES1: 1 | ET1: 1 | EU1: 1 | EV1: 1 | EW1: 1 | EX1: 1 | EY1: 1 | EZ1: 1 | FA1: 1
B3: Ministerio de Obras Públicas – Partida 12
B4: Miles de pesos – moneda corriente – montos devengados
B5: Subtítulo 31 – Iniciativas de Inversión
B7: Presupuesto Ley de Inversión en Infraestructura Pública del Ministerio de Obras Públicas, 2014-2026 (Subtítulo 31 – Iniciativas de Inversión, miles de pesos)
C8: 2014 | P8: 2015 | AC8: 2016 | AP8: 2017 | BC8: 2018 | BP8: 2019 | CC8: 2020 | CP8: 2021(1) | DC8: 2022(1) | DP8: 2023 | EC8: 2024 | EP8: 2025 | FC8: 2026
B9: Programa | C9: Ene | D9: Feb | E9: Mar | F9: Abr | G9: May | H9: Jun | I9: Jul | J9: Ago | K9: Sep | L9: Oct | M9: Nov | N9: Dic | O9: Total 2014 | P9: Ene | Q9: Feb | R9: Mar | S9: Abr | T9: May | U9: Jun | V9: Jul | W9: Ago | X9: Sep | Y9: Oct | Z9: Nov | AA9: Dic | AB9: Total 2015 | AC9: Ene | AD9: Feb | AE9: Mar | AF9: Abr | AG9: May | AH9: Jun | AI9: Jul | AJ9: Ago | AK9: Sep | AL9: Oct | AM9: Nov | AN9: Dic | AO9: Total 2016 | AP9: Ene | AQ9: Feb | AR9: Mar | AS9: Abr | AT9: May | AU9: Jun | AV9: Jul | AW9: Ago | AX9: Sep | AY9: Oct | AZ9: Nov | BA9: Dic | BB9: Total 2017 | BC9: Ene | BD9: Feb | BE9: Mar | BF9: Abr | BG9: May | BH9: Jun | BI9: Jul | BJ9: Ago | BK9: Sep | BL9: Oct | BM9: Nov | BN9: Dic | BO9: Total 2018 | BP9: Ene | BQ9: Feb | BR9: Mar | BS9: Abr | BT9: May | BU9: Jun | BV9: Jul | BW9: Ago | BX9: Sep | BY9: Oct | BZ9: Nov | CA9: Dic | CB9: Total 2019 | CC9: Ene | CD9: Feb | CE9: Mar | CF9: Abr | CG9: May | CH9: Jun | CI9: Jul | CJ9: Ago | CK9: Sep | CL9: Oct | CM9: Nov | CN9: Dic | CO9: Total 2020 | CP9: Ene | CQ9: Feb | CR9: Mar | CS9: Abr | CT9: May | CU9: Jun | CV9: Jul | CW9: Ago | CX9: Sep | CY9: Oct | CZ9: Nov | DA9: Dic | DB9: Total 2021 | DC9: Ene | DD9: Feb | DE9: Mar | DF9: Abr | DG9: May | DH9: Jun | DI9: Jul | DJ9: Ago | DK9: Sep | DL9: Oct | DM9: Nov | DN9: Dic | DO9: Total 2022 | DP9: Ene | DQ9: Feb | DR9: Mar | DS9: Abr | DT9: May | DU9: Jun | DV9: Jul | DW9: Ago | DX9: Sep | DY9: Oct | DZ9: Nov | EA9: Dic | EB9: Total 2023 | EC9: Ene | ED9: Feb | EE9: Mar | EF9: Abr | EG9: May | EH9: Jun | EI9: Jul | EJ9: Ago | EK9: Sep | EL9: Oct | EM9: Nov | EN9: Dic | EO9: Total 2024 | EP9: Ene | EQ9: Feb | ER9: Mar | ES9: Abr | ET9: May | EU9: Jun | EV9: Jul | EW9: Ago | EX9: Sep | EY9: Oct | EZ9: Nov | FA9: Dic | FB9: Total 2025 | FC9: Ene | FD9: Feb | FE9: Mar | FF9: Abr | FG9: May | FH9: Jun | FI9: Jul | FJ9: Ago | FK9: Sep | FL9: Oct | FM9: Nov | FN9: Dic | FO9: Total 2026
B10: Dirección de Vialidad | C10: 806907228 | D10: 806907228 | E10: 806907228 | F10: 806907228 | G10: 806907228 | H10: 806907228 | I10: 806907228 | J10: 806907228 | K10: 806907228 | L10: 806907228 | M10: 806907228 | N10: 806907228 | O10: =N10 -> 806907228 | P10: 957407656 | Q10: 957407656 | R10: 957407656 | S10: 957407656 | T10: 957407656 | U10: 957407656 | V10: 957407656 | W10: 957407656 | X10: 957407656 | Y10: 957407656 | Z10: 957407656 | AA10: 957407656 | AB10: =AA10 -> 957407656 | AC10: 937156766 | AD10: 937156766 | AE10: 937156766 | AF10: 937156766 | AG10: 937156766 | AH10: 937156766 | AI10: 937156766 | AJ10: 937156766 | AK10: 937156766 | AL10: 937156766 | AM10: 937156766 | AN10: 937156766 | AO10: =AN10 -> 937156766 | AP10: 982538421 | AQ10: 982538421 | AR10: 982538421 | AS10: 982538421 | AT10: 982538421 | AU10: 982538421 | AV10: 982538421 | AW10: 982538421 | AX10: 982538421 | AY10: 982538421 | AZ10: 982538421 | BA10: 982538421 | BB10: =BA10 -> 982538421 | BC10: 998447263 | BD10: 998447263 | BE10: 998447263 | BF10: 998447263 | BG10: 998447263 | BH10: 998447263 | BI10: 998447263 | BJ10: 998447263 | BK10: 998447263 | BL10: 998447263 | BM10: 998447263 | BN10: 998447263 | BO10: =BN10 -> 998447263 | BP10: 1056398949 | BQ10: 1056398949 | BR10: 1056398949 | BS10: 1056398949 | BT10: 1056398949 | BU10: 1056398949 | BV10: 1056398949 | BW10: 1056398949 | BX10: 1056398949 | BY10: 1056398949 | BZ10: 1056398949 | CA10: 1056398949 | CB10: =CA10 -> 1056398949 | CC10: 1148358839 | CD10: 1148358839 | CE10: 1148358839 | CF10: 1148358839 | CG10: 1148358839 | CH10: 1148358839 | CI10: 1148358839 | CJ10: 1148358839 | CK10: 1148358839 | CL10: 1148358839 | CM10: 1148358839 | CN10: 1148358839 | CO10: =CN10 -> 1148358839 | CP10: =1224421462+380805877 -> 1605227339 | CQ10: =1224421462+380805877 -> 1605227339 | CR10: =1224421462+380805877 -> 1605227339 | CS10: =1224421462+380805877 -> 1605227339 | CT10: =1224421462+380805877 -> 1605227339 | CU10: =1224421462+380805877 -> 1605227339 | CV10: =1224421462+380805877 -> 1605227339 | CW10: =1224421462+380805877 -> 1605227339 | ... DA10: =1224421462+380805877 -> 1605227339 | DB10: =DA10 -> 1605227339 | DC10: =1220635546+581829225 -> 1802464771 | DD10: =1220635546+581829225 -> 1802464771 | DE10: =1220635546+581829225 -> 1802464771 | DF10: =1220635546+581829225 -> 1802464771 | DG10: =1220635546+581829225 -> 1802464771 | DH10: =1220635546+581829225 -> 1802464771 | DI10: =1220635546+581829225 -> 1802464771 | DJ10: =1220635546+581829225 -> 1802464771 | ... DN10: =1220635546+581829225 -> 1802464771 | DO10: =DN10 -> 1802464771 | DP10: 1913855137 | DQ10: 1913855137 | DR10: 1913855137 | DS10: 1913855137 | DT10: 1913855137 | DU10: 1913855137 | DV10: 1913855137 | DW10: 1913855137 | DX10: 1913855137 | DY10: 1913855137 | DZ10: 1913855137 | EA10: 1913855137 | EB10: =EA10 -> 1913855137 | EC10: 2012684680 | ED10: 2012684680 | EE10: 2012684680 | EF10: 2012684680 | EG10: 2012684680 | EH10: 2012684680 | EI10: 2012684680 | EJ10: 2012684680 | EK10: 2012684680 | EL10: 2012684680 | EM10: 2012684680 | EN10: 2012684680 | EO10: =EN10 -> 2012684680 | EP10: 2083103023 | EQ10: 2083103023 | ER10: 2083103023 | ES10: 2083103023 | ET10: 2083103023 | EU10: 2083103023 | EV10: 2083103023 | EW10: 2083103023 | EX10: 2083103023 | EY10: 2083103023 | EZ10: 2083103023 | FA10: 2083103023 | FB10: =FA10 -> 2083103023 | FC10: 1951485600 | FD10: 1951485600 | FE10: 1951485600 | FF10: 1951485600 | FG10: 1951485600 | FH10: 1951485600 | FI10: 1951485600 | FO10: =FI10 -> 1951485600
B11: Dirección de Obras Hidráulicas | C11: 101236706 | D11: 101236706 | E11: 101236706 | F11: 101236706 | G11: 101236706 | H11: 101236706 | I11: 101236706 | J11: 101236706 | K11: 101236706 | L11: 101236706 | M11: 101236706 | N11: 101236706 | O11: =N11 -> 101236706 | P11: 117398169 | Q11: 117398169 | R11: 117398169 | S11: 117398169 | T11: 117398169 | U11: 117398169 | V11: 117398169 | W11: 117398169 | X11: 117398169 | Y11: 117398169 | Z11: 117398169 | AA11: 117398169 | AB11: =AA11 -> 117398169 | AC11: 127292924 | AD11: 127292924 | AE11: 127292924 | AF11: 127292924 | AG11: 127292924 | AH11: 127292924 | AI11: 127292924 | AJ11: 127292924 | AK11: 127292924 | AL11: 127292924 | AM11: 127292924 | AN11: 127292924 | AO11: =AN11 -> 127292924 | AP11: 121635713 | AQ11: 121635713 | AR11: 121635713 | AS11: 121635713 | AT11: 121635713 | AU11: 121635713 | AV11: 121635713 | AW11: 121635713 | AX11: 121635713 | AY11: 121635713 | AZ11: 121635713 | BA11: 121635713 | BB11: =BA11 -> 121635713 | BC11: 119785354 | BD11: 119785354 | BE11: 119785354 | BF11: 119785354 | BG11: 119785354 | BH11: 119785354 | BI11: 119785354 | BJ11: 119785354 | BK11: 119785354 | BL11: 119785354 | BM11: 119785354 | BN11: 119785354 | BO11: =BN11 -> 119785354 | BP11: 129182602 | BQ11: 129182602 | BR11: 129182602 | BS11: 129182602 | BT11: 129182602 | BU11: 129182602 | BV11: 129182602 | BW11: 129182602 | BX11: 129182602 | BY11: 129182602 | BZ11: 129182602 | CA11: 129182602 | CB11: =CA11 -> 129182602 | CC11: 137671350 | CD11: 137671350 | CE11: 137671350 | CF11: 137671350 | CG11: 137671350 | CH11: 137671350 | CI11: 137671350 | CJ11: 137671350 | CK11: 137671350 | CL11: 137671350 | CM11: 137671350 | CN11: 137671350 | CO11: =CN11 -> 137671350 | CP11: =140801596+100700947 -> 241502543 | CQ11: =140801596+100700947 -> 241502543 | CR11: =140801596+100700947 -> 241502543 | CS11: =140801596+100700947 -> 241502543 | CT11: =140801596+100700947 -> 241502543 | CU11: =140801596+100700947 -> 241502543 | CV11: =140801596+100700947 -> 241502543 | CW11: =140801596+100700947 -> 241502543 | ... DA11: =140801596+100700947 -> 241502543 | DB11: =DA11 -> 241502543 | DC11: =147022684+130812721 -> 277835405 | DD11: =147022684+130812721 -> 277835405 | DE11: =147022684+130812721 -> 277835405 | DF11: =147022684+130812721 -> 277835405 | DG11: =147022684+130812721 -> 277835405 | DH11: =147022684+130812721 -> 277835405 | DI11: =147022684+130812721 -> 277835405 | DJ11: =147022684+130812721 -> 277835405 | ... DN11: =147022684+130812721 -> 277835405 | DO11: =DN11 -> 277835405 | DP11: 293591805 | DQ11: 293591805 | DR11: 293591805 | DS11: 293591805 | DT11: 293591805 | DU11: 293591805 | DV11: 293591805 | DW11: 293591805 | DX11: 293591805 | DY11: 293591805 | DZ11: 293591805 | EA11: 293591805 | EB11: =EA11 -> 293591805 | EC11: 295701947 | ED11: 295701947 | EE11: 295701947 | EF11: 295701947 | EG11: 295701947 | EH11: 295701947 | EI11: 295701947 | EJ11: 295701947 | EK11: 295701947 | EL11: 295701947 | EM11: 295701947 | EN11: 295701947 | EO11: =EN11 -> 295701947 | EP11: 308121429 | EQ11: 308121429 | ER11: 308121429 | ES11: 308121429 | ET11: 308121429 | EU11: 308121429 | EV11: 308121429 | EW11: 308121429 | EX11: 308121429 | EY11: 308121429 | EZ11: 308121429 | FA11: 308121429 | FB11: =FA11 -> 308121429 | FC11: 195906100 | FD11: 195906100 | FE11: 195906100 | FF11: 195906100 | FG11: 195906100 | FH11: 195906100 | FI11: 195906100 | FO11: =FI11 -> 195906100
B12: Subdirección de APR | C12: 49407947 | D12: 49407947 | E12: 49407947 | F12: 49407947 | G12: 49407947 | H12: 49407947 | I12: 49407947 | J12: 49407947 | K12: 49407947 | L12: 49407947 | M12: 49407947 | N12: 49407947 | O12: =N12 -> 49407947 | P12: 68884752 | Q12: 68884752 | R12: 68884752 | S12: 68884752 | T12: 68884752 | U12: 68884752 | V12: 68884752 | W12: 68884752 | X12: 68884752 | Y12: 68884752 | Z12: 68884752 | AA12: 68884752 | AB12: =AA12 -> 68884752 | AC12: 71502372 | AD12: 71502372 | AE12: 71502372 | AF12: 71502372 | AG12: 71502372 | AH12: 71502372 | AI12: 71502372 | AJ12: 71502372 | AK12: 71502372 | AL12: 71502372 | AM12: 71502372 | AN12: 71502372 | AO12: =AN12 -> 71502372 | AP12: 89991483 | AQ12: 89991483 | AR12: 89991483 | AS12: 89991483 | AT12: 89991483 | AU12: 89991483 | AV12: 89991483 | AW12: 89991483 | AX12: 89991483 | AY12: 89991483 | AZ12: 89991483 | BA12: 89991483 | BB12: =BA12 -> 89991483 | BC12: 102433801 | BD12: 102433801 | BE12: 102433801 | BF12: 102433801 | BG12: 102433801 | BH12: 102433801 | BI12: 102433801 | BJ12: 102433801 | BK12: 102433801 | BL12: 102433801 | BM12: 102433801 | BN12: 102433801 | BO12: =BN12 -> 102433801 | BP12: 114691671 | BQ12: 114691671 | BR12: 114691671 | BS12: 114691671 | BT12: 114691671 | BU12: 114691671 | BV12: 114691671 | BW12: 114691671 | BX12: 114691671 | BY12: 114691671 | BZ12: 114691671 | CA12: 114691671 | CB12: =CA12 -> 114691671 | CC12: 135338654 | CD12: 135338654 | CE12: 135338654 | CF12: 135338654 | CG12: 135338654 | CH12: 135338654 | CI12: 135338654 | CJ12: 135338654 | CK12: 135338654 | CL12: 135338654 | CM12: 135338654 | CN12: 135338654 | CO12: =CN12 -> 135338654 | CP12: =142048072+104543895 -> 246591967 | CQ12: =142048072+104543895 -> 246591967 | CR12: =142048072+104543895 -> 246591967 | CS12: =142048072+104543895 -> 246591967 | CT12: =142048072+104543895 -> 246591967 | CU12: =142048072+104543895 -> 246591967 | CV12: =142048072+104543895 -> 246591967 | CW12: =142048072+104543895 -> 246591967 | ... DA12: =142048072+104543895 -> 246591967 | DB12: =DA12 -> 246591967 | DC12: =148440561+129907392 -> 278347953 | DD12: =148440561+129907392 -> 278347953 | DE12: =148440561+129907392 -> 278347953 | DF12: =148440561+129907392 -> 278347953 | DG12: =148440561+129907392 -> 278347953 | DH12: =148440561+129907392 -> 278347953 | DI12: =148440561+129907392 -> 278347953 | DJ12: =148440561+129907392 -> 278347953 | ... DN12: =148440561+129907392 -> 278347953 | DO12: =DN12 -> 278347953 | DP12: 295780655 | DQ12: 295780655 | DR12: 295780655 | DS12: 295780655 | DT12: 295780655 | DU12: 295780655 | DV12: 295780655 | DW12: 295780655 | DX12: 295780655 | DY12: 295780655 | DZ12: 295780655 | EA12: 295780655 | EB12: =EA12 -> 295780655 | EC12: 315696642 | ED12: 315696642 | EE12: 315696642 | EF12: 315696642 | EG12: 315696642 | EH12: 315696642 | EI12: 315696642 | EJ12: 315696642 | EK12: 315696642 | EL12: 315696642 | EM12: 315696642 | EN12: 315696642 | EO12: =EN12 -> 315696642 | EP12: 329603442 | EQ12: 329603442 | ER12: 329603442 | ES12: 329603442 | ET12: 329603442 | EU12: 329603442 | EV12: 329603442 | EW12: 329603442 | EX12: 329603442 | EY12: 329603442 | EZ12: 329603442 | FA12: 329603442 | FB12: =FA12 -> 329603442 | FC12: 290113797 | FD12: 290113797 | FE12: 290113797 | FF12: 290113797 | FG12: 290113797 | FH12: 290113797 | FI12: 290113797 | FO12: =FI12 -> 290113797
B13: Dirección de Obras Portuarias | C13: 55038550 | D13: 55038550 | E13: 55038550 | F13: 55038550 | G13: 55038550 | H13: 55038550 | I13: 55038550 | J13: 55038550 | K13: 55038550 | L13: 55038550 | M13: 55038550 | N13: 55038550 | O13: =N13 -> 55038550 | P13: 63737311 | Q13: 63737311 | R13: 63737311 | S13: 63737311 | T13: 63737311 | U13: 63737311 | V13: 63737311 | W13: 63737311 | X13: 63737311 | Y13: 63737311 | Z13: 63737311 | AA13: 63737311 | AB13: =AA13 -> 63737311 | AC13: 66005341 | AD13: 66005341 | AE13: 66005341 | AF13: 66005341 | AG13: 66005341 | AH13: 66005341 | AI13: 66005341 | AJ13: 66005341 | AK13: 66005341 | AL13: 66005341 | AM13: 66005341 | AN13: 66005341 | AO13: =AN13 -> 66005341 | AP13: 68152361 | AQ13: 68152361 | AR13: 68152361 | AS13: 68152361 | AT13: 68152361 | AU13: 68152361 | AV13: 68152361 | AW13: 68152361 | AX13: 68152361 | AY13: 68152361 | AZ13: 68152361 | BA13: 68152361 | BB13: =BA13 -> 68152361 | BC13: 69097793 | BD13: 69097793 | BE13: 69097793 | BF13: 69097793 | BG13: 69097793 | BH13: 69097793 | BI13: 69097793 | BJ13: 69097793 | BK13: 69097793 | BL13: 69097793 | BM13: 69097793 | BN13: 69097793 | BO13: =BN13 -> 69097793 | BP13: 69888575 | BQ13: 69888575 | BR13: 69888575 | BS13: 69888575 | BT13: 69888575 | BU13: 69888575 | BV13: 69888575 | BW13: 69888575 | BX13: 69888575 | BY13: 69888575 | BZ13: 69888575 | CA13: 69888575 | CB13: =CA13 -> 69888575 | CC13: 71705676 | CD13: 71705676 | CE13: 71705676 | CF13: 71705676 | CG13: 71705676 | CH13: 71705676 | CI13: 71705676 | CJ13: 71705676 | CK13: 71705676 | CL13: 71705676 | CM13: 71705676 | CN13: 71705676 | CO13: =CN13 -> 71705676 | CP13: =73670723+10507533 -> 84178256 | CQ13: =73670723+10507533 -> 84178256 | CR13: =73670723+10507533 -> 84178256 | CS13: =73670723+10507533 -> 84178256 | CT13: =73670723+10507533 -> 84178256 | CU13: =73670723+10507533 -> 84178256 | CV13: =73670723+10507533 -> 84178256 | CW13: =73670723+10507533 -> 84178256 | ... DA13: =73670723+10507533 -> 84178256 | DB13: =DA13 -> 84178256 | DC13: =76882481+23172423 -> 100054904 | DD13: =76882481+23172423 -> 100054904 | DE13: =76882481+23172423 -> 100054904 | DF13: =76882481+23172423 -> 100054904 | DG13: =76882481+23172423 -> 100054904 | DH13: =76882481+23172423 -> 100054904 | DI13: =76882481+23172423 -> 100054904 | DJ13: =76882481+23172423 -> 100054904 | ... DN13: =76882481+23172423 -> 100054904 | DO13: =DN13 -> 100054904 | DP13: 115171552 | DQ13: 115171552 | DR13: 115171552 | DS13: 115171552 | DT13: 115171552 | DU13: 115171552 | DV13: 115171552 | DW13: 115171552 | DX13: 115171552 | DY13: 115171552 | DZ13: 115171552 | EA13: 115171552 | EB13: =EA13 -> 115171552 | EC13: 127117895 | ED13: 127117895 | EE13: 127117895 | EF13: 127117895 | EG13: 127117895 | EH13: 127117895 | EI13: 127117895 | EJ13: 127117895 | EK13: 127117895 | EL13: 127117895 | EM13: 127117895 | EN13: 127117895 | EO13: =EN13 -> 127117895 | EP13: 125417585 | EQ13: 125417585 | ER13: 125417585 | ES13: 125417585 | ET13: 125417585 | EU13: 125417585 | EV13: 125417585 | EW13: 125417585 | EX13: 125417585 | EY13: 125417585 | EZ13: 125417585 | FA13: 125417585 | FB13: =FA13 -> 125417585 | FC13: 109909690 | FD13: 109909690 | FE13: 109909690 | FF13: 109909690 | FG13: 109909690 | FH13: 109909690 | FI13: 109909690 | FO13: =FI13 -> 109909690
B14: Dirección de Aeropuertos | C14: 41285665 | D14: 41285665 | E14: 41285665 | F14: 41285665 | G14: 41285665 | H14: 41285665 | I14: 41285665 | J14: 41285665 | K14: 41285665 | L14: 41285665 | M14: 41285665 | N14: 41285665 | O14: =N14 -> 41285665 | P14: 41009608 | Q14: 41009608 | R14: 41009608 | S14: 41009608 | T14: 41009608 | U14: 41009608 | V14: 41009608 | W14: 41009608 | X14: 41009608 | Y14: 41009608 | Z14: 41009608 | AA14: 41009608 | AB14: =AA14 -> 41009608 | AC14: 43953347 | AD14: 43953347 | AE14: 43953347 | AF14: 43953347 | AG14: 43953347 | AH14: 43953347 | AI14: 43953347 | AJ14: 43953347 | AK14: 43953347 | AL14: 43953347 | AM14: 43953347 | AN14: 43953347 | AO14: =AN14 -> 43953347 | AP14: 45271947 | AQ14: 45271947 | AR14: 45271947 | AS14: 45271947 | AT14: 45271947 | AU14: 45271947 | AV14: 45271947 | AW14: 45271947 | AX14: 45271947 | AY14: 45271947 | AZ14: 45271947 | BA14: 45271947 | BB14: =BA14 -> 45271947 | BC14: 35602336 | BD14: 35602336 | BE14: 35602336 | BF14: 35602336 | BG14: 35602336 | BH14: 35602336 | BI14: 35602336 | BJ14: 35602336 | BK14: 35602336 | BL14: 35602336 | BM14: 35602336 | BN14: 35602336 | BO14: =BN14 -> 35602336 | BP14: 53068499 | BQ14: 53068499 | BR14: 53068499 | BS14: 53068499 | BT14: 53068499 | BU14: 53068499 | BV14: 53068499 | BW14: 53068499 | BX14: 53068499 | BY14: 53068499 | BZ14: 53068499 | CA14: 53068499 | CB14: =CA14 -> 53068499 | CC14: 58584599 | CD14: 58584599 | CE14: 58584599 | CF14: 58584599 | CG14: 58584599 | CH14: 58584599 | CI14: 58584599 | CJ14: 58584599 | CK14: 58584599 | CL14: 58584599 | CM14: 58584599 | CN14: 58584599 | CO14: =CN14 -> 58584599 | CP14: =60144148+46830346 -> 106974494 | CQ14: =60144148+46830346 -> 106974494 | CR14: =60144148+46830346 -> 106974494 | CS14: =60144148+46830346 -> 106974494 | CT14: =60144148+46830346 -> 106974494 | CU14: =60144148+46830346 -> 106974494 | CV14: =60144148+46830346 -> 106974494 | CW14: =60144148+46830346 -> 106974494 | ... DA14: =60144148+46830346 -> 106974494 | DB14: =DA14 -> 106974494 | DC14: =62797413+55033938 -> 117831351 | DD14: =62797413+55033938 -> 117831351 | DE14: =62797413+55033938 -> 117831351 | DF14: =62797413+55033938 -> 117831351 | DG14: =62797413+55033938 -> 117831351 | DH14: =62797413+55033938 -> 117831351 | DI14: =62797413+55033938 -> 117831351 | DJ14: =62797413+55033938 -> 117831351 | ... DN14: =62797413+55033938 -> 117831351 | DO14: =DN14 -> 117831351 | DP14: 135318267 | DQ14: 135318267 | DR14: 135318267 | DS14: 135318267 | DT14: 135318267 | DU14: 135318267 | DV14: 135318267 | DW14: 135318267 | DX14: 135318267 | DY14: 135318267 | DZ14: 135318267 | EA14: 135318267 | EB14: =EA14 -> 135318267 | EC14: 137741639 | ED14: 137741639 | EE14: 137741639 | EF14: 137741639 | EG14: 137741639 | EH14: 137741639 | EI14: 137741639 | EJ14: 137741639 | EK14: 137741639 | EL14: 137741639 | EM14: 137741639 | EN14: 137741639 | EO14: =EN14 -> 137741639 | EP14: 141825431 | EQ14: 141825431 | ER14: 141825431 | ES14: 141825431 | ET14: 141825431 | EU14: 141825431 | EV14: 141825431 | EW14: 141825431 | EX14: 141825431 | EY14: 141825431 | EZ14: 141825431 | FA14: 141825431 | FB14: =FA14 -> 141825431 | FC14: 127610750 | FD14: 127610750 | FE14: 127610750 | FF14: 127610750 | FG14: 127610750 | FH14: 127610750 | FI14: 127610750 | FO14: =FI14 -> 127610750
B15: Dirección de Arquitectura | C15: 26272563 | D15: 26272563 | E15: 26272563 | F15: 26272563 | G15: 26272563 | H15: 26272563 | I15: 26272563 | J15: 26272563 | K15: 26272563 | L15: 26272563 | M15: 26272563 | N15: 26272563 | O15: =N15 -> 26272563 | P15: 28203580 | Q15: 28203580 | R15: 28203580 | S15: 28203580 | T15: 28203580 | U15: 28203580 | V15: 28203580 | W15: 28203580 | X15: 28203580 | Y15: 28203580 | Z15: 28203580 | AA15: 28203580 | AB15: =AA15 -> 28203580 | AC15: 25719874 | AD15: 25719874 | AE15: 25719874 | AF15: 25719874 | AG15: 25719874 | AH15: 25719874 | AI15: 25719874 | AJ15: 25719874 | AK15: 25719874 | AL15: 25719874 | AM15: 25719874 | AN15: 25719874 | AO15: =AN15 -> 25719874 | AP15: 28283754 | AQ15: 28283754 | AR15: 28283754 | AS15: 28283754 | AT15: 28283754 | AU15: 28283754 | AV15: 28283754 | AW15: 28283754 | AX15: 28283754 | AY15: 28283754 | AZ15: 28283754 | BA15: 28283754 | BB15: =BA15 -> 28283754 | BC15: 30504194 | BD15: 30504194 | BE15: 30504194 | BF15: 30504194 | BG15: 30504194 | BH15: 30504194 | BI15: 30504194 | BJ15: 30504194 | BK15: 30504194 | BL15: 30504194 | BM15: 30504194 | BN15: 30504194 | BO15: =BN15 -> 30504194 | BP15: 25853361 | BQ15: 25853361 | BR15: 25853361 | BS15: 25853361 | BT15: 25853361 | BU15: 25853361 | BV15: 25853361 | BW15: 25853361 | BX15: 25853361 | BY15: 25853361 | BZ15: 25853361 | CA15: 25853361 | CB15: =CA15 -> 25853361 | CC15: 22096777 | CD15: 22096777 | CE15: 22096777 | CF15: 22096777 | CG15: 22096777 | CH15: 22096777 | CI15: 22096777 | CJ15: 22096777 | CK15: 22096777 | CL15: 22096777 | CM15: 22096777 | CN15: 22096777 | CO15: =CN15 -> 22096777 | CP15: =11904427+25061381 -> 36965808 | CQ15: =11904427+25061381 -> 36965808 | CR15: =11904427+25061381 -> 36965808 | CS15: =11904427+25061381 -> 36965808 | CT15: =11904427+25061381 -> 36965808 | CU15: =11904427+25061381 -> 36965808 | CV15: =11904427+25061381 -> 36965808 | CW15: =11904427+25061381 -> 36965808 | ... DA15: =11904427+25061381 -> 36965808 | DB15: =DA15 -> 36965808 | DC15: =8974172+32064677 -> 41038849 | DD15: =8974172+32064677 -> 41038849 | DE15: =8974172+32064677 -> 41038849 | DF15: =8974172+32064677 -> 41038849 | DG15: =8974172+32064677 -> 41038849 | DH15: =8974172+32064677 -> 41038849 | DI15: =8974172+32064677 -> 41038849 | DJ15: =8974172+32064677 -> 41038849 | ... DN15: =8974172+32064677 -> 41038849 | DO15: =DN15 -> 41038849 | DP15: 37590026 | DQ15: 37590026 | DR15: 37590026 | DS15: 37590026 | DT15: 37590026 | DU15: 37590026 | DV15: 37590026 | DW15: 37590026 | DX15: 37590026 | DY15: 37590026 | DZ15: 37590026 | EA15: 37590026 | EB15: =EA15 -> 37590026 | EC15: 44570138 | ED15: 44570138 | EE15: 44570138 | EF15: 44570138 | EG15: 44570138 | EH15: 44570138 | EI15: 44570138 | EJ15: 44570138 | EK15: 44570138 | EL15: 44570138 | EM15: 44570138 | EN15: 44570138 | EO15: =EN15 -> 44570138 | EP15: 57109595 | EQ15: 57109595 | ER15: 57109595 | ES15: 57109595 | ET15: 57109595 | EU15: 57109595 | EV15: 57109595 | EW15: 57109595 | EX15: 57109595 | EY15: 57109595 | EZ15: 57109595 | FA15: 57109595 | FB15: =FA15 -> 57109595 | FC15: 30479549 | FD15: 30479549 | FE15: 30479549 | FF15: 30479549 | FG15: 30479549 | FH15: 30479549 | FI15: 30479549 | FO15: =FI15 -> 30479549
B16: Total | C16: =SUM(C10:C15) -> 1080148659 | D16: =SUM(D10:D15) -> 1080148659 | E16: =SUM(E10:E15) -> 1080148659 | F16: =SUM(F10:F15) -> 1080148659 | G16: =SUM(G10:G15) -> 1080148659 | H16: =SUM(H10:H15) -> 1080148659 | I16: =SUM(I10:I15) -> 1080148659 | J16: =SUM(J10:J15) -> 1080148659 | ... FO16: =SUM(FO10:FO15) -> 2705505486
B17: (1) Los años 2021 y 2022 incluyen el Presupuesto Ley del Subtítulo 30, Ítem 10. Fuente: elaboración propia, Dipres.
B19: Presupuesto Vigente de Inversión en Infraestructura Pública del Ministerio de Obras Públicas, 2014-2026 (Subtítulo 31 – Iniciativas de Inversión, miles de pesos)
C20: 2014 | P20: 2015 | AC20: 2016 | AP20: 2017 | BC20: 2018 | BP20: 2019 | CC20: 2020 | CP20: 2021(1) | DC20: 2022(1) | DP20: 2023 | EC20: 2024 | EP20: 2025 | FC20: 2026
B21: Programa | C21: Ene | D21: Feb | E21: Mar | F21: Abr | G21: May | H21: Jun | I21: Jul | J21: Ago | K21: Sep | L21: Oct | M21: Nov | N21: Dic | O21: Total 2014 | P21: Ene | Q21: Feb | R21: Mar | S21: Abr | T21: May | U21: Jun | V21: Jul | W21: Ago | X21: Sep | Y21: Oct | Z21: Nov | AA21: Dic | AB21: Total 2015 | AC21: Ene | AD21: Feb | AE21: Mar | AF21: Abr | AG21: May | AH21: Jun | AI21: Jul | AJ21: Ago | AK21: Sep | AL21: Oct | AM21: Nov | AN21: Dic | AO21: Total 2016 | AP21: Ene | AQ21: Feb | AR21: Mar | AS21: Abr | AT21: May | AU21: Jun | AV21: Jul | AW21: Ago | AX21: Sep | AY21: Oct | AZ21: Nov | BA21: Dic | BB21: Total 2017 | BC21: Ene | BD21: Feb | BE21: Mar | BF21: Abr | BG21: May | BH21: Jun | BI21: Jul | BJ21: Ago | BK21: Sep | BL21: Oct | BM21: Nov | BN21: Dic | BO21: Total 2018 | BP21: Ene | BQ21: Feb | BR21: Mar | BS21: Abr | BT21: May | BU21: Jun | BV21: Jul | BW21: Ago | BX21: Sep | BY21: Oct | BZ21: Nov | CA21: Dic | CB21: Total 2019 | CC21: Ene | CD21: Feb | CE21: Mar | CF21: Abr | CG21: May | CH21: Jun | CI21: Jul | CJ21: Ago | CK21: Sep | CL21: Oct | CM21: Nov | CN21: Dic | CO21: Total 2020 | CP21: Ene | CQ21: Feb | CR21: Mar | CS21: Abr | CT21: May | CU21: Jun | CV21: Jul | CW21: Ago | CX21: Sep | CY21: Oct | CZ21: Nov | DA21: Dic | DB21: Total 2021 | DC21: Ene | DD21: Feb | DE21: Mar | DF21: Abr | DG21: May | DH21: Jun | DI21: Jul | DJ21: Ago | DK21: Sep | DL21: Oct | DM21: Nov | DN21: Dic | DO21: Total 2022 | DP21: Ene | DQ21: Feb | DR21: Mar | DS21: Abr | DT21: May | DU21: Jun | DV21: Jul | DW21: Ago | DX21: Sep | DY21: Oct | DZ21: Nov | EA21: Dic | EB21: Total 2023 | EC21: Ene | ED21: Feb | EE21: Mar | EF21: Abr | EG21: May | EH21: Jun | EI21: Jul | EJ21: Ago | EK21: Sep | EL21: Oct | EM21: Nov | EN21: Dic | EO21: Total 2024 | EP21: Ene | EQ21: Feb | ER21: Mar | ES21: Abr | ET21: May | EU21: Jun | EV21: Jul | EW21: Ago | EX21: Sep | EY21: Oct | EZ21: Nov | FA21: Dic | FB21: Total 2025 | FC21: Ene | FD21: Feb | FE21: Mar | FF21: Abr | FG21: May | FH21: Jun | FI21: Jul | FJ21: Ago | FK21: Sep | FL21: Oct | FM21: Nov | FN21: Dic | FO21: Total 2026
B22: Dirección de Vialidad | C22: 806907228 | D22: 806907228 | E22: 797207228 | F22: 797207228 | G22: 799193228 | H22: 801043262 | I22: 797883262 | J22: 817043262 | K22: 818043262 | L22: 842704970 | M22: 843143806 | N22: 853032416 | O22: =N22 -> 853032416 | P22: 957407656 | Q22: 958801347 | R22: 952446725 | S22: 944486725 | T22: 948962726 | U22: 949105726 | V22: 949005726 | W22: 949071698 | X22: 949071698 | Y22: 949071698 | Z22: 978416698 | AA22: 978378698 | AB22: =AA22 -> 978378698 | AC22: 937156766 | AD22: 930976766 | AE22: 939666557 | AF22: 937705385 | AG22: 937705385 | AH22: 937166385 | AI22: 937166385 | AJ22: 937166385 | AK22: 937166385 | AL22: 937166385 | AM22: 937073385 | AN22: 940884842 | AO22: =AN22 -> 940884842 | AP22: 982538421 | AQ22: 982538421 | AR22: 982260421 | AS22: 982260421 | AT22: 982060421 | AU22: 963745421 | AV22: 963304221 | AW22: 951169721 | AX22: 951169721 | AY22: 934145882 | AZ22: 931388882 | BA22: 909483945 | BB22: =BA22 -> 909483945 | BC22: 998447263 | BD22: 998447263 | BE22: 992502179 | BF22: 997730439 | BG22: 997415248 | BH22: 989715248 | BI22: 987815248 | BJ22: 987280248 | BK22: 987280248 | BL22: 987265248 | BM22: 986833548 | BN22: 903724337 | BO22: =BN22 -> 903724337 | BP22: 1056398949 | BQ22: 1056398949 | BR22: 1056398949 | BS22: 1061857019 | BT22: 1066368519 | BU22: 1061536519 | BV22: 1061502269 | BW22: 1074213648 | BX22: 1085679831 | BY22: 1085679831 | BZ22: 1085679831 | CA22: 1085267877 | CB22: =CA22 -> 1085267877 | CC22: 1148358839 | CD22: 1151054581 | CE22: 1248782581 | CF22: 1248782581 | CG22: 1216917979 | CH22: 1216917979 | CI22: 1216383979 | CJ22: 1216383979 | CK22: 1216383979 | CL22: 1197726086 | CM22: 1197588086 | CN22: 961564167 | CO22: =CN22 -> 961564167 | CP22: 1224421462 | CQ22: 1224421462 | CR22: 1139453884 | CS22: 1067186833 | CT22: 1048239333 | CU22: 1048217333 | CV22: 1048217333 | CW22: 1048116163 | CX22: 1048116163 | CY22: 1035718353 | CZ22: 1035625353 | DA22: =991797481+130932798 -> 1122730279 | DB22: =DA22 -> 1122730279 | DC22: 1220635546 | DD22: 1220635546 | DE22: 1220279119 | DF22: 1220279119 | DG22: 1218682119 | DH22: 1218249119 | DI22: 1092879968 | DJ22: 1092879968 | DK22: 1082339533 | DL22: 1082339533 | DM22: 1081913803 | DN22: 967670999 | DO22: =DN22 -> 967670999 | DP22: 1913855137 | DQ22: 1913855137 | DR22: 1913855137 | DS22: 1893896951 | DT22: 1850161211 | DU22: 1774161211 | DV22: 1774161211 | DW22: 1623406641 | DX22: 1620225968 | DY22: 1542961468 | DZ22: 1542961468 | EA22: 1427470479 | EB22: =EA22 -> 1427470479 | EC22: 2012684680 | ED22: 2012684680 | EE22: 1959842560 | EF22: 1959842560 | EG22: 1959505267 | EH22: 1939427267 | EI22: 1939427267 | EJ22: 1938757501 | EK22: 1937457501 | EL22: 1929646738 | EM22: 1891922336 | EN22: 1608652526 | EO22: =EN22 -> 1608652526 | EP22: 2083103023 | EQ22: 2083103023 | ER22: 2068572694 | ES22: 2068438694 | ET22: 2067139640 | EU22: 1962984489 | EV22: 1968056577 | EW22: 1968056577 | EX22: 1968056577 | EY22: 1968056577 | EZ22: 1968056577 | FA22: 1976677470 | FB22: =FA22 -> 1976677470 | FC22: 1951485600 | FD22: 1951485600 | FE22: 1905464563 | FF22: 1905464563 | FG22: 1817932962 | FH22: 1801311962 | FI22: 1801311962 | FO22: =FI22 -> 1801311962
B23: Dirección de Obras Hidráulicas | C23: 101236706 | D23: 101236706 | E23: 101236706 | F23: 101236706 | G23: 101236706 | H23: 101236706 | I23: 101236706 | J23: 101236706 | K23: 101236706 | L23: 104448787 | M23: 104448787 | N23: 105052138 | O23: =N23 -> 105052138 | P23: 117398169 | Q23: 117398169 | R23: 117398169 | S23: 117398169 | T23: 117398169 | U23: 119398169 | V23: 119398169 | W23: 119398169 | X23: 119398169 | Y23: 126602707 | Z23: 126602707 | AA23: 127586435 | AB23: =AA23 -> 127586435 | AC23: 127292924 | AD23: 127292924 | AE23: 127292924 | AF23: 127292924 | AG23: 127292924 | AH23: 127292924 | AI23: 127292924 | AJ23: 127292924 | AK23: 127292924 | AL23: 127292924 | AM23: 127292924 | AN23: 125791938 | AO23: =AN23 -> 125791938 | AP23: 121635713 | AQ23: 121635713 | AR23: 121635713 | AS23: 121635713 | AT23: 121635713 | AU23: 129989213 | AV23: 129989213 | AW23: 141642213 | AX23: 141642213 | AY23: 147144690 | AZ23: 147144690 | BA23: 146472297 | BB23: =BA23 -> 146472297 | BC23: 119785354 | BD23: 119785354 | BE23: 119835354 | BF23: 119835354 | BG23: 119835354 | BH23: 119835354 | BI23: 119601854 | BJ23: 119601854 | BK23: 121911854 | BL23: 125699985 | BM23: 125699985 | BN23: 120161746 | BO23: =BN23 -> 120161746 | BP23: 129182602 | BQ23: 129182602 | BR23: 129182602 | BS23: 129182602 | BT23: 129182602 | BU23: 129182602 | BV23: 129182602 | BW23: 131234832 | BX23: 140899926 | BY23: 140899926 | BZ23: 140899926 | CA23: 138342165 | CB23: =CA23 -> 138342165 | CC23: 137671350 | CD23: 137671350 | CE23: 152971350 | CF23: 152971350 | CG23: 143861214 | CH23: 143861214 | CI23: 143861214 | CJ23: 143861214 | CK23: 143861214 | CL23: 143861214 | CM23: 143861214 | CN23: 141821958 | CO23: =CN23 -> 141821958 | CP23: 140801596 | CQ23: 140801596 | CR23: 140801596 | CS23: 140801596 | CT23: 133918279 | CU23: 133918279 | CV23: 133918279 | CW23: 133918279 | CX23: 133918279 | CY23: 133918279 | CZ23: 133918279 | DA23: =131504761+8520124 -> 140024885 | DB23: =DA23 -> 140024885 | DC23: 147022684 | DD23: 147022684 | DE23: 147022684 | DF23: 147022684 | DG23: 147022684 | DH23: 147022684 | DI23: 147022684 | DJ23: 146848818 | DK23: 144824178 | DL23: 130697780 | DM23: 130518293 | DN23: 129672445 | DO23: =DN23 -> 129672445 | DP23: 293591805 | DQ23: 293591805 | DR23: 293591805 | DS23: 293591805 | DT23: 293591805 | DU23: 255048822 | DV23: 219099761 | DW23: 212099761 | DX23: 212099761 | DY23: 212099761 | DZ23: 212099761 | EA23: 198709088 | EB23: =EA23 -> 198709088 | EC23: 295701947 | ED23: 295701947 | EE23: 278607232 | EF23: 278607232 | EG23: 278543079 | EH23: 278543079 | EI23: 278543079 | EJ23: 282942267 | EK23: 282942267 | EL23: 282942267 | EM23: 282942267 | EN23: 244313644 | EO23: =EN23 -> 244313644 | EP23: 308121429 | EQ23: 308121429 | ER23: 308121429 | ES23: 308121429 | ET23: 308121429 | EU23: 288121429 | EV23: 288121429 | EW23: 288121429 | EX23: 288121429 | EY23: 284126983 | EZ23: 284126983 | FA23: 255720965 | FB23: =FA23 -> 255720965 | FC23: 195906100 | FD23: 195906100 | FE23: 192119100 | FF23: 192119100 | FG23: 186241917 | FH23: 202307917 | FI23: 202307917 | FO23: =FI23 -> 202307917
B24: Subdirección de APR | C24: 49407947 | D24: 49407947 | E24: 49407947 | F24: 49407947 | G24: 49407947 | H24: 55507947 | I24: 55507947 | J24: 60507947 | K24: 60507947 | L24: 65278980 | M24: 65278980 | N24: 67579947 | O24: =N24 -> 67579947 | P24: 68884752 | Q24: 68884752 | R24: 68884752 | S24: 68884752 | T24: 68884752 | U24: 85940845 | V24: 85940845 | W24: 87740845 | X24: 87740845 | Y24: 88355845 | Z24: 93717760 | AA24: 93689760 | AB24: =AA24 -> 93689760 | AC24: 71502372 | AD24: 71502372 | AE24: 71502372 | AF24: 71502372 | AG24: 71502372 | AH24: 71502372 | AI24: 71502372 | AJ24: 75002372 | AK24: 75002372 | AL24: 75002372 | AM24: 79147193 | AN24: 80579039 | AO24: =AN24 -> 80579039 | AP24: 89991483 | AQ24: 89991483 | AR24: 89991483 | AS24: 89991483 | AT24: 89991483 | AU24: 92696068 | AV24: 92696068 | AW24: 92696068 | AX24: 92696068 | AY24: 98217166 | AZ24: 98217166 | BA24: 100477231 | BB24: =BA24 -> 100477231 | BC24: 102433801 | BD24: 102433801 | BE24: 102433801 | BF24: 102433801 | BG24: 102433801 | BH24: 102433801 | BI24: 102433801 | BJ24: 102433801 | BK24: 102433801 | BL24: 106891813 | BM24: 106891813 | BN24: 102680557 | BO24: =BN24 -> 102680557 | BP24: 114691671 | BQ24: 114691671 | BR24: 114691671 | BS24: 114691671 | BT24: 114691671 | BU24: 114691671 | BV24: 114691671 | BW24: 123071862 | BX24: 118010898 | BY24: 118010898 | BZ24: 118010898 | CA24: 112674850 | CB24: =CA24 -> 112674850 | CC24: 135338654 | CD24: 135338654 | CE24: 135338654 | CF24: 158338654 | CG24: 155319586 | CH24: 155319586 | CI24: 155319586 | CJ24: 155319586 | CK24: 155319586 | CL24: 155319586 | CM24: 155319586 | CN24: 148506367 | CO24: =CN24 -> 148506367 | CP24: 142048072 | CQ24: 142048072 | CR24: 142048072 | CS24: 142048072 | CT24: 160995572 | CU24: 160995572 | CV24: 160995572 | CW24: 160995572 | CX24: 160995572 | CY24: 160995572 | CZ24: 160995572 | DA24: =142300803+21041416 -> 163342219 | DB24: =DA24 -> 163342219 | DC24: 148440561 | DD24: 148440561 | DE24: 148440561 | DF24: 148440561 | DG24: 148440561 | DH24: 148440561 | DI24: 148440561 | DJ24: 148440561 | DK24: 148440561 | DL24: 141404870 | DM24: 141404870 | DN24: 110932143 | DO24: =DN24 -> 110932143 | DP24: 295780655 | DQ24: 295780655 | DR24: 295780655 | DS24: 295780655 | DT24: 295780655 | DU24: 275780655 | DV24: 309887671 | DW24: 309887671 | DX24: 309887671 | DY24: 299857312 | DZ24: 265750296 | EA24: 249472319 | EB24: =EA24 -> 249472319 | EC24: 315696642 | ED24: 315696642 | EE24: 315696642 | EF24: 232705862 | EG24: 232705862 | EH24: 232705862 | EI24: 232705862 | EJ24: 227906674 | EK24: 227906674 | EL24: 227906674 | EM24: 227906674 | EN24: 192186387 | EO24: =EN24 -> 192186387 | EP24: 329603442 | EQ24: 329603442 | ER24: 307603442 | ES24: 307603442 | ET24: 307603442 | EU24: 284751010 | EV24: 284751010 | EW24: 284751010 | EX24: 284751010 | EY24: 273184204 | EZ24: 273184204 | FA24: 234336066 | FB24: =FA24 -> 234336066 | FC24: 290113797 | FD24: 290113797 | FE24: 282113797 | FF24: 282113797 | FG24: 273410383 | FH24: 273410383 | FI24: 273410383 | FO24: =FI24 -> 273410383
B25: Dirección de Obras Portuarias | C25: 55038550 | D25: 55038550 | E25: 55038550 | F25: 55038550 | G25: 55038550 | H25: 55038550 | I25: 56087343 | J25: 56087343 | K25: 56087343 | L25: 56087343 | M25: 56087343 | N25: 55967642 | O25: =N25 -> 55967642 | P25: 63737311 | Q25: 63737311 | R25: 63737311 | S25: 63737311 | T25: 63737311 | U25: 63737311 | V25: 63737311 | W25: 63737311 | X25: 63737311 | Y25: 60537311 | Z25: 66537311 | AA25: 66227311 | AB25: =AA25 -> 66227311 | AC25: 66005341 | AD25: 66005341 | AE25: 66005341 | AF25: 66005341 | AG25: 66005341 | AH25: 66005341 | AI25: 66005341 | AJ25: 66005341 | AK25: 66005341 | AL25: 66005341 | AM25: 66005341 | AN25: 66601585 | AO25: =AN25 -> 66601585 | AP25: 68152361 | AQ25: 68152361 | AR25: 68152361 | AS25: 68152361 | AT25: 68152361 | AU25: 68152361 | AV25: 68152361 | AW25: 68152361 | AX25: 68152361 | AY25: 68292361 | AZ25: 70792361 | BA25: 72233361 | BB25: =BA25 -> 72233361 | BC25: 69097793 | BD25: 69097793 | BE25: 69097793 | BF25: 69097793 | BG25: 69097793 | BH25: 69097793 | BI25: 68963100 | BJ25: 68963100 | BK25: 66653100 | BL25: 64364969 | BM25: 64332418 | BN25: 60805995 | BO25: =BN25 -> 60805995 | BP25: 69888575 | BQ25: 69888575 | BR25: 69888575 | BS25: 69888575 | BT25: 69888575 | BU25: 69888575 | BV25: 69888575 | BW25: 69888575 | BX25: 68888575 | BY25: 68888575 | BZ25: 68888575 | CA25: 62099040 | CB25: =CA25 -> 62099040 | CC25: 71705676 | CD25: 71705676 | CE25: 80110666 | CF25: 80110666 | CG25: 79796573 | CH25: 79796573 | CI25: 74160268 | CJ25: 74160268 | CK25: 74160268 | CL25: 74160268 | CM25: 73045737 | CN25: 71705970 | CO25: =CN25 -> 71705970 | CP25: 73670723 | CQ25: 73670723 | CR25: 73670723 | CS25: 73670723 | CT25: 73670723 | CU25: 73670723 | CV25: 73670723 | CW25: 73670723 | CX25: 73670723 | CY25: 73670723 | CZ25: 73670723 | DA25: =73116242+62000 -> 73178242 | DB25: =DA25 -> 73178242 | DC25: 76882481 | DD25: 76882481 | DE25: 76882481 | DF25: 76882481 | DG25: 76882481 | DH25: 76882481 | DI25: 76882481 | DJ25: 76882481 | DK25: 76882481 | DL25: 76882481 | DM25: 76882481 | DN25: 64614673 | DO25: =DN25 -> 64614673 | DP25: 115171552 | DQ25: 115171552 | DR25: 115171552 | DS25: 115171552 | DT25: 115171552 | DU25: 115171552 | DV25: 115171552 | DW25: 115171552 | DX25: 115171552 | DY25: 108472329 | DZ25: 108472329 | EA25: 104861138 | EB25: =EA25 -> 104861138 | EC25: 127117895 | ED25: 127117895 | EE25: 127117895 | EF25: 127117895 | EG25: 127117895 | EH25: 127117895 | EI25: 127117895 | EJ25: 127117895 | EK25: 127117895 | EL25: 127117895 | EM25: 127117895 | EN25: 123682417 | EO25: =EN25 -> 123682417 | EP25: 125417585 | EQ25: 125417585 | ER25: 139947914 | ES25: 139947914 | ET25: 139947914 | EU25: 139947914 | EV25: 145917564 | EW25: 145917564 | EX25: 145917564 | EY25: 151478816 | EZ25: 151478816 | FA25: 143006856 | FB25: =FA25 -> 143006856 | FC25: 109909690 | FD25: 109909690 | FE25: 109909690 | FF25: 109909690 | FG25: 106612399 | FH25: 106612399 | FI25: 106612399 | FO25: =FI25 -> 106612399
B26: Dirección de Aeropuertos | C26: 41285665 | D26: 41285665 | E26: 41285665 | F26: 41285665 | G26: 41769665 | H26: 41769665 | I26: 41769665 | J26: 43790807 | K26: 43790807 | L26: 44708207 | M26: 44708207 | N26: 45507263 | O26: =N26 -> 45507263 | P26: 41009608 | Q26: 41009608 | R26: 41009608 | S26: 41009608 | T26: 41009608 | U26: 41009608 | V26: 41009608 | W26: 39209608 | X26: 39209608 | Y26: 39209608 | Z26: 38038808 | AA26: 34834080 | AB26: =AA26 -> 34834080 | AC26: 43953347 | AD26: 43953347 | AE26: 43953347 | AF26: 43633347 | AG26: 43633347 | AH26: 43633347 | AI26: 43633347 | AJ26: 43633347 | AK26: 43633347 | AL26: 43171347 | AM26: 43171347 | AN26: 43860342 | AO26: =AN26 -> 43860342 | AP26: 45271947 | AQ26: 45271947 | AR26: 45271947 | AS26: 45271947 | AT26: 45271947 | AU26: 45271947 | AV26: 45271947 | AW26: 45271947 | AX26: 45271947 | AY26: 46889947 | AZ26: 46889947 | BA26: 49070760 | BB26: =BA26 -> 49070760 | BC26: 35602336 | BD26: 35602336 | BE26: 35602336 | BF26: 35602336 | BG26: 35602336 | BH26: 43302336 | BI26: 43302336 | BJ26: 43802336 | BK26: 43802336 | BL26: 43802336 | BM26: 43802336 | BN26: 34299269 | BO26: =BN26 -> 34299269 | BP26: 53068499 | BQ26: 53068499 | BR26: 53068499 | BS26: 53068499 | BT26: 53068499 | BU26: 53068499 | BV26: 53068499 | BW26: 55300713 | BX26: 55300713 | BY26: 55300713 | BZ26: 55300713 | CA26: 54338642 | CB26: =CA26 -> 54338642 | CC26: 58584599 | CD26: 58584599 | CE26: 58584599 | CF26: 66247946 | CG26: 66247946 | CH26: 66247946 | CI26: 66147946 | CJ26: 64991732 | CK26: 64991732 | CL26: 64570095 | CM26: 64570095 | CN26: 58584599 | CO26: =CN26 -> 58584599 | CP26: 60144148 | CQ26: 60144148 | CR26: 60144148 | CS26: 60144148 | CT26: 60144148 | CU26: 60144148 | CV26: 60144148 | CW26: 60144148 | CX26: 60144148 | CY26: 60144148 | CZ26: 60144148 | DA26: =57087148+74000 -> 57161148 | DB26: =DA26 -> 57161148 | DC26: 62797413 | DD26: 62797413 | DE26: 62797413 | DF26: 62797413 | DG26: 62712374 | DH26: 62712374 | DI26: 62487413 | DJ26: 62487413 | DK26: 62487413 | DL26: 62487413 | DM26: 62487413 | DN26: 66143610 | DO26: =DN26 -> 66143610 | DP26: 135318267 | DQ26: 135318267 | DR26: 135318267 | DS26: 135318267 | DT26: 135318267 | DU26: 135318267 | DV26: 135318267 | DW26: 135318267 | DX26: 135318267 | DY26: 131318267 | DZ26: 131318267 | EA26: 123846968 | EB26: =EA26 -> 123846968 | EC26: 137741639 | ED26: 137741639 | EE26: 137741639 | EF26: 135914151 | EG26: 135885801 | EH26: 135885801 | EI26: 135885801 | EJ26: 135885801 | EK26: 135885801 | EL26: 137734161 | EM26: 137734161 | EN26: 121300022 | EO26: =EN26 -> 121300022 | EP26: 141825431 | EQ26: 141825431 | ER26: 141825431 | ES26: 141825431 | ET26: 141825431 | EU26: 141825431 | EV26: 141825431 | EW26: 141825431 | EX26: 141825431 | EY26: 141825431 | EZ26: 141825431 | FA26: 143001334 | FB26: =FA26 -> 143001334 | FC26: 127610750 | FD26: 127610750 | FE26: 127610750 | FF26: 127610750 | FG26: 124345173 | FH26: 124345173 | FI26: 124345173 | FO26: =FI26 -> 124345173
B27: Dirección de Arquitectura | C27: 26272563 | D27: 26272563 | E27: 26955763 | F27: 26955763 | G27: 26955763 | H27: 26955763 | I27: 26955763 | J27: 27252763 | K27: 27252763 | L27: 27252763 | M27: 27558870 | N27: 25516525 | O27: =N27 -> 25516525 | P27: 28203580 | Q27: 28203580 | R27: 28176903 | S27: 28176903 | T27: 28176903 | U27: 22493729 | V27: 22493729 | W27: 22477989 | X27: 22277989 | Y27: 17658451 | Z27: 14124507 | AA27: 12055801 | AB27: =AA27 -> 12055801 | AC27: 25719874 | AD27: 25719874 | AE27: 25719874 | AF27: 25719874 | AG27: 25719874 | AH27: 25684874 | AI27: 25684874 | AJ27: 22184874 | AK27: 19898360 | AL27: 19898360 | AM27: 19898360 | AN27: 16279503 | AO27: =AN27 -> 16279503 | AP27: 28283754 | AQ27: 28283754 | AR27: 28283754 | AS27: 28283754 | AT27: 28283754 | AU27: 28260646 | AV27: 28337248 | AW27: 28337248 | AX27: 28337248 | AY27: 31399972 | AZ27: 31399972 | BA27: 21498175 | BB27: =BA27 -> 21498175 | BC27: 30504194 | BD27: 30504194 | BE27: 30504194 | BF27: 30504194 | BG27: 30445086 | BH27: 30445086 | BI27: 30385624 | BJ27: 30385624 | BK27: 30385624 | BL27: 24302238 | BM27: 24302238 | BN27: 20961721 | BO27: =BN27 -> 20961721 | BP27: 25853361 | BQ27: 25853361 | BR27: 25853361 | BS27: 25853361 | BT27: 25853361 | BU27: 25853361 | BV27: 25853361 | BW27: 21612552 | BX27: 17506566 | BY27: 17506566 | BZ27: 17506566 | CA27: 15189077 | CB27: =CA27 -> 15189077 | CC27: 22096777 | CD27: 22096777 | CE27: 22096777 | CF27: 22096777 | CG27: 8619318 | CH27: 8619318 | CI27: 8619318 | CJ27: 8619318 | CK27: 8619318 | CL27: 8619318 | CM27: 5194154 | CN27: 5194154 | CO27: =CN27 -> 5194154 | CP27: 15515216 | CQ27: 17211034 | CR27: 17211034 | CS27: 17211034 | CT27: 17211034 | CU27: 15949460 | CV27: 15949460 | CW27: 15949460 | CX27: 15514843 | CY27: 15514843 | CZ27: 15514843 | DA27: =7205919+7501242 -> 14707161 | DB27: =DA27 -> 14707161 | DC27: 31608353 | DD27: 31608353 | DE27: 19272005 | DF27: 19272005 | DG27: 19272005 | DH27: 18848017 | DI27: 8974172 | DJ27: 8890172 | DK27: 8890172 | DL27: 8663807 | DM27: 7863807 | DN27: 7392258 | DO27: =DN27 -> 7392258 | DP27: 37590026 | DQ27: 36790026 | DR27: 36790026 | DS27: 36790026 | DT27: 36790026 | DU27: 32790026 | DV27: 32790026 | DW27: 32707536 | DX27: 32707536 | DY27: 31426536 | DZ27: 8720551 | EA27: 8559879 | EB27: =EA27 -> 8559879 | EC27: 44570138 | ED27: 44570138 | EE27: 44570138 | EF27: 44570138 | EG27: 44670138 | EH27: 44670138 | EI27: 44670138 | EJ27: 41933638 | EK27: 41744274 | EL27: 41744274 | EM27: 41673300 | EN27: 33685852 | EO27: =EN27 -> 33685852 | EP27: 57109595 | EQ27: 57109595 | ER27: 84609595 | ES27: 84609595 | ET27: 77572649 | EU27: 77572649 | EV27: 77594122 | EW27: 77456003 | EX27: 77456003 | EY27: 77456003 | EZ27: 77456003 | FA27: 55621639 | FB27: =FA27 -> 55621639 | FC27: 30479549 | FD27: 30479549 | FE27: 30479549 | FF27: 30479549 | FG27: 29565163 | FH27: 29565163 | FI27: 29565163 | FO27: =FI27 -> 29565163
B28: Total | C28: =SUM(C22:C27) -> 1080148659 | D28: =SUM(D22:D27) -> 1080148659 | E28: =SUM(E22:E27) -> 1071131859 | F28: =SUM(F22:F27) -> 1071131859 | G28: =SUM(G22:G27) -> 1073601859 | H28: =SUM(H22:H27) -> 1081551893 | I28: =SUM(I22:I27) -> 1079440686 | J28: =SUM(J22:J27) -> 1105918828 | ... FO28: =SUM(FO22:FO27) -> 2537552997
B29: (1) Los años 2021 y 2022 incluyen el Presupuesto Vigente del Subtítulo 30, Ítem 10. Fuente: elaboración propia, Dipres.
B31: Ejecución de Inversión en Infraestructura Pública del Ministerio de Obras Públicas, 2014-2026 (Subtítulo 31 – Iniciativas de Inversión, miles de pesos)
C32: 2014 | P32: 2015 | AC32: 2016 | AP32: 2017 | BC32: 2018 | BP32: 2019 | CC32: 2020 | CP32: 2021(1) | DC32: 2022(1) | DP32: 2023 | EC32: 2024 | EP32: 2025 | FC32: 2026
B33: Programa | C33: Ene | D33: Feb | E33: Mar | F33: Abr | G33: May | H33: Jun | I33: Jul | J33: Ago | K33: Sep | L33: Oct | M33: Nov | N33: Dic | O33: Total 2014 | P33: Ene | Q33: Feb | R33: Mar | S33: Abr | T33: May | U33: Jun | V33: Jul | W33: Ago | X33: Sep | Y33: Oct | Z33: Nov | AA33: Dic | AB33: Total 2015 | AC33: Ene | AD33: Feb | AE33: Mar | AF33: Abr | AG33: May | AH33: Jun | AI33: Jul | AJ33: Ago | AK33: Sep | AL33: Oct | AM33: Nov | AN33: Dic | AO33: Total 2016 | AP33: Ene | AQ33: Feb | AR33: Mar | AS33: Abr | AT33: May | AU33: Jun | AV33: Jul | AW33: Ago | AX33: Sep | AY33: Oct | AZ33: Nov | BA33: Dic | BB33: Total 2017 | BC33: Ene | BD33: Feb | BE33: Mar | BF33: Abr | BG33: May | BH33: Jun | BI33: Jul | BJ33: Ago | BK33: Sep | BL33: Oct | BM33: Nov | BN33: Dic | BO33: Total 2018 | BP33: Ene | BQ33: Feb | BR33: Mar | BS33: Abr | BT33: May | BU33: Jun | BV33: Jul | BW33: Ago | BX33: Sep | BY33: Oct | BZ33: Nov | CA33: Dic | CB33: Total 2019 | CC33: Ene | CD33: Feb | CE33: Mar | CF33: Abr | CG33: May | CH33: Jun | CI33: Jul | CJ33: Ago | CK33: Sep | CL33: Oct | CM33: Nov | CN33: Dic | CO33: Total 2020 | CP33: Ene | CQ33: Feb | CR33: Mar | CS33: Abr | CT33: May | CU33: Jun | CV33: Jul | CW33: Ago | CX33: Sep | CY33: Oct | CZ33: Nov | DA33: Dic | DB33: Total 2021 | DC33: Ene | DD33: Feb | DE33: Mar | DF33: Abr | DG33: May | DH33: Jun | DI33: Jul | DJ33: Ago | DK33: Sep | DL33: Oct | DM33: Nov | DN33: Dic | DO33: Total 2022 | DP33: Ene | DQ33: Feb | DR33: Mar | DS33: Abr | DT33: May | DU33: Jun | DV33: Jul | DW33: Ago | DX33: Sep | DY33: Oct | DZ33: Nov | EA33: Dic | EB33: Total 2023 | EC33: Ene | ED33: Feb | EE33: Mar | EF33: Abr | EG33: May | EH33: Jun | EI33: Jul | EJ33: Ago | EK33: Sep | EL33: Oct | EM33: Nov | EN33: Dic | EO33: Total 2024 | EP33: Ene | EQ33: Feb | ER33: Mar | ES33: Abr | ET33: May | EU33: Jun | EV33: Jul | EW33: Ago | EX33: Sep | EY33: Oct | EZ33: Nov | FA33: Dic | FB33: Total 2025 | FC33: Ene | FD33: Feb | FE33: Mar | FF33: Abr | FG33: May | FH33: Jun | FI33: Jul | FJ33: Ago | FK33: Sep | FL33: Oct | FM33: Nov | FN33: Dic | FO33: Total 2026
B34: Dirección de Vialidad | C34: 0 | D34: 109495507 | E34: 187847739 | F34: 265238101 | G34: 332568897 | H34: 394278543 | I34: 446664037 | J34: 504805550 | K34: 557993422 | L34: 619454289 | M34: 701289585 | N34: 852007357 | O34: =N34 -> 852007357 | P34: 35691957 | Q34: 115879618 | R34: 210457678 | S34: 292947200 | T34: 361894458 | U34: 419786083 | V34: 476513994 | W34: 546526929 | X34: 608703218 | Y34: 688327936 | Z34: 772280679 | AA34: 976840711 | AB34: =AA34 -> 976840711 | AC34: 40005015 | AD34: 118158110 | AE34: 206609169 | AF34: 287881130 | AG34: 358249243 | AH34: 428512091 | AI34: 493195502 | AJ34: 565430649 | AK34: 635240221 | AL34: 720114806 | AM34: 799381459 | AN34: 939632633 | AO34: =AN34 -> 939632633 | AP34: 40701104 | AQ34: 108107750 | AR34: 184856578 | AS34: 252856020 | AT34: 319104639 | AU34: 374972572 | AV34: 431914072 | AW34: 497890053 | AX34: 572274603 | AY34: 640444837 | AZ34: 725045158 | BA34: 907408172 | BB34: =BA34 -> 907408172 | BC34: 0 | BD34: 80673042 | BE34: 168539648 | BF34: 237340393 | BG34: 309376504 | BH34: 379148992 | BI34: 442209871 | BJ34: 504027341 | BK34: 570803171 | BL34: 654884646 | BM34: 732454087 | BN34: 901443445 | BO34: =BN34 -> 901443445 | BP34: 0 | BQ34: 102696407 | BR34: 193837202 | BS34: 287563262 | BT34: 363596898 | BU34: 432817167 | BV34: 525171083 | BW34: 613755849 | BX34: 681368937 | BY34: 768886920 | BZ34: 859787144 | CA34: 1081677766 | CB34: =CA34 -> 1081677766 | CC34: 0 | CD34: 96871169 | CE34: 193870511 | CF34: 272631717 | CG34: 327561887 | CH34: 418295604 | CI34: 502258190 | CJ34: 574520045 | CK34: 633600171 | CL34: 713927353 | CM34: 800349975 | CN34: 945847843 | CO34: =CN34 -> 945847843 | CP34: 0 | CQ34: 101383549 | CR34: 198441247 | CS34: 284324137 | CT34: 358590676 | CU34: 433048907 | CV34: 503354400 | CW34: 586218042 | CX34: 653892258 | CY34: 714435373 | CZ34: 802149786 | DA34: 979979167 | DB34: =DA34 -> 979979167 | DC34: 0 | DD34: 58153045 | DE34: 139608998 | DF34: 206666427 | DG34: 283374746 | DH34: 345265825 | DI34: 405594742 | DJ34: 472550892 | DK34: 616595780 | DL34: 680714110 | DM34: 760339461 | DN34: 955760345 | DO34: =DN34 -> 955760345 | DP34: 0 | DQ34: 18205266 | DR34: 138456688 | DS34: 309745351 | DT34: 436281161 | DU34: 544941612 | DV34: 643572937 | DW34: 731872328 | DX34: 824719400 | DY34: 940512329 | DZ34: 1088998456 | EA34: 1417380025 | EB34: =EA34 -> 1417380025 | EC34: 0 | ED34: 115017803 | EE34: 245067556 | EF34: 379975864 | EG34: 521874015 | EH34: 774852600 | EI34: 856290603 | EJ34: 943020316 | EK34: 1073272838 | EL34: 1212620083 | EM34: 1411133522 | EN34: 1603559540 | EO34: =EN34 -> 1603559540 | EP34: 1418928 | EQ34: 262166719 | ER34: 478250448 | ES34: 666185288 | ET34: 837833362 | EU34: 982362882 | EV34: 1108324387 | EW34: 1217723031 | EX34: 1369623467 | EY34: 1492337572 | EZ34: 1632445535 | FA34: 1947648753 | FB34: =FA34 -> 1947648753 | FC34: 0 | FD34: 162224034 | FE34: 321332158 | FF34: 469566556 | FG34: 614978745 | FH34: 776558972 | FI34: 909487841 | FO34: =FI34 -> 909487841
B35: Dirección de Obras Hidráulicas | C35: 0 | D35: 0 | E35: 0 | F35: 12849023 | G35: 18502602 | H35: 24001975 | I35: 28200302 | J35: 35581648 | K35: 44712998 | L35: 54749457 | M35: 68221191 | N35: 104714724 | O35: =N35 -> 104714724 | P35: 4135149 | Q35: 12016222 | R35: 22838957 | S35: 31173658 | T35: 38126481 | U35: 48008563 | V35: 54996009 | W35: 62015391 | X35: 73214656 | Y35: 81368537 | Z35: 95966048 | AA35: 127205691 | AB35: =AA35 -> 127205691 | AC35: 1644472 | AD35: 6760437 | AE35: 14482109 | AF35: 20055802 | AG35: 26700349 | AH35: 38755843 | AI35: 45496469 | AJ35: 52480551 | AK35: 60402105 | AL35: 68110654 | AM35: 84499774 | AN35: 125549909 | AO35: =AN35 -> 125549909 | AP35: 1269137 | AQ35: 5677714 | AR35: 11079172 | AS35: 19699660 | AT35: 26881172 | AU35: 36009564 | AV35: 43753678 | AW35: 54111195 | AX35: 65957670 | AY35: 79535288 | AZ35: 98614598 | BA35: 145867704 | BB35: =BA35 -> 145867704 | BC35: 0 | BD35: 8476734 | BE35: 15590064 | BF35: 22689725 | BG35: 31479542 | BH35: 41016085 | BI35: 50471408 | BJ35: 56335889 | BK35: 65509002 | BL35: 73476914 | BM35: 84787919 | BN35: 119645504 | BO35: =BN35 -> 119645504 | BP35: 0 | BQ35: 0 | BR35: 0 | BS35: 14799182 | BT35: 20928761 | BU35: 27050471 | BV35: 36175836 | BW35: 44639401 | BX35: 52882663 | BY35: 68082147 | BZ35: 91945190 | CA35: 132633546 | CB35: =CA35 -> 132633546 | CC35: 0 | CD35: 0 | CE35: 15933925 | CF35: 27347698 | CG35: 34970453 | CH35: 42227599 | CI35: 50004801 | CJ35: 60357141 | CK35: 71496670 | CL35: 87043293 | CM35: 108285783 | CN35: 139288956 | CO35: =CN35 -> 139288956 | CP35: 0 | CQ35: 9524739 | CR35: 18778382 | CS35: 27058037 | CT35: 38359267 | CU35: 46029534 | CV35: 54019806 | CW35: 63431000 | CX35: 74898419 | CY35: 87833845 | CZ35: 101123468 | DA35: 129806818 | DB35: =DA35 -> 129806818 | DC35: 0 | DD35: 2161172 | DE35: 9902695 | DF35: 17446259 | DG35: 23088738 | DH35: 30830389 | DI35: 40520841 | DJ35: 46926966 | DK35: 55522281 | DL35: 68952930 | DM35: 83462172 | DN35: 128495787 | DO35: =DN35 -> 128495787 | DP35: 0 | DQ35: 6431623 | DR35: 21339974 | DS35: 32945027 | DT35: 47577177 | DU35: 63593303 | DV35: 79376685 | DW35: 92813663 | DX35: 104125697 | DY35: 112739918 | DZ35: 129397461 | EA35: 195957467 | EB35: =EA35 -> 195957467 | EC35: 0 | ED35: 6377090 | EE35: 23890040 | EF35: 39902005 | EG35: 58620170 | EH35: 119341758 | EI35: 136670909 | EJ35: 157100022 | EK35: 175138873 | EL35: 193499950 | EM35: 211590153 | EN35: 243896208 | EO35: =EN35 -> 243896208 | EP35: 2068692 | EQ35: 14027617 | ER35: 36168803 | ES35: 53822571 | ET35: 71880596 | EU35: 92473645 | EV35: 108898696 | EW35: 131234326 | EX35: 152827107 | EY35: 173770614 | EZ35: 201417551 | FA35: 252789386 | FB35: =FA35 -> 252789386 | FC35: 0 | FD35: 9585447 | FE35: 24838996 | FF35: 36118123 | FG35: 47381569 | FH35: 59374806 | FI35: 73650703 | FO35: =FI35 -> 73650703
B36: Subdirección de APR | C36: 0 | D36: 0 | E36: 2123137 | F36: 11318242 | G36: 16412231 | H36: 21503320 | I36: 26571960 | J36: 31336635 | K36: 36845348 | L36: 42847765 | M36: 49413111 | N36: 67417598 | O36: =N36 -> 67417598 | P36: 3681645 | Q36: 8539463 | R36: 18555701 | S36: 26344808 | T36: 33283091 | U36: 38882927 | V36: 45906320 | W36: 51669887 | X36: 58317963 | Y36: 63943837 | Z36: 72706421 | AA36: 93526873 | AB36: =AA36 -> 93526873 | AC36: 0 | AD36: 7489256 | AE36: 14608985 | AF36: 20077326 | AG36: 25109701 | AH36: 31740697 | AI36: 36595708 | AJ36: 43957889 | AK36: 48847708 | AL36: 53992956 | AM36: 60335109 | AN36: 80271976 | AO36: =AN36 -> 80271976 | AP36: 0 | AQ36: 7437942 | AR36: 15597962 | AS36: 22904045 | AT36: 29421513 | AU36: 37145004 | AV36: 44696488 | AW36: 52727926 | AX36: 60463520 | AY36: 67026822 | AZ36: 76122310 | BA36: 100202686 | BB36: =BA36 -> 100202686 | BC36: 0 | BD36: 1539829 | BE36: 9980097 | BF36: 15990396 | BG36: 26512540 | BH36: 32634743 | BI36: 38873532 | BJ36: 44503197 | BK36: 51124646 | BL36: 58962002 | BM36: 71960162 | BN36: 101837360 | BO36: =BN36 -> 101837360 | BP36: 0 | BQ36: 8543845 | BR36: 16492779 | BS36: 25420378 | BT36: 33246158 | BU36: 39464017 | BV36: 45418356 | BW36: 54819773 | BX36: 62481533 | BY36: 71071550 | BZ36: 80774307 | CA36: 109754082 | CB36: =CA36 -> 109754082 | CC36: 0 | CD36: 0 | CE36: 14046798 | CF36: 23975486 | CG36: 32933206 | CH36: 44476459 | CI36: 54767019 | CJ36: 64603134 | CK36: 75187064 | CL36: 91643647 | CM36: 112911790 | CN36: 145498589 | CO36: =CN36 -> 145498589 | CP36: 0 | CQ36: 6666332 | CR36: 21867716 | CS36: 35651365 | CT36: 47287710 | CU36: 58269490 | CV36: 67196224 | CW36: 76194121 | CX36: 86850665 | CY36: 100525220 | CZ36: 114625930 | DA36: 138846156 | DB36: =DA36 -> 138846156 | DC36: 0 | DD36: 0 | DE36: 7252609 | DF36: 18124947 | DG36: 26400403 | DH36: 33265233 | DI36: 41025465 | DJ36: 48098388 | DK36: 56515227 | DL36: 64874125 | DM36: 77789880 | DN36: 108974292 | DO36: =DN36 -> 108974292 | DP36: 0 | DQ36: 2303161 | DR36: 29583551 | DS36: 49465414 | DT36: 68683761 | DU36: 84807286 | DV36: 102765834 | DW36: 120298096 | DX36: 135987986 | DY36: 156018552 | DZ36: 183226741 | EA36: 244037387 | EB36: =EA36 -> 244037387 | EC36: 0 | ED36: 11025007 | EE36: 25342159 | EF36: 43422173 | EG36: 59731566 | EH36: 80871277 | EI36: 90939725 | EJ36: 104887838 | EK36: 121545898 | EL36: 134718420 | EM36: 150454729 | EN36: 189747396 | EO36: =EN36 -> 189747396 | EP36: 2010108 | EQ36: 18132777 | ER36: 36591973 | ES36: 55560502 | ET36: 73627660 | EU36: 93134581 | EV36: 109996503 | EW36: 127458124 | EX36: 147026821 | EY36: 167611651 | EZ36: 186253362 | FA36: 231742834 | FB36: =FA36 -> 231742834 | FC36: 0 | FD36: 19469514 | FE36: 40366706 | FF36: 60258504 | FG36: 79539794 | FH36: 99543928 | FI36: 119758712 | FO36: =FI36 -> 119758712
