Workbook

Sheet Dashboard
B2: MINISTERIO DE VIVIENDA Y URBANISMO — DASHBOARD DE INVERSIÓN Y EJECUCIÓN PRESUPUESTARIA
B3: Visualizador Analítico Interactivo Tabla a Tabla | Subtítulos 33 (Subsidios/Capital), 31 (Inversión Directa), 29 (Activos) y Consolidado | Cifras en miles de pesos ($)
B4: AÑO SELECCIONADO: | C4: 2024 | D4: COBERTURA TEMPORAL: | F4: 2014 - 2026 (Ene - Dic) | H4: UNIDAD MONETARIA: | J4: Miles de $ Corrientes (DIPRES)
B6: PRESUPUESTO LEY (INICIAL) | D6: PRESUPUESTO VIGENTE | F6: EJECUCIÓN ACUMULADA | H6: % CUMPLIMIENTO PRESUPUESTARIO | J6: SALDO POR EJECUTAR
B7: =D17 -> 3320541734 | D7: =E17 -> 3332768183 | F7: =F17 -> 3312699040 | H7: =H17 -> 0.99397824 | J7: =G17 -> 20069143
B9: Aprobado Ley de Presupuesto | D9: Presupuesto anual actualizado | F9: Total devengado en el ejercicio | H9: Ejecución devengada / Presupuesto vigente | J9: Monto disponible no devengado
B11: TABLA 1: RESUMEN CONSOLIDADO POR SUBTÍTULO PRESUPUESTARIO
B13: Subtítulo Presupuestario | C13: Cód. | D13: Presupuesto Ley | E13: Presupuesto Vigente | F13: Ejecución Acumulada | G13: Saldo por Ejecutar | H13: % Ejecución | I13: % Participación
B14: Subtítulo 33 – Transferencias de Capital (Subsidios) | C14: 33 | D14: =INDEX(MINVU_Mes_Corriente!$1:$300, 164, 3 + ($C$4 - 2014)*13 + 12) -> 2729162964 | E14: =INDEX(MINVU_Mes_Corriente!$1:$300, 186, 3 + ($C$4 - 2014)*13 + 12) -> 2913408485 | F14: =INDEX(MINVU_Mes_Corriente!$1:$300, 208, 3 + ($C$4 - 2014)*13 + 12) -> 2904924599 | G14: =E14 - F14 -> 8483886 | H14: =IF(E14>0, F14/E14, 0) -> 0.99708799 | I14: =IF($E$17>0, E14/$E$17, 0) -> 0.87417076
B15: Subtítulo 31 – Iniciativas de Inversión | C15: 31 | D15: =INDEX(MINVU_Mes_Corriente!$1:$300, 26, 3 + ($C$4 - 2014)*13 + 12) -> 560704016 | E15: =INDEX(MINVU_Mes_Corriente!$1:$300, 48, 3 + ($C$4 - 2014)*13 + 12) -> 400142072 | F15: =INDEX(MINVU_Mes_Corriente!$1:$300, 70, 3 + ($C$4 - 2014)*13 + 12) -> 388712182 | G15: =E15 - F15 -> 11429890 | H15: =IF(E15>0, F15/E15, 0) -> 0.97143542 | I15: =IF($E$17>0, E15/$E$17, 0) -> 0.12006298
B16: Subtítulo 29 – Activos No Financieros | C16: 29 | D16: =INDEX(MINVU_Mes_Corriente!$1:$300, 95, 3 + ($C$4 - 2014)*13 + 12) -> 30674754 | E16: =INDEX(MINVU_Mes_Corriente!$1:$300, 117, 3 + ($C$4 - 2014)*13 + 12) -> 19217626 | F16: =INDEX(MINVU_Mes_Corriente!$1:$300, 139, 3 + ($C$4 - 2014)*13 + 12) -> 19062259 | G16: =E16 - F16 -> 155367 | H16: =IF(E16>0, F16/E16, 0) -> 0.99191539 | I16: =IF($E$17>0, E16/$E$17, 0) -> 0.0057662654
B17: TOTAL INVERSIÓN MINVU (33 + 31 + 29) | C17: TOTAL | D17: =SUM(D14:D16) -> 3320541734 | E17: =SUM(E14:E16) -> 3332768183 | F17: =SUM(F14:F16) -> 3312699040 | G17: =E17 - F17 -> 20069143 | H17: =IF(E17>0, F17/E17, 0) -> 0.99397824 | I17: =SUM(I14:I16) -> 1
B19: TABLA 2: DESGLOSE COMPLETO POR ENTIDAD / PROGRAMA / SERVIU (AÑO SELECCIONADO)
B21: Entidad / SERVIU Regional | C21: Subt. 33 Vigente | D21: Subt. 33 Ejecución | E21: Subt. 31 Vigente | F21: Subt. 31 Ejecución | G21: Subt. 29 Vigente | H21: Subt. 29 Ejecución | I21: Total Vigente | J21: Total Ejecución | K21: Saldo | L21: % Ejecución | M21: % Part. MINVU
B22: Subsecretaría y Programas Centrales | C22: =INDEX(MINVU_Mes_Corriente!$1:$300, 168, 3 + ($C$4 - 2014)*13 + 12) -> 253260952 | D22: =INDEX(MINVU_Mes_Corriente!$1:$300, 190, 3 + ($C$4 - 2014)*13 + 12) -> 249185192 | E22: =INDEX(MINVU_Mes_Corriente!$1:$300, 30, 3 + ($C$4 - 2014)*13 + 12) -> 1858597 | F22: =INDEX(MINVU_Mes_Corriente!$1:$300, 52, 3 + ($C$4 - 2014)*13 + 12) -> 1765056 | G22: =INDEX(MINVU_Mes_Corriente!$1:$300, 99, 3 + ($C$4 - 2014)*13 + 12) -> 3168714 | H22: =INDEX(MINVU_Mes_Corriente!$1:$300, 121, 3 + ($C$4 - 2014)*13 + 12) -> 3071041 | I22: =C22 + E22 + G22 -> 258288263 | J22: =D22 + F22 + H22 -> 254021289 | K22: =I22 - J22 -> 4266974 | L22: =IF(I22>0, J22/I22, 0) -> 0.9834798 | M22: =IF($I$40>0, I22/$I$40, 0) -> 0.077499619
B23: Parque Metropolitano (PARQUEMET) | C23: =INDEX(MINVU_Mes_Corriente!$1:$300, 169, 3 + ($C$4 - 2014)*13 + 12) -> 0 | D23: =INDEX(MINVU_Mes_Corriente!$1:$300, 191, 3 + ($C$4 - 2014)*13 + 12) -> 0 | E23: =INDEX(MINVU_Mes_Corriente!$1:$300, 31, 3 + ($C$4 - 2014)*13 + 12) -> 27933416 | F23: =INDEX(MINVU_Mes_Corriente!$1:$300, 53, 3 + ($C$4 - 2014)*13 + 12) -> 27847917 | G23: =INDEX(MINVU_Mes_Corriente!$1:$300, 100, 3 + ($C$4 - 2014)*13 + 12) -> 240920 | H23: =INDEX(MINVU_Mes_Corriente!$1:$300, 122, 3 + ($C$4 - 2014)*13 + 12) -> 240208 | I23: =C23 + E23 + G23 -> 28174336 | J23: =D23 + F23 + H23 -> 28088125 | K23: =I23 - J23 -> 86211 | L23: =IF(I23>0, J23/I23, 0) -> 0.99694009 | M23: =IF($I$40>0, I23/$I$40, 0) -> 0.0084537341
B24: SERVIU Arica y Parinacota | C24: =INDEX(MINVU_Mes_Corriente!$1:$300, 170, 3 + ($C$4 - 2014)*13 + 12) -> 83210671 | D24: =INDEX(MINVU_Mes_Corriente!$1:$300, 192, 3 + ($C$4 - 2014)*13 + 12) -> 83196155 | E24: =INDEX(MINVU_Mes_Corriente!$1:$300, 32, 3 + ($C$4 - 2014)*13 + 12) -> 4403210 | F24: =INDEX(MINVU_Mes_Corriente!$1:$300, 54, 3 + ($C$4 - 2014)*13 + 12) -> 4379123 | G24: =INDEX(MINVU_Mes_Corriente!$1:$300, 101, 3 + ($C$4 - 2014)*13 + 12) -> 7496 | H24: =INDEX(MINVU_Mes_Corriente!$1:$300, 123, 3 + ($C$4 - 2014)*13 + 12) -> 7431 | I24: =C24 + E24 + G24 -> 87621377 | J24: =D24 + F24 + H24 -> 87582709 | K24: =I24 - J24 -> 38668 | L24: =IF(I24>0, J24/I24, 0) -> 0.99955869 | M24: =IF($I$40>0, I24/$I$40, 0) -> 0.026290871
B25: SERVIU Tarapacá | C25: =INDEX(MINVU_Mes_Corriente!$1:$300, 171, 3 + ($C$4 - 2014)*13 + 12) -> 81745804 | D25: =INDEX(MINVU_Mes_Corriente!$1:$300, 193, 3 + ($C$4 - 2014)*13 + 12) -> 81667751 | E25: =INDEX(MINVU_Mes_Corriente!$1:$300, 33, 3 + ($C$4 - 2014)*13 + 12) -> 8998445 | F25: =INDEX(MINVU_Mes_Corriente!$1:$300, 55, 3 + ($C$4 - 2014)*13 + 12) -> 8453266 | G25: =INDEX(MINVU_Mes_Corriente!$1:$300, 102, 3 + ($C$4 - 2014)*13 + 12) -> 3479 | H25: =INDEX(MINVU_Mes_Corriente!$1:$300, 124, 3 + ($C$4 - 2014)*13 + 12) -> 3340 | I25: =C25 + E25 + G25 -> 90747728 | J25: =D25 + F25 + H25 -> 90124357 | K25: =I25 - J25 -> 623371 | L25: =IF(I25>0, J25/I25, 0) -> 0.99313073 | M25: =IF($I$40>0, I25/$I$40, 0) -> 0.027228935
B26: SERVIU Antofagasta | C26: =INDEX(MINVU_Mes_Corriente!$1:$300, 172, 3 + ($C$4 - 2014)*13 + 12) -> 73119497 | D26: =INDEX(MINVU_Mes_Corriente!$1:$300, 194, 3 + ($C$4 - 2014)*13 + 12) -> 73069447 | E26: =INDEX(MINVU_Mes_Corriente!$1:$300, 34, 3 + ($C$4 - 2014)*13 + 12) -> 15465604 | F26: =INDEX(MINVU_Mes_Corriente!$1:$300, 56, 3 + ($C$4 - 2014)*13 + 12) -> 14221677 | G26: =INDEX(MINVU_Mes_Corriente!$1:$300, 103, 3 + ($C$4 - 2014)*13 + 12) -> 6270 | H26: =INDEX(MINVU_Mes_Corriente!$1:$300, 125, 3 + ($C$4 - 2014)*13 + 12) -> 4665 | I26: =C26 + E26 + G26 -> 88591371 | J26: =D26 + F26 + H26 -> 87295789 | K26: =I26 - J26 -> 1295582 | L26: =IF(I26>0, J26/I26, 0) -> 0.98537575 | M26: =IF($I$40>0, I26/$I$40, 0) -> 0.026581918
B27: SERVIU Atacama | C27: =INDEX(MINVU_Mes_Corriente!$1:$300, 173, 3 + ($C$4 - 2014)*13 + 12) -> 50339570 | D27: =INDEX(MINVU_Mes_Corriente!$1:$300, 195, 3 + ($C$4 - 2014)*13 + 12) -> 50275024 | E27: =INDEX(MINVU_Mes_Corriente!$1:$300, 35, 3 + ($C$4 - 2014)*13 + 12) -> 8570431 | F27: =INDEX(MINVU_Mes_Corriente!$1:$300, 57, 3 + ($C$4 - 2014)*13 + 12) -> 8070989 | G27: =INDEX(MINVU_Mes_Corriente!$1:$300, 104, 3 + ($C$4 - 2014)*13 + 12) -> 6646 | H27: =INDEX(MINVU_Mes_Corriente!$1:$300, 126, 3 + ($C$4 - 2014)*13 + 12) -> 6646 | I27: =C27 + E27 + G27 -> 58916647 | J27: =D27 + F27 + H27 -> 58352659 | K27: =I27 - J27 -> 563988 | L27: =IF(I27>0, J27/I27, 0) -> 0.99042736 | M27: =IF($I$40>0, I27/$I$40, 0) -> 0.017677991
B28: SERVIU Coquimbo | C28: =INDEX(MINVU_Mes_Corriente!$1:$300, 174, 3 + ($C$4 - 2014)*13 + 12) -> 107360177 | D28: =INDEX(MINVU_Mes_Corriente!$1:$300, 196, 3 + ($C$4 - 2014)*13 + 12) -> 106974951 | E28: =INDEX(MINVU_Mes_Corriente!$1:$300, 36, 3 + ($C$4 - 2014)*13 + 12) -> 18466482 | F28: =INDEX(MINVU_Mes_Corriente!$1:$300, 58, 3 + ($C$4 - 2014)*13 + 12) -> 18304746 | G28: =INDEX(MINVU_Mes_Corriente!$1:$300, 105, 3 + ($C$4 - 2014)*13 + 12) -> 6092813 | H28: =INDEX(MINVU_Mes_Corriente!$1:$300, 127, 3 + ($C$4 - 2014)*13 + 12) -> 6065343 | I28: =C28 + E28 + G28 -> 131919472 | J28: =D28 + F28 + H28 -> 131345040 | K28: =I28 - J28 -> 574432 | L28: =IF(I28>0, J28/I28, 0) -> 0.99564559 | M28: =IF($I$40>0, I28/$I$40, 0) -> 0.039582553
B29: SERVIU Valparaíso | C29: =INDEX(MINVU_Mes_Corriente!$1:$300, 175, 3 + ($C$4 - 2014)*13 + 12) -> 226125474 | D29: =INDEX(MINVU_Mes_Corriente!$1:$300, 197, 3 + ($C$4 - 2014)*13 + 12) -> 225998740 | E29: =INDEX(MINVU_Mes_Corriente!$1:$300, 37, 3 + ($C$4 - 2014)*13 + 12) -> 37750186 | F29: =INDEX(MINVU_Mes_Corriente!$1:$300, 59, 3 + ($C$4 - 2014)*13 + 12) -> 35664606 | G29: =INDEX(MINVU_Mes_Corriente!$1:$300, 106, 3 + ($C$4 - 2014)*13 + 12) -> 21887 | H29: =INDEX(MINVU_Mes_Corriente!$1:$300, 128, 3 + ($C$4 - 2014)*13 + 12) -> 21833 | I29: =C29 + E29 + G29 -> 263897547 | J29: =D29 + F29 + H29 -> 261685179 | K29: =I29 - J29 -> 2212368 | L29: =IF(I29>0, J29/I29, 0) -> 0.99161656 | M29: =IF($I$40>0, I29/$I$40, 0) -> 0.079182689
B30: SERVIU Metropolitano | C30: =INDEX(MINVU_Mes_Corriente!$1:$300, 176, 3 + ($C$4 - 2014)*13 + 12) -> 536507887 | D30: =INDEX(MINVU_Mes_Corriente!$1:$300, 198, 3 + ($C$4 - 2014)*13 + 12) -> 535781681 | E30: =INDEX(MINVU_Mes_Corriente!$1:$300, 38, 3 + ($C$4 - 2014)*13 + 12) -> 86087430 | F30: =INDEX(MINVU_Mes_Corriente!$1:$300, 60, 3 + ($C$4 - 2014)*13 + 12) -> 84329419 | G30: =INDEX(MINVU_Mes_Corriente!$1:$300, 107, 3 + ($C$4 - 2014)*13 + 12) -> 44560 | H30: =INDEX(MINVU_Mes_Corriente!$1:$300, 129, 3 + ($C$4 - 2014)*13 + 12) -> 44534 | I30: =C30 + E30 + G30 -> 622639877 | J30: =D30 + F30 + H30 -> 620155634 | K30: =I30 - J30 -> 2484243 | L30: =IF(I30>0, J30/I30, 0) -> 0.99601014 | M30: =IF($I$40>0, I30/$I$40, 0) -> 0.18682364
B31: SERVIU O'Higgins | C31: =INDEX(MINVU_Mes_Corriente!$1:$300, 177, 3 + ($C$4 - 2014)*13 + 12) -> 172944682 | D31: =INDEX(MINVU_Mes_Corriente!$1:$300, 199, 3 + ($C$4 - 2014)*13 + 12) -> 172843913 | E31: =INDEX(MINVU_Mes_Corriente!$1:$300, 39, 3 + ($C$4 - 2014)*13 + 12) -> 5515173 | F31: =INDEX(MINVU_Mes_Corriente!$1:$300, 61, 3 + ($C$4 - 2014)*13 + 12) -> 5186229 | G31: =INDEX(MINVU_Mes_Corriente!$1:$300, 108, 3 + ($C$4 - 2014)*13 + 12) -> 300457 | H31: =INDEX(MINVU_Mes_Corriente!$1:$300, 130, 3 + ($C$4 - 2014)*13 + 12) -> 300441 | I31: =C31 + E31 + G31 -> 178760312 | J31: =D31 + F31 + H31 -> 178330583 | K31: =I31 - J31 -> 429729 | L31: =IF(I31>0, J31/I31, 0) -> 0.99759606 | M31: =IF($I$40>0, I31/$I$40, 0) -> 0.053637188
B32: SERVIU Maule | C32: =INDEX(MINVU_Mes_Corriente!$1:$300, 178, 3 + ($C$4 - 2014)*13 + 12) -> 213444748 | D32: =INDEX(MINVU_Mes_Corriente!$1:$300, 200, 3 + ($C$4 - 2014)*13 + 12) -> 213325058 | E32: =INDEX(MINVU_Mes_Corriente!$1:$300, 40, 3 + ($C$4 - 2014)*13 + 12) -> 20053849 | F32: =INDEX(MINVU_Mes_Corriente!$1:$300, 62, 3 + ($C$4 - 2014)*13 + 12) -> 19302172 | G32: =INDEX(MINVU_Mes_Corriente!$1:$300, 109, 3 + ($C$4 - 2014)*13 + 12) -> 6865 | H32: =INDEX(MINVU_Mes_Corriente!$1:$300, 131, 3 + ($C$4 - 2014)*13 + 12) -> 6833 | I32: =C32 + E32 + G32 -> 233505462 | J32: =D32 + F32 + H32 -> 232634063 | K32: =I32 - J32 -> 871399 | L32: =IF(I32>0, J32/I32, 0) -> 0.99626819 | M32: =IF($I$40>0, I32/$I$40, 0) -> 0.070063518
B33: SERVIU Ñuble | C33: =INDEX(MINVU_Mes_Corriente!$1:$300, 179, 3 + ($C$4 - 2014)*13 + 12) -> 154702362 | D33: =INDEX(MINVU_Mes_Corriente!$1:$300, 201, 3 + ($C$4 - 2014)*13 + 12) -> 154664738 | E33: =INDEX(MINVU_Mes_Corriente!$1:$300, 41, 3 + ($C$4 - 2014)*13 + 12) -> 19120001 | F33: =INDEX(MINVU_Mes_Corriente!$1:$300, 63, 3 + ($C$4 - 2014)*13 + 12) -> 17950052 | G33: =INDEX(MINVU_Mes_Corriente!$1:$300, 110, 3 + ($C$4 - 2014)*13 + 12) -> 6270 | H33: =INDEX(MINVU_Mes_Corriente!$1:$300, 132, 3 + ($C$4 - 2014)*13 + 12) -> 6042 | I33: =C33 + E33 + G33 -> 173828633 | J33: =D33 + F33 + H33 -> 172620832 | K33: =I33 - J33 -> 1207801 | L33: =IF(I33>0, J33/I33, 0) -> 0.99305177 | M33: =IF($I$40>0, I33/$I$40, 0) -> 0.052157433
B34: SERVIU Biobío | C34: =INDEX(MINVU_Mes_Corriente!$1:$300, 180, 3 + ($C$4 - 2014)*13 + 12) -> 303934966 | D34: =INDEX(MINVU_Mes_Corriente!$1:$300, 202, 3 + ($C$4 - 2014)*13 + 12) -> 303859023 | E34: =INDEX(MINVU_Mes_Corriente!$1:$300, 42, 3 + ($C$4 - 2014)*13 + 12) -> 52850218 | F34: =INDEX(MINVU_Mes_Corriente!$1:$300, 64, 3 + ($C$4 - 2014)*13 + 12) -> 52001305 | G34: =INDEX(MINVU_Mes_Corriente!$1:$300, 111, 3 + ($C$4 - 2014)*13 + 12) -> 12960 | H34: =INDEX(MINVU_Mes_Corriente!$1:$300, 133, 3 + ($C$4 - 2014)*13 + 12) -> 12190 | I34: =C34 + E34 + G34 -> 356798144 | J34: =D34 + F34 + H34 -> 355872518 | K34: =I34 - J34 -> 925626 | L34: =IF(I34>0, J34/I34, 0) -> 0.99740574 | M34: =IF($I$40>0, I34/$I$40, 0) -> 0.10705759
B35: SERVIU La Araucanía | C35: =INDEX(MINVU_Mes_Corriente!$1:$300, 181, 3 + ($C$4 - 2014)*13 + 12) -> 266347073 | D35: =INDEX(MINVU_Mes_Corriente!$1:$300, 203, 3 + ($C$4 - 2014)*13 + 12) -> 265754901 | E35: =INDEX(MINVU_Mes_Corriente!$1:$300, 43, 3 + ($C$4 - 2014)*13 + 12) -> 36728957 | F35: =INDEX(MINVU_Mes_Corriente!$1:$300, 65, 3 + ($C$4 - 2014)*13 + 12) -> 36426224 | G35: =INDEX(MINVU_Mes_Corriente!$1:$300, 112, 3 + ($C$4 - 2014)*13 + 12) -> 12161 | H35: =INDEX(MINVU_Mes_Corriente!$1:$300, 134, 3 + ($C$4 - 2014)*13 + 12) -> 12134 | I35: =C35 + E35 + G35 -> 303088191 | J35: =D35 + F35 + H35 -> 302193259 | K35: =I35 - J35 -> 894932 | L35: =IF(I35>0, J35/I35, 0) -> 0.99704729 | M35: =IF($I$40>0, I35/$I$40, 0) -> 0.090941876
B36: SERVIU Los Ríos | C36: =INDEX(MINVU_Mes_Corriente!$1:$300, 182, 3 + ($C$4 - 2014)*13 + 12) -> 73852164 | D36: =INDEX(MINVU_Mes_Corriente!$1:$300, 204, 3 + ($C$4 - 2014)*13 + 12) -> 72195760 | E36: =INDEX(MINVU_Mes_Corriente!$1:$300, 44, 3 + ($C$4 - 2014)*13 + 12) -> 13330524 | F36: =INDEX(MINVU_Mes_Corriente!$1:$300, 66, 3 + ($C$4 - 2014)*13 + 12) -> 12655537 | G36: =INDEX(MINVU_Mes_Corriente!$1:$300, 113, 3 + ($C$4 - 2014)*13 + 12) -> 9216 | H36: =INDEX(MINVU_Mes_Corriente!$1:$300, 135, 3 + ($C$4 - 2014)*13 + 12) -> 9209 | I36: =C36 + E36 + G36 -> 87191904 | J36: =D36 + F36 + H36 -> 84860506 | K36: =I36 - J36 -> 2331398 | L36: =IF(I36>0, J36/I36, 0) -> 0.9732613 | M36: =IF($I$40>0, I36/$I$40, 0) -> 0.026162007
B37: SERVIU Los Lagos | C37: =INDEX(MINVU_Mes_Corriente!$1:$300, 183, 3 + ($C$4 - 2014)*13 + 12) -> 209110935 | D37: =INDEX(MINVU_Mes_Corriente!$1:$300, 205, 3 + ($C$4 - 2014)*13 + 12) -> 209043392 | E37: =INDEX(MINVU_Mes_Corriente!$1:$300, 45, 3 + ($C$4 - 2014)*13 + 12) -> 17300120 | F37: =INDEX(MINVU_Mes_Corriente!$1:$300, 67, 3 + ($C$4 - 2014)*13 + 12) -> 16578842 | G37: =INDEX(MINVU_Mes_Corriente!$1:$300, 114, 3 + ($C$4 - 2014)*13 + 12) -> 9262299 | H37: =INDEX(MINVU_Mes_Corriente!$1:$300, 136, 3 + ($C$4 - 2014)*13 + 12) -> 9235856 | I37: =C37 + E37 + G37 -> 235673354 | J37: =D37 + F37 + H37 -> 234858090 | K37: =I37 - J37 -> 815264 | L37: =IF(I37>0, J37/I37, 0) -> 0.9965407 | M37: =IF($I$40>0, I37/$I$40, 0) -> 0.070713995
B38: SERVIU Aysén | C38: =INDEX(MINVU_Mes_Corriente!$1:$300, 184, 3 + ($C$4 - 2014)*13 + 12) -> 40911462 | D38: =INDEX(MINVU_Mes_Corriente!$1:$300, 206, 3 + ($C$4 - 2014)*13 + 12) -> 40629172 | E38: =INDEX(MINVU_Mes_Corriente!$1:$300, 46, 3 + ($C$4 - 2014)*13 + 12) -> 7723948 | F38: =INDEX(MINVU_Mes_Corriente!$1:$300, 68, 3 + ($C$4 - 2014)*13 + 12) -> 7636879 | G38: =INDEX(MINVU_Mes_Corriente!$1:$300, 115, 3 + ($C$4 - 2014)*13 + 12) -> 6270 | H38: =INDEX(MINVU_Mes_Corriente!$1:$300, 137, 3 + ($C$4 - 2014)*13 + 12) -> 6224 | I38: =C38 + E38 + G38 -> 48641680 | J38: =D38 + F38 + H38 -> 48272275 | K38: =I38 - J38 -> 369405 | L38: =IF(I38>0, J38/I38, 0) -> 0.99240559 | M38: =IF($I$40>0, I38/$I$40, 0) -> 0.014594979
B39: SERVIU Magallanes | C39: =INDEX(MINVU_Mes_Corriente!$1:$300, 185, 3 + ($C$4 - 2014)*13 + 12) -> 66490061 | D39: =INDEX(MINVU_Mes_Corriente!$1:$300, 207, 3 + ($C$4 - 2014)*13 + 12) -> 66459701 | E39: =INDEX(MINVU_Mes_Corriente!$1:$300, 47, 3 + ($C$4 - 2014)*13 + 12) -> 17985481 | F39: =INDEX(MINVU_Mes_Corriente!$1:$300, 69, 3 + ($C$4 - 2014)*13 + 12) -> 17938143 | G39: =INDEX(MINVU_Mes_Corriente!$1:$300, 116, 3 + ($C$4 - 2014)*13 + 12) -> 8343 | H39: =INDEX(MINVU_Mes_Corriente!$1:$300, 138, 3 + ($C$4 - 2014)*13 + 12) -> 8289 | I39: =C39 + E39 + G39 -> 84483885 | J39: =D39 + F39 + H39 -> 84406133 | K39: =I39 - J39 -> 77752 | L39: =IF(I39>0, J39/I39, 0) -> 0.99907968 | M39: =IF($I$40>0, I39/$I$40, 0) -> 0.025349463
B40: TOTAL MINVU | C40: =SUM(C22:C39) -> 2913408485 | D40: =SUM(D22:D39) -> 2904924599 | E40: =SUM(E22:E39) -> 400142072 | F40: =SUM(F22:F39) -> 388712182 | G40: =SUM(G22:G39) -> 19217626 | H40: =SUM(H22:H39) -> 19062259 | I40: =SUM(I22:I39) -> 3332768183 | J40: =SUM(J22:J39) -> 3312699040 | K40: =SUM(K22:K39) -> 20069143 | L40: =IF(I40>0, J40/I40, 0) -> 0.99397824 | M40: =SUM(M22:M39) -> 1
B42: TABLA 3: EVOLUCIÓN MENSUAL DEL AÑO SELECCIONADO (ENERO A DICIEMBRE)
B44: Concepto / Mes | C44: Ene | D44: Feb | E44: Mar | F44: Abr | G44: May | H44: Jun | I44: Jul | J44: Ago | K44: Sep | L44: Oct | M44: Nov | N44: Dic | O44: Cierre Total
B45: Presupuesto Ley | C45: =INDEX(MINVU_Mes_Corriente!$1:$300, 164, 3 + ($C$4 - 2014)*13 + 0) + INDEX(MINVU_Mes_Corriente!$1:$300, 26, 3 + ($C$4 - 2014)*13 + 0) + INDEX(MINVU_Mes_Corriente!$1:$300, 95, 3 + ($C$4 - 2014)*13 + 0) -> 3320541734 | D45: =INDEX(MINVU_Mes_Corriente!$1:$300, 164, 3 + ($C$4 - 2014)*13 + 1) + INDEX(MINVU_Mes_Corriente!$1:$300, 26, 3 + ($C$4 - 2014)*13 + 1) + INDEX(MINVU_Mes_Corriente!$1:$300, 95, 3 + ($C$4 - 2014)*13 + 1) -> 3320541734 | E45: =INDEX(MINVU_Mes_Corriente!$1:$300, 164, 3 + ($C$4 - 2014)*13 + 2) + INDEX(MINVU_Mes_Corriente!$1:$300, 26, 3 + ($C$4 - 2014)*13 + 2) + INDEX(MINVU_Mes_Corriente!$1:$300, 95, 3 + ($C$4 - 2014)*13 + 2) -> 3320541734 | F45: =INDEX(MINVU_Mes_Corriente!$1:$300, 164, 3 + ($C$4 - 2014)*13 + 3) + INDEX(MINVU_Mes_Corriente!$1:$300, 26, 3 + ($C$4 - 2014)*13 + 3) + INDEX(MINVU_Mes_Corriente!$1:$300, 95, 3 + ($C$4 - 2014)*13 + 3) -> 3320541734 | G45: =INDEX(MINVU_Mes_Corriente!$1:$300, 164, 3 + ($C$4 - 2014)*13 + 4) + INDEX(MINVU_Mes_Corriente!$1:$300, 26, 3 + ($C$4 - 2014)*13 + 4) + INDEX(MINVU_Mes_Corriente!$1:$300, 95, 3 + ($C$4 - 2014)*13 + 4) -> 3320541734 | H45: =INDEX(MINVU_Mes_Corriente!$1:$300, 164, 3 + ($C$4 - 2014)*13 + 5) + INDEX(MINVU_Mes_Corriente!$1:$300, 26, 3 + ($C$4 - 2014)*13 + 5) + INDEX(MINVU_Mes_Corriente!$1:$300, 95, 3 + ($C$4 - 2014)*13 + 5) -> 3320541734 | I45: =INDEX(MINVU_Mes_Corriente!$1:$300, 164, 3 + ($C$4 - 2014)*13 + 6) + INDEX(MINVU_Mes_Corriente!$1:$300, 26, 3 + ($C$4 - 2014)*13 + 6) + INDEX(MINVU_Mes_Corriente!$1:$300, 95, 3 + ($C$4 - 2014)*13 + 6) -> 3320541734 | J45: =INDEX(MINVU_Mes_Corriente!$1:$300, 164, 3 + ($C$4 - 2014)*13 + 7) + INDEX(MINVU_Mes_Corriente!$1:$300, 26, 3 + ($C$4 - 2014)*13 + 7) + INDEX(MINVU_Mes_Corriente!$1:$300, 95, 3 + ($C$4 - 2014)*13 + 7) -> 3320541734 | K45: =INDEX(MINVU_Mes_Corriente!$1:$300, 164, 3 + ($C$4 - 2014)*13 + 8) + INDEX(MINVU_Mes_Corriente!$1:$300, 26, 3 + ($C$4 - 2014)*13 + 8) + INDEX(MINVU_Mes_Corriente!$1:$300, 95, 3 + ($C$4 - 2014)*13 + 8) -> 3320541734 | L45: =INDEX(MINVU_Mes_Corriente!$1:$300, 164, 3 + ($C$4 - 2014)*13 + 9) + INDEX(MINVU_Mes_Corriente!$1:$300, 26, 3 + ($C$4 - 2014)*13 + 9) + INDEX(MINVU_Mes_Corriente!$1:$300, 95, 3 + ($C$4 - 2014)*13 + 9) -> 3320541734 | M45: =INDEX(MINVU_Mes_Corriente!$1:$300, 164, 3 + ($C$4 - 2014)*13 + 10) + INDEX(MINVU_Mes_Corriente!$1:$300, 26, 3 + ($C$4 - 2014)*13 + 10) + INDEX(MINVU_Mes_Corriente!$1:$300, 95, 3 + ($C$4 - 2014)*13 + 10) -> 3320541734 | N45: =INDEX(MINVU_Mes_Corriente!$1:$300, 164, 3 + ($C$4 - 2014)*13 + 11) + INDEX(MINVU_Mes_Corriente!$1:$300, 26, 3 + ($C$4 - 2014)*13 + 11) + INDEX(MINVU_Mes_Corriente!$1:$300, 95, 3 + ($C$4 - 2014)*13 + 11) -> 3320541734 | O45: =INDEX(MINVU_Mes_Corriente!$1:$300, 164, 3 + ($C$4 - 2014)*13 + 12) + INDEX(MINVU_Mes_Corriente!$1:$300, 26, 3 + ($C$4 - 2014)*13 + 12) + INDEX(MINVU_Mes_Corriente!$1:$300, 95, 3 + ($C$4 - 2014)*13 + 12) -> 3320541734
B46: Presupuesto Vigente | C46: =INDEX(MINVU_Mes_Corriente!$1:$300, 186, 3 + ($C$4 - 2014)*13 + 0) + INDEX(MINVU_Mes_Corriente!$1:$300, 48, 3 + ($C$4 - 2014)*13 + 0) + INDEX(MINVU_Mes_Corriente!$1:$300, 117, 3 + ($C$4 - 2014)*13 + 0) -> 3320541734 | D46: =INDEX(MINVU_Mes_Corriente!$1:$300, 186, 3 + ($C$4 - 2014)*13 + 1) + INDEX(MINVU_Mes_Corriente!$1:$300, 48, 3 + ($C$4 - 2014)*13 + 1) + INDEX(MINVU_Mes_Corriente!$1:$300, 117, 3 + ($C$4 - 2014)*13 + 1) -> 3320541734 | E46: =INDEX(MINVU_Mes_Corriente!$1:$300, 186, 3 + ($C$4 - 2014)*13 + 2) + INDEX(MINVU_Mes_Corriente!$1:$300, 48, 3 + ($C$4 - 2014)*13 + 2) + INDEX(MINVU_Mes_Corriente!$1:$300, 117, 3 + ($C$4 - 2014)*13 + 2) -> 3320541734 | F46: =INDEX(MINVU_Mes_Corriente!$1:$300, 186, 3 + ($C$4 - 2014)*13 + 3) + INDEX(MINVU_Mes_Corriente!$1:$300, 48, 3 + ($C$4 - 2014)*13 + 3) + INDEX(MINVU_Mes_Corriente!$1:$300, 117, 3 + ($C$4 - 2014)*13 + 3) -> 3320541734 | G46: =INDEX(MINVU_Mes_Corriente!$1:$300, 186, 3 + ($C$4 - 2014)*13 + 4) + INDEX(MINVU_Mes_Corriente!$1:$300, 48, 3 + ($C$4 - 2014)*13 + 4) + INDEX(MINVU_Mes_Corriente!$1:$300, 117, 3 + ($C$4 - 2014)*13 + 4) -> 3320643534 | H46: =INDEX(MINVU_Mes_Corriente!$1:$300, 186, 3 + ($C$4 - 2014)*13 + 5) + INDEX(MINVU_Mes_Corriente!$1:$300, 48, 3 + ($C$4 - 2014)*13 + 5) + INDEX(MINVU_Mes_Corriente!$1:$300, 117, 3 + ($C$4 - 2014)*13 + 5) -> 3320643534 | I46: =INDEX(MINVU_Mes_Corriente!$1:$300, 186, 3 + ($C$4 - 2014)*13 + 6) + INDEX(MINVU_Mes_Corriente!$1:$300, 48, 3 + ($C$4 - 2014)*13 + 6) + INDEX(MINVU_Mes_Corriente!$1:$300, 117, 3 + ($C$4 - 2014)*13 + 6) -> 3329424159 | J46: =INDEX(MINVU_Mes_Corriente!$1:$300, 186, 3 + ($C$4 - 2014)*13 + 7) + INDEX(MINVU_Mes_Corriente!$1:$300, 48, 3 + ($C$4 - 2014)*13 + 7) + INDEX(MINVU_Mes_Corriente!$1:$300, 117, 3 + ($C$4 - 2014)*13 + 7) -> 3376717372 | K46: =INDEX(MINVU_Mes_Corriente!$1:$300, 186, 3 + ($C$4 - 2014)*13 + 8) + INDEX(MINVU_Mes_Corriente!$1:$300, 48, 3 + ($C$4 - 2014)*13 + 8) + INDEX(MINVU_Mes_Corriente!$1:$300, 117, 3 + ($C$4 - 2014)*13 + 8) -> 3421717372 | L46: =INDEX(MINVU_Mes_Corriente!$1:$300, 186, 3 + ($C$4 - 2014)*13 + 9) + INDEX(MINVU_Mes_Corriente!$1:$300, 48, 3 + ($C$4 - 2014)*13 + 9) + INDEX(MINVU_Mes_Corriente!$1:$300, 117, 3 + ($C$4 - 2014)*13 + 9) -> 3491232791 | M46: =INDEX(MINVU_Mes_Corriente!$1:$300, 186, 3 + ($C$4 - 2014)*13 + 10) + INDEX(MINVU_Mes_Corriente!$1:$300, 48, 3 + ($C$4 - 2014)*13 + 10) + INDEX(MINVU_Mes_Corriente!$1:$300, 117, 3 + ($C$4 - 2014)*13 + 10) -> 3488688633 | N46: =INDEX(MINVU_Mes_Corriente!$1:$300, 186, 3 + ($C$4 - 2014)*13 + 11) + INDEX(MINVU_Mes_Corriente!$1:$300, 48, 3 + ($C$4 - 2014)*13 + 11) + INDEX(MINVU_Mes_Corriente!$1:$300, 117, 3 + ($C$4 - 2014)*13 + 11) -> 3332768183 | O46: =INDEX(MINVU_Mes_Corriente!$1:$300, 186, 3 + ($C$4 - 2014)*13 + 12) + INDEX(MINVU_Mes_Corriente!$1:$300, 48, 3 + ($C$4 - 2014)*13 + 12) + INDEX(MINVU_Mes_Corriente!$1:$300, 117, 3 + ($C$4 - 2014)*13 + 12) -> 3332768183
B47: Ejecución Acumulada | C47: =INDEX(MINVU_Mes_Corriente!$1:$300, 208, 3 + ($C$4 - 2014)*13 + 0) + INDEX(MINVU_Mes_Corriente!$1:$300, 70, 3 + ($C$4 - 2014)*13 + 0) + INDEX(MINVU_Mes_Corriente!$1:$300, 139, 3 + ($C$4 - 2014)*13 + 0) -> 144905537 | D47: =INDEX(MINVU_Mes_Corriente!$1:$300, 208, 3 + ($C$4 - 2014)*13 + 1) + INDEX(MINVU_Mes_Corriente!$1:$300, 70, 3 + ($C$4 - 2014)*13 + 1) + INDEX(MINVU_Mes_Corriente!$1:$300, 139, 3 + ($C$4 - 2014)*13 + 1) -> 392112901 | E47: =INDEX(MINVU_Mes_Corriente!$1:$300, 208, 3 + ($C$4 - 2014)*13 + 2) + INDEX(MINVU_Mes_Corriente!$1:$300, 70, 3 + ($C$4 - 2014)*13 + 2) + INDEX(MINVU_Mes_Corriente!$1:$300, 139, 3 + ($C$4 - 2014)*13 + 2) -> 734004289 | F47: =INDEX(MINVU_Mes_Corriente!$1:$300, 208, 3 + ($C$4 - 2014)*13 + 3) + INDEX(MINVU_Mes_Corriente!$1:$300, 70, 3 + ($C$4 - 2014)*13 + 3) + INDEX(MINVU_Mes_Corriente!$1:$300, 139, 3 + ($C$4 - 2014)*13 + 3) -> 1004471755 | G47: =INDEX(MINVU_Mes_Corriente!$1:$300, 208, 3 + ($C$4 - 2014)*13 + 4) + INDEX(MINVU_Mes_Corriente!$1:$300, 70, 3 + ($C$4 - 2014)*13 + 4) + INDEX(MINVU_Mes_Corriente!$1:$300, 139, 3 + ($C$4 - 2014)*13 + 4) -> 1303821878 | H47: =INDEX(MINVU_Mes_Corriente!$1:$300, 208, 3 + ($C$4 - 2014)*13 + 5) + INDEX(MINVU_Mes_Corriente!$1:$300, 70, 3 + ($C$4 - 2014)*13 + 5) + INDEX(MINVU_Mes_Corriente!$1:$300, 139, 3 + ($C$4 - 2014)*13 + 5) -> 1551877586 | I47: =INDEX(MINVU_Mes_Corriente!$1:$300, 208, 3 + ($C$4 - 2014)*13 + 6) + INDEX(MINVU_Mes_Corriente!$1:$300, 70, 3 + ($C$4 - 2014)*13 + 6) + INDEX(MINVU_Mes_Corriente!$1:$300, 139, 3 + ($C$4 - 2014)*13 + 6) -> 1800513314 | J47: =INDEX(MINVU_Mes_Corriente!$1:$300, 208, 3 + ($C$4 - 2014)*13 + 7) + INDEX(MINVU_Mes_Corriente!$1:$300, 70, 3 + ($C$4 - 2014)*13 + 7) + INDEX(MINVU_Mes_Corriente!$1:$300, 139, 3 + ($C$4 - 2014)*13 + 7) -> 2056646958 | K47: =INDEX(MINVU_Mes_Corriente!$1:$300, 208, 3 + ($C$4 - 2014)*13 + 8) + INDEX(MINVU_Mes_Corriente!$1:$300, 70, 3 + ($C$4 - 2014)*13 + 8) + INDEX(MINVU_Mes_Corriente!$1:$300, 139, 3 + ($C$4 - 2014)*13 + 8) -> 2287303377 | L47: =INDEX(MINVU_Mes_Corriente!$1:$300, 208, 3 + ($C$4 - 2014)*13 + 9) + INDEX(MINVU_Mes_Corriente!$1:$300, 70, 3 + ($C$4 - 2014)*13 + 9) + INDEX(MINVU_Mes_Corriente!$1:$300, 139, 3 + ($C$4 - 2014)*13 + 9) -> 2541084845 | M47: =INDEX(MINVU_Mes_Corriente!$1:$300, 208, 3 + ($C$4 - 2014)*13 + 10) + INDEX(MINVU_Mes_Corriente!$1:$300, 70, 3 + ($C$4 - 2014)*13 + 10) + INDEX(MINVU_Mes_Corriente!$1:$300, 139, 3 + ($C$4 - 2014)*13 + 10) -> 2810519043 | N47: =INDEX(MINVU_Mes_Corriente!$1:$300, 208, 3 + ($C$4 - 2014)*13 + 11) + INDEX(MINVU_Mes_Corriente!$1:$300, 70, 3 + ($C$4 - 2014)*13 + 11) + INDEX(MINVU_Mes_Corriente!$1:$300, 139, 3 + ($C$4 - 2014)*13 + 11) -> 3312699040 | O47: =INDEX(MINVU_Mes_Corriente!$1:$300, 208, 3 + ($C$4 - 2014)*13 + 12) + INDEX(MINVU_Mes_Corriente!$1:$300, 70, 3 + ($C$4 - 2014)*13 + 12) + INDEX(MINVU_Mes_Corriente!$1:$300, 139, 3 + ($C$4 - 2014)*13 + 12) -> 3312699040
B48: % Avance Ejecución | C48: =IF(C46>0, C47/C46, 0) -> 0.043639125 | D48: =IF(D46>0, D47/D46, 0) -> 0.11808703 | E48: =IF(E46>0, E47/E46, 0) -> 0.22104956 | F48: =IF(F46>0, F47/F46, 0) -> 0.30250237 | G48: =IF(G46>0, G47/G46, 0) -> 0.39264133 | H48: =IF(H46>0, H47/H46, 0) -> 0.46734242 | I48: =IF(I46>0, I47/I46, 0) -> 0.5407882 | J48: =IF(J46>0, J47/J46, 0) -> 0.60906695 | ... O48: =IF(O46>0, O47/O46, 0) -> 0.99397824
B50: TABLA 4: COMPARATIVA HISTÓRICA MULTIANUAL (2014 - 2026)
...

Sheet MINVU_Mes_Corriente
B1: Ministerio de Vivienda y Urbanismo — Partida 18
B2: Miles de pesos — moneda corriente — montos devengados
B4: SUBTÍTULO 31 – INICIATIVAS DE INVERSIÓN
B5: Presupuesto Ley (Subtítulo 31)
C6: 2014 | P6: 2015 | AC6: 2016 | AP6: 2017 | BC6: 2018 | BP6: 2019 | CC6: 2020 | CP6: 2021 | DC6: 2022 | DP6: 2023 | EC6: 2024 | EP6: 2025 | FC6: 2026
B7: Programa / Entidad | C7: Ene | D7: Feb | E7: Mar | F7: Abr | G7: May | H7: Jun | I7: Jul | J7: Ago | K7: Sep | L7: Oct | M7: Nov | N7: Dic | O7: Total 2014 | P7: Ene | Q7: Feb | R7: Mar | S7: Abr | T7: May | U7: Jun | V7: Jul | W7: Ago | X7: Sep | Y7: Oct | Z7: Nov | AA7: Dic | AB7: Total 2015 | AC7: Ene | AD7: Feb | AE7: Mar | AF7: Abr | AG7: May | AH7: Jun | AI7: Jul | AJ7: Ago | AK7: Sep | AL7: Oct | AM7: Nov | AN7: Dic | AO7: Total 2016 | AP7: Ene | AQ7: Feb | AR7: Mar | AS7: Abr | AT7: May | AU7: Jun | AV7: Jul | AW7: Ago | AX7: Sep | AY7: Oct | AZ7: Nov | BA7: Dic | BB7: Total 2017 | BC7: Ene | BD7: Feb | BE7: Mar | BF7: Abr | BG7: May | BH7: Jun | BI7: Jul | BJ7: Ago | BK7: Sep | BL7: Oct | BM7: Nov | BN7: Dic | BO7: Total 2018 | BP7: Ene | BQ7: Feb | BR7: Mar | BS7: Abr | BT7: May | BU7: Jun | BV7: Jul | BW7: Ago | BX7: Sep | BY7: Oct | BZ7: Nov | CA7: Dic | CB7: Total 2019 | CC7: Ene | CD7: Feb | CE7: Mar | CF7: Abr | CG7: May | CH7: Jun | CI7: Jul | CJ7: Ago | CK7: Sep | CL7: Oct | CM7: Nov | CN7: Dic | CO7: Total 2020 | CP7: Ene | CQ7: Feb | CR7: Mar | CS7: Abr | CT7: May | CU7: Jun | CV7: Jul | CW7: Ago | CX7: Sep | CY7: Oct | CZ7: Nov | DA7: Dic | DB7: Total 2021 | DC7: Ene | DD7: Feb | DE7: Mar | DF7: Abr | DG7: May | DH7: Jun | DI7: Jul | DJ7: Ago | DK7: Sep | DL7: Oct | DM7: Nov | DN7: Dic | DO7: Total 2022 | DP7: Ene | DQ7: Feb | DR7: Mar | DS7: Abr | DT7: May | DU7: Jun | DV7: Jul | DW7: Ago | DX7: Sep | DY7: Oct | DZ7: Nov | EA7: Dic | EB7: Total 2023 | EC7: Ene | ED7: Feb | EE7: Mar | EF7: Abr | EG7: May | EH7: Jun | EI7: Jul | EJ7: Ago | EK7: Sep | EL7: Oct | EM7: Nov | EN7: Dic | EO7: Total 2024 | EP7: Ene | EQ7: Feb | ER7: Mar | ES7: Abr | ET7: May | EU7: Jun | EV7: Jul | EW7: Ago | EX7: Sep | EY7: Oct | EZ7: Nov | FA7: Dic | FB7: Total 2025 | FC7: Ene | FD7: Feb | FE7: Mar | FF7: Abr | FG7: May | FH7: Jun | FI7: Jul | FJ7: Ago | FK7: Sep | FL7: Oct | FM7: Nov | FN7: Dic | FO7: Total 2026
B8: Subsecretaría y Programas Centrales | C8: 46689781 | D8: 46689781 | E8: 47980703 | F8: 47980703 | G8: 47980703 | H8: 47980703 | I8: 47980703 | J8: 47980703 | K8: 47980703 | L8: 47980703 | M8: 47980703 | N8: 47980703 | O8: 47980703 | P8: 52447510 | Q8: 52447510 | R8: 52447510 | S8: 52447510 | T8: 52447510 | U8: 52447510 | V8: 52447510 | W8: 52447510 | X8: 52447510 | Y8: 52447510 | Z8: 52447510 | AA8: 52447510 | AB8: 52447510 | AC8: 49700606 | AD8: 49700606 | AE8: 49700606 | AF8: 49700606 | AG8: 49700606 | AH8: 49700606 | AI8: 49700606 | AJ8: 49700606 | AK8: 49700606 | AL8: 49700606 | AM8: 49700606 | AN8: 49700606 | AO8: 49700606 | AP8: 45980831 | AQ8: 45980831 | AR8: 45980831 | AS8: 45980831 | AT8: 45980831 | AU8: 45980831 | AV8: 45980831 | AW8: 45980831 | AX8: 45980831 | AY8: 45980831 | AZ8: 45980831 | BA8: 45980831 | BB8: 45980831 | BC8: 45443730 | BD8: 45443730 | BE8: 45443730 | BF8: 45443730 | BG8: 45443730 | BH8: 45443730 | BI8: 45443730 | BJ8: 45443730 | BK8: 45443730 | BL8: 45443730 | BM8: 45443730 | BN8: 45443730 | BO8: 45443730 | BP8: 51220903 | BQ8: 51220903 | BR8: 51220903 | BS8: 51220903 | BT8: 51220903 | BU8: 51220903 | BV8: 51220903 | BW8: 51220903 | BX8: 51220903 | BY8: 51220903 | BZ8: 51220903 | CA8: 51220903 | CB8: 51220903 | CC8: 51587816 | CD8: 51587816 | CE8: 51587816 | CF8: 51587816 | CG8: 51587816 | CH8: 51587816 | CI8: 51587816 | CJ8: 51587816 | CK8: 51587816 | CL8: 51587816 | CM8: 51587816 | CN8: 51587816 | CO8: 51587816 | CP8: 35339308 | CQ8: 35339308 | CR8: 35339308 | CS8: 35339308 | CT8: 35339308 | CU8: 35339308 | CV8: 35339308 | CW8: 35339308 | CX8: 35339308 | CY8: 35339308 | CZ8: 35339308 | DA8: 35339308 | DB8: 35339308 | DC8: 22751821 | DD8: 22751821 | DE8: 22751821 | DF8: 22751821 | DG8: 22751821 | DH8: 22751821 | DI8: 22751821 | DJ8: 22751821 | DK8: 22751821 | DL8: 22751821 | DM8: 22751821 | DN8: 22751821 | DO8: 22751821 | DP8: 22326757 | DQ8: 22326757 | DR8: 22326757 | DS8: 22326757 | DT8: 22326757 | DU8: 22326757 | DV8: 22326757 | DW8: 22326757 | DX8: 22326757 | DY8: 22326757 | DZ8: 22326757 | EA8: 22326757 | EB8: 22326757 | EC8: 65885700 | ED8: 65885700 | EE8: 65885700 | EF8: 65885700 | EG8: 65885700 | EH8: 65885700 | EI8: 65885700 | EJ8: 65885700 | EK8: 65885700 | EL8: 65885700 | EM8: 65885700 | EN8: 65885700 | EO8: 65885700 | EP8: 31496963 | EQ8: 31496963 | ER8: 31496963 | ES8: 31496963 | ET8: 31496963 | EU8: 31496963 | EV8: 31496963 | EW8: 31496963 | EX8: 31496963 | EY8: 31496963 | EZ8: 31496963 | FA8: 31496963 | FB8: 31496963 | FC8: 15772873 | FD8: 15772873 | FE8: 15772873 | FF8: 15772873 | FG8: 15772873 | FH8: 15772873 | FI8: 15772873 | FJ8: 15772873 | FK8: 15772873 | FL8: 15772873 | FM8: 15772873 | FN8: 15772873 | FO8: 15772873
B9: Parque Metropolitano (PARQUEMET) | C9: 11852830 | D9: 11852830 | E9: 11852830 | F9: 11852830 | G9: 11852830 | H9: 11852830 | I9: 11852830 | J9: 11852830 | K9: 11852830 | L9: 11852830 | M9: 11852830 | N9: 11852830 | O9: 11852830 | P9: 12432312 | Q9: 12432312 | R9: 12432312 | S9: 12432312 | T9: 12432312 | U9: 12432312 | V9: 12432312 | W9: 12432312 | X9: 12432312 | Y9: 12432312 | Z9: 12432312 | AA9: 12432312 | AB9: 12432312 | AC9: 15376817 | AD9: 15376817 | AE9: 15376817 | AF9: 15376817 | AG9: 15376817 | AH9: 15376817 | AI9: 15376817 | AJ9: 15376817 | AK9: 15376817 | AL9: 15376817 | AM9: 15376817 | AN9: 15376817 | AO9: 15376817 | AP9: 19125128 | AQ9: 19125128 | AR9: 19125128 | AS9: 19125128 | AT9: 19125128 | AU9: 19125128 | AV9: 19125128 | AW9: 19125128 | AX9: 19125128 | AY9: 19125128 | AZ9: 19125128 | BA9: 19125128 | BB9: 19125128 | BC9: 22875150 | BD9: 22875150 | BE9: 22875150 | BF9: 22875150 | BG9: 22875150 | BH9: 22875150 | BI9: 22875150 | BJ9: 22875150 | BK9: 22875150 | BL9: 22875150 | BM9: 22875150 | BN9: 22875150 | BO9: 22875150 | BP9: 23805335 | BQ9: 23805335 | BR9: 23805335 | BS9: 23805335 | BT9: 23805335 | BU9: 23805335 | BV9: 23805335 | BW9: 23805335 | BX9: 23805335 | BY9: 23805335 | BZ9: 23805335 | CA9: 23805335 | CB9: 23805335 | CC9: 30005711 | CD9: 30005711 | CE9: 30005711 | CF9: 30005711 | CG9: 30005711 | CH9: 30005711 | CI9: 30005711 | CJ9: 30005711 | CK9: 30005711 | CL9: 30005711 | CM9: 30005711 | CN9: 30005711 | CO9: 30005711 | CP9: 28313204 | CQ9: 28313204 | CR9: 28313204 | CS9: 28313204 | CT9: 28313204 | CU9: 28313204 | CV9: 28313204 | CW9: 28313204 | CX9: 28313204 | CY9: 28313204 | CZ9: 28313204 | DA9: 28313204 | DB9: 28313204 | DC9: 26279513 | DD9: 26279513 | DE9: 26279513 | DF9: 26279513 | DG9: 26279513 | DH9: 26279513 | DI9: 26279513 | DJ9: 26279513 | DK9: 26279513 | DL9: 26279513 | DM9: 26279513 | DN9: 26279513 | DO9: 26279513 | DP9: 23921092 | DQ9: 23921092 | DR9: 23921092 | DS9: 23921092 | DT9: 23921092 | DU9: 23921092 | DV9: 23921092 | DW9: 23921092 | DX9: 23921092 | DY9: 23921092 | DZ9: 23921092 | EA9: 23921092 | EB9: 23921092 | EC9: 32623118 | ED9: 32623118 | EE9: 32623118 | EF9: 32623118 | EG9: 32623118 | EH9: 32623118 | EI9: 32623118 | EJ9: 32623118 | EK9: 32623118 | EL9: 32623118 | EM9: 32623118 | EN9: 32623118 | EO9: 32623118 | EP9: 31388552 | EQ9: 31388552 | ER9: 31388552 | ES9: 31388552 | ET9: 31388552 | EU9: 31388552 | EV9: 31388552 | EW9: 31388552 | EX9: 31388552 | EY9: 31388552 | EZ9: 31388552 | FA9: 31388552 | FB9: 31388552 | FC9: 32099544 | FD9: 32099544 | FE9: 32099544 | FF9: 32099544 | FG9: 32099544 | FH9: 32099544 | FI9: 32099544 | FJ9: 32099544 | FK9: 32099544 | FL9: 32099544 | FM9: 32099544 | FN9: 32099544 | FO9: 32099544
B10: SERVIU Arica y Parinacota | C10: 5502314 | D10: 5502314 | E10: 5502314 | F10: 5502314 | G10: 5502314 | H10: 5502314 | I10: 5502314 | J10: 5502314 | K10: 5502314 | L10: 5502314 | M10: 5502314 | N10: 5502314 | O10: 5502314 | P10: 7116496 | Q10: 7116496 | R10: 7116496 | S10: 7116496 | T10: 7116496 | U10: 7116496 | V10: 7116496 | W10: 7116496 | X10: 7116496 | Y10: 7116496 | Z10: 7116496 | AA10: 7116496 | AB10: 7116496 | AC10: 7118243 | AD10: 7118243 | AE10: 7118243 | AF10: 7118243 | AG10: 7118243 | AH10: 7118243 | AI10: 7118243 | AJ10: 7118243 | AK10: 7118243 | AL10: 7118243 | AM10: 7118243 | AN10: 7118243 | AO10: 7118243 | AP10: 6360483 | AQ10: 6360483 | AR10: 6360483 | AS10: 6360483 | AT10: 6360483 | AU10: 6360483 | AV10: 6360483 | AW10: 6360483 | AX10: 6360483 | AY10: 6360483 | AZ10: 6360483 | BA10: 6360483 | BB10: 6360483 | BC10: 8905218 | BD10: 8905218 | BE10: 8905218 | BF10: 8905218 | BG10: 8905218 | BH10: 8905218 | BI10: 8905218 | BJ10: 8905218 | BK10: 8905218 | BL10: 8905218 | BM10: 8905218 | BN10: 8905218 | BO10: 8905218 | BP10: 5657692 | BQ10: 5657692 | BR10: 5657692 | BS10: 5657692 | BT10: 5657692 | BU10: 5657692 | BV10: 5657692 | BW10: 5657692 | BX10: 5657692 | BY10: 5657692 | BZ10: 5657692 | CA10: 5657692 | CB10: 5657692 | CC10: 8447722 | CD10: 8447722 | CE10: 8447722 | CF10: 8447722 | CG10: 8447722 | CH10: 8447722 | CI10: 8447722 | CJ10: 8447722 | CK10: 8447722 | CL10: 8447722 | CM10: 8447722 | CN10: 8447722 | CO10: 8447722 | CP10: 9734344 | CQ10: 9734344 | CR10: 9734344 | CS10: 9734344 | CT10: 9734344 | CU10: 9734344 | CV10: 9734344 | CW10: 9734344 | CX10: 9734344 | CY10: 9734344 | CZ10: 9734344 | DA10: 9734344 | DB10: 9734344 | DC10: 8027524 | DD10: 8027524 | DE10: 8027524 | DF10: 8027524 | DG10: 8027524 | DH10: 8027524 | DI10: 8027524 | DJ10: 8027524 | DK10: 8027524 | DL10: 8027524 | DM10: 8027524 | DN10: 8027524 | DO10: 8027524 | DP10: 9623696 | DQ10: 9623696 | DR10: 9623696 | DS10: 9623696 | DT10: 9623696 | DU10: 9623696 | DV10: 9623696 | DW10: 9623696 | DX10: 9623696 | DY10: 9623696 | DZ10: 9623696 | EA10: 9623696 | EB10: 9623696 | EC10: 7002032 | ED10: 7002032 | EE10: 7002032 | EF10: 7002032 | EG10: 7002032 | EH10: 7002032 | EI10: 7002032 | EJ10: 7002032 | EK10: 7002032 | EL10: 7002032 | EM10: 7002032 | EN10: 7002032 | EO10: 7002032 | EP10: 7819491 | EQ10: 7819491 | ER10: 7819491 | ES10: 7819491 | ET10: 7819491 | EU10: 7819491 | EV10: 7819491 | EW10: 7819491 | EX10: 7819491 | EY10: 7819491 | EZ10: 7819491 | FA10: 7819491 | FB10: 7819491 | FC10: 2323330 | FD10: 2323330 | FE10: 2323330 | FF10: 2323330 | FG10: 2323330 | FH10: 2323330 | FI10: 2323330 | FJ10: 2323330 | FK10: 2323330 | FL10: 2323330 | FM10: 2323330 | FN10: 2323330 | FO10: 2323330
B11: SERVIU Tarapacá | C11: 17762256 | D11: 17762256 | E11: 17762256 | F11: 17762256 | G11: 17762256 | H11: 17762256 | I11: 17762256 | J11: 17762256 | K11: 17762256 | L11: 17762256 | M11: 17762256 | N11: 17762256 | O11: 17762256 | P11: 21803885 | Q11: 21803885 | R11: 21803885 | S11: 21803885 | T11: 21803885 | U11: 21803885 | V11: 21803885 | W11: 21803885 | X11: 21803885 | Y11: 21803885 | Z11: 21803885 | AA11: 21803885 | AB11: 21803885 | AC11: 20753826 | AD11: 20753826 | AE11: 20753826 | AF11: 20753826 | AG11: 20753826 | AH11: 20753826 | AI11: 20753826 | AJ11: 20753826 | AK11: 20753826 | AL11: 20753826 | AM11: 20753826 | AN11: 20753826 | AO11: 20753826 | AP11: 19705469 | AQ11: 19705469 | AR11: 19705469 | AS11: 19705469 | AT11: 19705469 | AU11: 19705469 | AV11: 19705469 | AW11: 19705469 | AX11: 19705469 | AY11: 19705469 | AZ11: 19705469 | BA11: 19705469 | BB11: 19705469 | BC11: 20697782 | BD11: 20697782 | BE11: 20697782 | BF11: 20697782 | BG11: 20697782 | BH11: 20697782 | BI11: 20697782 | BJ11: 20697782 | BK11: 20697782 | BL11: 20697782 | BM11: 20697782 | BN11: 20697782 | BO11: 20697782 | BP11: 12609240 | BQ11: 12609240 | BR11: 12609240 | BS11: 12609240 | BT11: 12609240 | BU11: 12609240 | BV11: 12609240 | BW11: 12609240 | BX11: 12609240 | BY11: 12609240 | BZ11: 12609240 | CA11: 12609240 | CB11: 12609240 | CC11: 8704861 | CD11: 8704861 | CE11: 8704861 | CF11: 8704861 | CG11: 8704861 | CH11: 8704861 | CI11: 8704861 | CJ11: 8704861 | CK11: 8704861 | CL11: 8704861 | CM11: 8704861 | CN11: 8704861 | CO11: 8704861 | CP11: 7005376 | CQ11: 7005376 | CR11: 7005376 | CS11: 7005376 | CT11: 7005376 | CU11: 7005376 | CV11: 7005376 | CW11: 7005376 | CX11: 7005376 | CY11: 7005376 | CZ11: 7005376 | DA11: 7005376 | DB11: 7005376 | DC11: 4659283 | DD11: 4659283 | DE11: 4659283 | DF11: 4659283 | DG11: 4659283 | DH11: 4659283 | DI11: 4659283 | DJ11: 4659283 | DK11: 4659283 | DL11: 4659283 | DM11: 4659283 | DN11: 4659283 | DO11: 4659283 | DP11: 9013306 | DQ11: 9013306 | DR11: 9013306 | DS11: 9013306 | DT11: 9013306 | DU11: 9013306 | DV11: 9013306 | DW11: 9013306 | DX11: 9013306 | DY11: 9013306 | DZ11: 9013306 | EA11: 9013306 | EB11: 9013306 | EC11: 11846836 | ED11: 11846836 | EE11: 11846836 | EF11: 11846836 | EG11: 11846836 | EH11: 11846836 | EI11: 11846836 | EJ11: 11846836 | EK11: 11846836 | EL11: 11846836 | EM11: 11846836 | EN11: 11846836 | EO11: 11846836 | EP11: 9956278 | EQ11: 9956278 | ER11: 9956278 | ES11: 9956278 | ET11: 9956278 | EU11: 9956278 | EV11: 9956278 | EW11: 9956278 | EX11: 9956278 | EY11: 9956278 | EZ11: 9956278 | FA11: 9956278 | FB11: 9956278 | FC11: 8706346 | FD11: 8706346 | FE11: 8706346 | FF11: 8706346 | FG11: 8706346 | FH11: 8706346 | FI11: 8706346 | FJ11: 8706346 | FK11: 8706346 | FL11: 8706346 | FM11: 8706346 | FN11: 8706346 | FO11: 8706346
B12: SERVIU Antofagasta | C12: 8823051 | D12: 8823051 | E12: 8823051 | F12: 8823051 | G12: 8823051 | H12: 8823051 | I12: 8823051 | J12: 8823051 | K12: 8823051 | L12: 8823051 | M12: 8823051 | N12: 8823051 | O12: 8823051 | P12: 9265514 | Q12: 9265514 | R12: 9265514 | S12: 9265514 | T12: 9265514 | U12: 9265514 | V12: 9265514 | W12: 9265514 | X12: 9265514 | Y12: 9265514 | Z12: 9265514 | AA12: 9265514 | AB12: 9265514 | AC12: 17751422 | AD12: 17751422 | AE12: 17751422 | AF12: 17751422 | AG12: 17751422 | AH12: 17751422 | AI12: 17751422 | AJ12: 17751422 | AK12: 17751422 | AL12: 17751422 | AM12: 17751422 | AN12: 17751422 | AO12: 17751422 | AP12: 23414402 | AQ12: 23414402 | AR12: 23414402 | AS12: 23414402 | AT12: 23414402 | AU12: 23414402 | AV12: 23414402 | AW12: 23414402 | AX12: 23414402 | AY12: 23414402 | AZ12: 23414402 | BA12: 23414402 | BB12: 23414402 | BC12: 16518133 | BD12: 16518133 | BE12: 16518133 | BF12: 16518133 | BG12: 16518133 | BH12: 16518133 | BI12: 16518133 | BJ12: 16518133 | BK12: 16518133 | BL12: 16518133 | BM12: 16518133 | BN12: 16518133 | BO12: 16518133 | BP12: 9624594 | BQ12: 9624594 | BR12: 9624594 | BS12: 9624594 | BT12: 9624594 | BU12: 9624594 | BV12: 9624594 | BW12: 9624594 | BX12: 9624594 | BY12: 9624594 | BZ12: 9624594 | CA12: 9624594 | CB12: 9624594 | CC12: 25370209 | CD12: 25370209 | CE12: 25370209 | CF12: 25370209 | CG12: 25370209 | CH12: 25370209 | CI12: 25370209 | CJ12: 25370209 | CK12: 25370209 | CL12: 25370209 | CM12: 25370209 | CN12: 25370209 | CO12: 25370209 | CP12: 35181732 | CQ12: 35181732 | CR12: 35181732 | CS12: 35181732 | CT12: 35181732 | CU12: 35181732 | CV12: 35181732 | CW12: 35181732 | CX12: 35181732 | CY12: 35181732 | CZ12: 35181732 | DA12: 35181732 | DB12: 35181732 | DC12: 35548395 | DD12: 35548395 | DE12: 35548395 | DF12: 35548395 | DG12: 35548395 | DH12: 35548395 | DI12: 35548395 | DJ12: 35548395 | DK12: 35548395 | DL12: 35548395 | DM12: 35548395 | DN12: 35548395 | DO12: 35548395 | DP12: 30263070 | DQ12: 30263070 | DR12: 30263070 | DS12: 30263070 | DT12: 30263070 | DU12: 30263070 | DV12: 30263070 | DW12: 30263070 | DX12: 30263070 | DY12: 30263070 | DZ12: 30263070 | EA12: 30263070 | EB12: 30263070 | EC12: 10878804 | ED12: 10878804 | EE12: 10878804 | EF12: 10878804 | EG12: 10878804 | EH12: 10878804 | EI12: 10878804 | EJ12: 10878804 | EK12: 10878804 | EL12: 10878804 | EM12: 10878804 | EN12: 10878804 | EO12: 10878804 | EP12: 13585888 | EQ12: 13585888 | ER12: 13585888 | ES12: 13585888 | ET12: 13585888 | EU12: 13585888 | EV12: 13585888 | EW12: 13585888 | EX12: 13585888 | EY12: 13585888 | EZ12: 13585888 | FA12: 13585888 | FB12: 13585888 | FC12: 13197867 | FD12: 13197867 | FE12: 13197867 | FF12: 13197867 | FG12: 13197867 | FH12: 13197867 | FI12: 13197867 | FJ12: 13197867 | FK12: 13197867 | FL12: 13197867 | FM12: 13197867 | FN12: 13197867 | FO12: 13197867
B13: SERVIU Atacama | C13: 5303372 | D13: 5303372 | E13: 5303372 | F13: 5303372 | G13: 5303372 | H13: 5303372 | I13: 5303372 | J13: 5303372 | K13: 5303372 | L13: 5303372 | M13: 5303372 | N13: 5303372 | O13: 5303372 | P13: 10483676 | Q13: 10483676 | R13: 10483676 | S13: 10483676 | T13: 10483676 | U13: 10483676 | V13: 10483676 | W13: 10483676 | X13: 10483676 | Y13: 10483676 | Z13: 10483676 | AA13: 10483676 | AB13: 10483676 | AC13: 7956960 | AD13: 7956960 | AE13: 7956960 | AF13: 7956960 | AG13: 7956960 | AH13: 7956960 | AI13: 7956960 | AJ13: 7956960 | AK13: 7956960 | AL13: 7956960 | AM13: 7956960 | AN13: 7956960 | AO13: 7956960 | AP13: 22558714 | AQ13: 22558714 | AR13: 22558714 | AS13: 22558714 | AT13: 22558714 | AU13: 22558714 | AV13: 22558714 | AW13: 22558714 | AX13: 22558714 | AY13: 22558714 | AZ13: 22558714 | BA13: 22558714 | BB13: 22558714 | BC13: 26064643 | BD13: 26064643 | BE13: 26064643 | BF13: 26064643 | BG13: 26064643 | BH13: 26064643 | BI13: 26064643 | BJ13: 26064643 | BK13: 26064643 | BL13: 26064643 | BM13: 26064643 | BN13: 26064643 | BO13: 26064643 | BP13: 16889432 | BQ13: 16889432 | BR13: 16889432 | BS13: 16889432 | BT13: 16889432 | BU13: 16889432 | BV13: 16889432 | BW13: 16889432 | BX13: 16889432 | BY13: 16889432 | BZ13: 16889432 | CA13: 16889432 | CB13: 16889432 | CC13: 17341145 | CD13: 17341145 | CE13: 17341145 | CF13: 17341145 | CG13: 17341145 | CH13: 17341145 | CI13: 17341145 | CJ13: 17341145 | CK13: 17341145 | CL13: 17341145 | CM13: 17341145 | CN13: 17341145 | CO13: 17341145 | CP13: 18709251 | CQ13: 18709251 | CR13: 18709251 | CS13: 18709251 | CT13: 18709251 | CU13: 18709251 | CV13: 18709251 | CW13: 18709251 | CX13: 18709251 | CY13: 18709251 | CZ13: 18709251 | DA13: 18709251 | DB13: 18709251 | DC13: 24875325 | DD13: 24875325 | DE13: 24875325 | DF13: 24875325 | DG13: 24875325 | DH13: 24875325 | DI13: 24875325 | DJ13: 24875325 | DK13: 24875325 | DL13: 24875325 | DM13: 24875325 | DN13: 24875325 | DO13: 24875325 | DP13: 21315123 | DQ13: 21315123 | DR13: 21315123 | DS13: 21315123 | DT13: 21315123 | DU13: 21315123 | DV13: 21315123 | DW13: 21315123 | DX13: 21315123 | DY13: 21315123 | DZ13: 21315123 | EA13: 21315123 | EB13: 21315123 | EC13: 21518444 | ED13: 21518444 | EE13: 21518444 | EF13: 21518444 | EG13: 21518444 | EH13: 21518444 | EI13: 21518444 | EJ13: 21518444 | EK13: 21518444 | EL13: 21518444 | EM13: 21518444 | EN13: 21518444 | EO13: 21518444 | EP13: 24183340 | EQ13: 24183340 | ER13: 24183340 | ES13: 24183340 | ET13: 24183340 | EU13: 24183340 | EV13: 24183340 | EW13: 24183340 | EX13: 24183340 | EY13: 24183340 | EZ13: 24183340 | FA13: 24183340 | FB13: 24183340 | FC13: 9416801 | FD13: 9416801 | FE13: 9416801 | FF13: 9416801 | FG13: 9416801 | FH13: 9416801 | FI13: 9416801 | FJ13: 9416801 | FK13: 9416801 | FL13: 9416801 | FM13: 9416801 | FN13: 9416801 | FO13: 9416801
B14: SERVIU Coquimbo | C14: 16064354 | D14: 16064354 | E14: 16064354 | F14: 16064354 | G14: 16064354 | H14: 16064354 | I14: 16064354 | J14: 16064354 | K14: 16064354 | L14: 16064354 | M14: 16064354 | N14: 16064354 | O14: 16064354 | P14: 19283793 | Q14: 19283793 | R14: 19283793 | S14: 19283793 | T14: 19283793 | U14: 19283793 | V14: 19283793 | W14: 19283793 | X14: 19283793 | Y14: 19283793 | Z14: 19283793 | AA14: 19283793 | AB14: 19283793 | AC14: 18570059 | AD14: 18570059 | AE14: 18570059 | AF14: 18570059 | AG14: 18570059 | AH14: 18570059 | AI14: 18570059 | AJ14: 18570059 | AK14: 18570059 | AL14: 18570059 | AM14: 18570059 | AN14: 18570059 | AO14: 18570059 | AP14: 27391856 | AQ14: 27391856 | AR14: 27391856 | AS14: 27391856 | AT14: 27391856 | AU14: 27391856 | AV14: 27391856 | AW14: 27391856 | AX14: 27391856 | AY14: 27391856 | AZ14: 27391856 | BA14: 27391856 | BB14: 27391856 | BC14: 16967208 | BD14: 16967208 | BE14: 16967208 | BF14: 16967208 | BG14: 16967208 | BH14: 16967208 | BI14: 16967208 | BJ14: 16967208 | BK14: 16967208 | BL14: 16967208 | BM14: 16967208 | BN14: 16967208 | BO14: 16967208 | BP14: 14997280 | BQ14: 14997280 | BR14: 14997280 | BS14: 14997280 | BT14: 14997280 | BU14: 14997280 | BV14: 14997280 | BW14: 14997280 | BX14: 14997280 | BY14: 14997280 | BZ14: 14997280 | CA14: 14997280 | CB14: 14997280 | CC14: 15408322 | CD14: 15408322 | CE14: 15408322 | CF14: 15408322 | CG14: 15408322 | CH14: 15408322 | CI14: 15408322 | CJ14: 15408322 | CK14: 15408322 | CL14: 15408322 | CM14: 15408322 | CN14: 15408322 | CO14: 15408322 | CP14: 16689514 | CQ14: 16689514 | CR14: 16689514 | CS14: 16689514 | CT14: 16689514 | CU14: 16689514 | CV14: 16689514 | CW14: 16689514 | CX14: 16689514 | CY14: 16689514 | CZ14: 16689514 | DA14: 16689514 | DB14: 16689514 | DC14: 29291800 | DD14: 29291800 | DE14: 29291800 | DF14: 29291800 | DG14: 29291800 | DH14: 29291800 | DI14: 29291800 | DJ14: 29291800 | DK14: 29291800 | DL14: 29291800 | DM14: 29291800 | DN14: 29291800 | DO14: 29291800 | DP14: 36352142 | DQ14: 36352142 | DR14: 36352142 | DS14: 36352142 | DT14: 36352142 | DU14: 36352142 | DV14: 36352142 | DW14: 36352142 | DX14: 36352142 | DY14: 36352142 | DZ14: 36352142 | EA14: 36352142 | EB14: 36352142 | EC14: 38254690 | ED14: 38254690 | EE14: 38254690 | EF14: 38254690 | EG14: 38254690 | EH14: 38254690 | EI14: 38254690 | EJ14: 38254690 | EK14: 38254690 | EL14: 38254690 | EM14: 38254690 | EN14: 38254690 | EO14: 38254690 | EP14: 27966487 | EQ14: 27966487 | ER14: 27966487 | ES14: 27966487 | ET14: 27966487 | EU14: 27966487 | EV14: 27966487 | EW14: 27966487 | EX14: 27966487 | EY14: 27966487 | EZ14: 27966487 | FA14: 27966487 | FB14: 27966487 | FC14: 30615904 | FD14: 30615904 | FE14: 30615904 | FF14: 30615904 | FG14: 30615904 | FH14: 30615904 | FI14: 30615904 | FJ14: 30615904 | FK14: 30615904 | FL14: 30615904 | FM14: 30615904 | FN14: 30615904 | FO14: 30615904
B15: SERVIU Valparaíso | C15: 18833256 | D15: 18833256 | E15: 18833256 | F15: 18833256 | G15: 18833256 | H15: 18833256 | I15: 18833256 | J15: 18833256 | K15: 18833256 | L15: 18833256 | M15: 18833256 | N15: 18833256 | O15: 18833256 | P15: 34473321 | Q15: 34473321 | R15: 34473321 | S15: 34473321 | T15: 34473321 | U15: 34473321 | V15: 34473321 | W15: 34473321 | X15: 34473321 | Y15: 34473321 | Z15: 34473321 | AA15: 34473321 | AB15: 34473321 | AC15: 32958542 | AD15: 32958542 | AE15: 32958542 | AF15: 32958542 | AG15: 32958542 | AH15: 32958542 | AI15: 32958542 | AJ15: 32958542 | AK15: 32958542 | AL15: 32958542 | AM15: 32958542 | AN15: 32958542 | AO15: 32958542 | AP15: 41283218 | AQ15: 41283218 | AR15: 41283218 | AS15: 41283218 | AT15: 41283218 | AU15: 41283218 | AV15: 41283218 | AW15: 41283218 | AX15: 41283218 | AY15: 41283218 | AZ15: 41283218 | BA15: 41283218 | BB15: 41283218 | BC15: 30569054 | BD15: 30569054 | BE15: 30569054 | BF15: 30569054 | BG15: 30569054 | BH15: 30569054 | BI15: 30569054 | BJ15: 30569054 | BK15: 30569054 | BL15: 30569054 | BM15: 30569054 | BN15: 30569054 | BO15: 30569054 | BP15: 28738435 | BQ15: 28738435 | BR15: 28738435 | BS15: 28738435 | BT15: 28738435 | BU15: 28738435 | BV15: 28738435 | BW15: 28738435 | BX15: 28738435 | BY15: 28738435 | BZ15: 28738435 | CA15: 28738435 | CB15: 28738435 | CC15: 33362165 | CD15: 33362165 | CE15: 33362165 | CF15: 33362165 | CG15: 33362165 | CH15: 33362165 | CI15: 33362165 | CJ15: 33362165 | CK15: 33362165 | CL15: 33362165 | CM15: 33362165 | CN15: 33362165 | CO15: 33362165 | CP15: 53755591 | CQ15: 53755591 | CR15: 53755591 | CS15: 53755591 | CT15: 53755591 | CU15: 53755591 | CV15: 53755591 | CW15: 53755591 | CX15: 53755591 | CY15: 53755591 | CZ15: 53755591 | DA15: 53755591 | DB15: 53755591 | DC15: 43170852 | DD15: 43170852 | DE15: 43170852 | DF15: 43170852 | DG15: 43170852 | DH15: 43170852 | DI15: 43170852 | DJ15: 43170852 | DK15: 43170852 | DL15: 43170852 | DM15: 43170852 | DN15: 43170852 | DO15: 43170852 | DP15: 40478579 | DQ15: 40478579 | DR15: 40478579 | DS15: 40478579 | DT15: 40478579 | DU15: 40478579 | DV15: 40478579 | DW15: 40478579 | DX15: 40478579 | DY15: 40478579 | DZ15: 40478579 | EA15: 40478579 | EB15: 40478579 | EC15: 44262543 | ED15: 44262543 | EE15: 44262543 | EF15: 44262543 | EG15: 44262543 | EH15: 44262543 | EI15: 44262543 | EJ15: 44262543 | EK15: 44262543 | EL15: 44262543 | EM15: 44262543 | EN15: 44262543 | EO15: 44262543 | EP15: 42009797 | EQ15: 42009797 | ER15: 42009797 | ES15: 42009797 | ET15: 42009797 | EU15: 42009797 | EV15: 42009797 | EW15: 42009797 | EX15: 42009797 | EY15: 42009797 | EZ15: 42009797 | FA15: 42009797 | FB15: 42009797 | FC15: 36533880 | FD15: 36533880 | FE15: 36533880 | FF15: 36533880 | FG15: 36533880 | FH15: 36533880 | FI15: 36533880 | FJ15: 36533880 | FK15: 36533880 | FL15: 36533880 | FM15: 36533880 | FN15: 36533880 | FO15: 36533880
B16: SERVIU Metropolitano | C16: 58929368 | D16: 58929368 | E16: 58929368 | F16: 58929368 | G16: 58929368 | H16: 58929368 | I16: 58929368 | J16: 58929368 | K16: 58929368 | L16: 58929368 | M16: 58929368 | N16: 58929368 | O16: 58929368 | P16: 63938761 | Q16: 63938761 | R16: 63938761 | S16: 63938761 | T16: 63938761 | U16: 63938761 | V16: 63938761 | W16: 63938761 | X16: 63938761 | Y16: 63938761 | Z16: 63938761 | AA16: 63938761 | AB16: 63938761 | AC16: 60602895 | AD16: 60602895 | AE16: 60602895 | AF16: 60602895 | AG16: 60602895 | AH16: 60602895 | AI16: 60602895 | AJ16: 60602895 | AK16: 60602895 | AL16: 60602895 | AM16: 60602895 | AN16: 60602895 | AO16: 60602895 | AP16: 56615435 | AQ16: 56615435 | AR16: 56615435 | AS16: 56615435 | AT16: 56615435 | AU16: 56615435 | AV16: 56615435 | AW16: 56615435 | AX16: 56615435 | AY16: 56615435 | AZ16: 56615435 | BA16: 56615435 | BB16: 56615435 | BC16: 45393646 | BD16: 45393646 | BE16: 45393646 | BF16: 45393646 | BG16: 45393646 | BH16: 45393646 | BI16: 45393646 | BJ16: 45393646 | BK16: 45393646 | BL16: 45393646 | BM16: 45393646 | BN16: 45393646 | BO16: 45393646 | BP16: 50282027 | BQ16: 50282027 | BR16: 50282027 | BS16: 50282027 | BT16: 50282027 | BU16: 50282027 | BV16: 50282027 | BW16: 50282027 | BX16: 50282027 | BY16: 50282027 | BZ16: 50282027 | CA16: 50282027 | CB16: 50282027 | CC16: 68935312 | CD16: 68935312 | CE16: 68935312 | CF16: 68935312 | CG16: 68935312 | CH16: 68935312 | CI16: 68935312 | CJ16: 68935312 | CK16: 68935312 | CL16: 68935312 | CM16: 68935312 | CN16: 68935312 | CO16: 68935312 | CP16: 75469606 | CQ16: 75469606 | CR16: 75469606 | CS16: 75469606 | CT16: 75469606 | CU16: 75469606 | CV16: 75469606 | CW16: 75469606 | CX16: 75469606 | CY16: 75469606 | CZ16: 75469606 | DA16: 75469606 | DB16: 75469606 | DC16: 100098472 | DD16: 100098472 | DE16: 100098472 | DF16: 100098472 | DG16: 100098472 | DH16: 100098472 | DI16: 100098472 | DJ16: 100098472 | DK16: 100098472 | DL16: 100098472 | DM16: 100098472 | DN16: 100098472 | DO16: 100098472 | DP16: 105488522 | DQ16: 105488522 | DR16: 105488522 | DS16: 105488522 | DT16: 105488522 | DU16: 105488522 | DV16: 105488522 | DW16: 105488522 | DX16: 105488522 | DY16: 105488522 | DZ16: 105488522 | EA16: 105488522 | EB16: 105488522 | EC16: 87253576 | ED16: 87253576 | EE16: 87253576 | EF16: 87253576 | EG16: 87253576 | EH16: 87253576 | EI16: 87253576 | EJ16: 87253576 | EK16: 87253576 | EL16: 87253576 | EM16: 87253576 | EN16: 87253576 | EO16: 87253576 | EP16: 74587862 | EQ16: 74587862 | ER16: 74587862 | ES16: 74587862 | ET16: 74587862 | EU16: 74587862 | EV16: 74587862 | EW16: 74587862 | EX16: 74587862 | EY16: 74587862 | EZ16: 74587862 | FA16: 74587862 | FB16: 74587862 | FC16: 90590002 | FD16: 90590002 | FE16: 90590002 | FF16: 90590002 | FG16: 90590002 | FH16: 90590002 | FI16: 90590002 | FJ16: 90590002 | FK16: 90590002 | FL16: 90590002 | FM16: 90590002 | FN16: 90590002 | FO16: 90590002
B17: SERVIU O'Higgins | C17: 26277535 | D17: 26277535 | E17: 26277535 | F17: 26277535 | G17: 26277535 | H17: 26277535 | I17: 26277535 | J17: 26277535 | K17: 26277535 | L17: 26277535 | M17: 26277535 | N17: 26277535 | O17: 26277535 | P17: 18864208 | Q17: 18864208 | R17: 18864208 | S17: 18864208 | T17: 18864208 | U17: 18864208 | V17: 18864208 | W17: 18864208 | X17: 18864208 | Y17: 18864208 | Z17: 18864208 | AA17: 18864208 | AB17: 18864208 | AC17: 16417514 | AD17: 16417514 | AE17: 16417514 | AF17: 16417514 | AG17: 16417514 | AH17: 16417514 | AI17: 16417514 | AJ17: 16417514 | AK17: 16417514 | AL17: 16417514 | AM17: 16417514 | AN17: 16417514 | AO17: 16417514 | AP17: 7822380 | AQ17: 7822380 | AR17: 7822380 | AS17: 7822380 | AT17: 7822380 | AU17: 7822380 | AV17: 7822380 | AW17: 7822380 | AX17: 7822380 | AY17: 7822380 | AZ17: 7822380 | BA17: 7822380 | BB17: 7822380 | BC17: 14195819 | BD17: 14195819 | BE17: 14195819 | BF17: 14195819 | BG17: 14195819 | BH17: 14195819 | BI17: 14195819 | BJ17: 14195819 | BK17: 14195819 | BL17: 14195819 | BM17: 14195819 | BN17: 14195819 | BO17: 14195819 | BP17: 10934837 | BQ17: 10934837 | BR17: 10934837 | BS17: 10934837 | BT17: 10934837 | BU17: 10934837 | BV17: 10934837 | BW17: 10934837 | BX17: 10934837 | BY17: 10934837 | BZ17: 10934837 | CA17: 10934837 | CB17: 10934837 | CC17: 12638831 | CD17: 12638831 | CE17: 12638831 | CF17: 12638831 | CG17: 12638831 | CH17: 12638831 | CI17: 12638831 | CJ17: 12638831 | CK17: 12638831 | CL17: 12638831 | CM17: 12638831 | CN17: 12638831 | CO17: 12638831 | CP17: 9595472 | CQ17: 9595472 | CR17: 9595472 | CS17: 9595472 | CT17: 9595472 | CU17: 9595472 | CV17: 9595472 | CW17: 9595472 | CX17: 9595472 | CY17: 9595472 | CZ17: 9595472 | DA17: 9595472 | DB17: 9595472 | DC17: 11870060 | DD17: 11870060 | DE17: 11870060 | DF17: 11870060 | DG17: 11870060 | DH17: 11870060 | DI17: 11870060 | DJ17: 11870060 | DK17: 11870060 | DL17: 11870060 | DM17: 11870060 | DN17: 11870060 | DO17: 11870060 | DP17: 16473882 | DQ17: 16473882 | DR17: 16473882 | DS17: 16473882 | DT17: 16473882 | DU17: 16473882 | DV17: 16473882 | DW17: 16473882 | DX17: 16473882 | DY17: 16473882 | DZ17: 16473882 | EA17: 16473882 | EB17: 16473882 | EC17: 16690085 | ED17: 16690085 | EE17: 16690085 | EF17: 16690085 | EG17: 16690085 | EH17: 16690085 | EI17: 16690085 | EJ17: 16690085 | EK17: 16690085 | EL17: 16690085 | EM17: 16690085 | EN17: 16690085 | EO17: 16690085 | EP17: 17865780 | EQ17: 17865780 | ER17: 17865780 | ES17: 17865780 | ET17: 17865780 | EU17: 17865780 | EV17: 17865780 | EW17: 17865780 | EX17: 17865780 | EY17: 17865780 | EZ17: 17865780 | FA17: 17865780 | FB17: 17865780 | FC17: 14196992 | FD17: 14196992 | FE17: 14196992 | FF17: 14196992 | FG17: 14196992 | FH17: 14196992 | FI17: 14196992 | FJ17: 14196992 | FK17: 14196992 | FL17: 14196992 | FM17: 14196992 | FN17: 14196992 | FO17: 14196992
B18: SERVIU Maule | C18: 18959297 | D18: 18959297 | E18: 18959297 | F18: 18959297 | G18: 18959297 | H18: 18959297 | I18: 18959297 | J18: 18959297 | K18: 18959297 | L18: 18959297 | M18: 18959297 | N18: 18959297 | O18: 18959297 | P18: 28078883 | Q18: 28078883 | R18: 28078883 | S18: 28078883 | T18: 28078883 | U18: 28078883 | V18: 28078883 | W18: 28078883 | X18: 28078883 | Y18: 28078883 | Z18: 28078883 | AA18: 28078883 | AB18: 28078883 | AC18: 27091258 | AD18: 27091258 | AE18: 27091258 | AF18: 27091258 | AG18: 27091258 | AH18: 27091258 | AI18: 27091258 | AJ18: 27091258 | AK18: 27091258 | AL18: 27091258 | AM18: 27091258 | AN18: 27091258 | AO18: 27091258 | AP18: 41060039 | AQ18: 41060039 | AR18: 41060039 | AS18: 41060039 | AT18: 41060039 | AU18: 41060039 | AV18: 41060039 | AW18: 41060039 | AX18: 41060039 | AY18: 41060039 | AZ18: 41060039 | BA18: 41060039 | BB18: 41060039 | BC18: 44459639 | BD18: 44459639 | BE18: 44459639 | BF18: 44459639 | BG18: 44459639 | BH18: 44459639 | BI18: 44459639 | BJ18: 44459639 | BK18: 44459639 | BL18: 44459639 | BM18: 44459639 | BN18: 44459639 | BO18: 44459639 | BP18: 36664986 | BQ18: 36664986 | BR18: 36664986 | BS18: 36664986 | BT18: 36664986 | BU18: 36664986 | BV18: 36664986 | BW18: 36664986 | BX18: 36664986 | BY18: 36664986 | BZ18: 36664986 | CA18: 36664986 | CB18: 36664986 | CC18: 28819307 | CD18: 28819307 | CE18: 28819307 | CF18: 28819307 | CG18: 28819307 | CH18: 28819307 | CI18: 28819307 | CJ18: 28819307 | CK18: 28819307 | CL18: 28819307 | CM18: 28819307 | CN18: 28819307 | CO18: 28819307 | CP18: 32317785 | CQ18: 32317785 | CR18: 32317785 | CS18: 32317785 | CT18: 32317785 | CU18: 32317785 | CV18: 32317785 | CW18: 32317785 | CX18: 32317785 | CY18: 32317785 | CZ18: 32317785 | DA18: 32317785 | DB18: 32317785 | DC18: 41575245 | DD18: 41575245 | DE18: 41575245 | DF18: 41575245 | DG18: 41575245 | DH18: 41575245 | DI18: 41575245 | DJ18: 41575245 | DK18: 41575245 | DL18: 41575245 | DM18: 41575245 | DN18: 41575245 | DO18: 41575245 | DP18: 34076619 | DQ18: 34076619 | DR18: 34076619 | DS18: 34076619 | DT18: 34076619 | DU18: 34076619 | DV18: 34076619 | DW18: 34076619 | DX18: 34076619 | DY18: 34076619 | DZ18: 34076619 | EA18: 34076619 | EB18: 34076619 | EC18: 28318956 | ED18: 28318956 | EE18: 28318956 | EF18: 28318956 | EG18: 28318956 | EH18: 28318956 | EI18: 28318956 | EJ18: 28318956 | EK18: 28318956 | EL18: 28318956 | EM18: 28318956 | EN18: 28318956 | EO18: 28318956 | EP18: 30628977 | EQ18: 30628977 | ER18: 30628977 | ES18: 30628977 | ET18: 30628977 | EU18: 30628977 | EV18: 30628977 | EW18: 30628977 | EX18: 30628977 | EY18: 30628977 | EZ18: 30628977 | FA18: 30628977 | FB18: 30628977 | FC18: 25030745 | FD18: 25030745 | FE18: 25030745 | FF18: 25030745 | FG18: 25030745 | FH18: 25030745 | FI18: 25030745 | FJ18: 25030745 | FK18: 25030745 | FL18: 25030745 | FM18: 25030745 | FN18: 25030745 | FO18: 25030745
