Workbook

Sheet Dashboard
B2: MINISTERIO DE VIVIENDA Y URBANISMO — DASHBOARD DE INVERSIÓN Y EJECUCIÓN PRESUPUESTARIA
B3: Visualizador Analítico Interactivo Tabla a Tabla | Subtítulos 33 (Subsidios/Capital), 31 (Inversión Directa), 29 (Activos) y Consolidado | Cifras en miles de pesos ($)
B4: AÑO SELECCIONADO: | C4: 2024 | D4: COBERTURA TEMPORAL: | F4: 2021 - 2026 (Ene - Dic) | H4: UNIDAD MONETARIA: | J4: Miles de $ Corrientes (DIPRES)
B6: PRESUPUESTO LEY (INICIAL) | D6: PRESUPUESTO VIGENTE | F6: EJECUCIÓN ACUMULADA | H6: % CUMPLIMIENTO PRESUPUESTARIO | J6: SALDO POR EJECUTAR
B7: =D17 -> 3320541734 | D7: =E17 -> 3332768183 | F7: =F17 -> 3312699040 | H7: =H17 -> 0.99397824 | J7: =G17 -> 20069143
B9: Aprobado Ley de Presupuesto | D9: Presupuesto anual actualizado | F9: Total devengado en el ejercicio | H9: Ejecución devengada / Presupuesto vigente | J9: Monto disponible no devengado
B11: TABLA 1: RESUMEN CONSOLIDADO POR SUBTÍTULO PRESUPUESTARIO
B13: Subtítulo Presupuestario | C13: Cód. | D13: Presupuesto Ley | E13: Presupuesto Vigente | F13: Ejecución Acumulada | G13: Saldo por Ejecutar | H13: % Ejecución | I13: % Participación
B14: Subtítulo 33 – Transferencias de Capital (Subsidios) | C14: 33 | D14: =INDEX(MINVU_Mes_Corriente!$1:$300, 164, 3 + ($C$4 - 2021)*13 + 12) -> 2729162964 | E14: =INDEX(MINVU_Mes_Corriente!$1:$300, 186, 3 + ($C$4 - 2021)*13 + 12) -> 2913408485 | F14: =INDEX(MINVU_Mes_Corriente!$1:$300, 208, 3 + ($C$4 - 2021)*13 + 12) -> 2904924599 | G14: =E14 - F14 -> 8483886 | H14: =IF(E14>0, F14/E14, 0) -> 0.99708799 | I14: =IF($E$17>0, E14/$E$17, 0) -> 0.87417076
B15: Subtítulo 31 – Iniciativas de Inversión | C15: 31 | D15: =INDEX(MINVU_Mes_Corriente!$1:$300, 26, 3 + ($C$4 - 2021)*13 + 12) -> 560704016 | E15: =INDEX(MINVU_Mes_Corriente!$1:$300, 48, 3 + ($C$4 - 2021)*13 + 12) -> 400142072 | F15: =INDEX(MINVU_Mes_Corriente!$1:$300, 70, 3 + ($C$4 - 2021)*13 + 12) -> 388712182 | G15: =E15 - F15 -> 11429890 | H15: =IF(E15>0, F15/E15, 0) -> 0.97143542 | I15: =IF($E$17>0, E15/$E$17, 0) -> 0.12006298
B16: Subtítulo 29 – Activos No Financieros | C16: 29 | D16: =INDEX(MINVU_Mes_Corriente!$1:$300, 95, 3 + ($C$4 - 2021)*13 + 12) -> 30674754 | E16: =INDEX(MINVU_Mes_Corriente!$1:$300, 117, 3 + ($C$4 - 2021)*13 + 12) -> 19217626 | F16: =INDEX(MINVU_Mes_Corriente!$1:$300, 139, 3 + ($C$4 - 2021)*13 + 12) -> 19062259 | G16: =E16 - F16 -> 155367 | H16: =IF(E16>0, F16/E16, 0) -> 0.99191539 | I16: =IF($E$17>0, E16/$E$17, 0) -> 0.0057662654
B17: TOTAL INVERSIÓN MINVU (33 + 31 + 29) | C17: TOTAL | D17: =SUM(D14:D16) -> 3320541734 | E17: =SUM(E14:E16) -> 3332768183 | F17: =SUM(F14:F16) -> 3312699040 | G17: =E17 - F17 -> 20069143 | H17: =IF(E17>0, F17/E17, 0) -> 0.99397824 | I17: =SUM(I14:I16) -> 1
B19: TABLA 2: DESGLOSE COMPLETO POR ENTIDAD / PROGRAMA / SERVIU (AÑO SELECCIONADO)
B21: Entidad / SERVIU Regional | C21: Subt. 33 Vigente | D21: Subt. 33 Ejecución | E21: Subt. 31 Vigente | F21: Subt. 31 Ejecución | G21: Subt. 29 Vigente | H21: Subt. 29 Ejecución | I21: Total Vigente | J21: Total Ejecución | K21: Saldo | L21: % Ejecución | M21: % Part. MINVU
B22: Subsecretaría y Programas Centrales | C22: =INDEX(MINVU_Mes_Corriente!$1:$300, 168, 3 + ($C$4 - 2021)*13 + 12) -> 253260952 | D22: =INDEX(MINVU_Mes_Corriente!$1:$300, 190, 3 + ($C$4 - 2021)*13 + 12) -> 249185192 | E22: =INDEX(MINVU_Mes_Corriente!$1:$300, 30, 3 + ($C$4 - 2021)*13 + 12) -> 1858597 | F22: =INDEX(MINVU_Mes_Corriente!$1:$300, 52, 3 + ($C$4 - 2021)*13 + 12) -> 1765056 | G22: =INDEX(MINVU_Mes_Corriente!$1:$300, 99, 3 + ($C$4 - 2021)*13 + 12) -> 3168714 | H22: =INDEX(MINVU_Mes_Corriente!$1:$300, 121, 3 + ($C$4 - 2021)*13 + 12) -> 3071041 | I22: =C22 + E22 + G22 -> 258288263 | J22: =D22 + F22 + H22 -> 254021289 | K22: =I22 - J22 -> 4266974 | L22: =IF(I22>0, J22/I22, 0) -> 0.9834798 | M22: =IF($I$40>0, I22/$I$40, 0) -> 0.077499619
B23: Parque Metropolitano (PARQUEMET) | C23: =INDEX(MINVU_Mes_Corriente!$1:$300, 169, 3 + ($C$4 - 2021)*13 + 12) -> 0 | D23: =INDEX(MINVU_Mes_Corriente!$1:$300, 191, 3 + ($C$4 - 2021)*13 + 12) -> 0 | E23: =INDEX(MINVU_Mes_Corriente!$1:$300, 31, 3 + ($C$4 - 2021)*13 + 12) -> 27933416 | F23: =INDEX(MINVU_Mes_Corriente!$1:$300, 53, 3 + ($C$4 - 2021)*13 + 12) -> 27847917 | G23: =INDEX(MINVU_Mes_Corriente!$1:$300, 100, 3 + ($C$4 - 2021)*13 + 12) -> 240920 | H23: =INDEX(MINVU_Mes_Corriente!$1:$300, 122, 3 + ($C$4 - 2021)*13 + 12) -> 240208 | I23: =C23 + E23 + G23 -> 28174336 | J23: =D23 + F23 + H23 -> 28088125 | K23: =I23 - J23 -> 86211 | L23: =IF(I23>0, J23/I23, 0) -> 0.99694009 | M23: =IF($I$40>0, I23/$I$40, 0) -> 0.0084537341
B24: SERVIU Arica y Parinacota | C24: =INDEX(MINVU_Mes_Corriente!$1:$300, 170, 3 + ($C$4 - 2021)*13 + 12) -> 83210671 | D24: =INDEX(MINVU_Mes_Corriente!$1:$300, 192, 3 + ($C$4 - 2021)*13 + 12) -> 83196155 | E24: =INDEX(MINVU_Mes_Corriente!$1:$300, 32, 3 + ($C$4 - 2021)*13 + 12) -> 4403210 | F24: =INDEX(MINVU_Mes_Corriente!$1:$300, 54, 3 + ($C$4 - 2021)*13 + 12) -> 4379123 | G24: =INDEX(MINVU_Mes_Corriente!$1:$300, 101, 3 + ($C$4 - 2021)*13 + 12) -> 7496 | H24: =INDEX(MINVU_Mes_Corriente!$1:$300, 123, 3 + ($C$4 - 2021)*13 + 12) -> 7431 | I24: =C24 + E24 + G24 -> 87621377 | J24: =D24 + F24 + H24 -> 87582709 | K24: =I24 - J24 -> 38668 | L24: =IF(I24>0, J24/I24, 0) -> 0.99955869 | M24: =IF($I$40>0, I24/$I$40, 0) -> 0.026290871
B25: SERVIU Tarapacá | C25: =INDEX(MINVU_Mes_Corriente!$1:$300, 171, 3 + ($C$4 - 2021)*13 + 12) -> 81745804 | D25: =INDEX(MINVU_Mes_Corriente!$1:$300, 193, 3 + ($C$4 - 2021)*13 + 12) -> 81667751 | E25: =INDEX(MINVU_Mes_Corriente!$1:$300, 33, 3 + ($C$4 - 2021)*13 + 12) -> 8998445 | F25: =INDEX(MINVU_Mes_Corriente!$1:$300, 55, 3 + ($C$4 - 2021)*13 + 12) -> 8453266 | G25: =INDEX(MINVU_Mes_Corriente!$1:$300, 102, 3 + ($C$4 - 2021)*13 + 12) -> 3479 | H25: =INDEX(MINVU_Mes_Corriente!$1:$300, 124, 3 + ($C$4 - 2021)*13 + 12) -> 3340 | I25: =C25 + E25 + G25 -> 90747728 | J25: =D25 + F25 + H25 -> 90124357 | K25: =I25 - J25 -> 623371 | L25: =IF(I25>0, J25/I25, 0) -> 0.99313073 | M25: =IF($I$40>0, I25/$I$40, 0) -> 0.027228935
B26: SERVIU Antofagasta | C26: =INDEX(MINVU_Mes_Corriente!$1:$300, 172, 3 + ($C$4 - 2021)*13 + 12) -> 73119497 | D26: =INDEX(MINVU_Mes_Corriente!$1:$300, 194, 3 + ($C$4 - 2021)*13 + 12) -> 73069447 | E26: =INDEX(MINVU_Mes_Corriente!$1:$300, 34, 3 + ($C$4 - 2021)*13 + 12) -> 15465604 | F26: =INDEX(MINVU_Mes_Corriente!$1:$300, 56, 3 + ($C$4 - 2021)*13 + 12) -> 14221677 | G26: =INDEX(MINVU_Mes_Corriente!$1:$300, 103, 3 + ($C$4 - 2021)*13 + 12) -> 6270 | H26: =INDEX(MINVU_Mes_Corriente!$1:$300, 125, 3 + ($C$4 - 2021)*13 + 12) -> 4665 | I26: =C26 + E26 + G26 -> 88591371 | J26: =D26 + F26 + H26 -> 87295789 | K26: =I26 - J26 -> 1295582 | L26: =IF(I26>0, J26/I26, 0) -> 0.98537575 | M26: =IF($I$40>0, I26/$I$40, 0) -> 0.026581918
B27: SERVIU Atacama | C27: =INDEX(MINVU_Mes_Corriente!$1:$300, 173, 3 + ($C$4 - 2021)*13 + 12) -> 50339570 | D27: =INDEX(MINVU_Mes_Corriente!$1:$300, 195, 3 + ($C$4 - 2021)*13 + 12) -> 50275024 | E27: =INDEX(MINVU_Mes_Corriente!$1:$300, 35, 3 + ($C$4 - 2021)*13 + 12) -> 8570431 | F27: =INDEX(MINVU_Mes_Corriente!$1:$300, 57, 3 + ($C$4 - 2021)*13 + 12) -> 8070989 | G27: =INDEX(MINVU_Mes_Corriente!$1:$300, 104, 3 + ($C$4 - 2021)*13 + 12) -> 6646 | H27: =INDEX(MINVU_Mes_Corriente!$1:$300, 126, 3 + ($C$4 - 2021)*13 + 12) -> 6646 | I27: =C27 + E27 + G27 -> 58916647 | J27: =D27 + F27 + H27 -> 58352659 | K27: =I27 - J27 -> 563988 | L27: =IF(I27>0, J27/I27, 0) -> 0.99042736 | M27: =IF($I$40>0, I27/$I$40, 0) -> 0.017677991
B28: SERVIU Coquimbo | C28: =INDEX(MINVU_Mes_Corriente!$1:$300, 174, 3 + ($C$4 - 2021)*13 + 12) -> 107360177 | D28: =INDEX(MINVU_Mes_Corriente!$1:$300, 196, 3 + ($C$4 - 2021)*13 + 12) -> 106974951 | E28: =INDEX(MINVU_Mes_Corriente!$1:$300, 36, 3 + ($C$4 - 2021)*13 + 12) -> 18466482 | F28: =INDEX(MINVU_Mes_Corriente!$1:$300, 58, 3 + ($C$4 - 2021)*13 + 12) -> 18304746 | G28: =INDEX(MINVU_Mes_Corriente!$1:$300, 105, 3 + ($C$4 - 2021)*13 + 12) -> 6092813 | H28: =INDEX(MINVU_Mes_Corriente!$1:$300, 127, 3 + ($C$4 - 2021)*13 + 12) -> 6065343 | I28: =C28 + E28 + G28 -> 131919472 | J28: =D28 + F28 + H28 -> 131345040 | K28: =I28 - J28 -> 574432 | L28: =IF(I28>0, J28/I28, 0) -> 0.99564559 | M28: =IF($I$40>0, I28/$I$40, 0) -> 0.039582553
B29: SERVIU Valparaíso | C29: =INDEX(MINVU_Mes_Corriente!$1:$300, 175, 3 + ($C$4 - 2021)*13 + 12) -> 226125474 | D29: =INDEX(MINVU_Mes_Corriente!$1:$300, 197, 3 + ($C$4 - 2021)*13 + 12) -> 225998740 | E29: =INDEX(MINVU_Mes_Corriente!$1:$300, 37, 3 + ($C$4 - 2021)*13 + 12) -> 37750186 | F29: =INDEX(MINVU_Mes_Corriente!$1:$300, 59, 3 + ($C$4 - 2021)*13 + 12) -> 35664606 | G29: =INDEX(MINVU_Mes_Corriente!$1:$300, 106, 3 + ($C$4 - 2021)*13 + 12) -> 21887 | H29: =INDEX(MINVU_Mes_Corriente!$1:$300, 128, 3 + ($C$4 - 2021)*13 + 12) -> 21833 | I29: =C29 + E29 + G29 -> 263897547 | J29: =D29 + F29 + H29 -> 261685179 | K29: =I29 - J29 -> 2212368 | L29: =IF(I29>0, J29/I29, 0) -> 0.99161656 | M29: =IF($I$40>0, I29/$I$40, 0) -> 0.079182689
B30: SERVIU Metropolitano | C30: =INDEX(MINVU_Mes_Corriente!$1:$300, 176, 3 + ($C$4 - 2021)*13 + 12) -> 536507887 | D30: =INDEX(MINVU_Mes_Corriente!$1:$300, 198, 3 + ($C$4 - 2021)*13 + 12) -> 535781681 | E30: =INDEX(MINVU_Mes_Corriente!$1:$300, 38, 3 + ($C$4 - 2021)*13 + 12) -> 86087430 | F30: =INDEX(MINVU_Mes_Corriente!$1:$300, 60, 3 + ($C$4 - 2021)*13 + 12) -> 84329419 | G30: =INDEX(MINVU_Mes_Corriente!$1:$300, 107, 3 + ($C$4 - 2021)*13 + 12) -> 44560 | H30: =INDEX(MINVU_Mes_Corriente!$1:$300, 129, 3 + ($C$4 - 2021)*13 + 12) -> 44534 | I30: =C30 + E30 + G30 -> 622639877 | J30: =D30 + F30 + H30 -> 620155634 | K30: =I30 - J30 -> 2484243 | L30: =IF(I30>0, J30/I30, 0) -> 0.99601014 | M30: =IF($I$40>0, I30/$I$40, 0) -> 0.18682364
B31: SERVIU O'Higgins | C31: =INDEX(MINVU_Mes_Corriente!$1:$300, 177, 3 + ($C$4 - 2021)*13 + 12) -> 172944682 | D31: =INDEX(MINVU_Mes_Corriente!$1:$300, 199, 3 + ($C$4 - 2021)*13 + 12) -> 172843913 | E31: =INDEX(MINVU_Mes_Corriente!$1:$300, 39, 3 + ($C$4 - 2021)*13 + 12) -> 5515173 | F31: =INDEX(MINVU_Mes_Corriente!$1:$300, 61, 3 + ($C$4 - 2021)*13 + 12) -> 5186229 | G31: =INDEX(MINVU_Mes_Corriente!$1:$300, 108, 3 + ($C$4 - 2021)*13 + 12) -> 300457 | H31: =INDEX(MINVU_Mes_Corriente!$1:$300, 130, 3 + ($C$4 - 2021)*13 + 12) -> 300441 | I31: =C31 + E31 + G31 -> 178760312 | J31: =D31 + F31 + H31 -> 178330583 | K31: =I31 - J31 -> 429729 | L31: =IF(I31>0, J31/I31, 0) -> 0.99759606 | M31: =IF($I$40>0, I31/$I$40, 0) -> 0.053637188
B32: SERVIU Maule | C32: =INDEX(MINVU_Mes_Corriente!$1:$300, 178, 3 + ($C$4 - 2021)*13 + 12) -> 213444748 | D32: =INDEX(MINVU_Mes_Corriente!$1:$300, 200, 3 + ($C$4 - 2021)*13 + 12) -> 213325058 | E32: =INDEX(MINVU_Mes_Corriente!$1:$300, 40, 3 + ($C$4 - 2021)*13 + 12) -> 20053849 | F32: =INDEX(MINVU_Mes_Corriente!$1:$300, 62, 3 + ($C$4 - 2021)*13 + 12) -> 19302172 | G32: =INDEX(MINVU_Mes_Corriente!$1:$300, 109, 3 + ($C$4 - 2021)*13 + 12) -> 6865 | H32: =INDEX(MINVU_Mes_Corriente!$1:$300, 131, 3 + ($C$4 - 2021)*13 + 12) -> 6833 | I32: =C32 + E32 + G32 -> 233505462 | J32: =D32 + F32 + H32 -> 232634063 | K32: =I32 - J32 -> 871399 | L32: =IF(I32>0, J32/I32, 0) -> 0.99626819 | M32: =IF($I$40>0, I32/$I$40, 0) -> 0.070063518
B33: SERVIU Ñuble | C33: =INDEX(MINVU_Mes_Corriente!$1:$300, 179, 3 + ($C$4 - 2021)*13 + 12) -> 154702362 | D33: =INDEX(MINVU_Mes_Corriente!$1:$300, 201, 3 + ($C$4 - 2021)*13 + 12) -> 154664738 | E33: =INDEX(MINVU_Mes_Corriente!$1:$300, 41, 3 + ($C$4 - 2021)*13 + 12) -> 19120001 | F33: =INDEX(MINVU_Mes_Corriente!$1:$300, 63, 3 + ($C$4 - 2021)*13 + 12) -> 17950052 | G33: =INDEX(MINVU_Mes_Corriente!$1:$300, 110, 3 + ($C$4 - 2021)*13 + 12) -> 6270 | H33: =INDEX(MINVU_Mes_Corriente!$1:$300, 132, 3 + ($C$4 - 2021)*13 + 12) -> 6042 | I33: =C33 + E33 + G33 -> 173828633 | J33: =D33 + F33 + H33 -> 172620832 | K33: =I33 - J33 -> 1207801 | L33: =IF(I33>0, J33/I33, 0) -> 0.99305177 | M33: =IF($I$40>0, I33/$I$40, 0) -> 0.052157433
B34: SERVIU Biobío | C34: =INDEX(MINVU_Mes_Corriente!$1:$300, 180, 3 + ($C$4 - 2021)*13 + 12) -> 303934966 | D34: =INDEX(MINVU_Mes_Corriente!$1:$300, 202, 3 + ($C$4 - 2021)*13 + 12) -> 303859023 | E34: =INDEX(MINVU_Mes_Corriente!$1:$300, 42, 3 + ($C$4 - 2021)*13 + 12) -> 52850218 | F34: =INDEX(MINVU_Mes_Corriente!$1:$300, 64, 3 + ($C$4 - 2021)*13 + 12) -> 52001305 | G34: =INDEX(MINVU_Mes_Corriente!$1:$300, 111, 3 + ($C$4 - 2021)*13 + 12) -> 12960 | H34: =INDEX(MINVU_Mes_Corriente!$1:$300, 133, 3 + ($C$4 - 2021)*13 + 12) -> 12190 | I34: =C34 + E34 + G34 -> 356798144 | J34: =D34 + F34 + H34 -> 355872518 | K34: =I34 - J34 -> 925626 | L34: =IF(I34>0, J34/I34, 0) -> 0.99740574 | M34: =IF($I$40>0, I34/$I$40, 0) -> 0.10705759
B35: SERVIU La Araucanía | C35: =INDEX(MINVU_Mes_Corriente!$1:$300, 181, 3 + ($C$4 - 2021)*13 + 12) -> 266347073 | D35: =INDEX(MINVU_Mes_Corriente!$1:$300, 203, 3 + ($C$4 - 2021)*13 + 12) -> 265754901 | E35: =INDEX(MINVU_Mes_Corriente!$1:$300, 43, 3 + ($C$4 - 2021)*13 + 12) -> 36728957 | F35: =INDEX(MINVU_Mes_Corriente!$1:$300, 65, 3 + ($C$4 - 2021)*13 + 12) -> 36426224 | G35: =INDEX(MINVU_Mes_Corriente!$1:$300, 112, 3 + ($C$4 - 2021)*13 + 12) -> 12161 | H35: =INDEX(MINVU_Mes_Corriente!$1:$300, 134, 3 + ($C$4 - 2021)*13 + 12) -> 12134 | I35: =C35 + E35 + G35 -> 303088191 | J35: =D35 + F35 + H35 -> 302193259 | K35: =I35 - J35 -> 894932 | L35: =IF(I35>0, J35/I35, 0) -> 0.99704729 | M35: =IF($I$40>0, I35/$I$40, 0) -> 0.090941876
B36: SERVIU Los Ríos | C36: =INDEX(MINVU_Mes_Corriente!$1:$300, 182, 3 + ($C$4 - 2021)*13 + 12) -> 73852164 | D36: =INDEX(MINVU_Mes_Corriente!$1:$300, 204, 3 + ($C$4 - 2021)*13 + 12) -> 72195760 | E36: =INDEX(MINVU_Mes_Corriente!$1:$300, 44, 3 + ($C$4 - 2021)*13 + 12) -> 13330524 | F36: =INDEX(MINVU_Mes_Corriente!$1:$300, 66, 3 + ($C$4 - 2021)*13 + 12) -> 12655537 | G36: =INDEX(MINVU_Mes_Corriente!$1:$300, 113, 3 + ($C$4 - 2021)*13 + 12) -> 9216 | H36: =INDEX(MINVU_Mes_Corriente!$1:$300, 135, 3 + ($C$4 - 2021)*13 + 12) -> 9209 | I36: =C36 + E36 + G36 -> 87191904 | J36: =D36 + F36 + H36 -> 84860506 | K36: =I36 - J36 -> 2331398 | L36: =IF(I36>0, J36/I36, 0) -> 0.9732613 | M36: =IF($I$40>0, I36/$I$40, 0) -> 0.026162007
B37: SERVIU Los Lagos | C37: =INDEX(MINVU_Mes_Corriente!$1:$300, 183, 3 + ($C$4 - 2021)*13 + 12) -> 209110935 | D37: =INDEX(MINVU_Mes_Corriente!$1:$300, 205, 3 + ($C$4 - 2021)*13 + 12) -> 209043392 | E37: =INDEX(MINVU_Mes_Corriente!$1:$300, 45, 3 + ($C$4 - 2021)*13 + 12) -> 17300120 | F37: =INDEX(MINVU_Mes_Corriente!$1:$300, 67, 3 + ($C$4 - 2021)*13 + 12) -> 16578842 | G37: =INDEX(MINVU_Mes_Corriente!$1:$300, 114, 3 + ($C$4 - 2021)*13 + 12) -> 9262299 | H37: =INDEX(MINVU_Mes_Corriente!$1:$300, 136, 3 + ($C$4 - 2021)*13 + 12) -> 9235856 | I37: =C37 + E37 + G37 -> 235673354 | J37: =D37 + F37 + H37 -> 234858090 | K37: =I37 - J37 -> 815264 | L37: =IF(I37>0, J37/I37, 0) -> 0.9965407 | M37: =IF($I$40>0, I37/$I$40, 0) -> 0.070713995
B38: SERVIU Aysén | C38: =INDEX(MINVU_Mes_Corriente!$1:$300, 184, 3 + ($C$4 - 2021)*13 + 12) -> 40911462 | D38: =INDEX(MINVU_Mes_Corriente!$1:$300, 206, 3 + ($C$4 - 2021)*13 + 12) -> 40629172 | E38: =INDEX(MINVU_Mes_Corriente!$1:$300, 46, 3 + ($C$4 - 2021)*13 + 12) -> 7723948 | F38: =INDEX(MINVU_Mes_Corriente!$1:$300, 68, 3 + ($C$4 - 2021)*13 + 12) -> 7636879 | G38: =INDEX(MINVU_Mes_Corriente!$1:$300, 115, 3 + ($C$4 - 2021)*13 + 12) -> 6270 | H38: =INDEX(MINVU_Mes_Corriente!$1:$300, 137, 3 + ($C$4 - 2021)*13 + 12) -> 6224 | I38: =C38 + E38 + G38 -> 48641680 | J38: =D38 + F38 + H38 -> 48272275 | K38: =I38 - J38 -> 369405 | L38: =IF(I38>0, J38/I38, 0) -> 0.99240559 | M38: =IF($I$40>0, I38/$I$40, 0) -> 0.014594979
B39: SERVIU Magallanes | C39: =INDEX(MINVU_Mes_Corriente!$1:$300, 185, 3 + ($C$4 - 2021)*13 + 12) -> 66490061 | D39: =INDEX(MINVU_Mes_Corriente!$1:$300, 207, 3 + ($C$4 - 2021)*13 + 12) -> 66459701 | E39: =INDEX(MINVU_Mes_Corriente!$1:$300, 47, 3 + ($C$4 - 2021)*13 + 12) -> 17985481 | F39: =INDEX(MINVU_Mes_Corriente!$1:$300, 69, 3 + ($C$4 - 2021)*13 + 12) -> 17938143 | G39: =INDEX(MINVU_Mes_Corriente!$1:$300, 116, 3 + ($C$4 - 2021)*13 + 12) -> 8343 | H39: =INDEX(MINVU_Mes_Corriente!$1:$300, 138, 3 + ($C$4 - 2021)*13 + 12) -> 8289 | I39: =C39 + E39 + G39 -> 84483885 | J39: =D39 + F39 + H39 -> 84406133 | K39: =I39 - J39 -> 77752 | L39: =IF(I39>0, J39/I39, 0) -> 0.99907968 | M39: =IF($I$40>0, I39/$I$40, 0) -> 0.025349463
B40: TOTAL MINVU | C40: =SUM(C22:C39) -> 2913408485 | D40: =SUM(D22:D39) -> 2904924599 | E40: =SUM(E22:E39) -> 400142072 | F40: =SUM(F22:F39) -> 388712182 | G40: =SUM(G22:G39) -> 19217626 | H40: =SUM(H22:H39) -> 19062259 | I40: =SUM(I22:I39) -> 3332768183 | J40: =SUM(J22:J39) -> 3312699040 | K40: =SUM(K22:K39) -> 20069143 | L40: =IF(I40>0, J40/I40, 0) -> 0.99397824 | M40: =SUM(M22:M39) -> 1
B42: TABLA 3: EVOLUCIÓN MENSUAL DEL AÑO SELECCIONADO (ENERO A DICIEMBRE)
B44: Concepto / Mes | C44: Ene | D44: Feb | E44: Mar | F44: Abr | G44: May | H44: Jun | I44: Jul | J44: Ago | K44: Sep | L44: Oct | M44: Nov | N44: Dic | O44: Cierre Total
B45: Presupuesto Ley | C45: =INDEX(MINVU_Mes_Corriente!$1:$300, 164, 3 + ($C$4 - 2021)*13 + 0) + INDEX(MINVU_Mes_Corriente!$1:$300, 26, 3 + ($C$4 - 2021)*13 + 0) + INDEX(MINVU_Mes_Corriente!$1:$300, 95, 3 + ($C$4 - 2021)*13 + 0) -> 3320541734 | D45: =INDEX(MINVU_Mes_Corriente!$1:$300, 164, 3 + ($C$4 - 2021)*13 + 1) + INDEX(MINVU_Mes_Corriente!$1:$300, 26, 3 + ($C$4 - 2021)*13 + 1) + INDEX(MINVU_Mes_Corriente!$1:$300, 95, 3 + ($C$4 - 2021)*13 + 1) -> 3320541734 | E45: =INDEX(MINVU_Mes_Corriente!$1:$300, 164, 3 + ($C$4 - 2021)*13 + 2) + INDEX(MINVU_Mes_Corriente!$1:$300, 26, 3 + ($C$4 - 2021)*13 + 2) + INDEX(MINVU_Mes_Corriente!$1:$300, 95, 3 + ($C$4 - 2021)*13 + 2) -> 3320541734 | F45: =INDEX(MINVU_Mes_Corriente!$1:$300, 164, 3 + ($C$4 - 2021)*13 + 3) + INDEX(MINVU_Mes_Corriente!$1:$300, 26, 3 + ($C$4 - 2021)*13 + 3) + INDEX(MINVU_Mes_Corriente!$1:$300, 95, 3 + ($C$4 - 2021)*13 + 3) -> 3320541734 | G45: =INDEX(MINVU_Mes_Corriente!$1:$300, 164, 3 + ($C$4 - 2021)*13 + 4) + INDEX(MINVU_Mes_Corriente!$1:$300, 26, 3 + ($C$4 - 2021)*13 + 4) + INDEX(MINVU_Mes_Corriente!$1:$300, 95, 3 + ($C$4 - 2021)*13 + 4) -> 3320541734 | H45: =INDEX(MINVU_Mes_Corriente!$1:$300, 164, 3 + ($C$4 - 2021)*13 + 5) + INDEX(MINVU_Mes_Corriente!$1:$300, 26, 3 + ($C$4 - 2021)*13 + 5) + INDEX(MINVU_Mes_Corriente!$1:$300, 95, 3 + ($C$4 - 2021)*13 + 5) -> 3320541734 | I45: =INDEX(MINVU_Mes_Corriente!$1:$300, 164, 3 + ($C$4 - 2021)*13 + 6) + INDEX(MINVU_Mes_Corriente!$1:$300, 26, 3 + ($C$4 - 2021)*13 + 6) + INDEX(MINVU_Mes_Corriente!$1:$300, 95, 3 + ($C$4 - 2021)*13 + 6) -> 3320541734 | J45: =INDEX(MINVU_Mes_Corriente!$1:$300, 164, 3 + ($C$4 - 2021)*13 + 7) + INDEX(MINVU_Mes_Corriente!$1:$300, 26, 3 + ($C$4 - 2021)*13 + 7) + INDEX(MINVU_Mes_Corriente!$1:$300, 95, 3 + ($C$4 - 2021)*13 + 7) -> 3320541734 | K45: =INDEX(MINVU_Mes_Corriente!$1:$300, 164, 3 + ($C$4 - 2021)*13 + 8) + INDEX(MINVU_Mes_Corriente!$1:$300, 26, 3 + ($C$4 - 2021)*13 + 8) + INDEX(MINVU_Mes_Corriente!$1:$300, 95, 3 + ($C$4 - 2021)*13 + 8) -> 3320541734 | L45: =INDEX(MINVU_Mes_Corriente!$1:$300, 164, 3 + ($C$4 - 2021)*13 + 9) + INDEX(MINVU_Mes_Corriente!$1:$300, 26, 3 + ($C$4 - 2021)*13 + 9) + INDEX(MINVU_Mes_Corriente!$1:$300, 95, 3 + ($C$4 - 2021)*13 + 9) -> 3320541734 | M45: =INDEX(MINVU_Mes_Corriente!$1:$300, 164, 3 + ($C$4 - 2021)*13 + 10) + INDEX(MINVU_Mes_Corriente!$1:$300, 26, 3 + ($C$4 - 2021)*13 + 10) + INDEX(MINVU_Mes_Corriente!$1:$300, 95, 3 + ($C$4 - 2021)*13 + 10) -> 3320541734 | N45: =INDEX(MINVU_Mes_Corriente!$1:$300, 164, 3 + ($C$4 - 2021)*13 + 11) + INDEX(MINVU_Mes_Corriente!$1:$300, 26, 3 + ($C$4 - 2021)*13 + 11) + INDEX(MINVU_Mes_Corriente!$1:$300, 95, 3 + ($C$4 - 2021)*13 + 11) -> 3320541734 | O45: =INDEX(MINVU_Mes_Corriente!$1:$300, 164, 3 + ($C$4 - 2021)*13 + 12) + INDEX(MINVU_Mes_Corriente!$1:$300, 26, 3 + ($C$4 - 2021)*13 + 12) + INDEX(MINVU_Mes_Corriente!$1:$300, 95, 3 + ($C$4 - 2021)*13 + 12) -> 3320541734
B46: Presupuesto Vigente | C46: =INDEX(MINVU_Mes_Corriente!$1:$300, 186, 3 + ($C$4 - 2021)*13 + 0) + INDEX(MINVU_Mes_Corriente!$1:$300, 48, 3 + ($C$4 - 2021)*13 + 0) + INDEX(MINVU_Mes_Corriente!$1:$300, 117, 3 + ($C$4 - 2021)*13 + 0) -> 3320541734 | D46: =INDEX(MINVU_Mes_Corriente!$1:$300, 186, 3 + ($C$4 - 2021)*13 + 1) + INDEX(MINVU_Mes_Corriente!$1:$300, 48, 3 + ($C$4 - 2021)*13 + 1) + INDEX(MINVU_Mes_Corriente!$1:$300, 117, 3 + ($C$4 - 2021)*13 + 1) -> 3320541734 | E46: =INDEX(MINVU_Mes_Corriente!$1:$300, 186, 3 + ($C$4 - 2021)*13 + 2) + INDEX(MINVU_Mes_Corriente!$1:$300, 48, 3 + ($C$4 - 2021)*13 + 2) + INDEX(MINVU_Mes_Corriente!$1:$300, 117, 3 + ($C$4 - 2021)*13 + 2) -> 3320541734 | F46: =INDEX(MINVU_Mes_Corriente!$1:$300, 186, 3 + ($C$4 - 2021)*13 + 3) + INDEX(MINVU_Mes_Corriente!$1:$300, 48, 3 + ($C$4 - 2021)*13 + 3) + INDEX(MINVU_Mes_Corriente!$1:$300, 117, 3 + ($C$4 - 2021)*13 + 3) -> 3320541734 | G46: =INDEX(MINVU_Mes_Corriente!$1:$300, 186, 3 + ($C$4 - 2021)*13 + 4) + INDEX(MINVU_Mes_Corriente!$1:$300, 48, 3 + ($C$4 - 2021)*13 + 4) + INDEX(MINVU_Mes_Corriente!$1:$300, 117, 3 + ($C$4 - 2021)*13 + 4) -> 3320643534 | H46: =INDEX(MINVU_Mes_Corriente!$1:$300, 186, 3 + ($C$4 - 2021)*13 + 5) + INDEX(MINVU_Mes_Corriente!$1:$300, 48, 3 + ($C$4 - 2021)*13 + 5) + INDEX(MINVU_Mes_Corriente!$1:$300, 117, 3 + ($C$4 - 2021)*13 + 5) -> 3320643534 | I46: =INDEX(MINVU_Mes_Corriente!$1:$300, 186, 3 + ($C$4 - 2021)*13 + 6) + INDEX(MINVU_Mes_Corriente!$1:$300, 48, 3 + ($C$4 - 2021)*13 + 6) + INDEX(MINVU_Mes_Corriente!$1:$300, 117, 3 + ($C$4 - 2021)*13 + 6) -> 3329424159 | J46: =INDEX(MINVU_Mes_Corriente!$1:$300, 186, 3 + ($C$4 - 2021)*13 + 7) + INDEX(MINVU_Mes_Corriente!$1:$300, 48, 3 + ($C$4 - 2021)*13 + 7) + INDEX(MINVU_Mes_Corriente!$1:$300, 117, 3 + ($C$4 - 2021)*13 + 7) -> 3376717372 | K46: =INDEX(MINVU_Mes_Corriente!$1:$300, 186, 3 + ($C$4 - 2021)*13 + 8) + INDEX(MINVU_Mes_Corriente!$1:$300, 48, 3 + ($C$4 - 2021)*13 + 8) + INDEX(MINVU_Mes_Corriente!$1:$300, 117, 3 + ($C$4 - 2021)*13 + 8) -> 3421717372 | L46: =INDEX(MINVU_Mes_Corriente!$1:$300, 186, 3 + ($C$4 - 2021)*13 + 9) + INDEX(MINVU_Mes_Corriente!$1:$300, 48, 3 + ($C$4 - 2021)*13 + 9) + INDEX(MINVU_Mes_Corriente!$1:$300, 117, 3 + ($C$4 - 2021)*13 + 9) -> 3491232791 | M46: =INDEX(MINVU_Mes_Corriente!$1:$300, 186, 3 + ($C$4 - 2021)*13 + 10) + INDEX(MINVU_Mes_Corriente!$1:$300, 48, 3 + ($C$4 - 2021)*13 + 10) + INDEX(MINVU_Mes_Corriente!$1:$300, 117, 3 + ($C$4 - 2021)*13 + 10) -> 3488688633 | N46: =INDEX(MINVU_Mes_Corriente!$1:$300, 186, 3 + ($C$4 - 2021)*13 + 11) + INDEX(MINVU_Mes_Corriente!$1:$300, 48, 3 + ($C$4 - 2021)*13 + 11) + INDEX(MINVU_Mes_Corriente!$1:$300, 117, 3 + ($C$4 - 2021)*13 + 11) -> 3332768183 | O46: =INDEX(MINVU_Mes_Corriente!$1:$300, 186, 3 + ($C$4 - 2021)*13 + 12) + INDEX(MINVU_Mes_Corriente!$1:$300, 48, 3 + ($C$4 - 2021)*13 + 12) + INDEX(MINVU_Mes_Corriente!$1:$300, 117, 3 + ($C$4 - 2021)*13 + 12) -> 3332768183
B47: Ejecución Acumulada | C47: =INDEX(MINVU_Mes_Corriente!$1:$300, 208, 3 + ($C$4 - 2021)*13 + 0) + INDEX(MINVU_Mes_Corriente!$1:$300, 70, 3 + ($C$4 - 2021)*13 + 0) + INDEX(MINVU_Mes_Corriente!$1:$300, 139, 3 + ($C$4 - 2021)*13 + 0) -> 144905537 | D47: =INDEX(MINVU_Mes_Corriente!$1:$300, 208, 3 + ($C$4 - 2021)*13 + 1) + INDEX(MINVU_Mes_Corriente!$1:$300, 70, 3 + ($C$4 - 2021)*13 + 1) + INDEX(MINVU_Mes_Corriente!$1:$300, 139, 3 + ($C$4 - 2021)*13 + 1) -> 392112901 | E47: =INDEX(MINVU_Mes_Corriente!$1:$300, 208, 3 + ($C$4 - 2021)*13 + 2) + INDEX(MINVU_Mes_Corriente!$1:$300, 70, 3 + ($C$4 - 2021)*13 + 2) + INDEX(MINVU_Mes_Corriente!$1:$300, 139, 3 + ($C$4 - 2021)*13 + 2) -> 734004289 | F47: =INDEX(MINVU_Mes_Corriente!$1:$300, 208, 3 + ($C$4 - 2021)*13 + 3) + INDEX(MINVU_Mes_Corriente!$1:$300, 70, 3 + ($C$4 - 2021)*13 + 3) + INDEX(MINVU_Mes_Corriente!$1:$300, 139, 3 + ($C$4 - 2021)*13 + 3) -> 1004471755 | G47: =INDEX(MINVU_Mes_Corriente!$1:$300, 208, 3 + ($C$4 - 2021)*13 + 4) + INDEX(MINVU_Mes_Corriente!$1:$300, 70, 3 + ($C$4 - 2021)*13 + 4) + INDEX(MINVU_Mes_Corriente!$1:$300, 139, 3 + ($C$4 - 2021)*13 + 4) -> 1303821878 | H47: =INDEX(MINVU_Mes_Corriente!$1:$300, 208, 3 + ($C$4 - 2021)*13 + 5) + INDEX(MINVU_Mes_Corriente!$1:$300, 70, 3 + ($C$4 - 2021)*13 + 5) + INDEX(MINVU_Mes_Corriente!$1:$300, 139, 3 + ($C$4 - 2021)*13 + 5) -> 1551877586 | I47: =INDEX(MINVU_Mes_Corriente!$1:$300, 208, 3 + ($C$4 - 2021)*13 + 6) + INDEX(MINVU_Mes_Corriente!$1:$300, 70, 3 + ($C$4 - 2021)*13 + 6) + INDEX(MINVU_Mes_Corriente!$1:$300, 139, 3 + ($C$4 - 2021)*13 + 6) -> 1800513314 | J47: =INDEX(MINVU_Mes_Corriente!$1:$300, 208, 3 + ($C$4 - 2021)*13 + 7) + INDEX(MINVU_Mes_Corriente!$1:$300, 70, 3 + ($C$4 - 2021)*13 + 7) + INDEX(MINVU_Mes_Corriente!$1:$300, 139, 3 + ($C$4 - 2021)*13 + 7) -> 2056646958 | K47: =INDEX(MINVU_Mes_Corriente!$1:$300, 208, 3 + ($C$4 - 2021)*13 + 8) + INDEX(MINVU_Mes_Corriente!$1:$300, 70, 3 + ($C$4 - 2021)*13 + 8) + INDEX(MINVU_Mes_Corriente!$1:$300, 139, 3 + ($C$4 - 2021)*13 + 8) -> 2287303377 | L47: =INDEX(MINVU_Mes_Corriente!$1:$300, 208, 3 + ($C$4 - 2021)*13 + 9) + INDEX(MINVU_Mes_Corriente!$1:$300, 70, 3 + ($C$4 - 2021)*13 + 9) + INDEX(MINVU_Mes_Corriente!$1:$300, 139, 3 + ($C$4 - 2021)*13 + 9) -> 2541084845 | M47: =INDEX(MINVU_Mes_Corriente!$1:$300, 208, 3 + ($C$4 - 2021)*13 + 10) + INDEX(MINVU_Mes_Corriente!$1:$300, 70, 3 + ($C$4 - 2021)*13 + 10) + INDEX(MINVU_Mes_Corriente!$1:$300, 139, 3 + ($C$4 - 2021)*13 + 10) -> 2810519043 | N47: =INDEX(MINVU_Mes_Corriente!$1:$300, 208, 3 + ($C$4 - 2021)*13 + 11) + INDEX(MINVU_Mes_Corriente!$1:$300, 70, 3 + ($C$4 - 2021)*13 + 11) + INDEX(MINVU_Mes_Corriente!$1:$300, 139, 3 + ($C$4 - 2021)*13 + 11) -> 3312699040 | O47: =INDEX(MINVU_Mes_Corriente!$1:$300, 208, 3 + ($C$4 - 2021)*13 + 12) + INDEX(MINVU_Mes_Corriente!$1:$300, 70, 3 + ($C$4 - 2021)*13 + 12) + INDEX(MINVU_Mes_Corriente!$1:$300, 139, 3 + ($C$4 - 2021)*13 + 12) -> 3312699040
B48: % Avance Ejecución | C48: =IF(C46>0, C47/C46, 0) -> 0.043639125 | D48: =IF(D46>0, D47/D46, 0) -> 0.11808703 | E48: =IF(E46>0, E47/E46, 0) -> 0.22104956 | F48: =IF(F46>0, F47/F46, 0) -> 0.30250237 | G48: =IF(G46>0, G47/G46, 0) -> 0.39264133 | H48: =IF(H46>0, H47/H46, 0) -> 0.46734242 | I48: =IF(I46>0, I47/I46, 0) -> 0.5407882 | J48: =IF(J46>0, J47/J46, 0) -> 0.60906695 | ... O48: =IF(O46>0, O47/O46, 0) -> 0.99397824
B50: TABLA 4: COMPARATIVA HISTÓRICA MULTIANUAL (2021 - 2026)
...

Sheet MINVU_Mes_Corriente
B1: Ministerio de Vivienda y Urbanismo — Partida 18
B2: Miles de pesos — moneda corriente — montos devengados
B4: SUBTÍTULO 31 – INICIATIVAS DE INVERSIÓN
B5: Presupuesto Ley (Subtítulo 31)
C6: 2021 | P6: 2022 | AC6: 2023 | AP6: 2024 | BC6: 2025 | BP6: 2026
B7: Programa / Entidad | C7: Ene | D7: Feb | E7: Mar | F7: Abr | G7: May | H7: Jun | I7: Jul | J7: Ago | K7: Sep | L7: Oct | M7: Nov | N7: Dic | O7: Total 2021 | P7: Ene | Q7: Feb | R7: Mar | S7: Abr | T7: May | U7: Jun | V7: Jul | W7: Ago | X7: Sep | Y7: Oct | Z7: Nov | AA7: Dic | AB7: Total 2022 | AC7: Ene | AD7: Feb | AE7: Mar | AF7: Abr | AG7: May | AH7: Jun | AI7: Jul | AJ7: Ago | AK7: Sep | AL7: Oct | AM7: Nov | AN7: Dic | AO7: Total 2023 | AP7: Ene | AQ7: Feb | AR7: Mar | AS7: Abr | AT7: May | AU7: Jun | AV7: Jul | AW7: Ago | AX7: Sep | AY7: Oct | AZ7: Nov | BA7: Dic | BB7: Total 2024 | BC7: Ene | BD7: Feb | BE7: Mar | BF7: Abr | BG7: May | BH7: Jun | BI7: Jul | BJ7: Ago | BK7: Sep | BL7: Oct | BM7: Nov | BN7: Dic | BO7: Total 2025 | BP7: Ene | BQ7: Feb | BR7: Mar | BS7: Abr | BT7: May | BU7: Jun | BV7: Jul | BW7: Ago | BX7: Sep | BY7: Oct | BZ7: Nov | CA7: Dic | CB7: Total 2026
B8: Subsecretaría y Programas Centrales | C8: 35339308 | D8: 35339308 | E8: 35339308 | F8: 35339308 | G8: 35339308 | H8: 35339308 | I8: 35339308 | J8: 35339308 | K8: 35339308 | L8: 35339308 | M8: 35339308 | N8: 35339308 | O8: 35339308 | P8: 22751821 | Q8: 22751821 | R8: 22751821 | S8: 22751821 | T8: 22751821 | U8: 22751821 | V8: 22751821 | W8: 22751821 | X8: 22751821 | Y8: 22751821 | Z8: 22751821 | AA8: 22751821 | AB8: 22751821 | AC8: 22326757 | AD8: 22326757 | AE8: 22326757 | AF8: 22326757 | AG8: 22326757 | AH8: 22326757 | AI8: 22326757 | AJ8: 22326757 | AK8: 22326757 | AL8: 22326757 | AM8: 22326757 | AN8: 22326757 | AO8: 22326757 | AP8: 65885700 | AQ8: 65885700 | AR8: 65885700 | AS8: 65885700 | AT8: 65885700 | AU8: 65885700 | AV8: 65885700 | AW8: 65885700 | AX8: 65885700 | AY8: 65885700 | AZ8: 65885700 | BA8: 65885700 | BB8: 65885700 | BC8: 31496963 | BD8: 31496963 | BE8: 31496963 | BF8: 31496963 | BG8: 31496963 | BH8: 31496963 | BI8: 31496963 | BJ8: 31496963 | BK8: 31496963 | BL8: 31496963 | BM8: 31496963 | BN8: 31496963 | BO8: 31496963 | BP8: 15772873 | BQ8: 15772873 | BR8: 15772873 | BS8: 15772873 | BT8: 15772873 | BU8: 15772873 | BV8: 15772873 | BW8: 15772873 | BX8: 15772873 | BY8: 15772873 | BZ8: 15772873 | CA8: 15772873 | CB8: 15772873
B9: Parque Metropolitano (PARQUEMET) | C9: 28313204 | D9: 28313204 | E9: 28313204 | F9: 28313204 | G9: 28313204 | H9: 28313204 | I9: 28313204 | J9: 28313204 | K9: 28313204 | L9: 28313204 | M9: 28313204 | N9: 28313204 | O9: 28313204 | P9: 26279513 | Q9: 26279513 | R9: 26279513 | S9: 26279513 | T9: 26279513 | U9: 26279513 | V9: 26279513 | W9: 26279513 | X9: 26279513 | Y9: 26279513 | Z9: 26279513 | AA9: 26279513 | AB9: 26279513 | AC9: 23921092 | AD9: 23921092 | AE9: 23921092 | AF9: 23921092 | AG9: 23921092 | AH9: 23921092 | AI9: 23921092 | AJ9: 23921092 | AK9: 23921092 | AL9: 23921092 | AM9: 23921092 | AN9: 23921092 | AO9: 23921092 | AP9: 32623118 | AQ9: 32623118 | AR9: 32623118 | AS9: 32623118 | AT9: 32623118 | AU9: 32623118 | AV9: 32623118 | AW9: 32623118 | AX9: 32623118 | AY9: 32623118 | AZ9: 32623118 | BA9: 32623118 | BB9: 32623118 | BC9: 31388552 | BD9: 31388552 | BE9: 31388552 | BF9: 31388552 | BG9: 31388552 | BH9: 31388552 | BI9: 31388552 | BJ9: 31388552 | BK9: 31388552 | BL9: 31388552 | BM9: 31388552 | BN9: 31388552 | BO9: 31388552 | BP9: 32099544 | BQ9: 32099544 | BR9: 32099544 | BS9: 32099544 | BT9: 32099544 | BU9: 32099544 | BV9: 32099544 | BW9: 32099544 | BX9: 32099544 | BY9: 32099544 | BZ9: 32099544 | CA9: 32099544 | CB9: 32099544
B10: SERVIU Arica y Parinacota | C10: 9734344 | D10: 9734344 | E10: 9734344 | F10: 9734344 | G10: 9734344 | H10: 9734344 | I10: 9734344 | J10: 9734344 | K10: 9734344 | L10: 9734344 | M10: 9734344 | N10: 9734344 | O10: 9734344 | P10: 8027524 | Q10: 8027524 | R10: 8027524 | S10: 8027524 | T10: 8027524 | U10: 8027524 | V10: 8027524 | W10: 8027524 | X10: 8027524 | Y10: 8027524 | Z10: 8027524 | AA10: 8027524 | AB10: 8027524 | AC10: 9623696 | AD10: 9623696 | AE10: 9623696 | AF10: 9623696 | AG10: 9623696 | AH10: 9623696 | AI10: 9623696 | AJ10: 9623696 | AK10: 9623696 | AL10: 9623696 | AM10: 9623696 | AN10: 9623696 | AO10: 9623696 | AP10: 7002032 | AQ10: 7002032 | AR10: 7002032 | AS10: 7002032 | AT10: 7002032 | AU10: 7002032 | AV10: 7002032 | AW10: 7002032 | AX10: 7002032 | AY10: 7002032 | AZ10: 7002032 | BA10: 7002032 | BB10: 7002032 | BC10: 7819491 | BD10: 7819491 | BE10: 7819491 | BF10: 7819491 | BG10: 7819491 | BH10: 7819491 | BI10: 7819491 | BJ10: 7819491 | BK10: 7819491 | BL10: 7819491 | BM10: 7819491 | BN10: 7819491 | BO10: 7819491 | BP10: 2323330 | BQ10: 2323330 | BR10: 2323330 | BS10: 2323330 | BT10: 2323330 | BU10: 2323330 | BV10: 2323330 | BW10: 2323330 | BX10: 2323330 | BY10: 2323330 | BZ10: 2323330 | CA10: 2323330 | CB10: 2323330
B11: SERVIU Tarapacá | C11: 7005376 | D11: 7005376 | E11: 7005376 | F11: 7005376 | G11: 7005376 | H11: 7005376 | I11: 7005376 | J11: 7005376 | K11: 7005376 | L11: 7005376 | M11: 7005376 | N11: 7005376 | O11: 7005376 | P11: 4659283 | Q11: 4659283 | R11: 4659283 | S11: 4659283 | T11: 4659283 | U11: 4659283 | V11: 4659283 | W11: 4659283 | X11: 4659283 | Y11: 4659283 | Z11: 4659283 | AA11: 4659283 | AB11: 4659283 | AC11: 9013306 | AD11: 9013306 | AE11: 9013306 | AF11: 9013306 | AG11: 9013306 | AH11: 9013306 | AI11: 9013306 | AJ11: 9013306 | AK11: 9013306 | AL11: 9013306 | AM11: 9013306 | AN11: 9013306 | AO11: 9013306 | AP11: 11846836 | AQ11: 11846836 | AR11: 11846836 | AS11: 11846836 | AT11: 11846836 | AU11: 11846836 | AV11: 11846836 | AW11: 11846836 | AX11: 11846836 | AY11: 11846836 | AZ11: 11846836 | BA11: 11846836 | BB11: 11846836 | BC11: 9956278 | BD11: 9956278 | BE11: 9956278 | BF11: 9956278 | BG11: 9956278 | BH11: 9956278 | BI11: 9956278 | BJ11: 9956278 | BK11: 9956278 | BL11: 9956278 | BM11: 9956278 | BN11: 9956278 | BO11: 9956278 | BP11: 8706346 | BQ11: 8706346 | BR11: 8706346 | BS11: 8706346 | BT11: 8706346 | BU11: 8706346 | BV11: 8706346 | BW11: 8706346 | BX11: 8706346 | BY11: 8706346 | BZ11: 8706346 | CA11: 8706346 | CB11: 8706346
B12: SERVIU Antofagasta | C12: 35181732 | D12: 35181732 | E12: 35181732 | F12: 35181732 | G12: 35181732 | H12: 35181732 | I12: 35181732 | J12: 35181732 | K12: 35181732 | L12: 35181732 | M12: 35181732 | N12: 35181732 | O12: 35181732 | P12: 35548395 | Q12: 35548395 | R12: 35548395 | S12: 35548395 | T12: 35548395 | U12: 35548395 | V12: 35548395 | W12: 35548395 | X12: 35548395 | Y12: 35548395 | Z12: 35548395 | AA12: 35548395 | AB12: 35548395 | AC12: 30263070 | AD12: 30263070 | AE12: 30263070 | AF12: 30263070 | AG12: 30263070 | AH12: 30263070 | AI12: 30263070 | AJ12: 30263070 | AK12: 30263070 | AL12: 30263070 | AM12: 30263070 | AN12: 30263070 | AO12: 30263070 | AP12: 10878804 | AQ12: 10878804 | AR12: 10878804 | AS12: 10878804 | AT12: 10878804 | AU12: 10878804 | AV12: 10878804 | AW12: 10878804 | AX12: 10878804 | AY12: 10878804 | AZ12: 10878804 | BA12: 10878804 | BB12: 10878804 | BC12: 13585888 | BD12: 13585888 | BE12: 13585888 | BF12: 13585888 | BG12: 13585888 | BH12: 13585888 | BI12: 13585888 | BJ12: 13585888 | BK12: 13585888 | BL12: 13585888 | BM12: 13585888 | BN12: 13585888 | BO12: 13585888 | BP12: 13197867 | BQ12: 13197867 | BR12: 13197867 | BS12: 13197867 | BT12: 13197867 | BU12: 13197867 | BV12: 13197867 | BW12: 13197867 | BX12: 13197867 | BY12: 13197867 | BZ12: 13197867 | CA12: 13197867 | CB12: 13197867
B13: SERVIU Atacama | C13: 18709251 | D13: 18709251 | E13: 18709251 | F13: 18709251 | G13: 18709251 | H13: 18709251 | I13: 18709251 | J13: 18709251 | K13: 18709251 | L13: 18709251 | M13: 18709251 | N13: 18709251 | O13: 18709251 | P13: 24875325 | Q13: 24875325 | R13: 24875325 | S13: 24875325 | T13: 24875325 | U13: 24875325 | V13: 24875325 | W13: 24875325 | X13: 24875325 | Y13: 24875325 | Z13: 24875325 | AA13: 24875325 | AB13: 24875325 | AC13: 21315123 | AD13: 21315123 | AE13: 21315123 | AF13: 21315123 | AG13: 21315123 | AH13: 21315123 | AI13: 21315123 | AJ13: 21315123 | AK13: 21315123 | AL13: 21315123 | AM13: 21315123 | AN13: 21315123 | AO13: 21315123 | AP13: 21518444 | AQ13: 21518444 | AR13: 21518444 | AS13: 21518444 | AT13: 21518444 | AU13: 21518444 | AV13: 21518444 | AW13: 21518444 | AX13: 21518444 | AY13: 21518444 | AZ13: 21518444 | BA13: 21518444 | BB13: 21518444 | BC13: 24183340 | BD13: 24183340 | BE13: 24183340 | BF13: 24183340 | BG13: 24183340 | BH13: 24183340 | BI13: 24183340 | BJ13: 24183340 | BK13: 24183340 | BL13: 24183340 | BM13: 24183340 | BN13: 24183340 | BO13: 24183340 | BP13: 9416801 | BQ13: 9416801 | BR13: 9416801 | BS13: 9416801 | BT13: 9416801 | BU13: 9416801 | BV13: 9416801 | BW13: 9416801 | BX13: 9416801 | BY13: 9416801 | BZ13: 9416801 | CA13: 9416801 | CB13: 9416801
B14: SERVIU Coquimbo | C14: 16689514 | D14: 16689514 | E14: 16689514 | F14: 16689514 | G14: 16689514 | H14: 16689514 | I14: 16689514 | J14: 16689514 | K14: 16689514 | L14: 16689514 | M14: 16689514 | N14: 16689514 | O14: 16689514 | P14: 29291800 | Q14: 29291800 | R14: 29291800 | S14: 29291800 | T14: 29291800 | U14: 29291800 | V14: 29291800 | W14: 29291800 | X14: 29291800 | Y14: 29291800 | Z14: 29291800 | AA14: 29291800 | AB14: 29291800 | AC14: 36352142 | AD14: 36352142 | AE14: 36352142 | AF14: 36352142 | AG14: 36352142 | AH14: 36352142 | AI14: 36352142 | AJ14: 36352142 | AK14: 36352142 | AL14: 36352142 | AM14: 36352142 | AN14: 36352142 | AO14: 36352142 | AP14: 38254690 | AQ14: 38254690 | AR14: 38254690 | AS14: 38254690 | AT14: 38254690 | AU14: 38254690 | AV14: 38254690 | AW14: 38254690 | AX14: 38254690 | AY14: 38254690 | AZ14: 38254690 | BA14: 38254690 | BB14: 38254690 | BC14: 27966487 | BD14: 27966487 | BE14: 27966487 | BF14: 27966487 | BG14: 27966487 | BH14: 27966487 | BI14: 27966487 | BJ14: 27966487 | BK14: 27966487 | BL14: 27966487 | BM14: 27966487 | BN14: 27966487 | BO14: 27966487 | BP14: 30615904 | BQ14: 30615904 | BR14: 30615904 | BS14: 30615904 | BT14: 30615904 | BU14: 30615904 | BV14: 30615904 | BW14: 30615904 | BX14: 30615904 | BY14: 30615904 | BZ14: 30615904 | CA14: 30615904 | CB14: 30615904
B15: SERVIU Valparaíso | C15: 53755591 | D15: 53755591 | E15: 53755591 | F15: 53755591 | G15: 53755591 | H15: 53755591 | I15: 53755591 | J15: 53755591 | K15: 53755591 | L15: 53755591 | M15: 53755591 | N15: 53755591 | O15: 53755591 | P15: 43170852 | Q15: 43170852 | R15: 43170852 | S15: 43170852 | T15: 43170852 | U15: 43170852 | V15: 43170852 | W15: 43170852 | X15: 43170852 | Y15: 43170852 | Z15: 43170852 | AA15: 43170852 | AB15: 43170852 | AC15: 40478579 | AD15: 40478579 | AE15: 40478579 | AF15: 40478579 | AG15: 40478579 | AH15: 40478579 | AI15: 40478579 | AJ15: 40478579 | AK15: 40478579 | AL15: 40478579 | AM15: 40478579 | AN15: 40478579 | AO15: 40478579 | AP15: 44262543 | AQ15: 44262543 | AR15: 44262543 | AS15: 44262543 | AT15: 44262543 | AU15: 44262543 | AV15: 44262543 | AW15: 44262543 | AX15: 44262543 | AY15: 44262543 | AZ15: 44262543 | BA15: 44262543 | BB15: 44262543 | BC15: 42009797 | BD15: 42009797 | BE15: 42009797 | BF15: 42009797 | BG15: 42009797 | BH15: 42009797 | BI15: 42009797 | BJ15: 42009797 | BK15: 42009797 | BL15: 42009797 | BM15: 42009797 | BN15: 42009797 | BO15: 42009797 | BP15: 36533880 | BQ15: 36533880 | BR15: 36533880 | BS15: 36533880 | BT15: 36533880 | BU15: 36533880 | BV15: 36533880 | BW15: 36533880 | BX15: 36533880 | BY15: 36533880 | BZ15: 36533880 | CA15: 36533880 | CB15: 36533880
B16: SERVIU Metropolitano | C16: 75469606 | D16: 75469606 | E16: 75469606 | F16: 75469606 | G16: 75469606 | H16: 75469606 | I16: 75469606 | J16: 75469606 | K16: 75469606 | L16: 75469606 | M16: 75469606 | N16: 75469606 | O16: 75469606 | P16: 100098472 | Q16: 100098472 | R16: 100098472 | S16: 100098472 | T16: 100098472 | U16: 100098472 | V16: 100098472 | W16: 100098472 | X16: 100098472 | Y16: 100098472 | Z16: 100098472 | AA16: 100098472 | AB16: 100098472 | AC16: 105488522 | AD16: 105488522 | AE16: 105488522 | AF16: 105488522 | AG16: 105488522 | AH16: 105488522 | AI16: 105488522 | AJ16: 105488522 | AK16: 105488522 | AL16: 105488522 | AM16: 105488522 | AN16: 105488522 | AO16: 105488522 | AP16: 87253576 | AQ16: 87253576 | AR16: 87253576 | AS16: 87253576 | AT16: 87253576 | AU16: 87253576 | AV16: 87253576 | AW16: 87253576 | AX16: 87253576 | AY16: 87253576 | AZ16: 87253576 | BA16: 87253576 | BB16: 87253576 | BC16: 74587862 | BD16: 74587862 | BE16: 74587862 | BF16: 74587862 | BG16: 74587862 | BH16: 74587862 | BI16: 74587862 | BJ16: 74587862 | BK16: 74587862 | BL16: 74587862 | BM16: 74587862 | BN16: 74587862 | BO16: 74587862 | BP16: 90590002 | BQ16: 90590002 | BR16: 90590002 | BS16: 90590002 | BT16: 90590002 | BU16: 90590002 | BV16: 90590002 | BW16: 90590002 | BX16: 90590002 | BY16: 90590002 | BZ16: 90590002 | CA16: 90590002 | CB16: 90590002
B17: SERVIU O'Higgins | C17: 9595472 | D17: 9595472 | E17: 9595472 | F17: 9595472 | G17: 9595472 | H17: 9595472 | I17: 9595472 | J17: 9595472 | K17: 9595472 | L17: 9595472 | M17: 9595472 | N17: 9595472 | O17: 9595472 | P17: 11870060 | Q17: 11870060 | R17: 11870060 | S17: 11870060 | T17: 11870060 | U17: 11870060 | V17: 11870060 | W17: 11870060 | X17: 11870060 | Y17: 11870060 | Z17: 11870060 | AA17: 11870060 | AB17: 11870060 | AC17: 16473882 | AD17: 16473882 | AE17: 16473882 | AF17: 16473882 | AG17: 16473882 | AH17: 16473882 | AI17: 16473882 | AJ17: 16473882 | AK17: 16473882 | AL17: 16473882 | AM17: 16473882 | AN17: 16473882 | AO17: 16473882 | AP17: 16690085 | AQ17: 16690085 | AR17: 16690085 | AS17: 16690085 | AT17: 16690085 | AU17: 16690085 | AV17: 16690085 | AW17: 16690085 | AX17: 16690085 | AY17: 16690085 | AZ17: 16690085 | BA17: 16690085 | BB17: 16690085 | BC17: 17865780 | BD17: 17865780 | BE17: 17865780 | BF17: 17865780 | BG17: 17865780 | BH17: 17865780 | BI17: 17865780 | BJ17: 17865780 | BK17: 17865780 | BL17: 17865780 | BM17: 17865780 | BN17: 17865780 | BO17: 17865780 | BP17: 14196992 | BQ17: 14196992 | BR17: 14196992 | BS17: 14196992 | BT17: 14196992 | BU17: 14196992 | BV17: 14196992 | BW17: 14196992 | BX17: 14196992 | BY17: 14196992 | BZ17: 14196992 | CA17: 14196992 | CB17: 14196992
B18: SERVIU Maule | C18: 32317785 | D18: 32317785 | E18: 32317785 | F18: 32317785 | G18: 32317785 | H18: 32317785 | I18: 32317785 | J18: 32317785 | K18: 32317785 | L18: 32317785 | M18: 32317785 | N18: 32317785 | O18: 32317785 | P18: 41575245 | Q18: 41575245 | R18: 41575245 | S18: 41575245 | T18: 41575245 | U18: 41575245 | V18: 41575245 | W18: 41575245 | X18: 41575245 | Y18: 41575245 | Z18: 41575245 | AA18: 41575245 | AB18: 41575245 | AC18: 34076619 | AD18: 34076619 | AE18: 34076619 | AF18: 34076619 | AG18: 34076619 | AH18: 34076619 | AI18: 34076619 | AJ18: 34076619 | AK18: 34076619 | AL18: 34076619 | AM18: 34076619 | AN18: 34076619 | AO18: 34076619 | AP18: 28318956 | AQ18: 28318956 | AR18: 28318956 | AS18: 28318956 | AT18: 28318956 | AU18: 28318956 | AV18: 28318956 | AW18: 28318956 | AX18: 28318956 | AY18: 28318956 | AZ18: 28318956 | BA18: 28318956 | BB18: 28318956 | BC18: 30628977 | BD18: 30628977 | BE18: 30628977 | BF18: 30628977 | BG18: 30628977 | BH18: 30628977 | BI18: 30628977 | BJ18: 30628977 | BK18: 30628977 | BL18: 30628977 | BM18: 30628977 | BN18: 30628977 | BO18: 30628977 | BP18: 25030745 | BQ18: 25030745 | BR18: 25030745 | BS18: 25030745 | BT18: 25030745 | BU18: 25030745 | BV18: 25030745 | BW18: 25030745 | BX18: 25030745 | BY18: 25030745 | BZ18: 25030745 | CA18: 25030745 | CB18: 25030745
B19: SERVIU Ñuble | C19: 17998490 | D19: 17998490 | E19: 17998490 | F19: 17998490 | G19: 17998490 | H19: 17998490 | I19: 17998490 | J19: 17998490 | K19: 17998490 | L19: 17998490 | M19: 17998490 | N19: 17998490 | O19: 17998490 | P19: 36920320 | Q19: 36920320 | R19: 36920320 | S19: 36920320 | T19: 36920320 | U19: 36920320 | V19: 36920320 | W19: 36920320 | X19: 36920320 | Y19: 36920320 | Z19: 36920320 | AA19: 36920320 | AB19: 36920320 | AC19: 23700733 | AD19: 23700733 | AE19: 23700733 | AF19: 23700733 | AG19: 23700733 | AH19: 23700733 | AI19: 23700733 | AJ19: 23700733 | AK19: 23700733 | AL19: 23700733 | AM19: 23700733 | AN19: 23700733 | AO19: 23700733 | AP19: 23113535 | AQ19: 23113535 | AR19: 23113535 | AS19: 23113535 | AT19: 23113535 | AU19: 23113535 | AV19: 23113535 | AW19: 23113535 | AX19: 23113535 | AY19: 23113535 | AZ19: 23113535 | BA19: 23113535 | BB19: 23113535 | BC19: 22079448 | BD19: 22079448 | BE19: 22079448 | BF19: 22079448 | BG19: 22079448 | BH19: 22079448 | BI19: 22079448 | BJ19: 22079448 | BK19: 22079448 | BL19: 22079448 | BM19: 22079448 | BN19: 22079448 | BO19: 22079448 | BP19: 24086756 | BQ19: 24086756 | BR19: 24086756 | BS19: 24086756 | BT19: 24086756 | BU19: 24086756 | BV19: 24086756 | BW19: 24086756 | BX19: 24086756 | BY19: 24086756 | BZ19: 24086756 | CA19: 24086756 | CB19: 24086756
... B25: SERVIU Magallanes | C25: 9782662 | D25: 9782662 | E25: 9782662 | F25: 9782662 | G25: 9782662 | H25: 9782662 | I25: 9782662 | J25: 9782662 | K25: 9782662 | L25: 9782662 | M25: 9782662 | N25: 9782662 | O25: 9782662 | P25: 14902342 | Q25: 14902342 | R25: 14902342 | S25: 14902342 | T25: 14902342 | U25: 14902342 | V25: 14902342 | W25: 14902342 | X25: 14902342 | Y25: 14902342 | Z25: 14902342 | AA25: 14902342 | AB25: 14902342 | AC25: 22127832 | AD25: 22127832 | AE25: 22127832 | AF25: 22127832 | AG25: 22127832 | AH25: 22127832 | AI25: 22127832 | AJ25: 22127832 | AK25: 22127832 | AL25: 22127832 | AM25: 22127832 | AN25: 22127832 | AO25: 22127832 | AP25: 22256093 | AQ25: 22256093 | AR25: 22256093 | AS25: 22256093 | AT25: 22256093 | AU25: 22256093 | AV25: 22256093 | AW25: 22256093 | AX25: 22256093 | AY25: 22256093 | AZ25: 22256093 | BA25: 22256093 | BB25: 22256093 | BC25: 21184028 | BD25: 21184028 | BE25: 21184028 | BF25: 21184028 | BG25: 21184028 | BH25: 21184028 | BI25: 21184028 | BJ25: 21184028 | BK25: 21184028 | BL25: 21184028 | BM25: 21184028 | BN25: 21184028 | BO25: 21184028 | BP25: 24770394 | BQ25: 24770394 | BR25: 24770394 | BS25: 24770394 | BT25: 24770394 | BU25: 24770394 | BV25: 24770394 | BW25: 24770394 | BX25: 24770394 | BY25: 24770394 | BZ25: 24770394 | CA25: 24770394 | CB25: 24770394
B26: Total Presupuesto Ley (Subtítulo 31) | C26: =SUM(C8:C25) -> 469564689 | D26: =SUM(D8:D25) -> 469564689 | E26: =SUM(E8:E25) -> 469564689 | F26: =SUM(F8:F25) -> 469564689 | G26: =SUM(G8:G25) -> 469564689 | H26: =SUM(H8:H25) -> 469564689 | I26: =SUM(I8:I25) -> 469564689 | J26: =SUM(J8:J25) -> 469564689 | ... CB26: =SUM(CB8:CB25) -> 465461219
B27: Presupuesto Vigente (Subtítulo 31)
C28: 2021 | P28: 2022 | AC28: 2023 | AP28: 2024 | BC28: 2025 | BP28: 2026
B29: Programa / Entidad | C29: Ene | D29: Feb | E29: Mar | F29: Abr | G29: May | H29: Jun | I29: Jul | J29: Ago | K29: Sep | L29: Oct | M29: Nov | N29: Dic | O29: Total 2021 | P29: Ene | Q29: Feb | R29: Mar | S29: Abr | T29: May | U29: Jun | V29: Jul | W29: Ago | X29: Sep | Y29: Oct | Z29: Nov | AA29: Dic | AB29: Total 2022 | AC29: Ene | AD29: Feb | AE29: Mar | AF29: Abr | AG29: May | AH29: Jun | AI29: Jul | AJ29: Ago | AK29: Sep | AL29: Oct | AM29: Nov | AN29: Dic | AO29: Total 2023 | AP29: Ene | AQ29: Feb | AR29: Mar | AS29: Abr | AT29: May | AU29: Jun | AV29: Jul | AW29: Ago | AX29: Sep | AY29: Oct | AZ29: Nov | BA29: Dic | BB29: Total 2024 | BC29: Ene | BD29: Feb | BE29: Mar | BF29: Abr | BG29: May | BH29: Jun | BI29: Jul | BJ29: Ago | BK29: Sep | BL29: Oct | BM29: Nov | BN29: Dic | BO29: Total 2025 | BP29: Ene | BQ29: Feb | BR29: Mar | BS29: Abr | BT29: May | BU29: Jun | BV29: Jul | BW29: Ago | BX29: Sep | BY29: Oct | BZ29: Nov | CA29: Dic | CB29: Total 2026
B30: Subsecretaría y Programas Centrales | C30: 35339308 | D30: 34095082 | E30: 30900763 | F30: 30000165 | G30: 28431391 | H30: 28482712 | I30: 28482712 | J30: 28482712 | K30: 28482712 | L30: 26544090 | M30: 27401071 | N30: 26558777 | O30: 26558777 | P30: 22751821 | Q30: 14162616 | R30: 14162616 | S30: 14162616 | T30: 14094265 | U30: 14094265 | V30: 13994333 | W30: 14199833 | X30: 14199833 | Y30: 14215569 | Z30: 13257545 | AA30: 11513633 | AB30: 11513633 | AC30: 22326757 | AD30: 12413948 | AE30: 12413948 | AF30: 12169459 | AG30: 11694537 | AH30: 11453537 | AI30: 11207907 | AJ30: 11175513 | AK30: 11175513 | AL30: 11175513 | AM30: 3304471 | AN30: 2258817 | AO30: 2258817 | AP30: 65885700 | AQ30: 65885700 | AR30: 40863396 | AS30: 40863396 | AT30: 40441434 | AU30: 40130157 | AV30: 40110894 | AW30: 35322619 | AX30: 31954975 | AY30: 31882527 | AZ30: 19631668 | BA30: 1858597 | BB30: 1858597 | BC30: 31496963 | BD30: 21938918 | BE30: 17774772 | BF30: 17594772 | BG30: 17439772 | BH30: 16908124 | BI30: 10908124 | BJ30: 10908124 | BK30: 10908124 | BL30: 4377527 | BM30: 4377527 | BN30: 2042428 | BO30: 2042428 | BP30: 15772873 | BQ30: 15772873 | BR30: 15772873 | BS30: 15772873 | BT30: 3763881 | BU30: 3874066 | BV30: 2591940 | BW30: 2591940 | BX30: 2591940 | BY30: 2591940 | BZ30: 2591940 | CA30: 2591940 | CB30: 2591940
B31: Parque Metropolitano (PARQUEMET) | C31: 28313204 | D31: 30808704 | E31: 30808704 | F31: 30808704 | G31: 30808704 | H31: 30808704 | I31: 30808704 | J31: 30808704 | K31: 30808704 | L31: 30808704 | M31: 30808704 | N31: 30377501 | O31: 30377501 | P31: 26279513 | Q31: 26279513 | R31: 26279513 | S31: 26279513 | T31: 26279513 | U31: 26279513 | V31: 26279513 | W31: 26279513 | X31: 26279513 | Y31: 26279513 | Z31: 23402444 | AA31: 23403944 | AB31: 23403944 | AC31: 23921092 | AD31: 23921092 | AE31: 23921092 | AF31: 23921092 | AG31: 23921092 | AH31: 23921092 | AI31: 23998690 | AJ31: 23998690 | AK31: 23998690 | AL31: 23998690 | AM31: 23228459 | AN31: 22242755 | AO31: 22242755 | AP31: 32623118 | AQ31: 32623118 | AR31: 32623118 | AS31: 32623118 | AT31: 32623118 | AU31: 32623118 | AV31: 32623118 | AW31: 32388971 | AX31: 31969868 | AY31: 31969868 | AZ31: 28971461 | BA31: 27933416 | BB31: 27933416 | BC31: 31388552 | BD31: 31388552 | BE31: 31388552 | BF31: 31388552 | BG31: 31388552 | BH31: 31388552 | BI31: 31388552 | BJ31: 31388552 | BK31: 31388552 | BL31: 31049772 | BM31: 31049772 | BN31: 30251792 | BO31: 30251792 | BP31: 32099544 | BQ31: 32099544 | BR31: 32099544 | BS31: 32099544 | BT31: 32099544 | BU31: 32099544 | BV31: 32099544 | BW31: 32099544 | BX31: 32099544 | BY31: 32099544 | BZ31: 32099544 | CA31: 32099544 | CB31: 32099544
B32: SERVIU Arica y Parinacota | C32: 10293909 | D32: 10084346 | E32: 10084346 | F32: 10084346 | G32: 9752272 | H32: 9660314 | I32: 10182785 | J32: 10182785 | K32: 10182785 | L32: 10341874 | M32: 9584765 | N32: 8277587 | O32: 8277587 | P32: 8027524 | Q32: 8983763 | R32: 8983763 | S32: 8983763 | T32: 8983763 | U32: 8983763 | V32: 8402412 | W32: 8402412 | X32: 8402412 | Y32: 8402412 | Z32: 7108557 | AA32: 6707203 | AB32: 6707203 | AC32: 9623696 | AD32: 9643166 | AE32: 9643166 | AF32: 9643166 | AG32: 9643166 | AH32: 9643166 | AI32: 9643166 | AJ32: 6911926 | AK32: 6911926 | AL32: 6911926 | AM32: 5346460 | AN32: 5348904 | AO32: 5348904 | AP32: 7002032 | AQ32: 7002032 | AR32: 7171646 | AS32: 7171646 | AT32: 6646025 | AU32: 6646025 | AV32: 6646025 | AW32: 6646025 | AX32: 6646025 | AY32: 6646025 | AZ32: 6646025 | BA32: 4403210 | BB32: 4403210 | BC32: 7819491 | BD32: 8230260 | BE32: 10011051 | BF32: 10424875 | BG32: 10424875 | BH32: 10424875 | BI32: 10424875 | BJ32: 10424875 | BK32: 10424875 | BL32: 10350160 | BM32: 10350160 | BN32: 9544096 | BO32: 9544096 | BP32: 2323330 | BQ32: 2323330 | BR32: 2323330 | BS32: 2323330 | BT32: 2764330 | BU32: 3209529 | BV32: 3209529 | BW32: 3209529 | BX32: 3209529 | BY32: 3209529 | BZ32: 3209529 | CA32: 3209529 | CB32: 3209529
B33: SERVIU Tarapacá | C33: 10606403 | D33: 10981562 | E33: 10981562 | F33: 10981562 | G33: 9508988 | H33: 10027957 | I33: 9376062 | J33: 9426062 | K33: 9426062 | L33: 9426062 | M33: 8375529 | N33: 5044955 | O33: 5044955 | P33: 4659283 | Q33: 8287823 | R33: 8287823 | S33: 8287823 | T33: 8088031 | U33: 9085876 | V33: 8230787 | W33: 9146287 | X33: 9160548 | Y33: 9229516 | Z33: 8217063 | AA33: 5987379 | AB33: 5987379 | AC33: 9013306 | AD33: 9013306 | AE33: 9013306 | AF33: 9013306 | AG33: 9013306 | AH33: 9013306 | AI33: 9013306 | AJ33: 9013306 | AK33: 9013306 | AL33: 9013306 | AM33: 8829146 | AN33: 6845802 | AO33: 6845802 | AP33: 11846836 | AQ33: 11846836 | AR33: 13988953 | AS33: 13988953 | AT33: 14532621 | AU33: 15344415 | AV33: 15354765 | AW33: 15354765 | AX33: 15735185 | AY33: 15735185 | AZ33: 15739683 | BA33: 8998445 | BB33: 8998445 | BC33: 9956278 | BD33: 9956278 | BE33: 11346159 | BF33: 11346159 | BG33: 11346159 | BH33: 11544512 | BI33: 11544512 | BJ33: 11544512 | BK33: 11544512 | BL33: 11559267 | BM33: 11166267 | BN33: 10095312 | BO33: 10095312 | BP33: 8706346 | BQ33: 8706346 | BR33: 8811028 | BS33: 8811028 | BT33: 9302509 | BU33: 9302509 | BV33: 9302509 | BW33: 9302509 | BX33: 9302509 | BY33: 9302509 | BZ33: 9302509 | CA33: 9302509 | CB33: 9302509
B34: SERVIU Antofagasta | C34: 41468112 | D34: 36245332 | E34: 36663632 | F34: 36698206 | G34: 36732779 | H34: 36266351 | I34: 35758811 | J34: 35758811 | K34: 35758811 | L34: 35859421 | M34: 34878248 | N34: 29916675 | O34: 29916675 | P34: 35548395 | Q34: 41225450 | R34: 41757245 | S34: 41757245 | T34: 41771744 | U34: 41771744 | V34: 41815242 | W34: 40323711 | X34: 32895617 | Y34: 32895617 | Z34: 28719484 | AA34: 26431429 | AB34: 26431429 | AC34: 30263070 | AD34: 31368555 | AE34: 31368555 | AF34: 31368555 | AG34: 31368555 | AH34: 31368555 | AI34: 31368555 | AJ34: 31368555 | AK34: 31368555 | AL34: 31368555 | AM34: 24948049 | AN34: 17979056 | AO34: 17979056 | AP34: 10878804 | AQ34: 10878804 | AR34: 17648371 | AS34: 17845366 | AT34: 17871737 | AU34: 19717940 | AV34: 19717940 | AW34: 19717940 | AX34: 19480742 | AY34: 19480742 | AZ34: 18903775 | BA34: 15465604 | BB34: 15465604 | BC34: 13585888 | BD34: 14789146 | BE34: 15123006 | BF34: 15123006 | BG34: 15123006 | BH34: 15123006 | BI34: 15123006 | BJ34: 15123006 | BK34: 15123006 | BL34: 14248096 | BM34: 14248096 | BN34: 12638840 | BO34: 12638840 | BP34: 13197867 | BQ34: 12480252 | BR34: 12480252 | BS34: 12480252 | BT34: 14209379 | BU34: 14209379 | BV34: 14209379 | BW34: 14209379 | BX34: 14209379 | BY34: 14209379 | BZ34: 14209379 | CA34: 14209379 | CB34: 14209379
B35: SERVIU Atacama | C35: 21129078 | D35: 22568239 | E35: 22568239 | F35: 22774239 | G35: 22814239 | H35: 22814239 | I35: 22814239 | J35: 23235030 | K35: 23235030 | L35: 23235030 | M35: 18518157 | N35: 15731773 | O35: 15731773 | P35: 24875325 | Q35: 31089481 | R35: 27688501 | S35: 27688501 | T35: 27688501 | U35: 27688501 | V35: 25851245 | W35: 25851245 | X35: 25846245 | Y35: 25846245 | Z35: 19964707 | AA35: 18388246 | AB35: 18388246 | AC35: 21315123 | AD35: 21455123 | AE35: 21455123 | AF35: 21455123 | AG35: 22632742 | AH35: 22632742 | AI35: 22688742 | AJ35: 22688742 | AK35: 22688742 | AL35: 22688742 | AM35: 23118118 | AN35: 24322778 | AO35: 24322778 | AP35: 21518444 | AQ35: 21518444 | AR35: 17812520 | AS35: 17812520 | AT35: 17812520 | AU35: 17812520 | AV35: 17812520 | AW35: 17812520 | AX35: 17188321 | AY35: 17188321 | AZ35: 17188321 | BA35: 8570431 | BB35: 8570431 | BC35: 24183340 | BD35: 24535980 | BE35: 24535980 | BF35: 24535980 | BG35: 24535980 | BH35: 23536162 | BI35: 20536162 | BJ35: 20536162 | BK35: 20536162 | BL35: 20589662 | BM35: 20589662 | BN35: 15483238 | BO35: 15483238 | BP35: 9416801 | BQ35: 5916801 | BR35: 5916801 | BS35: 5916801 | BT35: 5916801 | BU35: 9175869 | BV35: 9175869 | BW35: 9175869 | BX35: 9175869 | BY35: 9175869 | BZ35: 9175869 | CA35: 9175869 | CB35: 9175869
B36: SERVIU Coquimbo | C36: 22488189 | D36: 20626973 | E36: 18390489 | F36: 18727330 | G36: 19034787 | H36: 19143744 | I36: 19143744 | J36: 19143744 | K36: 19561023 | L36: 19561023 | M36: 19550402 | N36: 12602298 | O36: 12602298 | P36: 29291800 | Q36: 34195489 | R36: 34195489 | S36: 34195489 | T36: 34245489 | U36: 34245489 | V36: 34245489 | W36: 34245489 | X36: 34062778 | Y36: 33922765 | Z36: 25336066 | AA36: 12697850 | AB36: 12697850 | AC36: 36352142 | AD36: 36370290 | AE36: 36370290 | AF36: 36370290 | AG36: 36370290 | AH36: 36361716 | AI36: 36391716 | AJ36: 36391716 | AK36: 36391716 | AL36: 36391716 | AM36: 35187465 | AN36: 21098315 | AO36: 21098315 | AP36: 38254690 | AQ36: 38254690 | AR36: 38299930 | AS36: 38299930 | AT36: 37058319 | AU36: 31127009 | AV36: 31127009 | AW36: 31127009 | AX36: 30852784 | AY36: 31053963 | AZ36: 27696869 | BA36: 18466482 | BB36: 18466482 | BC36: 27966487 | BD36: 27966487 | BE36: 27966487 | BF36: 27966487 | BG36: 27966487 | BH36: 27958887 | BI36: 27958887 | BJ36: 27958887 | BK36: 27958887 | BL36: 24576889 | BM36: 24265859 | BN36: 18613719 | BO36: 18613719 | BP36: 30615904 | BQ36: 26615904 | BR36: 26615904 | BS36: 26615904 | BT36: 26615904 | BU36: 24556836 | BV36: 24556836 | BW36: 24556836 | BX36: 24556836 | BY36: 24556836 | BZ36: 24556836 | CA36: 24556836 | CB36: 24556836
B37: SERVIU Valparaíso | C37: 62699377 | D37: 59024248 | E37: 60396733 | F37: 61299623 | G37: 61366769 | H37: 63349580 | I37: 63349580 | J37: 63259012 | K37: 62320472 | L37: 55598596 | M37: 55550496 | N37: 41461609 | O37: 41461609 | P37: 43170852 | Q37: 52549754 | R37: 52549754 | S37: 52549754 | T37: 52549754 | U37: 52549754 | V37: 52549754 | W37: 51105545 | X37: 38395230 | Y37: 38337494 | Z37: 36725387 | AA37: 35464491 | AB37: 35464491 | AC37: 40478579 | AD37: 42614131 | AE37: 42614131 | AF37: 42858620 | AG37: 42976422 | AH37: 43076422 | AI37: 43076422 | AJ37: 44994598 | AK37: 44994598 | AL37: 44994598 | AM37: 46728628 | AN37: 45394938 | AO37: 45394938 | AP37: 44262543 | AQ37: 44262543 | AR37: 48159048 | AS37: 48159048 | AT37: 48260848 | AU37: 48260848 | AV37: 48260848 | AW37: 52963275 | AX37: 54672379 | AY37: 54187315 | AZ37: 52019214 | BA37: 37750186 | BB37: 37750186 | BC37: 42009797 | BD37: 52978932 | BE37: 54382452 | BF37: 56213503 | BG37: 56213503 | BH37: 56953012 | BI37: 56953012 | BJ37: 56953012 | BK37: 56953012 | BL37: 57115499 | BM37: 57115499 | BN37: 58076198 | BO37: 58076198 | BP37: 55214851 | BQ37: 55906268 | BR37: 56878200 | BS37: 56878200 | BT37: 59441918 | BU37: 59526130 | BV37: 59526130 | BW37: 59526130 | BX37: 59526130 | BY37: 59526130 | BZ37: 59526130 | CA37: 59526130 | CB37: 59526130
B38: SERVIU Metropolitano | C38: 121451476 | D38: 129722304 | E38: 126707424 | F38: 126938685 | G38: 132323787 | H38: 128389149 | I38: 125484432 | J38: 125153718 | K38: 123524150 | L38: 122714026 | M38: 109967510 | N38: 95169709 | O38: 95169709 | P38: 100098472 | Q38: 121303403 | R38: 121303403 | S38: 120570587 | T38: 120556703 | U38: 119765730 | V38: 120443102 | W38: 118390115 | X38: 118390115 | Y38: 115077894 | Z38: 101166870 | AA38: 94520917 | AB38: 94520917 | AC38: 105488522 | AD38: 108633999 | AE38: 108633999 | AF38: 108633999 | AG38: 108633999 | AH38: 108774999 | AI38: 108897149 | AJ38: 108897149 | AK38: 108897149 | AL38: 108897149 | AM38: 92376604 | AN38: 73346177 | AO38: 73346177 | AP38: 87253576 | AQ38: 87253576 | AR38: 93927139 | AS38: 93927139 | AT38: 94027910 | AU38: 94051385 | AV38: 96196920 | AW38: 101535195 | AX38: 101582093 | AY38: 101562510 | AZ38: 100432485 | BA38: 86087430 | BB38: 86087430 | BC38: 74587862 | BD38: 76570114 | BE38: 76595114 | BF38: 76595114 | BG38: 76595114 | BH38: 80153860 | BI38: 80153860 | BJ38: 80153860 | BK38: 80153860 | BL38: 80236491 | BM38: 80236491 | BN38: 81413921 | BO38: 81413921 | BP38: 90590002 | BQ38: 90590002 | BR38: 90590002 | BS38: 90590002 | BT38: 92970431 | BU38: 92970431 | BV38: 93624803 | BW38: 93624803 | BX38: 93624803 | BY38: 93624803 | BZ38: 93624803 | CA38: 93624803 | CB38: 93624803
B39: SERVIU O'Higgins | C39: 14249499 | D39: 10546312 | E39: 12796312 | F39: 15015842 | G39: 15685395 | H39: 15785389 | I39: 15787719 | J39: 15831289 | K39: 16583631 | L39: 16483631 | M39: 13839062 | N39: 9678227 | O39: 9678227 | P39: 11870060 | Q39: 13917678 | R39: 14847860 | S39: 14847860 | T39: 14847860 | U39: 15300817 | V39: 15300817 | W39: 16297538 | X39: 16297538 | Y39: 16297538 | Z39: 11021810 | AA39: 7220234 | AB39: 7220234 | AC39: 16473882 | AD39: 16473882 | AE39: 16473882 | AF39: 16473882 | AG39: 16473882 | AH39: 16649669 | AI39: 16649669 | AJ39: 16649669 | AK39: 16649669 | AL39: 16649669 | AM39: 16911235 | AN39: 9607053 | AO39: 9607053 | AP39: 16690085 | AQ39: 16690085 | AR39: 16690085 | AS39: 16556501 | AT39: 14974879 | AU39: 14803771 | AV39: 12925518 | AW39: 12925518 | AX39: 11911329 | AY39: 12498650 | AZ39: 12535400 | BA39: 5515173 | BB39: 5515173 | BC39: 17865780 | BD39: 17865780 | BE39: 17865780 | BF39: 17865780 | BG39: 17865780 | BH39: 17865780 | BI39: 17865780 | BJ39: 17865780 | BK39: 17865780 | BL39: 16353696 | BM39: 14508227 | BN39: 9555042 | BO39: 9555042 | BP39: 14196992 | BQ39: 14196992 | BR39: 14196992 | BS39: 14196992 | BT39: 14196992 | BU39: 14707834 | BV39: 15769553 | BW39: 15769553 | BX39: 15769553 | BY39: 15769553 | BZ39: 15769553 | CA39: 15769553 | CB39: 15769553
