Workbook

Sheet MINVU_Mes_Corriente
B1: Ministerio de Salud — Partida 16
B2: Miles de pesos — moneda corriente — montos devengados
B4: SUBTÍTULO 31 – INICIATIVAS DE INVERSIÓN
B5: Presupuesto Ley (Subtítulo 31)
C6: 2014 | P6: 2015 | AC6: 2016 | AP6: 2017 | BC6: 2018 | BP6: 2019 | CC6: 2020 | CP6: 2021 | DC6: 2022 | DP6: 2023 | EC6: 2024 | EP6: 2025 | FC6: 2026
B7: Programa / Entidad | C7: Ene | D7: Feb | E7: Mar | F7: Abr | G7: May | H7: Jun | I7: Jul | J7: Ago | K7: Sep | L7: Oct | M7: Nov | N7: Dic | O7: Total 2014 | P7: Ene | Q7: Feb | R7: Mar | S7: Abr | T7: May | U7: Jun | V7: Jul | W7: Ago | X7: Sep | Y7: Oct | Z7: Nov | AA7: Dic | AB7: Total 2015 | AC7: Ene | AD7: Feb | AE7: Mar | AF7: Abr | AG7: May | AH7: Jun | AI7: Jul | AJ7: Ago | AK7: Sep | AL7: Oct | AM7: Nov | AN7: Dic | AO7: Total 2016 | AP7: Ene | AQ7: Feb | AR7: Mar | AS7: Abr | AT7: May | AU7: Jun | AV7: Jul | AW7: Ago | AX7: Sep | AY7: Oct | AZ7: Nov | BA7: Dic | BB7: Total 2017 | BC7: Ene | BD7: Feb | BE7: Mar | BF7: Abr | BG7: May | BH7: Jun | BI7: Jul | BJ7: Ago | BK7: Sep | BL7: Oct | BM7: Nov | BN7: Dic | BO7: Total 2018 | BP7: Ene | BQ7: Feb | BR7: Mar | BS7: Abr | BT7: May | BU7: Jun | BV7: Jul | BW7: Ago | BX7: Sep | BY7: Oct | BZ7: Nov | CA7: Dic | CB7: Total 2019 | CC7: Ene | CD7: Feb | CE7: Mar | CF7: Abr | CG7: May | CH7: Jun | CI7: Jul | CJ7: Ago | CK7: Sep | CL7: Oct | CM7: Nov | CN7: Dic | CO7: Total 2020 | CP7: Ene | CQ7: Feb | CR7: Mar | CS7: Abr | CT7: May | CU7: Jun | CV7: Jul | CW7: Ago | CX7: Sep | CY7: Oct | CZ7: Nov | DA7: Dic | DB7: Total 2021 | DC7: Ene | DD7: Feb | DE7: Mar | DF7: Abr | DG7: May | DH7: Jun | DI7: Jul | DJ7: Ago | DK7: Sep | DL7: Oct | DM7: Nov | DN7: Dic | DO7: Total 2022 | DP7: Ene | DQ7: Feb | DR7: Mar | DS7: Abr | DT7: May | DU7: Jun | DV7: Jul | DW7: Ago | DX7: Sep | DY7: Oct | DZ7: Nov | EA7: Dic | EB7: Total 2023 | EC7: Ene | ED7: Feb | EE7: Mar | EF7: Abr | EG7: May | EH7: Jun | EI7: Jul | EJ7: Ago | EK7: Sep | EL7: Oct | EM7: Nov | EN7: Dic | EO7: Total 2024 | EP7: Ene | EQ7: Feb | ER7: Mar | ES7: Abr | ET7: May | EU7: Jun | EV7: Jul | EW7: Ago | EX7: Sep | EY7: Oct | EZ7: Nov | FA7: Dic | FB7: Total 2025 | FC7: Ene | FD7: Feb | FE7: Mar | FF7: Abr | FG7: May | FH7: Jun | FI7: Jul | FJ7: Ago | FK7: Sep | FL7: Oct | FM7: Nov | FN7: Dic | FO7: Total 2026
B8: Instituto de Salud Pública | C8: 747570 | D8: 747570 | E8: 747570 | F8: 747570 | G8: 747570 | H8: 747570 | I8: 747570 | J8: 747570 | K8: 747570 | L8: 747570 | M8: 747570 | N8: 747570 | O8: =N8 -> 747570 | P8: 206000 | Q8: 206000 | R8: 206000 | S8: 206000 | T8: 206000 | U8: 206000 | V8: 206000 | W8: 206000 | X8: 206000 | Y8: 206000 | Z8: 206000 | AA8: 206000 | AB8: =AA8 -> 206000 | AC8: 0 | AD8: 0 | AE8: 0 | AF8: 0 | AG8: 0 | AH8: 0 | AI8: 0 | AJ8: 0 | AK8: 0 | AL8: 0 | AM8: 0 | AN8: 0 | AO8: =AN8 -> 0 | AP8: 237364 | AQ8: 237364 | AR8: 237364 | AS8: 237364 | AT8: 237364 | AU8: 237364 | AV8: 237364 | AW8: 237364 | AX8: 237364 | AY8: 237364 | AZ8: 237364 | BA8: 237364 | BB8: =BA8 -> 237364 | BC8: 0 | BD8: 0 | BE8: 0 | BF8: 0 | BG8: 0 | BH8: 0 | BI8: 0 | BJ8: 0 | BK8: 0 | BL8: 0 | BM8: 0 | BN8: 0 | BO8: =BN8 -> 0 | BP8: 0 | BQ8: 0 | BR8: 0 | BS8: 0 | BT8: 0 | BU8: 0 | BV8: 0 | BW8: 0 | BX8: 0 | BY8: 0 | BZ8: 0 | CA8: 0 | CB8: =CA8 -> 0 | CC8: 1026000 | CD8: 1026000 | CE8: 1026000 | CF8: 1026000 | CG8: 1026000 | CH8: 1026000 | CI8: 1026000 | CJ8: 1026000 | CK8: 1026000 | CL8: 1026000 | CM8: 1026000 | CN8: 1026000 | CO8: =CN8 -> 1026000 | CP8: 800605 | CQ8: 800605 | CR8: 800605 | CS8: 800605 | CT8: 800605 | CU8: 800605 | CV8: 800605 | CW8: 800605 | CX8: 800605 | CY8: 800605 | CZ8: 800605 | DA8: 800605 | DB8: =DA8 -> 800605 | DC8: 2301909 | DD8: 2301909 | DE8: 2301909 | DF8: 2301909 | DG8: 2301909 | DH8: 2301909 | DI8: 2301909 | DJ8: 2301909 | DK8: 2301909 | DL8: 2301909 | DM8: 2301909 | DN8: 2301909 | DO8: =DN8 -> 2301909 | DP8: 1324402 | DQ8: 1324402 | DR8: 1324402 | DS8: 1324402 | DT8: 1324402 | DU8: 1324402 | DV8: 1324402 | DW8: 1324402 | DX8: 1324402 | DY8: 1324402 | DZ8: 1324402 | EA8: 1324402 | EB8: =EA8 -> 1324402 | EC8: 1459534 | ED8: 1459534 | EE8: 1459534 | EF8: 1459534 | EG8: 1459534 | EH8: 1459534 | EI8: 1459534 | EJ8: 1459534 | EK8: 1459534 | EL8: 1459534 | EM8: 1459534 | EN8: 1459534 | EO8: =EN8 -> 1459534 | EP8: 781455 | EQ8: 781455 | ER8: 781455 | ES8: 781455 | ET8: 781455 | EU8: 781455 | EV8: 781455 | EW8: 781455 | EX8: 781455 | EY8: 781455 | EZ8: 781455 | FA8: 781455 | FB8: =FA8 -> 781455 | FC8: 657325 | FD8: 657325 | FE8: 657325 | FF8: 657325 | FG8: 657325 | FH8: 657325 | FI8: 657325 | FO8: =FI8 -> 657325
B9: Subsecretaría de Salud Pública | C9: 0 | D9: 0 | E9: 0 | F9: 0 | G9: 0 | H9: 0 | I9: 0 | J9: 0 | K9: 0 | L9: 0 | M9: 0 | N9: 0 | O9: =N9 -> 0 | P9: 0 | Q9: 0 | R9: 0 | S9: 0 | T9: 0 | U9: 0 | V9: 0 | W9: 0 | X9: 0 | Y9: 0 | Z9: 0 | AA9: 0 | AB9: =AA9 -> 0 | AC9: 0 | AD9: 0 | AE9: 0 | AF9: 0 | AG9: 0 | AH9: 0 | AI9: 0 | AJ9: 0 | AK9: 0 | AL9: 0 | AM9: 0 | AN9: 0 | AO9: =AN9 -> 0 | AP9: 0 | AQ9: 0 | AR9: 0 | AS9: 0 | AT9: 0 | AU9: 0 | AV9: 0 | AW9: 0 | AX9: 0 | AY9: 0 | AZ9: 0 | BA9: 0 | BB9: =BA9 -> 0 | BC9: 0 | BD9: 0 | BE9: 0 | BF9: 0 | BG9: 0 | BH9: 0 | BI9: 0 | BJ9: 0 | BK9: 0 | BL9: 0 | BM9: 0 | BN9: 0 | BO9: =BN9 -> 0 | BP9: 0 | BQ9: 0 | BR9: 0 | BS9: 0 | BT9: 0 | BU9: 0 | BV9: 0 | BW9: 0 | BX9: 0 | BY9: 0 | BZ9: 0 | CA9: 0 | CB9: =CA9 -> 0 | CC9: 0 | CD9: 0 | CE9: 0 | CF9: 0 | CG9: 0 | CH9: 0 | CI9: 0 | CJ9: 0 | CK9: 0 | CL9: 0 | CM9: 0 | CN9: 0 | CO9: =CN9 -> 0 | CP9: 0 | CQ9: 0 | CR9: 0 | CS9: 0 | CT9: 0 | CU9: 0 | CV9: 0 | CW9: 0 | CX9: 0 | CY9: 0 | CZ9: 0 | DA9: 0 | DB9: =DA9 -> 0 | DC9: 0 | DD9: 0 | DE9: 0 | DF9: 0 | DG9: 0 | DH9: 0 | DI9: 0 | DJ9: 0 | DK9: 0 | DL9: 0 | DM9: 0 | DN9: 0 | DO9: =DN9 -> 0 | DP9: 0 | DQ9: 0 | DR9: 0 | DS9: 0 | DT9: 0 | DU9: 0 | DV9: 0 | DW9: 0 | DX9: 0 | DY9: 0 | DZ9: 0 | EA9: 0 | EB9: =EA9 -> 0 | EC9: 0 | ED9: 0 | EE9: 0 | EF9: 0 | EG9: 0 | EH9: 0 | EI9: 0 | EJ9: 0 | EK9: 0 | EL9: 0 | EM9: 0 | EN9: 0 | EO9: =EN9 -> 0 | EP9: 0 | EQ9: 0 | ER9: 0 | ES9: 0 | ET9: 0 | EU9: 0 | EV9: 0 | EW9: 0 | EX9: 0 | EY9: 0 | EZ9: 0 | FA9: 0 | FB9: =FA9 -> 0 | FC9: 3133791 | FD9: 3133791 | FE9: 3133791 | FF9: 3133791 | FG9: 3133791 | FH9: 3133791 | FI9: 3133791 | FO9: =FI9 -> 3133791
B10: Inversión Sectorial en Salud | C10: 274548673 | D10: 274548673 | E10: 274548673 | F10: 274548673 | G10: 274548673 | H10: 274548673 | I10: 274548673 | J10: 274548673 | K10: 274548673 | L10: 274548673 | M10: 274548673 | N10: 274548673 | O10: =N10 -> 274548673 | P10: 528813287 | Q10: 528813287 | R10: 528813287 | S10: 528813287 | T10: 528813287 | U10: 528813287 | V10: 528813287 | W10: 528813287 | X10: 528813287 | Y10: 528813287 | Z10: 528813287 | AA10: 528813287 | AB10: =AA10 -> 528813287 | AC10: 497824800 | AD10: 497824800 | AE10: 497824800 | AF10: 497824800 | AG10: 497824800 | AH10: 497824800 | AI10: 497824800 | AJ10: 497824800 | AK10: 497824800 | AL10: 497824800 | AM10: 497824800 | AN10: 497824800 | AO10: =AN10 -> 497824800 | AP10: 349316570 | AQ10: 349316570 | AR10: 349316570 | AS10: 349316570 | AT10: 349316570 | AU10: 349316570 | AV10: 349316570 | AW10: 349316570 | AX10: 349316570 | AY10: 349316570 | AZ10: 349316570 | BA10: 349316570 | BB10: =BA10 -> 349316570 | BC10: 439600285 | BD10: 439600285 | BE10: 439600285 | BF10: 439600285 | BG10: 439600285 | BH10: 439600285 | BI10: 439600285 | BJ10: 439600285 | BK10: 439600285 | BL10: 439600285 | BM10: 439600285 | BN10: 439600285 | BO10: =BN10 -> 439600285 | BP10: 418874044 | BQ10: 418874044 | BR10: 418874044 | BS10: 418874044 | BT10: 418874044 | BU10: 418874044 | BV10: 418874044 | BW10: 418874044 | BX10: 418874044 | BY10: 418874044 | BZ10: 418874044 | CA10: 418874044 | CB10: =CA10 -> 418874044 | CC10: 733952985 | CD10: 733952985 | CE10: 733952985 | CF10: 733952985 | CG10: 733952985 | CH10: 733952985 | CI10: 733952985 | CJ10: 733952985 | CK10: 733952985 | CL10: 733952985 | CM10: 733952985 | CN10: 733952985 | CO10: =CN10 -> 733952985 | CP10: 653979311 | CQ10: 653979311 | CR10: 653979311 | CS10: 653979311 | CT10: 653979311 | CU10: 653979311 | CV10: 653979311 | CW10: 653979311 | CX10: 653979311 | CY10: 653979311 | CZ10: 653979311 | DA10: 653979311 | DB10: =DA10 -> 653979311 | DC10: 642175866 | DD10: 642175866 | DE10: 642175866 | DF10: 642175866 | DG10: 642175866 | DH10: 642175866 | DI10: 642175866 | DJ10: 642175866 | DK10: 642175866 | DL10: 642175866 | DM10: 642175866 | DN10: 642175866 | DO10: =DN10 -> 642175866 | DP10: 709260889 | DQ10: 709260889 | DR10: 709260889 | DS10: 709260889 | DT10: 709260889 | DU10: 709260889 | DV10: 709260889 | DW10: 709260889 | DX10: 709260889 | DY10: 709260889 | DZ10: 709260889 | EA10: 709260889 | EB10: =EA10 -> 709260889 | EC10: 581851338 | ED10: 581851338 | EE10: 581851338 | EF10: 581851338 | EG10: 581851338 | EH10: 581851338 | EI10: 581851338 | EJ10: 581851338 | EK10: 581851338 | EL10: 581851338 | EM10: 581851338 | EN10: 581851338 | EO10: =EN10 -> 581851338 | EP10: 573366549 | EQ10: 573366549 | ER10: 573366549 | ES10: 573366549 | ET10: 573366549 | EU10: 573366549 | EV10: 573366549 | EW10: 573366549 | EX10: 573366549 | EY10: 573366549 | EZ10: 573366549 | FA10: 573366549 | FB10: =FA10 -> 573366549 | FC10: 201002151 | FD10: 201002151 | FE10: 201002151 | FF10: 201002151 | FG10: 201002151 | FH10: 201002151 | FI10: 201002151 | FO10: =FI10 -> 201002151
B11: Servicio de Salud Arica y Parinacota | C11: 0 | D11: 0 | E11: 0 | F11: 0 | G11: 0 | H11: 0 | I11: 0 | J11: 0 | K11: 0 | L11: 0 | M11: 0 | N11: 0 | O11: =N11 -> 0 | P11: 0 | Q11: 0 | R11: 0 | S11: 0 | T11: 0 | U11: 0 | V11: 0 | W11: 0 | X11: 0 | Y11: 0 | Z11: 0 | AA11: 0 | AB11: =AA11 -> 0 | AC11: 0 | AD11: 0 | AE11: 0 | AF11: 0 | AG11: 0 | AH11: 0 | AI11: 0 | AJ11: 0 | AK11: 0 | AL11: 0 | AM11: 0 | AN11: 0 | AO11: =AN11 -> 0 | AP11: 0 | AQ11: 0 | AR11: 0 | AS11: 0 | AT11: 0 | AU11: 0 | AV11: 0 | AW11: 0 | AX11: 0 | AY11: 0 | AZ11: 0 | BA11: 0 | BB11: =BA11 -> 0 | BC11: 0 | BD11: 0 | BE11: 0 | BF11: 0 | BG11: 0 | BH11: 0 | BI11: 0 | BJ11: 0 | BK11: 0 | BL11: 0 | BM11: 0 | BN11: 0 | BO11: =BN11 -> 0 | BP11: 0 | BQ11: 0 | BR11: 0 | BS11: 0 | BT11: 0 | BU11: 0 | BV11: 0 | BW11: 0 | BX11: 0 | BY11: 0 | BZ11: 0 | CA11: 0 | CB11: =CA11 -> 0 | CC11: 0 | CD11: 0 | CE11: 0 | CF11: 0 | CG11: 0 | CH11: 0 | CI11: 0 | CJ11: 0 | CK11: 0 | CL11: 0 | CM11: 0 | CN11: 0 | CO11: =CN11 -> 0 | CP11: 0 | CQ11: 0 | CR11: 0 | CS11: 0 | CT11: 0 | CU11: 0 | CV11: 0 | CW11: 0 | CX11: 0 | CY11: 0 | CZ11: 0 | DA11: 0 | DB11: =DA11 -> 0 | DC11: 0 | DD11: 0 | DE11: 0 | DF11: 0 | DG11: 0 | DH11: 0 | DI11: 0 | DJ11: 0 | DK11: 0 | DL11: 0 | DM11: 0 | DN11: 0 | DO11: =DN11 -> 0 | DP11: 0 | DQ11: 0 | DR11: 0 | DS11: 0 | DT11: 0 | DU11: 0 | DV11: 0 | DW11: 0 | DX11: 0 | DY11: 0 | DZ11: 0 | EA11: 0 | EB11: =EA11 -> 0 | EC11: 0 | ED11: 0 | EE11: 0 | EF11: 0 | EG11: 0 | EH11: 0 | EI11: 0 | EJ11: 0 | EK11: 0 | EL11: 0 | EM11: 0 | EN11: 0 | EO11: =EN11 -> 0 | EP11: 0 | EQ11: 0 | ER11: 0 | ES11: 0 | ET11: 0 | EU11: 0 | EV11: 0 | EW11: 0 | EX11: 0 | EY11: 0 | EZ11: 0 | FA11: 0 | FB11: =FA11 -> 0 | FC11: 3783756 | FD11: 3783756 | FE11: 3783756 | FF11: 3783756 | FG11: 3783756 | FH11: 3783756 | FI11: 3783756 | FO11: =FI11 -> 3783756
B12: Servicio de Salud Tarapacá | C12: 0 | D12: 0 | E12: 0 | F12: 0 | G12: 0 | H12: 0 | I12: 0 | J12: 0 | K12: 0 | L12: 0 | M12: 0 | N12: 0 | O12: =N12 -> 0 | P12: 0 | Q12: 0 | R12: 0 | S12: 0 | T12: 0 | U12: 0 | V12: 0 | W12: 0 | X12: 0 | Y12: 0 | Z12: 0 | AA12: 0 | AB12: =AA12 -> 0 | AC12: 0 | AD12: 0 | AE12: 0 | AF12: 0 | AG12: 0 | AH12: 0 | AI12: 0 | AJ12: 0 | AK12: 0 | AL12: 0 | AM12: 0 | AN12: 0 | AO12: =AN12 -> 0 | AP12: 0 | AQ12: 0 | AR12: 0 | AS12: 0 | AT12: 0 | AU12: 0 | AV12: 0 | AW12: 0 | AX12: 0 | AY12: 0 | AZ12: 0 | BA12: 0 | BB12: =BA12 -> 0 | BC12: 0 | BD12: 0 | BE12: 0 | BF12: 0 | BG12: 0 | BH12: 0 | BI12: 0 | BJ12: 0 | BK12: 0 | BL12: 0 | BM12: 0 | BN12: 0 | BO12: =BN12 -> 0 | BP12: 0 | BQ12: 0 | BR12: 0 | BS12: 0 | BT12: 0 | BU12: 0 | BV12: 0 | BW12: 0 | BX12: 0 | BY12: 0 | BZ12: 0 | CA12: 0 | CB12: =CA12 -> 0 | CC12: 0 | CD12: 0 | CE12: 0 | CF12: 0 | CG12: 0 | CH12: 0 | CI12: 0 | CJ12: 0 | CK12: 0 | CL12: 0 | CM12: 0 | CN12: 0 | CO12: =CN12 -> 0 | CP12: 0 | CQ12: 0 | CR12: 0 | CS12: 0 | CT12: 0 | CU12: 0 | CV12: 0 | CW12: 0 | CX12: 0 | CY12: 0 | CZ12: 0 | DA12: 0 | DB12: =DA12 -> 0 | DC12: 0 | DD12: 0 | DE12: 0 | DF12: 0 | DG12: 0 | DH12: 0 | DI12: 0 | DJ12: 0 | DK12: 0 | DL12: 0 | DM12: 0 | DN12: 0 | DO12: =DN12 -> 0 | DP12: 0 | DQ12: 0 | DR12: 0 | DS12: 0 | DT12: 0 | DU12: 0 | DV12: 0 | DW12: 0 | DX12: 0 | DY12: 0 | DZ12: 0 | EA12: 0 | EB12: =EA12 -> 0 | EC12: 0 | ED12: 0 | EE12: 0 | EF12: 0 | EG12: 0 | EH12: 0 | EI12: 0 | EJ12: 0 | EK12: 0 | EL12: 0 | EM12: 0 | EN12: 0 | EO12: =EN12 -> 0 | EP12: 0 | EQ12: 0 | ER12: 0 | ES12: 0 | ET12: 0 | EU12: 0 | EV12: 0 | EW12: 0 | EX12: 0 | EY12: 0 | EZ12: 0 | FA12: 0 | FB12: =FA12 -> 0 | FC12: 22899006 | FD12: 22899006 | FE12: 22899006 | FF12: 22899006 | FG12: 22899006 | FH12: 22899006 | FI12: 22899006 | FO12: =FI12 -> 22899006
B13: Servicio de Salud Antofagasta | C13: 0 | D13: 0 | E13: 0 | F13: 0 | G13: 0 | H13: 0 | I13: 0 | J13: 0 | K13: 0 | L13: 0 | M13: 0 | N13: 0 | O13: =N13 -> 0 | P13: 0 | Q13: 0 | R13: 0 | S13: 0 | T13: 0 | U13: 0 | V13: 0 | W13: 0 | X13: 0 | Y13: 0 | Z13: 0 | AA13: 0 | AB13: =AA13 -> 0 | AC13: 0 | AD13: 0 | AE13: 0 | AF13: 0 | AG13: 0 | AH13: 0 | AI13: 0 | AJ13: 0 | AK13: 0 | AL13: 0 | AM13: 0 | AN13: 0 | AO13: =AN13 -> 0 | AP13: 0 | AQ13: 0 | AR13: 0 | AS13: 0 | AT13: 0 | AU13: 0 | AV13: 0 | AW13: 0 | AX13: 0 | AY13: 0 | AZ13: 0 | BA13: 0 | BB13: =BA13 -> 0 | BC13: 4104000 | BD13: 4104000 | BE13: 4104000 | BF13: 4104000 | BG13: 4104000 | BH13: 4104000 | BI13: 4104000 | BJ13: 4104000 | BK13: 4104000 | BL13: 4104000 | BM13: 4104000 | BN13: 4104000 | BO13: =BN13 -> 4104000 | BP13: 0 | BQ13: 0 | BR13: 0 | BS13: 0 | BT13: 0 | BU13: 0 | BV13: 0 | BW13: 0 | BX13: 0 | BY13: 0 | BZ13: 0 | CA13: 0 | CB13: =CA13 -> 0 | CC13: 0 | CD13: 0 | CE13: 0 | CF13: 0 | CG13: 0 | CH13: 0 | CI13: 0 | CJ13: 0 | CK13: 0 | CL13: 0 | CM13: 0 | CN13: 0 | CO13: =CN13 -> 0 | CP13: 0 | CQ13: 0 | CR13: 0 | CS13: 0 | CT13: 0 | CU13: 0 | CV13: 0 | CW13: 0 | CX13: 0 | CY13: 0 | CZ13: 0 | DA13: 0 | DB13: =DA13 -> 0 | DC13: 0 | DD13: 0 | DE13: 0 | DF13: 0 | DG13: 0 | DH13: 0 | DI13: 0 | DJ13: 0 | DK13: 0 | DL13: 0 | DM13: 0 | DN13: 0 | DO13: =DN13 -> 0 | DP13: 0 | DQ13: 0 | DR13: 0 | DS13: 0 | DT13: 0 | DU13: 0 | DV13: 0 | DW13: 0 | DX13: 0 | DY13: 0 | DZ13: 0 | EA13: 0 | EB13: =EA13 -> 0 | EC13: 0 | ED13: 0 | EE13: 0 | EF13: 0 | EG13: 0 | EH13: 0 | EI13: 0 | EJ13: 0 | EK13: 0 | EL13: 0 | EM13: 0 | EN13: 0 | EO13: =EN13 -> 0 | EP13: 0 | EQ13: 0 | ER13: 0 | ES13: 0 | ET13: 0 | EU13: 0 | EV13: 0 | EW13: 0 | EX13: 0 | EY13: 0 | EZ13: 0 | FA13: 0 | FB13: =FA13 -> 0 | FC13: 3191908 | FD13: 3191908 | FE13: 3191908 | FF13: 3191908 | FG13: 3191908 | FH13: 3191908 | FI13: 3191908 | FO13: =FI13 -> 3191908
B14: Servicio de Salud Atacama | C14: 0 | D14: 0 | E14: 0 | F14: 0 | G14: 0 | H14: 0 | I14: 0 | J14: 0 | K14: 0 | L14: 0 | M14: 0 | N14: 0 | O14: =N14 -> 0 | P14: 0 | Q14: 0 | R14: 0 | S14: 0 | T14: 0 | U14: 0 | V14: 0 | W14: 0 | X14: 0 | Y14: 0 | Z14: 0 | AA14: 0 | AB14: =AA14 -> 0 | AC14: 0 | AD14: 0 | AE14: 0 | AF14: 0 | AG14: 0 | AH14: 0 | AI14: 0 | AJ14: 0 | AK14: 0 | AL14: 0 | AM14: 0 | AN14: 0 | AO14: =AN14 -> 0 | AP14: 0 | AQ14: 0 | AR14: 0 | AS14: 0 | AT14: 0 | AU14: 0 | AV14: 0 | AW14: 0 | AX14: 0 | AY14: 0 | AZ14: 0 | BA14: 0 | BB14: =BA14 -> 0 | BC14: 0 | BD14: 0 | BE14: 0 | BF14: 0 | BG14: 0 | BH14: 0 | BI14: 0 | BJ14: 0 | BK14: 0 | BL14: 0 | BM14: 0 | BN14: 0 | BO14: =BN14 -> 0 | BP14: 0 | BQ14: 0 | BR14: 0 | BS14: 0 | BT14: 0 | BU14: 0 | BV14: 0 | BW14: 0 | BX14: 0 | BY14: 0 | BZ14: 0 | CA14: 0 | CB14: =CA14 -> 0 | CC14: 0 | CD14: 0 | CE14: 0 | CF14: 0 | CG14: 0 | CH14: 0 | CI14: 0 | CJ14: 0 | CK14: 0 | CL14: 0 | CM14: 0 | CN14: 0 | CO14: =CN14 -> 0 | CP14: 0 | CQ14: 0 | CR14: 0 | CS14: 0 | CT14: 0 | CU14: 0 | CV14: 0 | CW14: 0 | CX14: 0 | CY14: 0 | CZ14: 0 | DA14: 0 | DB14: =DA14 -> 0 | DC14: 0 | DD14: 0 | DE14: 0 | DF14: 0 | DG14: 0 | DH14: 0 | DI14: 0 | DJ14: 0 | DK14: 0 | DL14: 0 | DM14: 0 | DN14: 0 | DO14: =DN14 -> 0 | DP14: 0 | DQ14: 0 | DR14: 0 | DS14: 0 | DT14: 0 | DU14: 0 | DV14: 0 | DW14: 0 | DX14: 0 | DY14: 0 | DZ14: 0 | EA14: 0 | EB14: =EA14 -> 0 | EC14: 0 | ED14: 0 | EE14: 0 | EF14: 0 | EG14: 0 | EH14: 0 | EI14: 0 | EJ14: 0 | EK14: 0 | EL14: 0 | EM14: 0 | EN14: 0 | EO14: =EN14 -> 0 | EP14: 0 | EQ14: 0 | ER14: 0 | ES14: 0 | ET14: 0 | EU14: 0 | EV14: 0 | EW14: 0 | EX14: 0 | EY14: 0 | EZ14: 0 | FA14: 0 | FB14: =FA14 -> 0 | FC14: 14546113 | FD14: 14546113 | FE14: 14546113 | FF14: 14546113 | FG14: 14546113 | FH14: 14546113 | FI14: 14546113 | FO14: =FI14 -> 14546113
B15: Servicio de Salud Coquimbo | C15: 0 | D15: 0 | E15: 0 | F15: 0 | G15: 0 | H15: 0 | I15: 0 | J15: 0 | K15: 0 | L15: 0 | M15: 0 | N15: 0 | O15: =N15 -> 0 | P15: 0 | Q15: 0 | R15: 0 | S15: 0 | T15: 0 | U15: 0 | V15: 0 | W15: 0 | X15: 0 | Y15: 0 | Z15: 0 | AA15: 0 | AB15: =AA15 -> 0 | AC15: 0 | AD15: 0 | AE15: 0 | AF15: 0 | AG15: 0 | AH15: 0 | AI15: 0 | AJ15: 0 | AK15: 0 | AL15: 0 | AM15: 0 | AN15: 0 | AO15: =AN15 -> 0 | AP15: 0 | AQ15: 0 | AR15: 0 | AS15: 0 | AT15: 0 | AU15: 0 | AV15: 0 | AW15: 0 | AX15: 0 | AY15: 0 | AZ15: 0 | BA15: 0 | BB15: =BA15 -> 0 | BC15: 0 | BD15: 0 | BE15: 0 | BF15: 0 | BG15: 0 | BH15: 0 | BI15: 0 | BJ15: 0 | BK15: 0 | BL15: 0 | BM15: 0 | BN15: 0 | BO15: =BN15 -> 0 | BP15: 0 | BQ15: 0 | BR15: 0 | BS15: 0 | BT15: 0 | BU15: 0 | BV15: 0 | BW15: 0 | BX15: 0 | BY15: 0 | BZ15: 0 | CA15: 0 | CB15: =CA15 -> 0 | CC15: 0 | CD15: 0 | CE15: 0 | CF15: 0 | CG15: 0 | CH15: 0 | CI15: 0 | CJ15: 0 | CK15: 0 | CL15: 0 | CM15: 0 | CN15: 0 | CO15: =CN15 -> 0 | CP15: 0 | CQ15: 0 | CR15: 0 | CS15: 0 | CT15: 0 | CU15: 0 | CV15: 0 | CW15: 0 | CX15: 0 | CY15: 0 | CZ15: 0 | DA15: 0 | DB15: =DA15 -> 0 | DC15: 0 | DD15: 0 | DE15: 0 | DF15: 0 | DG15: 0 | DH15: 0 | DI15: 0 | DJ15: 0 | DK15: 0 | DL15: 0 | DM15: 0 | DN15: 0 | DO15: =DN15 -> 0 | DP15: 0 | DQ15: 0 | DR15: 0 | DS15: 0 | DT15: 0 | DU15: 0 | DV15: 0 | DW15: 0 | DX15: 0 | DY15: 0 | DZ15: 0 | EA15: 0 | EB15: =EA15 -> 0 | EC15: 0 | ED15: 0 | EE15: 0 | EF15: 0 | EG15: 0 | EH15: 0 | EI15: 0 | EJ15: 0 | EK15: 0 | EL15: 0 | EM15: 0 | EN15: 0 | EO15: =EN15 -> 0 | EP15: 0 | EQ15: 0 | ER15: 0 | ES15: 0 | ET15: 0 | EU15: 0 | EV15: 0 | EW15: 0 | EX15: 0 | EY15: 0 | EZ15: 0 | FA15: 0 | FB15: =FA15 -> 0 | FC15: 15086131 | FD15: 15086131 | FE15: 15086131 | FF15: 15086131 | FG15: 15086131 | FH15: 15086131 | FI15: 15086131 | FO15: =FI15 -> 15086131
B16: Servicio de Salud Valparaíso - San Antonio | C16: 0 | D16: 0 | E16: 0 | F16: 0 | G16: 0 | H16: 0 | I16: 0 | J16: 0 | K16: 0 | L16: 0 | M16: 0 | N16: 0 | O16: =N16 -> 0 | P16: 0 | Q16: 0 | R16: 0 | S16: 0 | T16: 0 | U16: 0 | V16: 0 | W16: 0 | X16: 0 | Y16: 0 | Z16: 0 | AA16: 0 | AB16: =AA16 -> 0 | AC16: 0 | AD16: 0 | AE16: 0 | AF16: 0 | AG16: 0 | AH16: 0 | AI16: 0 | AJ16: 0 | AK16: 0 | AL16: 0 | AM16: 0 | AN16: 0 | AO16: =AN16 -> 0 | AP16: 0 | AQ16: 0 | AR16: 0 | AS16: 0 | AT16: 0 | AU16: 0 | AV16: 0 | AW16: 0 | AX16: 0 | AY16: 0 | AZ16: 0 | BA16: 0 | BB16: =BA16 -> 0 | BC16: 0 | BD16: 0 | BE16: 0 | BF16: 0 | BG16: 0 | BH16: 0 | BI16: 0 | BJ16: 0 | BK16: 0 | BL16: 0 | BM16: 0 | BN16: 0 | BO16: =BN16 -> 0 | BP16: 0 | BQ16: 0 | BR16: 0 | BS16: 0 | BT16: 0 | BU16: 0 | BV16: 0 | BW16: 0 | BX16: 0 | BY16: 0 | BZ16: 0 | CA16: 0 | CB16: =CA16 -> 0 | CC16: 0 | CD16: 0 | CE16: 0 | CF16: 0 | CG16: 0 | CH16: 0 | CI16: 0 | CJ16: 0 | CK16: 0 | CL16: 0 | CM16: 0 | CN16: 0 | CO16: =CN16 -> 0 | CP16: 0 | CQ16: 0 | CR16: 0 | CS16: 0 | CT16: 0 | CU16: 0 | CV16: 0 | CW16: 0 | CX16: 0 | CY16: 0 | CZ16: 0 | DA16: 0 | DB16: =DA16 -> 0 | DC16: 0 | DD16: 0 | DE16: 0 | DF16: 0 | DG16: 0 | DH16: 0 | DI16: 0 | DJ16: 0 | DK16: 0 | DL16: 0 | DM16: 0 | DN16: 0 | DO16: =DN16 -> 0 | DP16: 0 | DQ16: 0 | DR16: 0 | DS16: 0 | DT16: 0 | DU16: 0 | DV16: 0 | DW16: 0 | DX16: 0 | DY16: 0 | DZ16: 0 | EA16: 0 | EB16: =EA16 -> 0 | EC16: 0 | ED16: 0 | EE16: 0 | EF16: 0 | EG16: 0 | EH16: 0 | EI16: 0 | EJ16: 0 | EK16: 0 | EL16: 0 | EM16: 0 | EN16: 0 | EO16: =EN16 -> 0 | EP16: 0 | EQ16: 0 | ER16: 0 | ES16: 0 | ET16: 0 | EU16: 0 | EV16: 0 | EW16: 0 | EX16: 0 | EY16: 0 | EZ16: 0 | FA16: 0 | FB16: =FA16 -> 0 | FC16: 21931475 | FD16: 21931475 | FE16: 21931475 | FF16: 21931475 | FG16: 21931475 | FH16: 21931475 | FI16: 21931475 | FO16: =FI16 -> 21931475
B17: Servicio de Salud Viña del Mar - Quillota | C17: 0 | D17: 0 | E17: 0 | F17: 0 | G17: 0 | H17: 0 | I17: 0 | J17: 0 | K17: 0 | L17: 0 | M17: 0 | N17: 0 | O17: =N17 -> 0 | P17: 0 | Q17: 0 | R17: 0 | S17: 0 | T17: 0 | U17: 0 | V17: 0 | W17: 0 | X17: 0 | Y17: 0 | Z17: 0 | AA17: 0 | AB17: =AA17 -> 0 | AC17: 0 | AD17: 0 | AE17: 0 | AF17: 0 | AG17: 0 | AH17: 0 | AI17: 0 | AJ17: 0 | AK17: 0 | AL17: 0 | AM17: 0 | AN17: 0 | AO17: =AN17 -> 0 | AP17: 0 | AQ17: 0 | AR17: 0 | AS17: 0 | AT17: 0 | AU17: 0 | AV17: 0 | AW17: 0 | AX17: 0 | AY17: 0 | AZ17: 0 | BA17: 0 | BB17: =BA17 -> 0 | BC17: 0 | BD17: 0 | BE17: 0 | BF17: 0 | BG17: 0 | BH17: 0 | BI17: 0 | BJ17: 0 | BK17: 0 | BL17: 0 | BM17: 0 | BN17: 0 | BO17: =BN17 -> 0 | BP17: 0 | BQ17: 0 | BR17: 0 | BS17: 0 | BT17: 0 | BU17: 0 | BV17: 0 | BW17: 0 | BX17: 0 | BY17: 0 | BZ17: 0 | CA17: 0 | CB17: =CA17 -> 0 | CC17: 0 | CD17: 0 | CE17: 0 | CF17: 0 | CG17: 0 | CH17: 0 | CI17: 0 | CJ17: 0 | CK17: 0 | CL17: 0 | CM17: 0 | CN17: 0 | CO17: =CN17 -> 0 | CP17: 0 | CQ17: 0 | CR17: 0 | CS17: 0 | CT17: 0 | CU17: 0 | CV17: 0 | CW17: 0 | CX17: 0 | CY17: 0 | CZ17: 0 | DA17: 0 | DB17: =DA17 -> 0 | DC17: 0 | DD17: 0 | DE17: 0 | DF17: 0 | DG17: 0 | DH17: 0 | DI17: 0 | DJ17: 0 | DK17: 0 | DL17: 0 | DM17: 0 | DN17: 0 | DO17: =DN17 -> 0 | DP17: 0 | DQ17: 0 | DR17: 0 | DS17: 0 | DT17: 0 | DU17: 0 | DV17: 0 | DW17: 0 | DX17: 0 | DY17: 0 | DZ17: 0 | EA17: 0 | EB17: =EA17 -> 0 | EC17: 0 | ED17: 0 | EE17: 0 | EF17: 0 | EG17: 0 | EH17: 0 | EI17: 0 | EJ17: 0 | EK17: 0 | EL17: 0 | EM17: 0 | EN17: 0 | EO17: =EN17 -> 0 | EP17: 0 | EQ17: 0 | ER17: 0 | ES17: 0 | ET17: 0 | EU17: 0 | EV17: 0 | EW17: 0 | EX17: 0 | EY17: 0 | EZ17: 0 | FA17: 0 | FB17: =FA17 -> 0 | FC17: 50768194 | FD17: 50768194 | FE17: 50768194 | FF17: 50768194 | FG17: 50768194 | FH17: 50768194 | FI17: 50768194 | FO17: =FI17 -> 50768194
B18: Servicio de Salud Aconcagua | C18: 0 | D18: 0 | E18: 0 | F18: 0 | G18: 0 | H18: 0 | I18: 0 | J18: 0 | K18: 0 | L18: 0 | M18: 0 | N18: 0 | O18: =N18 -> 0 | P18: 0 | Q18: 0 | R18: 0 | S18: 0 | T18: 0 | U18: 0 | V18: 0 | W18: 0 | X18: 0 | Y18: 0 | Z18: 0 | AA18: 0 | AB18: =AA18 -> 0 | AC18: 0 | AD18: 0 | AE18: 0 | AF18: 0 | AG18: 0 | AH18: 0 | AI18: 0 | AJ18: 0 | AK18: 0 | AL18: 0 | AM18: 0 | AN18: 0 | AO18: =AN18 -> 0 | AP18: 0 | AQ18: 0 | AR18: 0 | AS18: 0 | AT18: 0 | AU18: 0 | AV18: 0 | AW18: 0 | AX18: 0 | AY18: 0 | AZ18: 0 | BA18: 0 | BB18: =BA18 -> 0 | BC18: 0 | BD18: 0 | BE18: 0 | BF18: 0 | BG18: 0 | BH18: 0 | BI18: 0 | BJ18: 0 | BK18: 0 | BL18: 0 | BM18: 0 | BN18: 0 | BO18: =BN18 -> 0 | BP18: 0 | BQ18: 0 | BR18: 0 | BS18: 0 | BT18: 0 | BU18: 0 | BV18: 0 | BW18: 0 | BX18: 0 | BY18: 0 | BZ18: 0 | CA18: 0 | CB18: =CA18 -> 0 | CC18: 0 | CD18: 0 | CE18: 0 | CF18: 0 | CG18: 0 | CH18: 0 | CI18: 0 | CJ18: 0 | CK18: 0 | CL18: 0 | CM18: 0 | CN18: 0 | CO18: =CN18 -> 0 | CP18: 0 | CQ18: 0 | CR18: 0 | CS18: 0 | CT18: 0 | CU18: 0 | CV18: 0 | CW18: 0 | CX18: 0 | CY18: 0 | CZ18: 0 | DA18: 0 | DB18: =DA18 -> 0 | DC18: 0 | DD18: 0 | DE18: 0 | DF18: 0 | DG18: 0 | DH18: 0 | DI18: 0 | DJ18: 0 | DK18: 0 | DL18: 0 | DM18: 0 | DN18: 0 | DO18: =DN18 -> 0 | DP18: 0 | DQ18: 0 | DR18: 0 | DS18: 0 | DT18: 0 | DU18: 0 | DV18: 0 | DW18: 0 | DX18: 0 | DY18: 0 | DZ18: 0 | EA18: 0 | EB18: =EA18 -> 0 | EC18: 0 | ED18: 0 | EE18: 0 | EF18: 0 | EG18: 0 | EH18: 0 | EI18: 0 | EJ18: 0 | EK18: 0 | EL18: 0 | EM18: 0 | EN18: 0 | EO18: =EN18 -> 0 | EP18: 0 | EQ18: 0 | ER18: 0 | ES18: 0 | ET18: 0 | EU18: 0 | EV18: 0 | EW18: 0 | EX18: 0 | EY18: 0 | EZ18: 0 | FA18: 0 | FB18: =FA18 -> 0 | FC18: 1204885 | FD18: 1204885 | FE18: 1204885 | FF18: 1204885 | FG18: 1204885 | FH18: 1204885 | FI18: 1204885 | FO18: =FI18 -> 1204885
B19: Servicio de Salud O'Higgins | C19: 0 | D19: 0 | E19: 0 | F19: 0 | G19: 0 | H19: 0 | I19: 0 | J19: 0 | K19: 0 | L19: 0 | M19: 0 | N19: 0 | O19: =N19 -> 0 | P19: 0 | Q19: 0 | R19: 0 | S19: 0 | T19: 0 | U19: 0 | V19: 0 | W19: 0 | X19: 0 | Y19: 0 | Z19: 0 | AA19: 0 | AB19: =AA19 -> 0 | AC19: 0 | AD19: 0 | AE19: 0 | AF19: 0 | AG19: 0 | AH19: 0 | AI19: 0 | AJ19: 0 | AK19: 0 | AL19: 0 | AM19: 0 | AN19: 0 | AO19: =AN19 -> 0 | AP19: 0 | AQ19: 0 | AR19: 0 | AS19: 0 | AT19: 0 | AU19: 0 | AV19: 0 | AW19: 0 | AX19: 0 | AY19: 0 | AZ19: 0 | BA19: 0 | BB19: =BA19 -> 0 | BC19: 0 | BD19: 0 | BE19: 0 | BF19: 0 | BG19: 0 | BH19: 0 | BI19: 0 | BJ19: 0 | BK19: 0 | BL19: 0 | BM19: 0 | BN19: 0 | BO19: =BN19 -> 0 | BP19: 0 | BQ19: 0 | BR19: 0 | BS19: 0 | BT19: 0 | BU19: 0 | BV19: 0 | BW19: 0 | BX19: 0 | BY19: 0 | BZ19: 0 | CA19: 0 | CB19: =CA19 -> 0 | CC19: 0 | CD19: 0 | CE19: 0 | CF19: 0 | CG19: 0 | CH19: 0 | CI19: 0 | CJ19: 0 | CK19: 0 | CL19: 0 | CM19: 0 | CN19: 0 | CO19: =CN19 -> 0 | CP19: 0 | CQ19: 0 | CR19: 0 | CS19: 0 | CT19: 0 | CU19: 0 | CV19: 0 | CW19: 0 | CX19: 0 | CY19: 0 | CZ19: 0 | DA19: 0 | DB19: =DA19 -> 0 | DC19: 0 | DD19: 0 | DE19: 0 | DF19: 0 | DG19: 0 | DH19: 0 | DI19: 0 | DJ19: 0 | DK19: 0 | DL19: 0 | DM19: 0 | DN19: 0 | DO19: =DN19 -> 0 | DP19: 0 | DQ19: 0 | DR19: 0 | DS19: 0 | DT19: 0 | DU19: 0 | DV19: 0 | DW19: 0 | DX19: 0 | DY19: 0 | DZ19: 0 | EA19: 0 | EB19: =EA19 -> 0 | EC19: 0 | ED19: 0 | EE19: 0 | EF19: 0 | EG19: 0 | EH19: 0 | EI19: 0 | EJ19: 0 | EK19: 0 | EL19: 0 | EM19: 0 | EN19: 0 | EO19: =EN19 -> 0 | EP19: 0 | EQ19: 0 | ER19: 0 | ES19: 0 | ET19: 0 | EU19: 0 | EV19: 0 | EW19: 0 | EX19: 0 | EY19: 0 | EZ19: 0 | FA19: 0 | FB19: =FA19 -> 0 | FC19: 1473262 | FD19: 1473262 | FE19: 1473262 | FF19: 1473262 | FG19: 1473262 | FH19: 1473262 | FI19: 1473262 | FO19: =FI19 -> 1473262
... B39: Servicio de Salud Chiloé | C39: 0 | D39: 0 | E39: 0 | F39: 0 | G39: 0 | H39: 0 | I39: 0 | J39: 0 | K39: 0 | L39: 0 | M39: 0 | N39: 0 | O39: =N39 -> 0 | P39: 0 | Q39: 0 | R39: 0 | S39: 0 | T39: 0 | U39: 0 | V39: 0 | W39: 0 | X39: 0 | Y39: 0 | Z39: 0 | AA39: 0 | AB39: =AA39 -> 0 | AC39: 0 | AD39: 0 | AE39: 0 | AF39: 0 | AG39: 0 | AH39: 0 | AI39: 0 | AJ39: 0 | AK39: 0 | AL39: 0 | AM39: 0 | AN39: 0 | AO39: =AN39 -> 0 | AP39: 0 | AQ39: 0 | AR39: 0 | AS39: 0 | AT39: 0 | AU39: 0 | AV39: 0 | AW39: 0 | AX39: 0 | AY39: 0 | AZ39: 0 | BA39: 0 | BB39: =BA39 -> 0 | BC39: 0 | BD39: 0 | BE39: 0 | BF39: 0 | BG39: 0 | BH39: 0 | BI39: 0 | BJ39: 0 | BK39: 0 | BL39: 0 | BM39: 0 | BN39: 0 | BO39: =BN39 -> 0 | BP39: 0 | BQ39: 0 | BR39: 0 | BS39: 0 | BT39: 0 | BU39: 0 | BV39: 0 | BW39: 0 | BX39: 0 | BY39: 0 | BZ39: 0 | CA39: 0 | CB39: =CA39 -> 0 | CC39: 0 | CD39: 0 | CE39: 0 | CF39: 0 | CG39: 0 | CH39: 0 | CI39: 0 | CJ39: 0 | CK39: 0 | CL39: 0 | CM39: 0 | CN39: 0 | CO39: =CN39 -> 0 | CP39: 0 | CQ39: 0 | CR39: 0 | CS39: 0 | CT39: 0 | CU39: 0 | CV39: 0 | CW39: 0 | CX39: 0 | CY39: 0 | CZ39: 0 | DA39: 0 | DB39: =DA39 -> 0 | DC39: 0 | DD39: 0 | DE39: 0 | DF39: 0 | DG39: 0 | DH39: 0 | DI39: 0 | DJ39: 0 | DK39: 0 | DL39: 0 | DM39: 0 | DN39: 0 | DO39: =DN39 -> 0 | DP39: 0 | DQ39: 0 | DR39: 0 | DS39: 0 | DT39: 0 | DU39: 0 | DV39: 0 | DW39: 0 | DX39: 0 | DY39: 0 | DZ39: 0 | EA39: 0 | EB39: =EA39 -> 0 | EC39: 0 | ED39: 0 | EE39: 0 | EF39: 0 | EG39: 0 | EH39: 0 | EI39: 0 | EJ39: 0 | EK39: 0 | EL39: 0 | EM39: 0 | EN39: 0 | EO39: =EN39 -> 0 | EP39: 0 | EQ39: 0 | ER39: 0 | ES39: 0 | ET39: 0 | EU39: 0 | EV39: 0 | EW39: 0 | EX39: 0 | EY39: 0 | EZ39: 0 | FA39: 0 | FB39: =FA39 -> 0 | FC39: 9165660 | FD39: 9165660 | FE39: 9165660 | FF39: 9165660 | FG39: 9165660 | FH39: 9165660 | FI39: 9165660 | FO39: =FI39 -> 9165660
B40: Total Presupuesto Ley (Subtítulo 31) | C40: =SUM(C8:C39) -> 275296243 | D40: =SUM(D8:D39) -> 275296243 | E40: =SUM(E8:E39) -> 275296243 | F40: =SUM(F8:F39) -> 275296243 | G40: =SUM(G8:G39) -> 275296243 | H40: =SUM(H8:H39) -> 275296243 | I40: =SUM(I8:I39) -> 275296243 | J40: =SUM(J8:J39) -> 275296243 | ... FO40: =SUM(FO8:FO39) -> 648268110
B41: Presupuesto Vigente (Subtítulo 31)
C42: 2014 | P42: 2015 | AC42: 2016 | AP42: 2017 | BC42: 2018 | BP42: 2019 | CC42: 2020 | CP42: 2021 | DC42: 2022 | DP42: 2023 | EC42: 2024 | EP42: 2025 | FC42: 2026
B43: Programa / Entidad | C43: Ene | D43: Feb | E43: Mar | F43: Abr | G43: May | H43: Jun | I43: Jul | J43: Ago | K43: Sep | L43: Oct | M43: Nov | N43: Dic | O43: Total 2014 | P43: Ene | Q43: Feb | R43: Mar | S43: Abr | T43: May | U43: Jun | V43: Jul | W43: Ago | X43: Sep | Y43: Oct | Z43: Nov | AA43: Dic | AB43: Total 2015 | AC43: Ene | AD43: Feb | AE43: Mar | AF43: Abr | AG43: May | AH43: Jun | AI43: Jul | AJ43: Ago | AK43: Sep | AL43: Oct | AM43: Nov | AN43: Dic | AO43: Total 2016 | AP43: Ene | AQ43: Feb | AR43: Mar | AS43: Abr | AT43: May | AU43: Jun | AV43: Jul | AW43: Ago | AX43: Sep | AY43: Oct | AZ43: Nov | BA43: Dic | BB43: Total 2017 | BC43: Ene | BD43: Feb | BE43: Mar | BF43: Abr | BG43: May | BH43: Jun | BI43: Jul | BJ43: Ago | BK43: Sep | BL43: Oct | BM43: Nov | BN43: Dic | BO43: Total 2018 | BP43: Ene | BQ43: Feb | BR43: Mar | BS43: Abr | BT43: May | BU43: Jun | BV43: Jul | BW43: Ago | BX43: Sep | BY43: Oct | BZ43: Nov | CA43: Dic | CB43: Total 2019 | CC43: Ene | CD43: Feb | CE43: Mar | CF43: Abr | CG43: May | CH43: Jun | CI43: Jul | CJ43: Ago | CK43: Sep | CL43: Oct | CM43: Nov | CN43: Dic | CO43: Total 2020 | CP43: Ene | CQ43: Feb | CR43: Mar | CS43: Abr | CT43: May | CU43: Jun | CV43: Jul | CW43: Ago | CX43: Sep | CY43: Oct | CZ43: Nov | DA43: Dic | DB43: Total 2021 | DC43: Ene | DD43: Feb | DE43: Mar | DF43: Abr | DG43: May | DH43: Jun | DI43: Jul | DJ43: Ago | DK43: Sep | DL43: Oct | DM43: Nov | DN43: Dic | DO43: Total 2022 | DP43: Ene | DQ43: Feb | DR43: Mar | DS43: Abr | DT43: May | DU43: Jun | DV43: Jul | DW43: Ago | DX43: Sep | DY43: Oct | DZ43: Nov | EA43: Dic | EB43: Total 2023 | EC43: Ene | ED43: Feb | EE43: Mar | EF43: Abr | EG43: May | EH43: Jun | EI43: Jul | EJ43: Ago | EK43: Sep | EL43: Oct | EM43: Nov | EN43: Dic | EO43: Total 2024 | EP43: Ene | EQ43: Feb | ER43: Mar | ES43: Abr | ET43: May | EU43: Jun | EV43: Jul | EW43: Ago | EX43: Sep | EY43: Oct | EZ43: Nov | FA43: Dic | FB43: Total 2025 | FC43: Ene | FD43: Feb | FE43: Mar | FF43: Abr | FG43: May | FH43: Jun | FI43: Jul | FJ43: Ago | FK43: Sep | FL43: Oct | FM43: Nov | FN43: Dic | FO43: Total 2026
B44: Instituto de Salud Pública | C44: 747570 | D44: 747570 | E44: 747570 | F44: 747570 | G44: 747570 | H44: 747570 | I44: 747570 | J44: 747570 | K44: 747570 | L44: 747570 | M44: 747570 | N44: 80263 | O44: =N44 -> 80263 | P44: 206000 | Q44: 206000 | R44: 206000 | S44: 206000 | T44: 206000 | U44: 206000 | V44: 206000 | W44: 206000 | X44: 128319 | Y44: 128319 | Z44: 128319 | AA44: 128319 | AB44: =AA44 -> 128319 | AC44: 0 | AD44: 0 | AE44: 0 | AF44: 0 | AG44: 0 | AH44: 0 | AI44: 0 | AJ44: 0 | AK44: 79759 | AL44: 79759 | AM44: 79759 | AN44: 79759 | AO44: =AN44 -> 79759 | AP44: 237364 | AQ44: 237364 | AR44: 237364 | AS44: 237364 | AT44: 237364 | AU44: 237364 | AV44: 237364 | AW44: 237364 | AX44: 237364 | AY44: 237364 | AZ44: 237364 | BA44: 237365 | BB44: =BA44 -> 237365 | BC44: 0 | BD44: 0 | BE44: 0 | BF44: 0 | BG44: 0 | BH44: 0 | BI44: 0 | BJ44: 0 | BK44: 0 | BL44: 0 | BM44: 0 | BN44: 0 | BO44: =BN44 -> 0 | BP44: 0 | BQ44: 0 | BR44: 0 | BS44: 0 | BT44: 0 | BU44: 0 | BV44: 0 | BW44: 0 | BX44: 0 | BY44: 0 | BZ44: 0 | CA44: 0 | CB44: =CA44 -> 0 | CC44: 1026000 | CD44: 1026000 | CE44: 1026000 | CF44: 1026000 | CG44: 1026000 | CH44: 1026000 | CI44: 1026000 | CJ44: 1026000 | CK44: 1026000 | CL44: 1026000 | CM44: 1026000 | CN44: 10000 | CO44: =CN44 -> 10000 | CP44: 800605 | CQ44: 800605 | CR44: 800605 | CS44: 800605 | CT44: 800605 | CU44: 800605 | CV44: 800605 | CW44: 800605 | CX44: 800605 | CY44: 800605 | CZ44: 800605 | DA44: 6000 | DB44: =DA44 -> 6000 | DC44: 2301909 | DD44: 2301909 | DE44: 2301909 | DF44: 2301909 | DG44: 2301909 | DH44: 2301909 | DI44: 2301909 | DJ44: 908340 | DK44: 358340 | DL44: 358340 | DM44: 358340 | DN44: 198608 | DO44: =DN44 -> 198608 | DP44: 1324402 | DQ44: 1324402 | DR44: 1324402 | DS44: 1324402 | DT44: 1324402 | DU44: 1324402 | DV44: 1324402 | DW44: 1324402 | DX44: 1324402 | DY44: 1324402 | DZ44: 1324402 | EA44: 319465 | EB44: =EA44 -> 319465 | EC44: 1459534 | ED44: 1459534 | EE44: 1459534 | EF44: 1459534 | EG44: 1459534 | EH44: 933233 | EI44: 933233 | EJ44: 933233 | EK44: 933233 | EL44: 933233 | EM44: 890106 | EN44: 788149 | EO44: =EN44 -> 788149 | EP44: 781455 | EQ44: 781455 | ER44: 781455 | ES44: 781455 | ET44: 781455 | EU44: 781455 | EV44: 781455 | EW44: 781455 | EX44: 781455 | EY44: 781455 | EZ44: 781455 | FA44: 707580 | FB44: =FA44 -> 707580 | FC44: 657325 | FD44: 657325 | FE44: 657325 | FF44: 657325 | FG44: 657325 | FH44: 657325 | FI44: 657325 | FO44: =FI44 -> 657325
B45: Subsecretaría de Salud Pública | C45: 0 | D45: 750633 | E45: 750633 | F45: 750633 | G45: 750633 | H45: 750633 | I45: 750633 | J45: 750633 | K45: 827570 | L45: 827570 | M45: 1487216 | N45: 1487216 | O45: =N45 -> 1487216 | P45: 0 | Q45: 3549492 | R45: 3549492 | S45: 3549492 | T45: 3549492 | U45: 3788029 | V45: 4410235 | W45: 3972874 | X45: 3972874 | Y45: 1926749 | Z45: 1926749 | AA45: 1405037 | AB45: =AA45 -> 1405037 | AC45: 0 | AD45: 3247660 | AE45: 3247660 | AF45: 3247660 | AG45: 3247660 | AH45: 3247660 | AI45: 3247660 | AJ45: 3247660 | AK45: 3247660 | AL45: 3247660 | AM45: 3247660 | AN45: 2185033 | AO45: =AN45 -> 2185033 | AP45: 0 | AQ45: 0 | AR45: 5429494 | AS45: 5429494 | AT45: 5429494 | AU45: 5429494 | AV45: 5429494 | AW45: 5429494 | AX45: 5117881 | AY45: 5117881 | AZ45: 5117881 | BA45: 5117881 | BB45: =BA45 -> 5117881 | BC45: 0 | BD45: 0 | BE45: 7088322 | BF45: 7088322 | BG45: 7088322 | BH45: 7088322 | BI45: 3593921 | BJ45: 3593921 | BK45: 3593921 | BL45: 3593921 | BM45: 3744869 | BN45: 2622679 | BO45: =BN45 -> 2622679 | BP45: 0 | BQ45: 0 | BR45: 0 | BS45: 2225014 | BT45: 2225014 | BU45: 2225014 | BV45: 2225014 | BW45: 1650553 | BX45: 1650553 | BY45: 1650553 | BZ45: 1650553 | CA45: 1363609 | CB45: =CA45 -> 1363609 | CC45: 0 | CD45: 0 | CE45: 803087 | CF45: 803087 | CG45: 803087 | CH45: 1233087 | CI45: 1233087 | CJ45: 1233087 | CK45: 1233087 | CL45: 1233087 | CM45: 1233087 | CN45: 1233087 | CO45: =CN45 -> 1233087 | CP45: 0 | CQ45: 2660955 | CR45: 2660955 | CS45: 2660955 | CT45: 2660955 | CU45: 2660955 | CV45: 2660955 | CW45: 2660955 | CX45: 2660955 | CY45: 2660955 | CZ45: 2183561 | DA45: 2183561 | DB45: =DA45 -> 2183561 | DC45: 0 | DD45: 5771729 | DE45: 5771729 | DF45: 5771729 | DG45: 5771729 | DH45: 5771729 | DI45: 5771729 | DJ45: 5771729 | DK45: 4001508 | DL45: 4001508 | DM45: 1706851 | DN45: 1706851 | DO45: =DN45 -> 1706851 | DP45: 0 | DQ45: 3873629 | DR45: 3873629 | DS45: 3873629 | DT45: 3873629 | DU45: 4435938 | DV45: 4435938 | DW45: 4435938 | DX45: 4435938 | DY45: 4435938 | DZ45: 4435938 | EA45: 3219261 | EB45: =EA45 -> 3219261 | EC45: 0 | ED45: 0 | EE45: 3831000 | EF45: 3831000 | EG45: 3831000 | EH45: 3880281 | EI45: 3880281 | EJ45: 3880281 | EK45: 3921585 | EL45: 4149585 | EM45: 3920742 | EN45: 3670742 | EO45: =EN45 -> 3670742 | EP45: 0 | EQ45: 2843210 | ER45: 2843210 | ES45: 2843210 | ET45: 2843210 | EU45: 2843210 | EV45: 2843210 | EW45: 2843210 | EX45: 2843210 | EY45: 2877119 | EZ45: 2019159 | FA45: 1493716 | FB45: =FA45 -> 1493716 | FC45: 3133791 | FD45: 3133791 | FE45: 3133791 | FF45: 3133791 | FG45: 3133791 | FH45: 3133791 | FI45: 3133791 | FO45: =FI45 -> 3133791
B46: Inversión Sectorial en Salud | C46: 274548673 | D46: 150121133 | E46: 31215164 | F46: 31215164 | G46: 31215164 | H46: 37715555 | I46: 37437770 | J46: 37437770 | K46: 249893 | L46: 249893 | M46: 12546246 | N46: 416473 | O46: =N46 -> 416473 | P46: 528813287 | Q46: 358253969 | R46: 152865381 | S46: 124037746 | T46: 119885657 | U46: 108081968 | V46: 79852267 | W46: 82163159 | X46: 74844726 | Y46: 60792289 | Z46: 5401287 | AA46: -6864505 | AB46: =AA46 -> -6864505 | AC46: 497824800 | AD46: 232511416 | AE46: 209153984 | AF46: 107272608 | AG46: 49900020 | AH46: 45194077 | AI46: 24782680 | AJ46: 9231280 | AK46: 6143223 | AL46: 13151410 | AM46: 20153093 | AN46: 39813989 | AO46: =AN46 -> 39813989 | AP46: 349316570 | AQ46: 166700292 | AR46: 54265806 | AS46: 49451706 | AT46: 40784024 | AU46: 16177516 | AV46: 10305477 | AW46: 7619787 | AX46: 12091504 | AY46: 6660514 | AZ46: 6660514 | BA46: 7733812 | BB46: =BA46 -> 7733812 | BC46: 439600285 | BD46: 439600285 | BE46: 308112580 | BF46: 157413097 | BG46: 66811661 | BH46: 20245463 | BI46: 22882943 | BJ46: 6774352 | BK46: -10059378 | BL46: 947927 | BM46: 692735 | BN46: 5158801 | BO46: =BN46 -> 5158801 | BP46: 418874044 | BQ46: 386527607 | BR46: 3457344 | BS46: 16001650 | BT46: 1554910 | BU46: 11275 | BV46: 0 | BW46: 0 | BX46: 1309068 | BY46: 1309068 | BZ46: 331587 | CA46: 1708355 | CB46: =CA46 -> 1708355 | CC46: 733952985 | CD46: 573847941 | CE46: 124149289 | CF46: 72300655 | CG46: 73061576 | CH46: 3855700 | CI46: 4244680 | CJ46: 19381846 | CK46: 2591847 | CL46: 8137191 | CM46: 48121228 | CN46: 701310 | CO46: =CN46 -> 701310 | CP46: 653979311 | CQ46: 62477958 | CR46: 38977535 | CS46: 10314489 | CT46: 13682093 | CU46: 8737222 | CV46: 12487969 | CW46: 23205049 | CX46: 23205049 | CY46: 86696492 | CZ46: 100114500 | DA46: 0 | DB46: =DA46 -> 0 | DC46: 642175866 | DD46: 166328149 | DE46: 111071146 | DF46: 111071146 | DG46: 20272961 | DH46: 17508 | DI46: 21741755 | DJ46: 21421965 | DK46: 87759254 | DL46: 84617599 | DM46: 53927937 | DN46: 0 | DO46: =DN46 -> 0 | DP46: 709260889 | DQ46: 312198013 | DR46: 271703488 | DS46: 266360982 | DT46: 214176069 | DU46: 202257983 | DV46: 142541359 | DW46: 74241870 | DX46: 74241870 | DY46: 49385560 | DZ46: 14812250 | EA46: 463 | EB46: =EA46 -> 463 | EC46: 581851338 | ED46: 28935584 | EE46: -22048777 | EF46: 9105205 | EG46: 5262741 | EH46: 10901732 | EI46: 15558025 | EJ46: 67379 | EK46: 622246 | EL46: 28875009 | EM46: 26189376 | EN46: 0 | EO46: =EN46 -> 0 | EP46: 573366549 | EQ46: 53140143 | ER46: 41684097 | ES46: 41684097 | ET46: 15687112 | EU46: 2508407 | EV46: 1553156 | EW46: 7169832 | EX46: 10580484 | EY46: 8375929 | EZ46: 298318 | FA46: 0 | FB46: =FA46 -> 0 | FC46: 201002151 | FD46: 176224317 | FE46: 176224317 | FF46: 176224317 | FG46: 111319589 | FH46: 30121356 | FI46: 30121356 | FO46: =FI46 -> 30121356
B47: Servicio de Salud Arica y Parinacota | C47: 0 | D47: 0 | E47: 146938 | F47: 146938 | G47: 146938 | H47: 146938 | I47: 146938 | J47: 146938 | K47: 167749 | L47: 167749 | M47: 167749 | N47: 167749 | O47: =N47 -> 167749 | P47: 0 | Q47: 0 | R47: 0 | S47: 0 | T47: 0 | U47: 419336 | V47: 559389 | W47: 559389 | X47: 559389 | Y47: 559389 | Z47: 559389 | AA47: 196429 | AB47: =AA47 -> 196429 | AC47: 0 | AD47: 1437282 | AE47: 1437282 | AF47: 1437282 | AG47: 2025995 | AH47: 2025995 | AI47: 2025995 | AJ47: 2025995 | AK47: 2102131 | AL47: 2102131 | AM47: 616651 | AN47: 616651 | AO47: =AN47 -> 616651 | AP47: 0 | AQ47: 0 | AR47: 0 | AS47: 0 | AT47: 1567112 | AU47: 1567112 | AV47: 1567112 | AW47: 1567112 | AX47: 985447 | AY47: 985447 | AZ47: 985447 | BA47: 776176 | BB47: =BA47 -> 776176 | BC47: 0 | BD47: 0 | BE47: 0 | BF47: 1796003 | BG47: 1796003 | BH47: 1796003 | BI47: 1796003 | BJ47: 1796003 | BK47: 1176839 | BL47: 1176839 | BM47: 1176839 | BN47: 1176839 | BO47: =BN47 -> 1176839 | BP47: 0 | BQ47: 0 | BR47: 0 | BS47: 0 | BT47: 411667 | BU47: 411667 | BV47: 411667 | BW47: 417070 | BX47: 417070 | BY47: 417070 | BZ47: 417070 | CA47: 417070 | CB47: =CA47 -> 417070 | CC47: 0 | CD47: 0 | CE47: 1045022 | CF47: 1045022 | CG47: 1391169 | CH47: 1391169 | CI47: 1391169 | CJ47: 1391169 | CK47: 1391169 | CL47: 1391169 | CM47: 1391169 | CN47: 1026451 | CO47: =CN47 -> 1026451 | CP47: 0 | CQ47: 0 | CR47: 427986 | CS47: 427986 | CT47: 427986 | CU47: 427986 | CV47: 427986 | CW47: 427986 | CX47: 427986 | CY47: 427986 | CZ47: 427986 | DA47: 150921 | DB47: =DA47 -> 150921 | DC47: 0 | DD47: 277067 | DE47: 277067 | DF47: 277067 | DG47: 277067 | DH47: 277067 | DI47: 277067 | DJ47: 277067 | DK47: 277067 | DL47: 277067 | DM47: 277068 | DN47: 277068 | DO47: =DN47 -> 277068 | DP47: 0 | DQ47: 0 | DR47: 0 | DS47: 0 | DT47: 0 | DU47: 0 | DV47: 0 | DW47: 0 | DX47: 0 | DY47: 0 | DZ47: 0 | EA47: 10 | EB47: =EA47 -> 10 | EC47: 0 | ED47: 0 | EE47: 0 | EF47: 664444 | EG47: 664444 | EH47: 744659 | EI47: 744659 | EJ47: 744659 | EK47: 744659 | EL47: 40227 | EM47: 40227 | EN47: 40227 | EO47: =EN47 -> 40227 | EP47: 0 | EQ47: 1899765 | ER47: 1899765 | ES47: 1899765 | ET47: 1899765 | EU47: 1899765 | EV47: 1899765 | EW47: 303882 | EX47: 303882 | EY47: 303882 | EZ47: 303882 | FA47: 11953 | FB47: =FA47 -> 11953 | FC47: 3783756 | FD47: 3783756 | FE47: 3783756 | FF47: 3783756 | FG47: 3783756 | FH47: 3783756 | FI47: 3783756 | FO47: =FI47 -> 3783756
B48: Servicio de Salud Tarapacá | C48: 0 | D48: 9330792 | E48: 12114237 | F48: 12114237 | G48: 12114237 | H48: 12114237 | I48: 12114237 | J48: 12127183 | K48: 12127183 | L48: 12127183 | M48: 4489148 | N48: 4489148 | O48: =N48 -> 4489148 | P48: 0 | Q48: 2686505 | R48: 24386332 | S48: 24386332 | T48: 24386332 | U48: 24838693 | V48: 24838693 | W48: 25140945 | X48: 25140945 | Y48: 25309999 | Z48: 24085402 | AA48: 12068846 | AB48: =AA48 -> 12068846 | AC48: 0 | AD48: 11123386 | AE48: 11204910 | AF48: 11226518 | AG48: 11226518 | AH48: 11226518 | AI48: 11226518 | AJ48: 11226518 | AK48: 11226518 | AL48: 7677344 | AM48: 7015437 | AN48: 5076846 | AO48: =AN48 -> 5076846 | AP48: 0 | AQ48: 7310545 | AR48: 7625611 | AS48: 7625611 | AT48: 7899831 | AU48: 7961206 | AV48: 7961206 | AW48: 9736372 | AX48: 9736372 | AY48: 9826369 | AZ48: 9826369 | BA48: 9995842 | BB48: =BA48 -> 9995842 | BC48: 0 | BD48: 0 | BE48: 1594476 | BF48: 1594476 | BG48: 1594476 | BH48: 3740428 | BI48: 3740428 | BJ48: 3936840 | BK48: 3232335 | BL48: 3232335 | BM48: 3232335 | BN48: 2166427 | BO48: =BN48 -> 2166427 | BP48: 0 | BQ48: 0 | BR48: 23550759 | BS48: 23550759 | BT48: 23550759 | BU48: 21844806 | BV48: 21339907 | BW48: 21339907 | BX48: 20637777 | BY48: 20637777 | BZ48: 20637777 | CA48: 23000558 | CB48: =CA48 -> 23000558 | CC48: 0 | CD48: 0 | CE48: 43224315 | CF48: 43224315 | CG48: 43224315 | CH48: 43224315 | CI48: 43224315 | CJ48: 43224315 | CK48: 45576985 | CL48: 45627985 | CM48: 39471769 | CN48: 38865928 | CO48: =CN48 -> 38865928 | CP48: 0 | CQ48: 46961726 | CR48: 46961726 | CS48: 46961726 | CT48: 46961726 | CU48: 46961726 | CV48: 46961726 | CW48: 46961726 | CX48: 46961726 | CY48: 46807023 | CZ48: 46807023 | DA48: 28698759 | DB48: =DA48 -> 28698759 | DC48: 0 | DD48: 25034876 | DE48: 25034876 | DF48: 25034876 | DG48: 25034876 | DH48: 25374884 | DI48: 25374884 | DJ48: 25374884 | DK48: 9379245 | DL48: 9800349 | DM48: 9748221 | DN48: 7674856 | DO48: =DN48 -> 7674856 | DP48: 0 | DQ48: 24810484 | DR48: 24810484 | DS48: 24810484 | DT48: 24869844 | DU48: 24869844 | DV48: 25248939 | DW48: 24208690 | DX48: 24208690 | DY48: 24350128 | DZ48: 18475646 | EA48: 17778770 | EB48: =EA48 -> 17778770 | EC48: 0 | ED48: 14776835 | EE48: 16008220 | EF48: 16276948 | EG48: 16276948 | EH48: 16276948 | EI48: 18371513 | EJ48: 17302216 | EK48: 17302216 | EL48: 15384683 | EM48: 11016165 | EN48: 10745147 | EO48: =EN48 -> 10745147 | EP48: 0 | EQ48: 19414328 | ER48: 19414328 | ES48: 19414328 | ET48: 19414328 | EU48: 19414328 | EV48: 21993341 | EW48: 21993341 | EX48: 22644417 | EY48: 22644417 | EZ48: 22644417 | FA48: 23461897 | FB48: =FA48 -> 23461897 | FC48: 22899006 | FD48: 22899006 | FE48: 22899006 | FF48: 22899006 | FG48: 22899006 | FH48: 22899006 | FI48: 22899006 | FO48: =FI48 -> 22899006
B49: Servicio de Salud Antofagasta | C49: 0 | D49: 0 | E49: 3169356 | F49: 3169356 | G49: 3169356 | H49: 3169356 | I49: 3169356 | J49: 3169356 | K49: 3169356 | L49: 3169356 | M49: 2417883 | N49: 2417883 | O49: =N49 -> 2417883 | P49: 0 | Q49: 0 | R49: 8626880 | S49: 8128929 | T49: 8148822 | U49: 8591077 | V49: 8980944 | W49: 8980944 | X49: 18799697 | Y49: 18799697 | Z49: 19025203 | AA49: 19025203 | AB49: =AA49 -> 19025203 | AC49: 0 | AD49: 1189930 | AE49: 1189930 | AF49: 21881976 | AG49: 21881976 | AH49: 21881976 | AI49: 22465335 | AJ49: 22465335 | AK49: 22465335 | AL49: 22465335 | AM49: 17839555 | AN49: 17583523 | AO49: =AN49 -> 17583523 | AP49: 0 | AQ49: 619993 | AR49: 619993 | AS49: 1168432 | AT49: 5168432 | AU49: 29442306 | AV49: 29442306 | AW49: 29442306 | AX49: 29442306 | AY49: 25719657 | AZ49: 25719657 | BA49: 39734626 | BB49: =BA49 -> 39734626 | BC49: 4104000 | BD49: 4104000 | BE49: 7244308 | BF49: 7244308 | BG49: 24288326 | BH49: 24288326 | BI49: 24288326 | BJ49: 24288326 | BK49: 23970739 | BL49: 19359839 | BM49: 19255839 | BN49: 16135811 | BO49: =BN49 -> 16135811 | BP49: 0 | BQ49: 0 | BR49: 9974536 | BS49: 9974536 | BT49: 9974536 | BU49: 9974536 | BV49: 9974536 | BW49: 9858013 | BX49: 9858013 | BY49: 9858013 | BZ49: 9858013 | CA49: 9458568 | CB49: =CA49 -> 9458568 | CC49: 0 | CD49: 0 | CE49: 659657 | CF49: 5524930 | CG49: 5524930 | CH49: 5542363 | CI49: 5542363 | CJ49: 5542363 | CK49: 5542363 | CL49: 5542363 | CM49: 5299317 | CN49: 1256956 | CO49: =CN49 -> 1256956 | CP49: 0 | CQ49: 0 | CR49: 510743 | CS49: 510743 | CT49: 510743 | CU49: 840656 | CV49: 840656 | CW49: 840656 | CX49: 840656 | CY49: 831012 | CZ49: 831012 | DA49: 738988 | DB49: =DA49 -> 738988 | DC49: 0 | DD49: 0 | DE49: 0 | DF49: 0 | DG49: 0 | DH49: 0 | DI49: 41470 | DJ49: 41470 | DK49: 41470 | DL49: 41470 | DM49: 41470 | DN49: 6490 | DO49: =DN49 -> 6490 | DP49: 0 | DQ49: 34980 | DR49: 34980 | DS49: 34980 | DT49: 34980 | DU49: 34980 | DV49: 34980 | DW49: 34980 | DX49: 34980 | DY49: 101007 | DZ49: 126276 | EA49: 126286 | EB49: =EA49 -> 126286 | EC49: 0 | ED49: 516417 | EE49: 516417 | EF49: 516417 | EG49: 516417 | EH49: 516417 | EI49: 516417 | EJ49: 676071 | EK49: 676071 | EL49: 737349 | EM49: 372584 | EN49: 361585 | EO49: =EN49 -> 361585 | EP49: 0 | EQ49: 3180410 | ER49: 3180410 | ES49: 3180410 | ET49: 3180410 | EU49: 3180410 | EV49: 3408370 | EW49: 3408370 | EX49: 3408370 | EY49: 3408370 | EZ49: 481841 | FA49: 3808031 | FB49: =FA49 -> 3808031 | FC49: 3191908 | FD49: 3191908 | FE49: 3191908 | FF49: 3191908 | FG49: 3191908 | FH49: 3368346 | FI49: 3368346 | FO49: =FI49 -> 3368346
B50: Servicio de Salud Atacama | C50: 0 | D50: 2641266 | E50: 2641266 | F50: 2641266 | G50: 2641266 | H50: 2641266 | I50: 2641266 | J50: 2641266 | K50: 2641266 | L50: 2641266 | M50: 4210322 | N50: 4210322 | O50: =N50 -> 4210322 | P50: 0 | Q50: 3537372 | R50: 3537372 | S50: 3546863 | T50: 3546863 | U50: 3546863 | V50: 3546863 | W50: 5764045 | X50: 5764045 | Y50: 5764045 | Z50: 6059318 | AA50: 7177293 | AB50: =AA50 -> 7177293 | AC50: 0 | AD50: 5239778 | AE50: 5239778 | AF50: 5239778 | AG50: 5328458 | AH50: 5328458 | AI50: 5328458 | AJ50: 5328458 | AK50: 5328458 | AL50: 5328458 | AM50: 5492902 | AN50: 6438977 | AO50: =AN50 -> 6438977 | AP50: 0 | AQ50: 0 | AR50: 0 | AS50: 0 | AT50: 0 | AU50: 35657 | AV50: 35657 | AW50: 35657 | AX50: 35657 | AY50: 35657 | AZ50: 35657 | BA50: 184164 | BB50: =BA50 -> 184164 | BC50: 0 | BD50: 0 | BE50: 7846290 | BF50: 7987290 | BG50: 7987290 | BH50: 7987290 | BI50: 7987290 | BJ50: 3757264 | BK50: 3757264 | BL50: 3757264 | BM50: 3757264 | BN50: 179417 | BO50: =BN50 -> 179417 | BP50: 0 | BQ50: 0 | BR50: 2875419 | BS50: 2875419 | BT50: 2875419 | BU50: 2875419 | BV50: 1345290 | BW50: 471574 | BX50: 471574 | BY50: 471574 | BZ50: 471574 | CA50: 202802 | CB50: =CA50 -> 202802 | CC50: 0 | CD50: 2492104 | CE50: 4964848 | CF50: 5213320 | CG50: 5213320 | CH50: 5213320 | CI50: 5830861 | CJ50: 5830861 | CK50: 5838195 | CL50: 5838195 | CM50: 5834329 | CN50: 5146527 | CO50: =CN50 -> 5146527 | CP50: 0 | CQ50: 7781605 | CR50: 7781605 | CS50: 7781605 | CT50: 7781605 | CU50: 13029086 | CV50: 12015839 | CW50: 12015839 | CX50: 12015839 | CY50: 3499181 | CZ50: 3499181 | DA50: 3495147 | DB50: =DA50 -> 3495147 | DC50: 0 | DD50: 6510718 | DE50: 6510718 | DF50: 6510718 | DG50: 6510718 | DH50: 5241843 | DI50: 3391074 | DJ50: 3391074 | DK50: 3391074 | DL50: 3391074 | DM50: 500372 | DN50: 500372 | DO50: =DN50 -> 500372 | DP50: 0 | DQ50: 2286234 | DR50: 2286234 | DS50: 2286234 | DT50: 2286234 | DU50: 2822620 | DV50: 3113391 | DW50: 3149621 | DX50: 3149621 | DY50: 3149621 | DZ50: 2694759 | EA50: 1914003 | EB50: =EA50 -> 1914003 | EC50: 0 | ED50: 9351608 | EE50: 10474268 | EF50: 10622073 | EG50: 10622073 | EH50: 10622073 | EI50: 9056514 | EJ50: 9056514 | EK50: 10477544 | EL50: 9210176 | EM50: 8848694 | EN50: 8848694 | EO50: =EN50 -> 8848694 | EP50: 0 | EQ50: 18012526 | ER50: 18012526 | ES50: 18012526 | ET50: 19119938 | EU50: 19119938 | EV50: 19119938 | EW50: 19119938 | EX50: 25642997 | EY50: 25642997 | EZ50: 25642997 | FA50: 24091722 | FB50: =FA50 -> 24091722 | FC50: 14546113 | FD50: 14546113 | FE50: 14546113 | FF50: 14546113 | FG50: 14546113 | FH50: 14546113 | FI50: 14546113 | FO50: =FI50 -> 14546113
B51: Servicio de Salud Coquimbo | C51: 0 | D51: 345904 | E51: 4454874 | F51: 4454874 | G51: 4454874 | H51: 4454874 | I51: 4454874 | J51: 4454874 | K51: 4454874 | L51: 4454874 | M51: 1397898 | N51: 1397898 | O51: =N51 -> 1397898 | P51: 0 | Q51: 1959512 | R51: 29207336 | S51: 29207336 | T51: 29207336 | U51: 29595225 | V51: 31607082 | W51: 32938652 | X51: 32938652 | Y51: 32938652 | Z51: 30368502 | AA51: 32433196 | AB51: =AA51 -> 32433196 | AC51: 0 | AD51: 22924268 | AE51: 22924268 | AF51: 34137329 | AG51: 34945433 | AH51: 38549075 | AI51: 40544693 | AJ51: 40544693 | AK51: 40544693 | AL51: 39796581 | AM51: 39796581 | AN51: 33732703 | AO51: =AN51 -> 33732703 | AP51: 0 | AQ51: 10642316 | AR51: 31177412 | AS51: 31223104 | AT51: 31223104 | AU51: 31684092 | AV51: 32047649 | AW51: 32047649 | AX51: 32063275 | AY51: 34825129 | AZ51: 34825129 | BA51: 39387368 | BB51: =BA51 -> 39387368 | BC51: 0 | BD51: 0 | BE51: 3596099 | BF51: 31372988 | BG51: 31372988 | BH51: 33133147 | BI51: 33133147 | BJ51: 31916936 | BK51: 31233271 | BL51: 31233271 | BM51: 31233271 | BN51: 33998210 | BO51: =BN51 -> 33998210 | BP51: 0 | BQ51: 0 | BR51: 7711373 | BS51: 8159373 | BT51: 19850079 | BU51: 33035158 | BV51: 34001547 | BW51: 42902399 | BX51: 43252598 | BY51: 43252598 | BZ51: 43380504 | CA51: 42990744 | CB51: =CA51 -> 42990744 | CC51: 0 | CD51: 3548906 | CE51: 27589071 | CF51: 27769405 | CG51: 27786080 | CH51: 27786080 | CI51: 27786080 | CJ51: 27786080 | CK51: 36726968 | CL51: 36726968 | CM51: 36667691 | CN51: 34799647 | CO51: =CN51 -> 34799647 | CP51: 0 | CQ51: 25983059 | CR51: 25983059 | CS51: 25983059 | CT51: 25983059 | CU51: 25983059 | CV51: 25983059 | CW51: 25983059 | CX51: 25983059 | CY51: 23060165 | CZ51: 23060165 | DA51: 19776064 | DB51: =DA51 -> 19776064 | DC51: 0 | DD51: 5175093 | DE51: 11939315 | DF51: 11939315 | DG51: 11939315 | DH51: 11939315 | DI51: 11945115 | DJ51: 11945115 | DK51: 12989257 | DL51: 9044189 | DM51: 9044189 | DN51: 5887868 | DO51: =DN51 -> 5887868 | DP51: 0 | DQ51: 742082 | DR51: 1842082 | DS51: 1842082 | DT51: 1842082 | DU51: 2332216 | DV51: 2580761 | DW51: 2580761 | DX51: 2580761 | DY51: 2630763 | DZ51: 2130764 | EA51: 2231319 | EB51: =EA51 -> 2231319 | EC51: 0 | ED51: 9632104 | EE51: 11190703 | EF51: 13715752 | EG51: 13715752 | EH51: 14086953 | EI51: 6041399 | EJ51: 6071748 | EK51: 6071748 | EL51: 4664885 | EM51: 4664886 | EN51: 4432051 | EO51: =EN51 -> 4432051 | EP51: 0 | EQ51: 12759484 | ER51: 12759484 | ES51: 12759484 | ET51: 12759484 | EU51: 12759484 | EV51: 12759484 | EW51: 12759484 | EX51: 21660342 | EY51: 21660352 | EZ51: 21660352 | FA51: 23225106 | FB51: =FA51 -> 23225106 | FC51: 15086131 | FD51: 15086131 | FE51: 15086131 | FF51: 15086131 | FG51: 15086131 | FH51: 32743030 | FI51: 32743030 | FO51: =FI51 -> 32743030
B52: Servicio de Salud Valparaíso - San Antonio | C52: 0 | D52: 1916581 | E52: 3977404 | F52: 3977404 | G52: 3977404 | H52: 3977404 | I52: 3977404 | J52: 4173083 | K52: 4084865 | L52: 4084865 | M52: 2845839 | N52: 2845839 | O52: =N52 -> 2845839 | P52: 0 | Q52: 6374294 | R52: 6374294 | S52: 7287916 | T52: 7352711 | U52: 7352711 | V52: 8276225 | W52: 8276225 | X52: 8318756 | Y52: 8318756 | Z52: 9978629 | AA52: 9901229 | AB52: =AA52 -> 9901229 | AC52: 0 | AD52: 1350133 | AE52: 1350133 | AF52: 8952099 | AG52: 8952099 | AH52: 8952099 | AI52: 17067911 | AJ52: 17537003 | AK52: 17537003 | AL52: 17537003 | AM52: 16297726 | AN52: 7280150 | AO52: =AN52 -> 7280150 | AP52: 0 | AQ52: 0 | AR52: 4173687 | AS52: 4173687 | AT52: 4490532 | AU52: 4726084 | AV52: 4847908 | AW52: 4847908 | AX52: 4847908 | AY52: 9847908 | AZ52: 9847908 | BA52: 11580328 | BB52: =BA52 -> 11580328 | BC52: 0 | BD52: 0 | BE52: 1816004 | BF52: 7498429 | BG52: 20549147 | BH52: 20600725 | BI52: 20600725 | BJ52: 21065317 | BK52: 21811505 | BL52: 21811505 | BM52: 21811505 | BN52: 25096798 | BO52: =BN52 -> 25096798 | BP52: 0 | BQ52: 0 | BR52: 23839105 | BS52: 23839105 | BT52: 24267388 | BU52: 25551163 | BV52: 32469688 | BW52: 31819239 | BX52: 27176964 | BY52: 27176964 | BZ52: 27176964 | CA52: 24461848 | CB52: =CA52 -> 24461848 | CC52: 0 | CD52: 1194232 | CE52: 35224056 | CF52: 35224056 | CG52: 35224056 | CH52: 35224056 | CI52: 35224056 | CJ52: 35224056 | CK52: 39183354 | CL52: 38137553 | CM52: 38137553 | CN52: 39764885 | CO52: =CN52 -> 39764885 | CP52: 0 | CQ52: 94212588 | CR52: 94622434 | CS52: 94670565 | CT52: 94670565 | CU52: 94670565 | CV52: 94670565 | CW52: 94670565 | CX52: 94670565 | CY52: 94670565 | CZ52: 88981177 | DA52: 43077057 | DB52: =DA52 -> 43077057 | DC52: 0 | DD52: 61947100 | DE52: 61988684 | DF52: 61988684 | DG52: 61988684 | DH52: 61988684 | DI52: 61988684 | DJ52: 61993761 | DK52: 21670003 | DL52: 21670003 | DM52: 21546967 | DN52: 21371187 | DO52: =DN52 -> 21371187 | DP52: 0 | DQ52: 22148995 | DR52: 22148995 | DS52: 22148995 | DT52: 22521554 | DU52: 23131185 | DV52: 28207827 | DW52: 39289940 | DX52: 39289940 | DY52: 40072382 | DZ52: 40072382 | EA52: 27799825 | EB52: =EA52 -> 27799825 | EC52: 0 | ED52: 38060055 | EE52: 38884554 | EF52: 38913763 | EG52: 35119896 | EH52: 35134211 | EI52: 35134211 | EJ52: 35805869 | EK52: 34287274 | EL52: 20231382 | EM52: 19568840 | EN52: 16696164 | EO52: =EN52 -> 16696164 | EP52: 0 | EQ52: 11138854 | ER52: 14916172 | ES52: 14916172 | ET52: 14916172 | EU52: 14916172 | EV52: 14916172 | EW52: 22787635 | EX52: 19742032 | EY52: 19742032 | EZ52: 20748661 | FA52: 14450372 | FB52: =FA52 -> 14450372 | FC52: 21931475 | FD52: 21931475 | FE52: 21931475 | FF52: 21931475 | FG52: 21931475 | FH52: 21931475 | FI52: 21931475 | FO52: =FI52 -> 21931475
B53: Servicio de Salud Viña del Mar - Quillota | C53: 0 | D53: 14200952 | E53: 17211877 | F53: 17211877 | G53: 17211877 | H53: 17211877 | I53: 17211877 | J53: 17211877 | K53: 17571737 | L53: 17571737 | M53: 14432839 | N53: 14432839 | O53: =N53 -> 14432839 | P53: 0 | Q53: 37349058 | R53: 38544000 | S53: 38544000 | T53: 38544000 | U53: 19364883 | V53: 20174823 | W53: 20174823 | X53: 20174823 | Y53: 20174823 | Z53: 19731820 | AA53: 13971514 | AB53: =AA53 -> 13971514 | AC53: 0 | AD53: 28445774 | AE53: 28445774 | AF53: 28445774 | AG53: 28785782 | AH53: 28785782 | AI53: 28785782 | AJ53: 28785782 | AK53: 28785782 | AL53: 27934856 | AM53: 31293072 | AN53: 31036612 | AO53: =AN53 -> 31036612 | AP53: 0 | AQ53: 26170758 | AR53: 33080922 | AS53: 33080922 | AT53: 33352044 | AU53: 28542723 | AV53: 28542723 | AW53: 28542723 | AX53: 26202259 | AY53: 26222661 | AZ53: 26222661 | BA53: 32500455 | BB53: =BA53 -> 32500455 | BC53: 0 | BD53: 0 | BE53: 6767614 | BF53: 8951625 | BG53: 60797954 | BH53: 65607599 | BI53: 65607599 | BJ53: 65229175 | BK53: 59682383 | BL53: 54000995 | BM53: 54000995 | BN53: 57311644 | BO53: =BN53 -> 57311644 | BP53: 0 | BQ53: 0 | BR53: 68655332 | BS53: 68655332 | BT53: 68655332 | BU53: 87719084 | BV53: 109889410 | BW53: 105140785 | BX53: 81119392 | BY53: 81119392 | BZ53: 81119392 | CA53: 79006256 | CB53: =CA53 -> 79006256 | CC53: 0 | CD53: 1699139 | CE53: 59438757 | CF53: 59438757 | CG53: 59438757 | CH53: 59438757 | CI53: 70389228 | CJ53: 70389228 | CK53: 68983371 | CL53: 71283152 | CM53: 87062635 | CN53: 76996230 | CO53: =CN53 -> 76996230 | CP53: 0 | CQ53: 73129143 | CR53: 84952896 | CS53: 92682381 | CT53: 87098904 | CU53: 88402567 | CV53: 88402567 | CW53: 88402567 | CX53: 88402567 | CY53: 63708029 | CZ53: 63708029 | DA53: 58124956 | DB53: =DA53 -> 58124956 | DC53: 0 | DD53: 28198290 | DE53: 49698791 | DF53: 49698791 | DG53: 49822842 | DH53: 46663035 | DI53: 46668035 | DJ53: 46668036 | DK53: 40949590 | DL53: 40949590 | DM53: 38104655 | DN53: 38105075 | DO53: =DN53 -> 38105075 | DP53: 0 | DQ53: 37954062 | DR53: 37954062 | DS53: 37954062 | DT53: 37954062 | DU53: 37954062 | DV53: 40069991 | DW53: 38849601 | DX53: 38849601 | DY53: 53081099 | DZ53: 53081099 | EA53: 46577194 | EB53: =EA53 -> 46577194 | EC53: 0 | ED53: 54853078 | EE53: 60054090 | EF53: 60150724 | EG53: 60150724 | EH53: 60150724 | EI53: 88041423 | EJ53: 88041423 | EK53: 87680374 | EL53: 84793012 | EM53: 86351205 | EN53: 86176977 | EO53: =EN53 -> 86176977 | EP53: 0 | EQ53: 69438475 | ER53: 69438475 | ES53: 69438475 | ET53: 69438475 | EU53: 69438475 | EV53: 69438475 | EW53: 69438475 | EX53: 69438475 | EY53: 62110568 | EZ53: 62646658 | FA53: 53192169 | FB53: =FA53 -> 53192169 | FC53: 50768194 | FD53: 50768194 | FE53: 50768194 | FF53: 50768194 | FG53: 50768194 | FH53: 50768194 | FI53: 50768194 | FO53: =FI53 -> 50768194
B54: Servicio de Salud Aconcagua | C54: 0 | D54: 0 | E54: 5701337 | F54: 5701337 | G54: 5701337 | H54: 5701337 | I54: 5701337 | J54: 5701337 | K54: 5749103 | L54: 5749103 | M54: 6880351 | N54: 6880351 | O54: =N54 -> 6880351 | P54: 0 | Q54: 523372 | R54: 4092998 | S54: 4092998 | T54: 4094118 | U54: 4094118 | V54: 4481933 | W54: 4820379 | X54: 4820379 | Y54: 4820379 | Z54: 4820379 | AA54: 4712903 | AB54: =AA54 -> 4712903 | AC54: 0 | AD54: 2033337 | AE54: 2033337 | AF54: 2929829 | AG54: 2929829 | AH54: 2929829 | AI54: 5974542 | AJ54: 5974542 | AK54: 5974542 | AL54: 5974542 | AM54: 5974542 | AN54: 1090165 | AO54: =AN54 -> 1090165 | AP54: 0 | AQ54: 7995190 | AR54: 7995190 | AS54: 7995190 | AT54: 7995190 | AU54: 7995190 | AV54: 8235664 | AW54: 8235664 | AX54: 8235664 | AY54: 8235664 | AZ54: 8235664 | BA54: 7375229 | BB54: =BA54 -> 7375229 | BC54: 0 | BD54: 0 | BE54: 2769431 | BF54: 2938550 | BG54: 2938550 | BH54: 6638550 | BI54: 6638550 | BJ54: 7105224 | BK54: 4332695 | BL54: 4332695 | BM54: 4332695 | BN54: 5721273 | BO54: =BN54 -> 5721273 | BP54: 0 | BQ54: 0 | BR54: 6114000 | BS54: 6114000 | BT54: 6114000 | BU54: 8207493 | BV54: 8207493 | BW54: 7457441 | BX54: 7457441 | BY54: 7457441 | BZ54: 7457441 | CA54: 7222477 | CB54: =CA54 -> 7222477 | CC54: 0 | CD54: 161686 | CE54: 11162577 | CF54: 11803716 | CG54: 11803716 | CH54: 11803716 | CI54: 11803716 | CJ54: 11803716 | CK54: 11941495 | CL54: 11941495 | CM54: 5749218 | CN54: 5749218 | CO54: =CN54 -> 5749218 | CP54: 0 | CQ54: 7480282 | CR54: 7480282 | CS54: 7480282 | CT54: 7480282 | CU54: 7480282 | CV54: 7480282 | CW54: 7480282 | CX54: 7480282 | CY54: 6924886 | CZ54: 5513920 | DA54: 5518920 | DB54: =DA54 -> 5518920 | DC54: 0 | DD54: 0 | DE54: 8515350 | DF54: 8515350 | DG54: 8515350 | DH54: 8515350 | DI54: 8725865 | DJ54: 8747938 | DK54: 8747938 | DL54: 8839092 | DM54: 9730433 | DN54: 9586115 | DO54: =DN54 -> 9586115 | DP54: 0 | DQ54: 4526012 | DR54: 4526012 | DS54: 4526012 | DT54: 5166889 | DU54: 5166889 | DV54: 5878289 | DW54: 5878289 | DX54: 5878289 | DY54: 6239810 | DZ54: 6239810 | EA54: 4774007 | EB54: =EA54 -> 4774007 | EC54: 0 | ED54: 0 | EE54: 1726303 | EF54: 1726303 | EG54: 1726303 | EH54: 2913565 | EI54: 3098352 | EJ54: 3098352 | EK54: 2659288 | EL54: 1559535 | EM54: 1405224 | EN54: 1335225 | EO54: =EN54 -> 1335225 | EP54: 0 | EQ54: 4801570 | ER54: 4801570 | ES54: 4801570 | ET54: 4801570 | EU54: 5337303 | EV54: 5337303 | EW54: 5337303 | EX54: 5337303 | EY54: 5337303 | EZ54: 5337303 | FA54: 3499759 | FB54: =FA54 -> 3499759 | FC54: 1204885 | FD54: 1204885 | FE54: 1204885 | FF54: 1204885 | FG54: 1204885 | FH54: 1204885 | FI54: 1204885 | FO54: =FI54 -> 1204885
