Workbook

Sheet Dashboard
B2: MINISTERIO DE OBRAS PÚBLICAS — DASHBOARD DE INVERSIÓN Y EJECUCIÓN PRESUPUESTARIA
B3: Visualizador Analítico Interactivo Tabla a Tabla | Subtítulos 31, 29, 33 y Consolidado Total | Cifras en miles de pesos ($)
B4: AÑO SELECCIONADO: | C4: 2024 | D4: COBERTURA TEMPORAL: | F4: 2014 - 2026 (Ene - Dic) | H4: UNIDAD MONETARIA: | J4: Miles de $ Corrientes (DIPRES)
B6: PRESUPUESTO LEY (INICIAL) | D6: PRESUPUESTO VIGENTE | F6: EJECUCIÓN ACUMULADA | H6: % CUMPLIMIENTO PRESUPUESTARIO | J6: SALDO POR EJECUTAR
B7: =D17 -> 2942161253 | D7: =E17 -> 2330868371 | F7: =F17 -> 2321713289 | H7: =H17 -> 0.99607224 | J7: =G17 -> 9155082
B9: Aprobado Ley de Presupuesto | D9: Presupuesto anual actualizado | F9: Total devengado en el ejercicio | H9: Ejecución devengada / Presupuesto vigente | J9: Monto disponible no devengado
B11: TABLA 1: RESUMEN CONSOLIDADO POR SUBTÍTULO PRESUPUESTARIO
B13: Subtítulo Presupuestario | C13: Cód. | D13: Presupuesto Ley | E13: Presupuesto Vigente | F13: Ejecución Acumulada | G13: Saldo por Ejecutar | H13: % Ejecución | I13: % Participación
B14: Subtítulo 31 – Iniciativas de Inversión | C14: 31 | D14: =INDEX(MOP_Mes_Corriente!$1:$161, 14, 3 + ($C$4 - 2014)*13 + 12) -> 2933512941 | E14: =INDEX(MOP_Mes_Corriente!$1:$161, 26, 3 + ($C$4 - 2014)*13 + 12) -> 2323820848 | F14: =INDEX(MOP_Mes_Corriente!$1:$161, 38, 3 + ($C$4 - 2014)*13 + 12) -> 2314939413 | G14: =E14 - F14 -> 8881435 | H14: =IF(E14>0, F14/E14, 0) -> 0.99617809 | I14: =IF($E$17>0, E14/$E$17, 0) -> 0.99697644
B15: Subtítulo 29 – Activos No Financieros | C15: 29 | D15: =INDEX(MOP_Mes_Corriente!$1:$161, 53, 3 + ($C$4 - 2014)*13 + 12) -> 8648312 | E15: =INDEX(MOP_Mes_Corriente!$1:$161, 65, 3 + ($C$4 - 2014)*13 + 12) -> 7047523 | F15: =INDEX(MOP_Mes_Corriente!$1:$161, 77, 3 + ($C$4 - 2014)*13 + 12) -> 6773876 | G15: =E15 - F15 -> 273647 | H15: =IF(E15>0, F15/E15, 0) -> 0.96117118 | I15: =IF($E$17>0, E15/$E$17, 0) -> 0.0030235611
B16: Subtítulo 33 – Transferencias de Capital | C16: 33 | D16: =INDEX(MOP_Mes_Corriente!$1:$161, 92, 3 + ($C$4 - 2014)*13 + 12) -> 0 | E16: =INDEX(MOP_Mes_Corriente!$1:$161, 104, 3 + ($C$4 - 2014)*13 + 12) -> 0 | F16: =INDEX(MOP_Mes_Corriente!$1:$161, 116, 3 + ($C$4 - 2014)*13 + 12) -> 0 | G16: =E16 - F16 -> 0 | H16: =IF(E16>0, F16/E16, 0) -> 0 | I16: =IF($E$17>0, E16/$E$17, 0) -> 0
B17: TOTAL INVERSIÓN MOP (31 + 29 + 33) | C17: TOTAL | D17: =SUM(D14:D16) -> 2942161253 | E17: =SUM(E14:E16) -> 2330868371 | F17: =SUM(F14:F16) -> 2321713289 | G17: =E17 - F17 -> 9155082 | H17: =IF(E17>0, F17/E17, 0) -> 0.99607224 | I17: =SUM(I14:I16) -> 1
B19: TABLA 2: DESGLOSE COMPLETO POR PROGRAMA / DIRECCIÓN (AÑO SELECCIONADO)
B21: Dirección / Programa | C21: Subt. 31 Vigente | D21: Subt. 31 Ejecución | E21: Subt. 29 Vigente | F21: Subt. 29 Ejecución | G21: Subt. 33 Vigente | H21: Subt. 33 Ejecución | I21: Total Vigente | J21: Total Ejecución | K21: Saldo | L21: % Ejecución | M21: % Part. MOP
B22: Dirección de Vialidad | C22: =INDEX(MOP_Mes_Corriente!$1:$161, 20, 3 + ($C$4 - 2014)*13 + 12) -> 1608652526 | D22: =INDEX(MOP_Mes_Corriente!$1:$161, 32, 3 + ($C$4 - 2014)*13 + 12) -> 1603559540 | E22: =INDEX(MOP_Mes_Corriente!$1:$161, 59, 3 + ($C$4 - 2014)*13 + 12) -> 1135861 | F22: =INDEX(MOP_Mes_Corriente!$1:$161, 71, 3 + ($C$4 - 2014)*13 + 12) -> 1123525 | G22: =INDEX(MOP_Mes_Corriente!$1:$161, 98, 3 + ($C$4 - 2014)*13 + 12) -> 0 | H22: =INDEX(MOP_Mes_Corriente!$1:$161, 110, 3 + ($C$4 - 2014)*13 + 12) -> 0 | I22: =C22 + E22 + G22 -> 1609788387 | J22: =D22 + F22 + H22 -> 1604683065 | K22: =I22 - J22 -> 5105322 | L22: =IF(I22>0, J22/I22, 0) -> 0.99682858 | M22: =IF($I$28>0, I22/$I$28, 0) -> 0.69063891
B23: Dirección de Obras Hidráulicas | C23: =INDEX(MOP_Mes_Corriente!$1:$161, 21, 3 + ($C$4 - 2014)*13 + 12) -> 244313644 | D23: =INDEX(MOP_Mes_Corriente!$1:$161, 33, 3 + ($C$4 - 2014)*13 + 12) -> 243896208 | E23: =INDEX(MOP_Mes_Corriente!$1:$161, 60, 3 + ($C$4 - 2014)*13 + 12) -> 913626 | F23: =INDEX(MOP_Mes_Corriente!$1:$161, 72, 3 + ($C$4 - 2014)*13 + 12) -> 899916 | G23: =INDEX(MOP_Mes_Corriente!$1:$161, 99, 3 + ($C$4 - 2014)*13 + 12) -> 0 | H23: =INDEX(MOP_Mes_Corriente!$1:$161, 111, 3 + ($C$4 - 2014)*13 + 12) -> 0 | I23: =C23 + E23 + G23 -> 245227270 | J23: =D23 + F23 + H23 -> 244796124 | K23: =I23 - J23 -> 431146 | L23: =IF(I23>0, J23/I23, 0) -> 0.99824185 | M23: =IF($I$28>0, I23/$I$28, 0) -> 0.10520855
B24: Subdirección de APR | C24: =INDEX(MOP_Mes_Corriente!$1:$161, 22, 3 + ($C$4 - 2014)*13 + 12) -> 192186387 | D24: =INDEX(MOP_Mes_Corriente!$1:$161, 34, 3 + ($C$4 - 2014)*13 + 12) -> 189747396 | E24: =INDEX(MOP_Mes_Corriente!$1:$161, 61, 3 + ($C$4 - 2014)*13 + 12) -> 636104 | F24: =INDEX(MOP_Mes_Corriente!$1:$161, 73, 3 + ($C$4 - 2014)*13 + 12) -> 612897 | G24: =INDEX(MOP_Mes_Corriente!$1:$161, 100, 3 + ($C$4 - 2014)*13 + 12) -> 0 | H24: =INDEX(MOP_Mes_Corriente!$1:$161, 112, 3 + ($C$4 - 2014)*13 + 12) -> 0 | I24: =C24 + E24 + G24 -> 192822491 | J24: =D24 + F24 + H24 -> 190360293 | K24: =I24 - J24 -> 2462198 | L24: =IF(I24>0, J24/I24, 0) -> 0.98723075 | M24: =IF($I$28>0, I24/$I$28, 0) -> 0.082725603
B25: Dirección de Obras Portuarias | C25: =INDEX(MOP_Mes_Corriente!$1:$161, 23, 3 + ($C$4 - 2014)*13 + 12) -> 123682417 | D25: =INDEX(MOP_Mes_Corriente!$1:$161, 35, 3 + ($C$4 - 2014)*13 + 12) -> 122976500 | E25: =INDEX(MOP_Mes_Corriente!$1:$161, 62, 3 + ($C$4 - 2014)*13 + 12) -> 1731272 | F25: =INDEX(MOP_Mes_Corriente!$1:$161, 74, 3 + ($C$4 - 2014)*13 + 12) -> 1508486 | G25: =INDEX(MOP_Mes_Corriente!$1:$161, 101, 3 + ($C$4 - 2014)*13 + 12) -> 0 | H25: =INDEX(MOP_Mes_Corriente!$1:$161, 113, 3 + ($C$4 - 2014)*13 + 12) -> 0 | I25: =C25 + E25 + G25 -> 125413689 | J25: =D25 + F25 + H25 -> 124484986 | K25: =I25 - J25 -> 928703 | L25: =IF(I25>0, J25/I25, 0) -> 0.99259488 | M25: =IF($I$28>0, I25/$I$28, 0) -> 0.053805565
B26: Dirección de Aeropuertos | C26: =INDEX(MOP_Mes_Corriente!$1:$161, 24, 3 + ($C$4 - 2014)*13 + 12) -> 121300022 | D26: =INDEX(MOP_Mes_Corriente!$1:$161, 36, 3 + ($C$4 - 2014)*13 + 12) -> 121236421 | E26: =INDEX(MOP_Mes_Corriente!$1:$161, 63, 3 + ($C$4 - 2014)*13 + 12) -> 1998403 | F26: =INDEX(MOP_Mes_Corriente!$1:$161, 75, 3 + ($C$4 - 2014)*13 + 12) -> 1997225 | G26: =INDEX(MOP_Mes_Corriente!$1:$161, 102, 3 + ($C$4 - 2014)*13 + 12) -> 0 | H26: =INDEX(MOP_Mes_Corriente!$1:$161, 114, 3 + ($C$4 - 2014)*13 + 12) -> 0 | I26: =C26 + E26 + G26 -> 123298425 | J26: =D26 + F26 + H26 -> 123233646 | K26: =I26 - J26 -> 64779 | L26: =IF(I26>0, J26/I26, 0) -> 0.99947462 | M26: =IF($I$28>0, I26/$I$28, 0) -> 0.052898064
B27: Dirección de Arquitectura | C27: =INDEX(MOP_Mes_Corriente!$1:$161, 25, 3 + ($C$4 - 2014)*13 + 12) -> 33685852 | D27: =INDEX(MOP_Mes_Corriente!$1:$161, 37, 3 + ($C$4 - 2014)*13 + 12) -> 33523348 | E27: =INDEX(MOP_Mes_Corriente!$1:$161, 64, 3 + ($C$4 - 2014)*13 + 12) -> 632257 | F27: =INDEX(MOP_Mes_Corriente!$1:$161, 76, 3 + ($C$4 - 2014)*13 + 12) -> 631827 | G27: =INDEX(MOP_Mes_Corriente!$1:$161, 103, 3 + ($C$4 - 2014)*13 + 12) -> 0 | H27: =INDEX(MOP_Mes_Corriente!$1:$161, 115, 3 + ($C$4 - 2014)*13 + 12) -> 0 | I27: =C27 + E27 + G27 -> 34318109 | J27: =D27 + F27 + H27 -> 34155175 | K27: =I27 - J27 -> 162934 | L27: =IF(I27>0, J27/I27, 0) -> 0.99525224 | M27: =IF($I$28>0, I27/$I$28, 0) -> 0.014723315
B28: TOTAL MOP | C28: =SUM(C22:C27) -> 2323820848 | D28: =SUM(D22:D27) -> 2314939413 | E28: =SUM(E22:E27) -> 7047523 | F28: =SUM(F22:F27) -> 6773876 | G28: =SUM(G22:G27) -> 0 | H28: =SUM(H22:H27) -> 0 | I28: =SUM(I22:I27) -> 2330868371 | J28: =SUM(J22:J27) -> 2321713289 | K28: =SUM(K22:K27) -> 9155082 | L28: =IF(I28>0, J28/I28, 0) -> 0.99607224 | M28: =SUM(M22:M27) -> 1
B30: TABLA 3: EVOLUCIÓN MENSUAL DEL AÑO SELECCIONADO (ENERO A DICIEMBRE)
B32: Concepto / Mes | C32: Ene | D32: Feb | E32: Mar | F32: Abr | G32: May | H32: Jun | I32: Jul | J32: Ago | K32: Sep | L32: Oct | M32: Nov | N32: Dic | O32: Cierre Total
B33: Presupuesto Ley | C33: =INDEX(MOP_Mes_Corriente!$1:$161, 14, 3 + ($C$4 - 2014)*13 + 0) + INDEX(MOP_Mes_Corriente!$1:$161, 53, 3 + ($C$4 - 2014)*13 + 0) + INDEX(MOP_Mes_Corriente!$1:$161, 92, 3 + ($C$4 - 2014)*13 + 0) -> 2942161253 | D33: =INDEX(MOP_Mes_Corriente!$1:$161, 14, 3 + ($C$4 - 2014)*13 + 1) + INDEX(MOP_Mes_Corriente!$1:$161, 53, 3 + ($C$4 - 2014)*13 + 1) + INDEX(MOP_Mes_Corriente!$1:$161, 92, 3 + ($C$4 - 2014)*13 + 1) -> 2942161253 | E33: =INDEX(MOP_Mes_Corriente!$1:$161, 14, 3 + ($C$4 - 2014)*13 + 2) + INDEX(MOP_Mes_Corriente!$1:$161, 53, 3 + ($C$4 - 2014)*13 + 2) + INDEX(MOP_Mes_Corriente!$1:$161, 92, 3 + ($C$4 - 2014)*13 + 2) -> 2942161253 | F33: =INDEX(MOP_Mes_Corriente!$1:$161, 14, 3 + ($C$4 - 2014)*13 + 3) + INDEX(MOP_Mes_Corriente!$1:$161, 53, 3 + ($C$4 - 2014)*13 + 3) + INDEX(MOP_Mes_Corriente!$1:$161, 92, 3 + ($C$4 - 2014)*13 + 3) -> 2942161253 | G33: =INDEX(MOP_Mes_Corriente!$1:$161, 14, 3 + ($C$4 - 2014)*13 + 4) + INDEX(MOP_Mes_Corriente!$1:$161, 53, 3 + ($C$4 - 2014)*13 + 4) + INDEX(MOP_Mes_Corriente!$1:$161, 92, 3 + ($C$4 - 2014)*13 + 4) -> 2942161253 | H33: =INDEX(MOP_Mes_Corriente!$1:$161, 14, 3 + ($C$4 - 2014)*13 + 5) + INDEX(MOP_Mes_Corriente!$1:$161, 53, 3 + ($C$4 - 2014)*13 + 5) + INDEX(MOP_Mes_Corriente!$1:$161, 92, 3 + ($C$4 - 2014)*13 + 5) -> 2942161253 | I33: =INDEX(MOP_Mes_Corriente!$1:$161, 14, 3 + ($C$4 - 2014)*13 + 6) + INDEX(MOP_Mes_Corriente!$1:$161, 53, 3 + ($C$4 - 2014)*13 + 6) + INDEX(MOP_Mes_Corriente!$1:$161, 92, 3 + ($C$4 - 2014)*13 + 6) -> 2942161253 | J33: =INDEX(MOP_Mes_Corriente!$1:$161, 14, 3 + ($C$4 - 2014)*13 + 7) + INDEX(MOP_Mes_Corriente!$1:$161, 53, 3 + ($C$4 - 2014)*13 + 7) + INDEX(MOP_Mes_Corriente!$1:$161, 92, 3 + ($C$4 - 2014)*13 + 7) -> 2942161253 | K33: =INDEX(MOP_Mes_Corriente!$1:$161, 14, 3 + ($C$4 - 2014)*13 + 8) + INDEX(MOP_Mes_Corriente!$1:$161, 53, 3 + ($C$4 - 2014)*13 + 8) + INDEX(MOP_Mes_Corriente!$1:$161, 92, 3 + ($C$4 - 2014)*13 + 8) -> 2942161253 | L33: =INDEX(MOP_Mes_Corriente!$1:$161, 14, 3 + ($C$4 - 2014)*13 + 9) + INDEX(MOP_Mes_Corriente!$1:$161, 53, 3 + ($C$4 - 2014)*13 + 9) + INDEX(MOP_Mes_Corriente!$1:$161, 92, 3 + ($C$4 - 2014)*13 + 9) -> 2942161253 | M33: =INDEX(MOP_Mes_Corriente!$1:$161, 14, 3 + ($C$4 - 2014)*13 + 10) + INDEX(MOP_Mes_Corriente!$1:$161, 53, 3 + ($C$4 - 2014)*13 + 10) + INDEX(MOP_Mes_Corriente!$1:$161, 92, 3 + ($C$4 - 2014)*13 + 10) -> 2942161253 | N33: =INDEX(MOP_Mes_Corriente!$1:$161, 14, 3 + ($C$4 - 2014)*13 + 11) + INDEX(MOP_Mes_Corriente!$1:$161, 53, 3 + ($C$4 - 2014)*13 + 11) + INDEX(MOP_Mes_Corriente!$1:$161, 92, 3 + ($C$4 - 2014)*13 + 11) -> 2942161253 | O33: =INDEX(MOP_Mes_Corriente!$1:$161, 14, 3 + ($C$4 - 2014)*13 + 12) + INDEX(MOP_Mes_Corriente!$1:$161, 53, 3 + ($C$4 - 2014)*13 + 12) + INDEX(MOP_Mes_Corriente!$1:$161, 92, 3 + ($C$4 - 2014)*13 + 12) -> 2942161253
B34: Presupuesto Vigente | C34: =INDEX(MOP_Mes_Corriente!$1:$161, 26, 3 + ($C$4 - 2014)*13 + 0) + INDEX(MOP_Mes_Corriente!$1:$161, 65, 3 + ($C$4 - 2014)*13 + 0) + INDEX(MOP_Mes_Corriente!$1:$161, 104, 3 + ($C$4 - 2014)*13 + 0) -> 2942161253 | D34: =INDEX(MOP_Mes_Corriente!$1:$161, 26, 3 + ($C$4 - 2014)*13 + 1) + INDEX(MOP_Mes_Corriente!$1:$161, 65, 3 + ($C$4 - 2014)*13 + 1) + INDEX(MOP_Mes_Corriente!$1:$161, 104, 3 + ($C$4 - 2014)*13 + 1) -> 2942161253 | E34: =INDEX(MOP_Mes_Corriente!$1:$161, 26, 3 + ($C$4 - 2014)*13 + 2) + INDEX(MOP_Mes_Corriente!$1:$161, 65, 3 + ($C$4 - 2014)*13 + 2) + INDEX(MOP_Mes_Corriente!$1:$161, 104, 3 + ($C$4 - 2014)*13 + 2) -> 2872224418 | F34: =INDEX(MOP_Mes_Corriente!$1:$161, 26, 3 + ($C$4 - 2014)*13 + 3) + INDEX(MOP_Mes_Corriente!$1:$161, 65, 3 + ($C$4 - 2014)*13 + 3) + INDEX(MOP_Mes_Corriente!$1:$161, 104, 3 + ($C$4 - 2014)*13 + 3) -> 2789233638 | G34: =INDEX(MOP_Mes_Corriente!$1:$161, 26, 3 + ($C$4 - 2014)*13 + 4) + INDEX(MOP_Mes_Corriente!$1:$161, 65, 3 + ($C$4 - 2014)*13 + 4) + INDEX(MOP_Mes_Corriente!$1:$161, 104, 3 + ($C$4 - 2014)*13 + 4) -> 2788989293 | H34: =INDEX(MOP_Mes_Corriente!$1:$161, 26, 3 + ($C$4 - 2014)*13 + 5) + INDEX(MOP_Mes_Corriente!$1:$161, 65, 3 + ($C$4 - 2014)*13 + 5) + INDEX(MOP_Mes_Corriente!$1:$161, 104, 3 + ($C$4 - 2014)*13 + 5) -> 2768911293 | I34: =INDEX(MOP_Mes_Corriente!$1:$161, 26, 3 + ($C$4 - 2014)*13 + 6) + INDEX(MOP_Mes_Corriente!$1:$161, 65, 3 + ($C$4 - 2014)*13 + 6) + INDEX(MOP_Mes_Corriente!$1:$161, 104, 3 + ($C$4 - 2014)*13 + 6) -> 2768911293 | J34: =INDEX(MOP_Mes_Corriente!$1:$161, 26, 3 + ($C$4 - 2014)*13 + 7) + INDEX(MOP_Mes_Corriente!$1:$161, 65, 3 + ($C$4 - 2014)*13 + 7) + INDEX(MOP_Mes_Corriente!$1:$161, 104, 3 + ($C$4 - 2014)*13 + 7) -> 2765121527 | K34: =INDEX(MOP_Mes_Corriente!$1:$161, 26, 3 + ($C$4 - 2014)*13 + 8) + INDEX(MOP_Mes_Corriente!$1:$161, 65, 3 + ($C$4 - 2014)*13 + 8) + INDEX(MOP_Mes_Corriente!$1:$161, 104, 3 + ($C$4 - 2014)*13 + 8) -> 2763486063 | L34: =INDEX(MOP_Mes_Corriente!$1:$161, 26, 3 + ($C$4 - 2014)*13 + 9) + INDEX(MOP_Mes_Corriente!$1:$161, 65, 3 + ($C$4 - 2014)*13 + 9) + INDEX(MOP_Mes_Corriente!$1:$161, 104, 3 + ($C$4 - 2014)*13 + 9) -> 2757523660 | M34: =INDEX(MOP_Mes_Corriente!$1:$161, 26, 3 + ($C$4 - 2014)*13 + 10) + INDEX(MOP_Mes_Corriente!$1:$161, 65, 3 + ($C$4 - 2014)*13 + 10) + INDEX(MOP_Mes_Corriente!$1:$161, 104, 3 + ($C$4 - 2014)*13 + 10) -> 2716453128 | N34: =INDEX(MOP_Mes_Corriente!$1:$161, 26, 3 + ($C$4 - 2014)*13 + 11) + INDEX(MOP_Mes_Corriente!$1:$161, 65, 3 + ($C$4 - 2014)*13 + 11) + INDEX(MOP_Mes_Corriente!$1:$161, 104, 3 + ($C$4 - 2014)*13 + 11) -> 2330868371 | O34: =INDEX(MOP_Mes_Corriente!$1:$161, 26, 3 + ($C$4 - 2014)*13 + 12) + INDEX(MOP_Mes_Corriente!$1:$161, 65, 3 + ($C$4 - 2014)*13 + 12) + INDEX(MOP_Mes_Corriente!$1:$161, 104, 3 + ($C$4 - 2014)*13 + 12) -> 2330868371
B35: Ejecución Acumulada | C35: =INDEX(MOP_Mes_Corriente!$1:$161, 38, 3 + ($C$4 - 2014)*13 + 0) + INDEX(MOP_Mes_Corriente!$1:$161, 77, 3 + ($C$4 - 2014)*13 + 0) + INDEX(MOP_Mes_Corriente!$1:$161, 116, 3 + ($C$4 - 2014)*13 + 0) -> 10076 | D35: =INDEX(MOP_Mes_Corriente!$1:$161, 38, 3 + ($C$4 - 2014)*13 + 1) + INDEX(MOP_Mes_Corriente!$1:$161, 77, 3 + ($C$4 - 2014)*13 + 1) + INDEX(MOP_Mes_Corriente!$1:$161, 116, 3 + ($C$4 - 2014)*13 + 1) -> 158901130 | E35: =INDEX(MOP_Mes_Corriente!$1:$161, 38, 3 + ($C$4 - 2014)*13 + 2) + INDEX(MOP_Mes_Corriente!$1:$161, 77, 3 + ($C$4 - 2014)*13 + 2) + INDEX(MOP_Mes_Corriente!$1:$161, 116, 3 + ($C$4 - 2014)*13 + 2) -> 342245752 | F35: =INDEX(MOP_Mes_Corriente!$1:$161, 38, 3 + ($C$4 - 2014)*13 + 3) + INDEX(MOP_Mes_Corriente!$1:$161, 77, 3 + ($C$4 - 2014)*13 + 3) + INDEX(MOP_Mes_Corriente!$1:$161, 116, 3 + ($C$4 - 2014)*13 + 3) -> 535933925 | G35: =INDEX(MOP_Mes_Corriente!$1:$161, 38, 3 + ($C$4 - 2014)*13 + 4) + INDEX(MOP_Mes_Corriente!$1:$161, 77, 3 + ($C$4 - 2014)*13 + 4) + INDEX(MOP_Mes_Corriente!$1:$161, 116, 3 + ($C$4 - 2014)*13 + 4) -> 735766967 | H35: =INDEX(MOP_Mes_Corriente!$1:$161, 38, 3 + ($C$4 - 2014)*13 + 5) + INDEX(MOP_Mes_Corriente!$1:$161, 77, 3 + ($C$4 - 2014)*13 + 5) + INDEX(MOP_Mes_Corriente!$1:$161, 116, 3 + ($C$4 - 2014)*13 + 5) -> 1103900218 | I35: =INDEX(MOP_Mes_Corriente!$1:$161, 38, 3 + ($C$4 - 2014)*13 + 6) + INDEX(MOP_Mes_Corriente!$1:$161, 77, 3 + ($C$4 - 2014)*13 + 6) + INDEX(MOP_Mes_Corriente!$1:$161, 116, 3 + ($C$4 - 2014)*13 + 6) -> 1232252883 | J35: =INDEX(MOP_Mes_Corriente!$1:$161, 38, 3 + ($C$4 - 2014)*13 + 7) + INDEX(MOP_Mes_Corriente!$1:$161, 77, 3 + ($C$4 - 2014)*13 + 7) + INDEX(MOP_Mes_Corriente!$1:$161, 116, 3 + ($C$4 - 2014)*13 + 7) -> 1374995854 | K35: =INDEX(MOP_Mes_Corriente!$1:$161, 38, 3 + ($C$4 - 2014)*13 + 8) + INDEX(MOP_Mes_Corriente!$1:$161, 77, 3 + ($C$4 - 2014)*13 + 8) + INDEX(MOP_Mes_Corriente!$1:$161, 116, 3 + ($C$4 - 2014)*13 + 8) -> 1567303306 | L35: =INDEX(MOP_Mes_Corriente!$1:$161, 38, 3 + ($C$4 - 2014)*13 + 9) + INDEX(MOP_Mes_Corriente!$1:$161, 77, 3 + ($C$4 - 2014)*13 + 9) + INDEX(MOP_Mes_Corriente!$1:$161, 116, 3 + ($C$4 - 2014)*13 + 9) -> 1765889793 | M35: =INDEX(MOP_Mes_Corriente!$1:$161, 38, 3 + ($C$4 - 2014)*13 + 10) + INDEX(MOP_Mes_Corriente!$1:$161, 77, 3 + ($C$4 - 2014)*13 + 10) + INDEX(MOP_Mes_Corriente!$1:$161, 116, 3 + ($C$4 - 2014)*13 + 10) -> 2025828192 | N35: =INDEX(MOP_Mes_Corriente!$1:$161, 38, 3 + ($C$4 - 2014)*13 + 11) + INDEX(MOP_Mes_Corriente!$1:$161, 77, 3 + ($C$4 - 2014)*13 + 11) + INDEX(MOP_Mes_Corriente!$1:$161, 116, 3 + ($C$4 - 2014)*13 + 11) -> 2321713289 | O35: =INDEX(MOP_Mes_Corriente!$1:$161, 38, 3 + ($C$4 - 2014)*13 + 12) + INDEX(MOP_Mes_Corriente!$1:$161, 77, 3 + ($C$4 - 2014)*13 + 12) + INDEX(MOP_Mes_Corriente!$1:$161, 116, 3 + ($C$4 - 2014)*13 + 12) -> 2321713289
B36: % Avance Ejecución | C36: =IF(C34>0, C35/C34, 0) -> 3.4246933e-06 | D36: =IF(D34>0, D35/D34, 0) -> 0.054008301 | E36: =IF(E34>0, E35/E34, 0) -> 0.11915704 | F36: =IF(F34>0, F35/F34, 0) -> 0.19214379 | G36: =IF(G34>0, G35/G34, 0) -> 0.26381133 | H36: =IF(H34>0, H35/H34, 0) -> 0.39867663 | I36: =IF(I34>0, I35/I34, 0) -> 0.44503155 | J36: =IF(J34>0, J35/J34, 0) -> 0.49726417 | ... O36: =IF(O34>0, O35/O34, 0) -> 0.99607224
B38: TABLA 4: COMPARATIVA HISTÓRICA MULTIANUAL (2014 - 2026)
B40: Año | C40: Presupuesto Ley | D40: Presupuesto Vigente | E40: Ejecución Acumulada | F40: Saldo por Ejecutar | G40: % Ejecución | H40: Crec. Vigente (YoY) | I40: Crec. Ejecución (YoY)
B41: 2014 | C41: =MOP_Mes_Corriente!O14 + MOP_Mes_Corriente!O53 + MOP_Mes_Corriente!O92 -> 1084025889 | D41: =MOP_Mes_Corriente!O26 + MOP_Mes_Corriente!O65 + MOP_Mes_Corriente!O104 -> 1166387752 | E41: =MOP_Mes_Corriente!O38 + MOP_Mes_Corriente!O77 + MOP_Mes_Corriente!O116 -> 1164341987 | F41: =D41 - E41 -> 2045765 | G41: =IF(D41>0, E41/D41, 0) -> 0.99824607 | H41: - | I41: -
B42: 2015 | C42: =MOP_Mes_Corriente!AB14 + MOP_Mes_Corriente!AB53 + MOP_Mes_Corriente!AB92 -> 1280988401 | D42: =MOP_Mes_Corriente!AB26 + MOP_Mes_Corriente!AB65 + MOP_Mes_Corriente!AB104 -> 1327989832 | E42: =MOP_Mes_Corriente!AB38 + MOP_Mes_Corriente!AB77 + MOP_Mes_Corriente!AB116 -> 1325414832 | F42: =D42 - E42 -> 2575000 | G42: =IF(D42>0, E42/D42, 0) -> 0.99806098 | H42: =IF(D41>0, (D42-D41)/D41, 0) -> 0.13854919 | I42: =IF(E41>0, (E42-E41)/E41, 0) -> 0.13833809
B43: 2016 | C43: =MOP_Mes_Corriente!AO14 + MOP_Mes_Corriente!AO53 + MOP_Mes_Corriente!AO92 -> 1280211801 | D43: =MOP_Mes_Corriente!AO26 + MOP_Mes_Corriente!AO65 + MOP_Mes_Corriente!AO104 -> 1282280297 | E43: =MOP_Mes_Corriente!AO38 + MOP_Mes_Corriente!AO77 + MOP_Mes_Corriente!AO116 -> 1279809174 | F43: =D43 - E43 -> 2471123 | G43: =IF(D43>0, E43/D43, 0) -> 0.99807287 | H43: =IF(D42>0, (D43-D42)/D42, 0) -> -0.034420094 | I43: =IF(E42>0, (E43-E42)/E42, 0) -> -0.034408592
B44: 2017 | C44: =MOP_Mes_Corriente!BB14 + MOP_Mes_Corriente!BB53 + MOP_Mes_Corriente!BB92 -> 1341993281 | D44: =MOP_Mes_Corriente!BB26 + MOP_Mes_Corriente!BB65 + MOP_Mes_Corriente!BB104 -> 1319688378 | E44: =MOP_Mes_Corriente!BB38 + MOP_Mes_Corriente!BB77 + MOP_Mes_Corriente!BB116 -> 1316094896 | F44: =D44 - E44 -> 3593482 | G44: =IF(D44>0, E44/D44, 0) -> 0.99727702 | H44: =IF(D43>0, (D44-D43)/D43, 0) -> 0.029173092 | I44: =IF(E43>0, (E44-E43)/E43, 0) -> 0.028352447
B45: 2018 | C45: =MOP_Mes_Corriente!BO14 + MOP_Mes_Corriente!BO53 + MOP_Mes_Corriente!BO92 -> 1360411524 | D45: =MOP_Mes_Corriente!BO26 + MOP_Mes_Corriente!BO65 + MOP_Mes_Corriente!BO104 -> 1257040244 | E45: =MOP_Mes_Corriente!BO38 + MOP_Mes_Corriente!BO77 + MOP_Mes_Corriente!BO116 -> 1252583084 | F45: =D45 - E45 -> 4457160 | G45: =IF(D45>0, E45/D45, 0) -> 0.99645424 | H45: =IF(D44>0, (D45-D44)/D44, 0) -> -0.047471915 | I45: =IF(E44>0, (E45-E44)/E44, 0) -> -0.048257775
B46: 2019 | C46: =MOP_Mes_Corriente!CB14 + MOP_Mes_Corriente!CB53 + MOP_Mes_Corriente!CB92 -> 1453655213 | D46: =MOP_Mes_Corriente!CB26 + MOP_Mes_Corriente!CB65 + MOP_Mes_Corriente!CB104 -> 1476564275 | E46: =MOP_Mes_Corriente!CB38 + MOP_Mes_Corriente!CB77 + MOP_Mes_Corriente!CB116 -> 1462473656 | F46: =D46 - E46 -> 14090619 | G46: =IF(D46>0, E46/D46, 0) -> 0.99045716 | H46: =IF(D45>0, (D46-D45)/D45, 0) -> 0.17463564 | I46: =IF(E45>0, (E46-E45)/E45, 0) -> 0.16756619
B47: 2020 | C47: =MOP_Mes_Corriente!CO14 + MOP_Mes_Corriente!CO53 + MOP_Mes_Corriente!CO92 -> 1578601711 | D47: =MOP_Mes_Corriente!CO26 + MOP_Mes_Corriente!CO65 + MOP_Mes_Corriente!CO104 -> 1397548041 | E47: =MOP_Mes_Corriente!CO38 + MOP_Mes_Corriente!CO77 + MOP_Mes_Corriente!CO116 -> 1373767417 | F47: =D47 - E47 -> 23780624 | G47: =IF(D47>0, E47/D47, 0) -> 0.98298404 | H47: =IF(D46>0, (D47-D46)/D46, 0) -> -0.053513576 | I47: =IF(E46>0, (E47-E46)/E46, 0) -> -0.060654931
B48: 2021 | C48: =MOP_Mes_Corriente!DB14 + MOP_Mes_Corriente!DB53 + MOP_Mes_Corriente!DB92 -> 2326773489 | D48: =MOP_Mes_Corriente!DB26 + MOP_Mes_Corriente!DB65 + MOP_Mes_Corriente!DB104 -> 1577529365 | E48: =MOP_Mes_Corriente!DB38 + MOP_Mes_Corriente!DB77 + MOP_Mes_Corriente!DB116 -> 1391673062 | F48: =D48 - E48 -> 185856303 | G48: =IF(D48>0, E48/D48, 0) -> 0.8821852 | H48: =IF(D47>0, (D48-D47)/D47, 0) -> 0.12878364 | I48: =IF(E47>0, (E48-E47)/E47, 0) -> 0.013033971
B49: 2022 | C49: =MOP_Mes_Corriente!DO14 + MOP_Mes_Corriente!DO53 + MOP_Mes_Corriente!DO92 -> 2620025909 | D49: =MOP_Mes_Corriente!DO26 + MOP_Mes_Corriente!DO65 + MOP_Mes_Corriente!DO104 -> 1358582828 | E49: =MOP_Mes_Corriente!DO38 + MOP_Mes_Corriente!DO77 + MOP_Mes_Corriente!DO116 -> 1340723690 | F49: =D49 - E49 -> 17859138 | G49: =IF(D49>0, E49/D49, 0) -> 0.98685458 | H49: =IF(D48>0, (D49-D48)/D48, 0) -> -0.13879078 | I49: =IF(E48>0, (E49-E48)/E48, 0) -> -0.036610159
B50: 2023 | C50: =MOP_Mes_Corriente!EB14 + MOP_Mes_Corriente!EB53 + MOP_Mes_Corriente!EB92 -> 2835156480 | D50: =MOP_Mes_Corriente!EB26 + MOP_Mes_Corriente!EB65 + MOP_Mes_Corriente!EB104 -> 2132837420 | E50: =MOP_Mes_Corriente!EB38 + MOP_Mes_Corriente!EB77 + MOP_Mes_Corriente!EB116 -> 2106371463 | F50: =D50 - E50 -> 26465957 | G50: =IF(D50>0, E50/D50, 0) -> 0.9875912 | H50: =IF(D49>0, (D50-D49)/D49, 0) -> 0.5698987 | I50: =IF(E49>0, (E50-E49)/E49, 0) -> 0.57107052
B51: 2024 | C51: =MOP_Mes_Corriente!EO14 + MOP_Mes_Corriente!EO53 + MOP_Mes_Corriente!EO92 -> 2942161253 | D51: =MOP_Mes_Corriente!EO26 + MOP_Mes_Corriente!EO65 + MOP_Mes_Corriente!EO104 -> 2330868371 | E51: =MOP_Mes_Corriente!EO38 + MOP_Mes_Corriente!EO77 + MOP_Mes_Corriente!EO116 -> 2321713289 | F51: =D51 - E51 -> 9155082 | G51: =IF(D51>0, E51/D51, 0) -> 0.99607224 | H51: =IF(D50>0, (D51-D50)/D50, 0) -> 0.092848592 | I51: =IF(E50>0, (E51-E50)/E50, 0) -> 0.10223355
...

Sheet MOP_Mes_Corriente
B1: Ministerio de Obras Públicas – Partida 12
B2: Miles de pesos – moneda corriente – montos devengados
B3: Subtítulo 31 – Iniciativas de Inversión
B5: Presupuesto Ley de Inversión en Infraestructura Pública del Ministerio de Obras Públicas, 2014-2026 (Subtítulo 31 – Iniciativas de Inversión, miles de pesos)
C6: 2014 | P6: 2015 | AC6: 2016 | AP6: 2017 | BC6: 2018 | BP6: 2019 | CC6: 2020 | CP6: 2021(1) | DC6: 2022(1) | DP6: 2023 | EC6: 2024 | EP6: 2025 | FC6: 2026
B7: Programa | C7: Ene | D7: Feb | E7: Mar | F7: Abr | G7: May | H7: Jun | I7: Jul | J7: Ago | K7: Sep | L7: Oct | M7: Nov | N7: Dic | O7: Total 2014 | P7: Ene | Q7: Feb | R7: Mar | S7: Abr | T7: May | U7: Jun | V7: Jul | W7: Ago | X7: Sep | Y7: Oct | Z7: Nov | AA7: Dic | AB7: Total 2015 | AC7: Ene | AD7: Feb | AE7: Mar | AF7: Abr | AG7: May | AH7: Jun | AI7: Jul | AJ7: Ago | AK7: Sep | AL7: Oct | AM7: Nov | AN7: Dic | AO7: Total 2016 | AP7: Ene | AQ7: Feb | AR7: Mar | AS7: Abr | AT7: May | AU7: Jun | AV7: Jul | AW7: Ago | AX7: Sep | AY7: Oct | AZ7: Nov | BA7: Dic | BB7: Total 2017 | BC7: Ene | BD7: Feb | BE7: Mar | BF7: Abr | BG7: May | BH7: Jun | BI7: Jul | BJ7: Ago | BK7: Sep | BL7: Oct | BM7: Nov | BN7: Dic | BO7: Total 2018 | BP7: Ene | BQ7: Feb | BR7: Mar | BS7: Abr | BT7: May | BU7: Jun | BV7: Jul | BW7: Ago | BX7: Sep | BY7: Oct | BZ7: Nov | CA7: Dic | CB7: Total 2019 | CC7: Ene | CD7: Feb | CE7: Mar | CF7: Abr | CG7: May | CH7: Jun | CI7: Jul | CJ7: Ago | CK7: Sep | CL7: Oct | CM7: Nov | CN7: Dic | CO7: Total 2020 | CP7: Ene | CQ7: Feb | CR7: Mar | CS7: Abr | CT7: May | CU7: Jun | CV7: Jul | CW7: Ago | CX7: Sep | CY7: Oct | CZ7: Nov | DA7: Dic | DB7: Total 2021 | DC7: Ene | DD7: Feb | DE7: Mar | DF7: Abr | DG7: May | DH7: Jun | DI7: Jul | DJ7: Ago | DK7: Sep | DL7: Oct | DM7: Nov | DN7: Dic | DO7: Total 2022 | DP7: Ene | DQ7: Feb | DR7: Mar | DS7: Abr | DT7: May | DU7: Jun | DV7: Jul | DW7: Ago | DX7: Sep | DY7: Oct | DZ7: Nov | EA7: Dic | EB7: Total 2023 | EC7: Ene | ED7: Feb | EE7: Mar | EF7: Abr | EG7: May | EH7: Jun | EI7: Jul | EJ7: Ago | EK7: Sep | EL7: Oct | EM7: Nov | EN7: Dic | EO7: Total 2024 | EP7: Ene | EQ7: Feb | ER7: Mar | ES7: Abr | ET7: May | EU7: Jun | EV7: Jul | EW7: Ago | EX7: Sep | EY7: Oct | EZ7: Nov | FA7: Dic | FB7: Total 2025 | FC7: Ene | FD7: Feb | FE7: Mar | FF7: Abr | FG7: May | FH7: Jun | FI7: Jul | FJ7: Ago | FK7: Sep | FL7: Oct | FM7: Nov | FN7: Dic | FO7: Total 2026
B8: Dirección de Vialidad | C8: 806907228 | D8: 806907228 | E8: 806907228 | F8: 806907228 | G8: 806907228 | H8: 806907228 | I8: 806907228 | J8: 806907228 | K8: 806907228 | L8: 806907228 | M8: 806907228 | N8: 806907228 | O8: =N8 -> 806907228 | P8: 957407656 | Q8: 957407656 | R8: 957407656 | S8: 957407656 | T8: 957407656 | U8: 957407656 | V8: 957407656 | W8: 957407656 | X8: 957407656 | Y8: 957407656 | Z8: 957407656 | AA8: 957407656 | AB8: =AA8 -> 957407656 | AC8: 937156766 | AD8: 937156766 | AE8: 937156766 | AF8: 937156766 | AG8: 937156766 | AH8: 937156766 | AI8: 937156766 | AJ8: 937156766 | AK8: 937156766 | AL8: 937156766 | AM8: 937156766 | AN8: 937156766 | AO8: =AN8 -> 937156766 | AP8: 982538421 | AQ8: 982538421 | AR8: 982538421 | AS8: 982538421 | AT8: 982538421 | AU8: 982538421 | AV8: 982538421 | AW8: 982538421 | AX8: 982538421 | AY8: 982538421 | AZ8: 982538421 | BA8: 982538421 | BB8: =BA8 -> 982538421 | BC8: 998447263 | BD8: 998447263 | BE8: 998447263 | BF8: 998447263 | BG8: 998447263 | BH8: 998447263 | BI8: 998447263 | BJ8: 998447263 | BK8: 998447263 | BL8: 998447263 | BM8: 998447263 | BN8: 998447263 | BO8: =BN8 -> 998447263 | BP8: 1056398949 | BQ8: 1056398949 | BR8: 1056398949 | BS8: 1056398949 | BT8: 1056398949 | BU8: 1056398949 | BV8: 1056398949 | BW8: 1056398949 | BX8: 1056398949 | BY8: 1056398949 | BZ8: 1056398949 | CA8: 1056398949 | CB8: =CA8 -> 1056398949 | CC8: 1148358839 | CD8: 1148358839 | CE8: 1148358839 | CF8: 1148358839 | CG8: 1148358839 | CH8: 1148358839 | CI8: 1148358839 | CJ8: 1148358839 | CK8: 1148358839 | CL8: 1148358839 | CM8: 1148358839 | CN8: 1148358839 | CO8: =CN8 -> 1148358839 | CP8: =1224421462+380805877 -> 1605227339 | CQ8: =1224421462+380805877 -> 1605227339 | CR8: =1224421462+380805877 -> 1605227339 | CS8: =1224421462+380805877 -> 1605227339 | CT8: =1224421462+380805877 -> 1605227339 | CU8: =1224421462+380805877 -> 1605227339 | CV8: =1224421462+380805877 -> 1605227339 | CW8: =1224421462+380805877 -> 1605227339 | ... DA8: =1224421462+380805877 -> 1605227339 | DB8: =DA8 -> 1605227339 | DC8: =1220635546+581829225 -> 1802464771 | DD8: =1220635546+581829225 -> 1802464771 | DE8: =1220635546+581829225 -> 1802464771 | DF8: =1220635546+581829225 -> 1802464771 | DG8: =1220635546+581829225 -> 1802464771 | DH8: =1220635546+581829225 -> 1802464771 | DI8: =1220635546+581829225 -> 1802464771 | DJ8: =1220635546+581829225 -> 1802464771 | ... DN8: =1220635546+581829225 -> 1802464771 | DO8: =DN8 -> 1802464771 | DP8: 1913855137 | DQ8: 1913855137 | DR8: 1913855137 | DS8: 1913855137 | DT8: 1913855137 | DU8: 1913855137 | DV8: 1913855137 | DW8: 1913855137 | DX8: 1913855137 | DY8: 1913855137 | DZ8: 1913855137 | EA8: 1913855137 | EB8: =EA8 -> 1913855137 | EC8: 2012684680 | ED8: 2012684680 | EE8: 2012684680 | EF8: 2012684680 | EG8: 2012684680 | EH8: 2012684680 | EI8: 2012684680 | EJ8: 2012684680 | EK8: 2012684680 | EL8: 2012684680 | EM8: 2012684680 | EN8: 2012684680 | EO8: =EN8 -> 2012684680 | EP8: 2083103023 | EQ8: 2083103023 | ER8: 2083103023 | ES8: 2083103023 | ET8: 2083103023 | EU8: 2083103023 | EV8: 2083103023 | EW8: 2083103023 | EX8: 2083103023 | EY8: 2083103023 | EZ8: 2083103023 | FA8: 2083103023 | FB8: =FA8 -> 2083103023 | FC8: 1951485600 | FD8: 1951485600 | FE8: 1951485600 | FF8: 1951485600 | FG8: 1951485600 | FH8: 1951485600 | FI8: 1951485600 | FO8: =FI8 -> 1951485600
B9: Dirección de Obras Hidráulicas | C9: 101236706 | D9: 101236706 | E9: 101236706 | F9: 101236706 | G9: 101236706 | H9: 101236706 | I9: 101236706 | J9: 101236706 | K9: 101236706 | L9: 101236706 | M9: 101236706 | N9: 101236706 | O9: =N9 -> 101236706 | P9: 117398169 | Q9: 117398169 | R9: 117398169 | S9: 117398169 | T9: 117398169 | U9: 117398169 | V9: 117398169 | W9: 117398169 | X9: 117398169 | Y9: 117398169 | Z9: 117398169 | AA9: 117398169 | AB9: =AA9 -> 117398169 | AC9: 127292924 | AD9: 127292924 | AE9: 127292924 | AF9: 127292924 | AG9: 127292924 | AH9: 127292924 | AI9: 127292924 | AJ9: 127292924 | AK9: 127292924 | AL9: 127292924 | AM9: 127292924 | AN9: 127292924 | AO9: =AN9 -> 127292924 | AP9: 121635713 | AQ9: 121635713 | AR9: 121635713 | AS9: 121635713 | AT9: 121635713 | AU9: 121635713 | AV9: 121635713 | AW9: 121635713 | AX9: 121635713 | AY9: 121635713 | AZ9: 121635713 | BA9: 121635713 | BB9: =BA9 -> 121635713 | BC9: 119785354 | BD9: 119785354 | BE9: 119785354 | BF9: 119785354 | BG9: 119785354 | BH9: 119785354 | BI9: 119785354 | BJ9: 119785354 | BK9: 119785354 | BL9: 119785354 | BM9: 119785354 | BN9: 119785354 | BO9: =BN9 -> 119785354 | BP9: 129182602 | BQ9: 129182602 | BR9: 129182602 | BS9: 129182602 | BT9: 129182602 | BU9: 129182602 | BV9: 129182602 | BW9: 129182602 | BX9: 129182602 | BY9: 129182602 | BZ9: 129182602 | CA9: 129182602 | CB9: =CA9 -> 129182602 | CC9: 137671350 | CD9: 137671350 | CE9: 137671350 | CF9: 137671350 | CG9: 137671350 | CH9: 137671350 | CI9: 137671350 | CJ9: 137671350 | CK9: 137671350 | CL9: 137671350 | CM9: 137671350 | CN9: 137671350 | CO9: =CN9 -> 137671350 | CP9: =140801596+100700947 -> 241502543 | CQ9: =140801596+100700947 -> 241502543 | CR9: =140801596+100700947 -> 241502543 | CS9: =140801596+100700947 -> 241502543 | CT9: =140801596+100700947 -> 241502543 | CU9: =140801596+100700947 -> 241502543 | CV9: =140801596+100700947 -> 241502543 | CW9: =140801596+100700947 -> 241502543 | ... DA9: =140801596+100700947 -> 241502543 | DB9: =DA9 -> 241502543 | DC9: =147022684+130812721 -> 277835405 | DD9: =147022684+130812721 -> 277835405 | DE9: =147022684+130812721 -> 277835405 | DF9: =147022684+130812721 -> 277835405 | DG9: =147022684+130812721 -> 277835405 | DH9: =147022684+130812721 -> 277835405 | DI9: =147022684+130812721 -> 277835405 | DJ9: =147022684+130812721 -> 277835405 | ... DN9: =147022684+130812721 -> 277835405 | DO9: =DN9 -> 277835405 | DP9: 293591805 | DQ9: 293591805 | DR9: 293591805 | DS9: 293591805 | DT9: 293591805 | DU9: 293591805 | DV9: 293591805 | DW9: 293591805 | DX9: 293591805 | DY9: 293591805 | DZ9: 293591805 | EA9: 293591805 | EB9: =EA9 -> 293591805 | EC9: 295701947 | ED9: 295701947 | EE9: 295701947 | EF9: 295701947 | EG9: 295701947 | EH9: 295701947 | EI9: 295701947 | EJ9: 295701947 | EK9: 295701947 | EL9: 295701947 | EM9: 295701947 | EN9: 295701947 | EO9: =EN9 -> 295701947 | EP9: 308121429 | EQ9: 308121429 | ER9: 308121429 | ES9: 308121429 | ET9: 308121429 | EU9: 308121429 | EV9: 308121429 | EW9: 308121429 | EX9: 308121429 | EY9: 308121429 | EZ9: 308121429 | FA9: 308121429 | FB9: =FA9 -> 308121429 | FC9: 195906100 | FD9: 195906100 | FE9: 195906100 | FF9: 195906100 | FG9: 195906100 | FH9: 195906100 | FI9: 195906100 | FO9: =FI9 -> 195906100
B10: Subdirección de APR | C10: 49407947 | D10: 49407947 | E10: 49407947 | F10: 49407947 | G10: 49407947 | H10: 49407947 | I10: 49407947 | J10: 49407947 | K10: 49407947 | L10: 49407947 | M10: 49407947 | N10: 49407947 | O10: =N10 -> 49407947 | P10: 68884752 | Q10: 68884752 | R10: 68884752 | S10: 68884752 | T10: 68884752 | U10: 68884752 | V10: 68884752 | W10: 68884752 | X10: 68884752 | Y10: 68884752 | Z10: 68884752 | AA10: 68884752 | AB10: =AA10 -> 68884752 | AC10: 71502372 | AD10: 71502372 | AE10: 71502372 | AF10: 71502372 | AG10: 71502372 | AH10: 71502372 | AI10: 71502372 | AJ10: 71502372 | AK10: 71502372 | AL10: 71502372 | AM10: 71502372 | AN10: 71502372 | AO10: =AN10 -> 71502372 | AP10: 89991483 | AQ10: 89991483 | AR10: 89991483 | AS10: 89991483 | AT10: 89991483 | AU10: 89991483 | AV10: 89991483 | AW10: 89991483 | AX10: 89991483 | AY10: 89991483 | AZ10: 89991483 | BA10: 89991483 | BB10: =BA10 -> 89991483 | BC10: 102433801 | BD10: 102433801 | BE10: 102433801 | BF10: 102433801 | BG10: 102433801 | BH10: 102433801 | BI10: 102433801 | BJ10: 102433801 | BK10: 102433801 | BL10: 102433801 | BM10: 102433801 | BN10: 102433801 | BO10: =BN10 -> 102433801 | BP10: 114691671 | BQ10: 114691671 | BR10: 114691671 | BS10: 114691671 | BT10: 114691671 | BU10: 114691671 | BV10: 114691671 | BW10: 114691671 | BX10: 114691671 | BY10: 114691671 | BZ10: 114691671 | CA10: 114691671 | CB10: =CA10 -> 114691671 | CC10: 135338654 | CD10: 135338654 | CE10: 135338654 | CF10: 135338654 | CG10: 135338654 | CH10: 135338654 | CI10: 135338654 | CJ10: 135338654 | CK10: 135338654 | CL10: 135338654 | CM10: 135338654 | CN10: 135338654 | CO10: =CN10 -> 135338654 | CP10: =142048072+104543895 -> 246591967 | CQ10: =142048072+104543895 -> 246591967 | CR10: =142048072+104543895 -> 246591967 | CS10: =142048072+104543895 -> 246591967 | CT10: =142048072+104543895 -> 246591967 | CU10: =142048072+104543895 -> 246591967 | CV10: =142048072+104543895 -> 246591967 | CW10: =142048072+104543895 -> 246591967 | ... DA10: =142048072+104543895 -> 246591967 | DB10: =DA10 -> 246591967 | DC10: =148440561+129907392 -> 278347953 | DD10: =148440561+129907392 -> 278347953 | DE10: =148440561+129907392 -> 278347953 | DF10: =148440561+129907392 -> 278347953 | DG10: =148440561+129907392 -> 278347953 | DH10: =148440561+129907392 -> 278347953 | DI10: =148440561+129907392 -> 278347953 | DJ10: =148440561+129907392 -> 278347953 | ... DN10: =148440561+129907392 -> 278347953 | DO10: =DN10 -> 278347953 | DP10: 295780655 | DQ10: 295780655 | DR10: 295780655 | DS10: 295780655 | DT10: 295780655 | DU10: 295780655 | DV10: 295780655 | DW10: 295780655 | DX10: 295780655 | DY10: 295780655 | DZ10: 295780655 | EA10: 295780655 | EB10: =EA10 -> 295780655 | EC10: 315696642 | ED10: 315696642 | EE10: 315696642 | EF10: 315696642 | EG10: 315696642 | EH10: 315696642 | EI10: 315696642 | EJ10: 315696642 | EK10: 315696642 | EL10: 315696642 | EM10: 315696642 | EN10: 315696642 | EO10: =EN10 -> 315696642 | EP10: 329603442 | EQ10: 329603442 | ER10: 329603442 | ES10: 329603442 | ET10: 329603442 | EU10: 329603442 | EV10: 329603442 | EW10: 329603442 | EX10: 329603442 | EY10: 329603442 | EZ10: 329603442 | FA10: 329603442 | FB10: =FA10 -> 329603442 | FC10: 290113797 | FD10: 290113797 | FE10: 290113797 | FF10: 290113797 | FG10: 290113797 | FH10: 290113797 | FI10: 290113797 | FO10: =FI10 -> 290113797
B11: Dirección de Obras Portuarias | C11: 55038550 | D11: 55038550 | E11: 55038550 | F11: 55038550 | G11: 55038550 | H11: 55038550 | I11: 55038550 | J11: 55038550 | K11: 55038550 | L11: 55038550 | M11: 55038550 | N11: 55038550 | O11: =N11 -> 55038550 | P11: 63737311 | Q11: 63737311 | R11: 63737311 | S11: 63737311 | T11: 63737311 | U11: 63737311 | V11: 63737311 | W11: 63737311 | X11: 63737311 | Y11: 63737311 | Z11: 63737311 | AA11: 63737311 | AB11: =AA11 -> 63737311 | AC11: 66005341 | AD11: 66005341 | AE11: 66005341 | AF11: 66005341 | AG11: 66005341 | AH11: 66005341 | AI11: 66005341 | AJ11: 66005341 | AK11: 66005341 | AL11: 66005341 | AM11: 66005341 | AN11: 66005341 | AO11: =AN11 -> 66005341 | AP11: 68152361 | AQ11: 68152361 | AR11: 68152361 | AS11: 68152361 | AT11: 68152361 | AU11: 68152361 | AV11: 68152361 | AW11: 68152361 | AX11: 68152361 | AY11: 68152361 | AZ11: 68152361 | BA11: 68152361 | BB11: =BA11 -> 68152361 | BC11: 69097793 | BD11: 69097793 | BE11: 69097793 | BF11: 69097793 | BG11: 69097793 | BH11: 69097793 | BI11: 69097793 | BJ11: 69097793 | BK11: 69097793 | BL11: 69097793 | BM11: 69097793 | BN11: 69097793 | BO11: =BN11 -> 69097793 | BP11: 69888575 | BQ11: 69888575 | BR11: 69888575 | BS11: 69888575 | BT11: 69888575 | BU11: 69888575 | BV11: 69888575 | BW11: 69888575 | BX11: 69888575 | BY11: 69888575 | BZ11: 69888575 | CA11: 69888575 | CB11: =CA11 -> 69888575 | CC11: 71705676 | CD11: 71705676 | CE11: 71705676 | CF11: 71705676 | CG11: 71705676 | CH11: 71705676 | CI11: 71705676 | CJ11: 71705676 | CK11: 71705676 | CL11: 71705676 | CM11: 71705676 | CN11: 71705676 | CO11: =CN11 -> 71705676 | CP11: =73670723+10507533 -> 84178256 | CQ11: =73670723+10507533 -> 84178256 | CR11: =73670723+10507533 -> 84178256 | CS11: =73670723+10507533 -> 84178256 | CT11: =73670723+10507533 -> 84178256 | CU11: =73670723+10507533 -> 84178256 | CV11: =73670723+10507533 -> 84178256 | CW11: =73670723+10507533 -> 84178256 | ... DA11: =73670723+10507533 -> 84178256 | DB11: =DA11 -> 84178256 | DC11: =76882481+23172423 -> 100054904 | DD11: =76882481+23172423 -> 100054904 | DE11: =76882481+23172423 -> 100054904 | DF11: =76882481+23172423 -> 100054904 | DG11: =76882481+23172423 -> 100054904 | DH11: =76882481+23172423 -> 100054904 | DI11: =76882481+23172423 -> 100054904 | DJ11: =76882481+23172423 -> 100054904 | ... DN11: =76882481+23172423 -> 100054904 | DO11: =DN11 -> 100054904 | DP11: 115171552 | DQ11: 115171552 | DR11: 115171552 | DS11: 115171552 | DT11: 115171552 | DU11: 115171552 | DV11: 115171552 | DW11: 115171552 | DX11: 115171552 | DY11: 115171552 | DZ11: 115171552 | EA11: 115171552 | EB11: =EA11 -> 115171552 | EC11: 127117895 | ED11: 127117895 | EE11: 127117895 | EF11: 127117895 | EG11: 127117895 | EH11: 127117895 | EI11: 127117895 | EJ11: 127117895 | EK11: 127117895 | EL11: 127117895 | EM11: 127117895 | EN11: 127117895 | EO11: =EN11 -> 127117895 | EP11: 125417585 | EQ11: 125417585 | ER11: 125417585 | ES11: 125417585 | ET11: 125417585 | EU11: 125417585 | EV11: 125417585 | EW11: 125417585 | EX11: 125417585 | EY11: 125417585 | EZ11: 125417585 | FA11: 125417585 | FB11: =FA11 -> 125417585 | FC11: 109909690 | FD11: 109909690 | FE11: 109909690 | FF11: 109909690 | FG11: 109909690 | FH11: 109909690 | FI11: 109909690 | FO11: =FI11 -> 109909690
B12: Dirección de Aeropuertos | C12: 41285665 | D12: 41285665 | E12: 41285665 | F12: 41285665 | G12: 41285665 | H12: 41285665 | I12: 41285665 | J12: 41285665 | K12: 41285665 | L12: 41285665 | M12: 41285665 | N12: 41285665 | O12: =N12 -> 41285665 | P12: 41009608 | Q12: 41009608 | R12: 41009608 | S12: 41009608 | T12: 41009608 | U12: 41009608 | V12: 41009608 | W12: 41009608 | X12: 41009608 | Y12: 41009608 | Z12: 41009608 | AA12: 41009608 | AB12: =AA12 -> 41009608 | AC12: 43953347 | AD12: 43953347 | AE12: 43953347 | AF12: 43953347 | AG12: 43953347 | AH12: 43953347 | AI12: 43953347 | AJ12: 43953347 | AK12: 43953347 | AL12: 43953347 | AM12: 43953347 | AN12: 43953347 | AO12: =AN12 -> 43953347 | AP12: 45271947 | AQ12: 45271947 | AR12: 45271947 | AS12: 45271947 | AT12: 45271947 | AU12: 45271947 | AV12: 45271947 | AW12: 45271947 | AX12: 45271947 | AY12: 45271947 | AZ12: 45271947 | BA12: 45271947 | BB12: =BA12 -> 45271947 | BC12: 35602336 | BD12: 35602336 | BE12: 35602336 | BF12: 35602336 | BG12: 35602336 | BH12: 35602336 | BI12: 35602336 | BJ12: 35602336 | BK12: 35602336 | BL12: 35602336 | BM12: 35602336 | BN12: 35602336 | BO12: =BN12 -> 35602336 | BP12: 53068499 | BQ12: 53068499 | BR12: 53068499 | BS12: 53068499 | BT12: 53068499 | BU12: 53068499 | BV12: 53068499 | BW12: 53068499 | BX12: 53068499 | BY12: 53068499 | BZ12: 53068499 | CA12: 53068499 | CB12: =CA12 -> 53068499 | CC12: 58584599 | CD12: 58584599 | CE12: 58584599 | CF12: 58584599 | CG12: 58584599 | CH12: 58584599 | CI12: 58584599 | CJ12: 58584599 | CK12: 58584599 | CL12: 58584599 | CM12: 58584599 | CN12: 58584599 | CO12: =CN12 -> 58584599 | CP12: =60144148+46830346 -> 106974494 | CQ12: =60144148+46830346 -> 106974494 | CR12: =60144148+46830346 -> 106974494 | CS12: =60144148+46830346 -> 106974494 | CT12: =60144148+46830346 -> 106974494 | CU12: =60144148+46830346 -> 106974494 | CV12: =60144148+46830346 -> 106974494 | CW12: =60144148+46830346 -> 106974494 | ... DA12: =60144148+46830346 -> 106974494 | DB12: =DA12 -> 106974494 | DC12: =62797413+55033938 -> 117831351 | DD12: =62797413+55033938 -> 117831351 | DE12: =62797413+55033938 -> 117831351 | DF12: =62797413+55033938 -> 117831351 | DG12: =62797413+55033938 -> 117831351 | DH12: =62797413+55033938 -> 117831351 | DI12: =62797413+55033938 -> 117831351 | DJ12: =62797413+55033938 -> 117831351 | ... DN12: =62797413+55033938 -> 117831351 | DO12: =DN12 -> 117831351 | DP12: 135318267 | DQ12: 135318267 | DR12: 135318267 | DS12: 135318267 | DT12: 135318267 | DU12: 135318267 | DV12: 135318267 | DW12: 135318267 | DX12: 135318267 | DY12: 135318267 | DZ12: 135318267 | EA12: 135318267 | EB12: =EA12 -> 135318267 | EC12: 137741639 | ED12: 137741639 | EE12: 137741639 | EF12: 137741639 | EG12: 137741639 | EH12: 137741639 | EI12: 137741639 | EJ12: 137741639 | EK12: 137741639 | EL12: 137741639 | EM12: 137741639 | EN12: 137741639 | EO12: =EN12 -> 137741639 | EP12: 141825431 | EQ12: 141825431 | ER12: 141825431 | ES12: 141825431 | ET12: 141825431 | EU12: 141825431 | EV12: 141825431 | EW12: 141825431 | EX12: 141825431 | EY12: 141825431 | EZ12: 141825431 | FA12: 141825431 | FB12: =FA12 -> 141825431 | FC12: 127610750 | FD12: 127610750 | FE12: 127610750 | FF12: 127610750 | FG12: 127610750 | FH12: 127610750 | FI12: 127610750 | FO12: =FI12 -> 127610750
B13: Dirección de Arquitectura | C13: 26272563 | D13: 26272563 | E13: 26272563 | F13: 26272563 | G13: 26272563 | H13: 26272563 | I13: 26272563 | J13: 26272563 | K13: 26272563 | L13: 26272563 | M13: 26272563 | N13: 26272563 | O13: =N13 -> 26272563 | P13: 28203580 | Q13: 28203580 | R13: 28203580 | S13: 28203580 | T13: 28203580 | U13: 28203580 | V13: 28203580 | W13: 28203580 | X13: 28203580 | Y13: 28203580 | Z13: 28203580 | AA13: 28203580 | AB13: =AA13 -> 28203580 | AC13: 25719874 | AD13: 25719874 | AE13: 25719874 | AF13: 25719874 | AG13: 25719874 | AH13: 25719874 | AI13: 25719874 | AJ13: 25719874 | AK13: 25719874 | AL13: 25719874 | AM13: 25719874 | AN13: 25719874 | AO13: =AN13 -> 25719874 | AP13: 28283754 | AQ13: 28283754 | AR13: 28283754 | AS13: 28283754 | AT13: 28283754 | AU13: 28283754 | AV13: 28283754 | AW13: 28283754 | AX13: 28283754 | AY13: 28283754 | AZ13: 28283754 | BA13: 28283754 | BB13: =BA13 -> 28283754 | BC13: 30504194 | BD13: 30504194 | BE13: 30504194 | BF13: 30504194 | BG13: 30504194 | BH13: 30504194 | BI13: 30504194 | BJ13: 30504194 | BK13: 30504194 | BL13: 30504194 | BM13: 30504194 | BN13: 30504194 | BO13: =BN13 -> 30504194 | BP13: 25853361 | BQ13: 25853361 | BR13: 25853361 | BS13: 25853361 | BT13: 25853361 | BU13: 25853361 | BV13: 25853361 | BW13: 25853361 | BX13: 25853361 | BY13: 25853361 | BZ13: 25853361 | CA13: 25853361 | CB13: =CA13 -> 25853361 | CC13: 22096777 | CD13: 22096777 | CE13: 22096777 | CF13: 22096777 | CG13: 22096777 | CH13: 22096777 | CI13: 22096777 | CJ13: 22096777 | CK13: 22096777 | CL13: 22096777 | CM13: 22096777 | CN13: 22096777 | CO13: =CN13 -> 22096777 | CP13: =11904427+25061381 -> 36965808 | CQ13: =11904427+25061381 -> 36965808 | CR13: =11904427+25061381 -> 36965808 | CS13: =11904427+25061381 -> 36965808 | CT13: =11904427+25061381 -> 36965808 | CU13: =11904427+25061381 -> 36965808 | CV13: =11904427+25061381 -> 36965808 | CW13: =11904427+25061381 -> 36965808 | ... DA13: =11904427+25061381 -> 36965808 | DB13: =DA13 -> 36965808 | DC13: =8974172+32064677 -> 41038849 | DD13: =8974172+32064677 -> 41038849 | DE13: =8974172+32064677 -> 41038849 | DF13: =8974172+32064677 -> 41038849 | DG13: =8974172+32064677 -> 41038849 | DH13: =8974172+32064677 -> 41038849 | DI13: =8974172+32064677 -> 41038849 | DJ13: =8974172+32064677 -> 41038849 | ... DN13: =8974172+32064677 -> 41038849 | DO13: =DN13 -> 41038849 | DP13: 37590026 | DQ13: 37590026 | DR13: 37590026 | DS13: 37590026 | DT13: 37590026 | DU13: 37590026 | DV13: 37590026 | DW13: 37590026 | DX13: 37590026 | DY13: 37590026 | DZ13: 37590026 | EA13: 37590026 | EB13: =EA13 -> 37590026 | EC13: 44570138 | ED13: 44570138 | EE13: 44570138 | EF13: 44570138 | EG13: 44570138 | EH13: 44570138 | EI13: 44570138 | EJ13: 44570138 | EK13: 44570138 | EL13: 44570138 | EM13: 44570138 | EN13: 44570138 | EO13: =EN13 -> 44570138 | EP13: 57109595 | EQ13: 57109595 | ER13: 57109595 | ES13: 57109595 | ET13: 57109595 | EU13: 57109595 | EV13: 57109595 | EW13: 57109595 | EX13: 57109595 | EY13: 57109595 | EZ13: 57109595 | FA13: 57109595 | FB13: =FA13 -> 57109595 | FC13: 30479549 | FD13: 30479549 | FE13: 30479549 | FF13: 30479549 | FG13: 30479549 | FH13: 30479549 | FI13: 30479549 | FO13: =FI13 -> 30479549
B14: Total | C14: =SUM(C8:C13) -> 1080148659 | D14: =SUM(D8:D13) -> 1080148659 | E14: =SUM(E8:E13) -> 1080148659 | F14: =SUM(F8:F13) -> 1080148659 | G14: =SUM(G8:G13) -> 1080148659 | H14: =SUM(H8:H13) -> 1080148659 | I14: =SUM(I8:I13) -> 1080148659 | J14: =SUM(J8:J13) -> 1080148659 | ... FO14: =SUM(FO8:FO13) -> 2705505486
B15: (1) Los años 2021 y 2022 incluyen el Presupuesto Ley del Subtítulo 30, Ítem 10. Fuente: elaboración propia, Dipres.
B17: Presupuesto Vigente de Inversión en Infraestructura Pública del Ministerio de Obras Públicas, 2014-2026 (Subtítulo 31 – Iniciativas de Inversión, miles de pesos)
C18: 2014 | P18: 2015 | AC18: 2016 | AP18: 2017 | BC18: 2018 | BP18: 2019 | CC18: 2020 | CP18: 2021(1) | DC18: 2022(1) | DP18: 2023 | EC18: 2024 | EP18: 2025 | FC18: 2026
B19: Programa | C19: Ene | D19: Feb | E19: Mar | F19: Abr | G19: May | H19: Jun | I19: Jul | J19: Ago | K19: Sep | L19: Oct | M19: Nov | N19: Dic | O19: Total 2014 | P19: Ene | Q19: Feb | R19: Mar | S19: Abr | T19: May | U19: Jun | V19: Jul | W19: Ago | X19: Sep | Y19: Oct | Z19: Nov | AA19: Dic | AB19: Total 2015 | AC19: Ene | AD19: Feb | AE19: Mar | AF19: Abr | AG19: May | AH19: Jun | AI19: Jul | AJ19: Ago | AK19: Sep | AL19: Oct | AM19: Nov | AN19: Dic | AO19: Total 2016 | AP19: Ene | AQ19: Feb | AR19: Mar | AS19: Abr | AT19: May | AU19: Jun | AV19: Jul | AW19: Ago | AX19: Sep | AY19: Oct | AZ19: Nov | BA19: Dic | BB19: Total 2017 | BC19: Ene | BD19: Feb | BE19: Mar | BF19: Abr | BG19: May | BH19: Jun | BI19: Jul | BJ19: Ago | BK19: Sep | BL19: Oct | BM19: Nov | BN19: Dic | BO19: Total 2018 | BP19: Ene | BQ19: Feb | BR19: Mar | BS19: Abr | BT19: May | BU19: Jun | BV19: Jul | BW19: Ago | BX19: Sep | BY19: Oct | BZ19: Nov | CA19: Dic | CB19: Total 2019 | CC19: Ene | CD19: Feb | CE19: Mar | CF19: Abr | CG19: May | CH19: Jun | CI19: Jul | CJ19: Ago | CK19: Sep | CL19: Oct | CM19: Nov | CN19: Dic | CO19: Total 2020 | CP19: Ene | CQ19: Feb | CR19: Mar | CS19: Abr | CT19: May | CU19: Jun | CV19: Jul | CW19: Ago | CX19: Sep | CY19: Oct | CZ19: Nov | DA19: Dic | DB19: Total 2021 | DC19: Ene | DD19: Feb | DE19: Mar | DF19: Abr | DG19: May | DH19: Jun | DI19: Jul | DJ19: Ago | DK19: Sep | DL19: Oct | DM19: Nov | DN19: Dic | DO19: Total 2022 | DP19: Ene | DQ19: Feb | DR19: Mar | DS19: Abr | DT19: May | DU19: Jun | DV19: Jul | DW19: Ago | DX19: Sep | DY19: Oct | DZ19: Nov | EA19: Dic | EB19: Total 2023 | EC19: Ene | ED19: Feb | EE19: Mar | EF19: Abr | EG19: May | EH19: Jun | EI19: Jul | EJ19: Ago | EK19: Sep | EL19: Oct | EM19: Nov | EN19: Dic | EO19: Total 2024 | EP19: Ene | EQ19: Feb | ER19: Mar | ES19: Abr | ET19: May | EU19: Jun | EV19: Jul | EW19: Ago | EX19: Sep | EY19: Oct | EZ19: Nov | FA19: Dic | FB19: Total 2025 | FC19: Ene | FD19: Feb | FE19: Mar | FF19: Abr | FG19: May | FH19: Jun | FI19: Jul | FJ19: Ago | FK19: Sep | FL19: Oct | FM19: Nov | FN19: Dic | FO19: Total 2026
B20: Dirección de Vialidad | C20: 806907228 | D20: 806907228 | E20: 797207228 | F20: 797207228 | G20: 799193228 | H20: 801043262 | I20: 797883262 | J20: 817043262 | K20: 818043262 | L20: 842704970 | M20: 843143806 | N20: 853032416 | O20: =N20 -> 853032416 | P20: 957407656 | Q20: 958801347 | R20: 952446725 | S20: 944486725 | T20: 948962726 | U20: 949105726 | V20: 949005726 | W20: 949071698 | X20: 949071698 | Y20: 949071698 | Z20: 978416698 | AA20: 978378698 | AB20: =AA20 -> 978378698 | AC20: 937156766 | AD20: 930976766 | AE20: 939666557 | AF20: 937705385 | AG20: 937705385 | AH20: 937166385 | AI20: 937166385 | AJ20: 937166385 | AK20: 937166385 | AL20: 937166385 | AM20: 937073385 | AN20: 940884842 | AO20: =AN20 -> 940884842 | AP20: 982538421 | AQ20: 982538421 | AR20: 982260421 | AS20: 982260421 | AT20: 982060421 | AU20: 963745421 | AV20: 963304221 | AW20: 951169721 | AX20: 951169721 | AY20: 934145882 | AZ20: 931388882 | BA20: 909483945 | BB20: =BA20 -> 909483945 | BC20: 998447263 | BD20: 998447263 | BE20: 992502179 | BF20: 997730439 | BG20: 997415248 | BH20: 989715248 | BI20: 987815248 | BJ20: 987280248 | BK20: 987280248 | BL20: 987265248 | BM20: 986833548 | BN20: 903724337 | BO20: =BN20 -> 903724337 | BP20: 1056398949 | BQ20: 1056398949 | BR20: 1056398949 | BS20: 1061857019 | BT20: 1066368519 | BU20: 1061536519 | BV20: 1061502269 | BW20: 1074213648 | BX20: 1085679831 | BY20: 1085679831 | BZ20: 1085679831 | CA20: 1085267877 | CB20: =CA20 -> 1085267877 | CC20: 1148358839 | CD20: 1151054581 | CE20: 1248782581 | CF20: 1248782581 | CG20: 1216917979 | CH20: 1216917979 | CI20: 1216383979 | CJ20: 1216383979 | CK20: 1216383979 | CL20: 1197726086 | CM20: 1197588086 | CN20: 961564167 | CO20: =CN20 -> 961564167 | CP20: 1224421462 | CQ20: 1224421462 | CR20: 1139453884 | CS20: 1067186833 | CT20: 1048239333 | CU20: 1048217333 | CV20: 1048217333 | CW20: 1048116163 | CX20: 1048116163 | CY20: 1035718353 | CZ20: 1035625353 | DA20: =991797481+130932798 -> 1122730279 | DB20: =DA20 -> 1122730279 | DC20: 1220635546 | DD20: 1220635546 | DE20: 1220279119 | DF20: 1220279119 | DG20: 1218682119 | DH20: 1218249119 | DI20: 1092879968 | DJ20: 1092879968 | DK20: 1082339533 | DL20: 1082339533 | DM20: 1081913803 | DN20: 967670999 | DO20: =DN20 -> 967670999 | DP20: 1913855137 | DQ20: 1913855137 | DR20: 1913855137 | DS20: 1893896951 | DT20: 1850161211 | DU20: 1774161211 | DV20: 1774161211 | DW20: 1623406641 | DX20: 1620225968 | DY20: 1542961468 | DZ20: 1542961468 | EA20: 1427470479 | EB20: =EA20 -> 1427470479 | EC20: 2012684680 | ED20: 2012684680 | EE20: 1959842560 | EF20: 1959842560 | EG20: 1959505267 | EH20: 1939427267 | EI20: 1939427267 | EJ20: 1938757501 | EK20: 1937457501 | EL20: 1929646738 | EM20: 1891922336 | EN20: 1608652526 | EO20: =EN20 -> 1608652526 | EP20: 2083103023 | EQ20: 2083103023 | ER20: 2068572694 | ES20: 2068438694 | ET20: 2067139640 | EU20: 1962984489 | EV20: 1968056577 | EW20: 1968056577 | EX20: 1968056577 | EY20: 1968056577 | EZ20: 1968056577 | FA20: 1976677470 | FB20: =FA20 -> 1976677470 | FC20: 1951485600 | FD20: 1951485600 | FE20: 1905464563 | FF20: 1905464563 | FG20: 1817932962 | FH20: 1801311962 | FI20: 1801311962 | FO20: =FI20 -> 1801311962
B21: Dirección de Obras Hidráulicas | C21: 101236706 | D21: 101236706 | E21: 101236706 | F21: 101236706 | G21: 101236706 | H21: 101236706 | I21: 101236706 | J21: 101236706 | K21: 101236706 | L21: 104448787 | M21: 104448787 | N21: 105052138 | O21: =N21 -> 105052138 | P21: 117398169 | Q21: 117398169 | R21: 117398169 | S21: 117398169 | T21: 117398169 | U21: 119398169 | V21: 119398169 | W21: 119398169 | X21: 119398169 | Y21: 126602707 | Z21: 126602707 | AA21: 127586435 | AB21: =AA21 -> 127586435 | AC21: 127292924 | AD21: 127292924 | AE21: 127292924 | AF21: 127292924 | AG21: 127292924 | AH21: 127292924 | AI21: 127292924 | AJ21: 127292924 | AK21: 127292924 | AL21: 127292924 | AM21: 127292924 | AN21: 125791938 | AO21: =AN21 -> 125791938 | AP21: 121635713 | AQ21: 121635713 | AR21: 121635713 | AS21: 121635713 | AT21: 121635713 | AU21: 129989213 | AV21: 129989213 | AW21: 141642213 | AX21: 141642213 | AY21: 147144690 | AZ21: 147144690 | BA21: 146472297 | BB21: =BA21 -> 146472297 | BC21: 119785354 | BD21: 119785354 | BE21: 119835354 | BF21: 119835354 | BG21: 119835354 | BH21: 119835354 | BI21: 119601854 | BJ21: 119601854 | BK21: 121911854 | BL21: 125699985 | BM21: 125699985 | BN21: 120161746 | BO21: =BN21 -> 120161746 | BP21: 129182602 | BQ21: 129182602 | BR21: 129182602 | BS21: 129182602 | BT21: 129182602 | BU21: 129182602 | BV21: 129182602 | BW21: 131234832 | BX21: 140899926 | BY21: 140899926 | BZ21: 140899926 | CA21: 138342165 | CB21: =CA21 -> 138342165 | CC21: 137671350 | CD21: 137671350 | CE21: 152971350 | CF21: 152971350 | CG21: 143861214 | CH21: 143861214 | CI21: 143861214 | CJ21: 143861214 | CK21: 143861214 | CL21: 143861214 | CM21: 143861214 | CN21: 141821958 | CO21: =CN21 -> 141821958 | CP21: 140801596 | CQ21: 140801596 | CR21: 140801596 | CS21: 140801596 | CT21: 133918279 | CU21: 133918279 | CV21: 133918279 | CW21: 133918279 | CX21: 133918279 | CY21: 133918279 | CZ21: 133918279 | DA21: =131504761+8520124 -> 140024885 | DB21: =DA21 -> 140024885 | DC21: 147022684 | DD21: 147022684 | DE21: 147022684 | DF21: 147022684 | DG21: 147022684 | DH21: 147022684 | DI21: 147022684 | DJ21: 146848818 | DK21: 144824178 | DL21: 130697780 | DM21: 130518293 | DN21: 129672445 | DO21: =DN21 -> 129672445 | DP21: 293591805 | DQ21: 293591805 | DR21: 293591805 | DS21: 293591805 | DT21: 293591805 | DU21: 255048822 | DV21: 219099761 | DW21: 212099761 | DX21: 212099761 | DY21: 212099761 | DZ21: 212099761 | EA21: 198709088 | EB21: =EA21 -> 198709088 | EC21: 295701947 | ED21: 295701947 | EE21: 278607232 | EF21: 278607232 | EG21: 278543079 | EH21: 278543079 | EI21: 278543079 | EJ21: 282942267 | EK21: 282942267 | EL21: 282942267 | EM21: 282942267 | EN21: 244313644 | EO21: =EN21 -> 244313644 | EP21: 308121429 | EQ21: 308121429 | ER21: 308121429 | ES21: 308121429 | ET21: 308121429 | EU21: 288121429 | EV21: 288121429 | EW21: 288121429 | EX21: 288121429 | EY21: 284126983 | EZ21: 284126983 | FA21: 255720965 | FB21: =FA21 -> 255720965 | FC21: 195906100 | FD21: 195906100 | FE21: 192119100 | FF21: 192119100 | FG21: 186241917 | FH21: 202307917 | FI21: 202307917 | FO21: =FI21 -> 202307917
B22: Subdirección de APR | C22: 49407947 | D22: 49407947 | E22: 49407947 | F22: 49407947 | G22: 49407947 | H22: 55507947 | I22: 55507947 | J22: 60507947 | K22: 60507947 | L22: 65278980 | M22: 65278980 | N22: 67579947 | O22: =N22 -> 67579947 | P22: 68884752 | Q22: 68884752 | R22: 68884752 | S22: 68884752 | T22: 68884752 | U22: 85940845 | V22: 85940845 | W22: 87740845 | X22: 87740845 | Y22: 88355845 | Z22: 93717760 | AA22: 93689760 | AB22: =AA22 -> 93689760 | AC22: 71502372 | AD22: 71502372 | AE22: 71502372 | AF22: 71502372 | AG22: 71502372 | AH22: 71502372 | AI22: 71502372 | AJ22: 75002372 | AK22: 75002372 | AL22: 75002372 | AM22: 79147193 | AN22: 80579039 | AO22: =AN22 -> 80579039 | AP22: 89991483 | AQ22: 89991483 | AR22: 89991483 | AS22: 89991483 | AT22: 89991483 | AU22: 92696068 | AV22: 92696068 | AW22: 92696068 | AX22: 92696068 | AY22: 98217166 | AZ22: 98217166 | BA22: 100477231 | BB22: =BA22 -> 100477231 | BC22: 102433801 | BD22: 102433801 | BE22: 102433801 | BF22: 102433801 | BG22: 102433801 | BH22: 102433801 | BI22: 102433801 | BJ22: 102433801 | BK22: 102433801 | BL22: 106891813 | BM22: 106891813 | BN22: 102680557 | BO22: =BN22 -> 102680557 | BP22: 114691671 | BQ22: 114691671 | BR22: 114691671 | BS22: 114691671 | BT22: 114691671 | BU22: 114691671 | BV22: 114691671 | BW22: 123071862 | BX22: 118010898 | BY22: 118010898 | BZ22: 118010898 | CA22: 112674850 | CB22: =CA22 -> 112674850 | CC22: 135338654 | CD22: 135338654 | CE22: 135338654 | CF22: 158338654 | CG22: 155319586 | CH22: 155319586 | CI22: 155319586 | CJ22: 155319586 | CK22: 155319586 | CL22: 155319586 | CM22: 155319586 | CN22: 148506367 | CO22: =CN22 -> 148506367 | CP22: 142048072 | CQ22: 142048072 | CR22: 142048072 | CS22: 142048072 | CT22: 160995572 | CU22: 160995572 | CV22: 160995572 | CW22: 160995572 | CX22: 160995572 | CY22: 160995572 | CZ22: 160995572 | DA22: =142300803+21041416 -> 163342219 | DB22: =DA22 -> 163342219 | DC22: 148440561 | DD22: 148440561 | DE22: 148440561 | DF22: 148440561 | DG22: 148440561 | DH22: 148440561 | DI22: 148440561 | DJ22: 148440561 | DK22: 148440561 | DL22: 141404870 | DM22: 141404870 | DN22: 110932143 | DO22: =DN22 -> 110932143 | DP22: 295780655 | DQ22: 295780655 | DR22: 295780655 | DS22: 295780655 | DT22: 295780655 | DU22: 275780655 | DV22: 309887671 | DW22: 309887671 | DX22: 309887671 | DY22: 299857312 | DZ22: 265750296 | EA22: 249472319 | EB22: =EA22 -> 249472319 | EC22: 315696642 | ED22: 315696642 | EE22: 315696642 | EF22: 232705862 | EG22: 232705862 | EH22: 232705862 | EI22: 232705862 | EJ22: 227906674 | EK22: 227906674 | EL22: 227906674 | EM22: 227906674 | EN22: 192186387 | EO22: =EN22 -> 192186387 | EP22: 329603442 | EQ22: 329603442 | ER22: 307603442 | ES22: 307603442 | ET22: 307603442 | EU22: 284751010 | EV22: 284751010 | EW22: 284751010 | EX22: 284751010 | EY22: 273184204 | EZ22: 273184204 | FA22: 234336066 | FB22: =FA22 -> 234336066 | FC22: 290113797 | FD22: 290113797 | FE22: 282113797 | FF22: 282113797 | FG22: 273410383 | FH22: 273410383 | FI22: 273410383 | FO22: =FI22 -> 273410383
B23: Dirección de Obras Portuarias | C23: 55038550 | D23: 55038550 | E23: 55038550 | F23: 55038550 | G23: 55038550 | H23: 55038550 | I23: 56087343 | J23: 56087343 | K23: 56087343 | L23: 56087343 | M23: 56087343 | N23: 55967642 | O23: =N23 -> 55967642 | P23: 63737311 | Q23: 63737311 | R23: 63737311 | S23: 63737311 | T23: 63737311 | U23: 63737311 | V23: 63737311 | W23: 63737311 | X23: 63737311 | Y23: 60537311 | Z23: 66537311 | AA23: 66227311 | AB23: =AA23 -> 66227311 | AC23: 66005341 | AD23: 66005341 | AE23: 66005341 | AF23: 66005341 | AG23: 66005341 | AH23: 66005341 | AI23: 66005341 | AJ23: 66005341 | AK23: 66005341 | AL23: 66005341 | AM23: 66005341 | AN23: 66601585 | AO23: =AN23 -> 66601585 | AP23: 68152361 | AQ23: 68152361 | AR23: 68152361 | AS23: 68152361 | AT23: 68152361 | AU23: 68152361 | AV23: 68152361 | AW23: 68152361 | AX23: 68152361 | AY23: 68292361 | AZ23: 70792361 | BA23: 72233361 | BB23: =BA23 -> 72233361 | BC23: 69097793 | BD23: 69097793 | BE23: 69097793 | BF23: 69097793 | BG23: 69097793 | BH23: 69097793 | BI23: 68963100 | BJ23: 68963100 | BK23: 66653100 | BL23: 64364969 | BM23: 64332418 | BN23: 60805995 | BO23: =BN23 -> 60805995 | BP23: 69888575 | BQ23: 69888575 | BR23: 69888575 | BS23: 69888575 | BT23: 69888575 | BU23: 69888575 | BV23: 69888575 | BW23: 69888575 | BX23: 68888575 | BY23: 68888575 | BZ23: 68888575 | CA23: 62099040 | CB23: =CA23 -> 62099040 | CC23: 71705676 | CD23: 71705676 | CE23: 80110666 | CF23: 80110666 | CG23: 79796573 | CH23: 79796573 | CI23: 74160268 | CJ23: 74160268 | CK23: 74160268 | CL23: 74160268 | CM23: 73045737 | CN23: 71705970 | CO23: =CN23 -> 71705970 | CP23: 73670723 | CQ23: 73670723 | CR23: 73670723 | CS23: 73670723 | CT23: 73670723 | CU23: 73670723 | CV23: 73670723 | CW23: 73670723 | CX23: 73670723 | CY23: 73670723 | CZ23: 73670723 | DA23: =73116242+62000 -> 73178242 | DB23: =DA23 -> 73178242 | DC23: 76882481 | DD23: 76882481 | DE23: 76882481 | DF23: 76882481 | DG23: 76882481 | DH23: 76882481 | DI23: 76882481 | DJ23: 76882481 | DK23: 76882481 | DL23: 76882481 | DM23: 76882481 | DN23: 64614673 | DO23: =DN23 -> 64614673 | DP23: 115171552 | DQ23: 115171552 | DR23: 115171552 | DS23: 115171552 | DT23: 115171552 | DU23: 115171552 | DV23: 115171552 | DW23: 115171552 | DX23: 115171552 | DY23: 108472329 | DZ23: 108472329 | EA23: 104861138 | EB23: =EA23 -> 104861138 | EC23: 127117895 | ED23: 127117895 | EE23: 127117895 | EF23: 127117895 | EG23: 127117895 | EH23: 127117895 | EI23: 127117895 | EJ23: 127117895 | EK23: 127117895 | EL23: 127117895 | EM23: 127117895 | EN23: 123682417 | EO23: =EN23 -> 123682417 | EP23: 125417585 | EQ23: 125417585 | ER23: 139947914 | ES23: 139947914 | ET23: 139947914 | EU23: 139947914 | EV23: 145917564 | EW23: 145917564 | EX23: 145917564 | EY23: 151478816 | EZ23: 151478816 | FA23: 143006856 | FB23: =FA23 -> 143006856 | FC23: 109909690 | FD23: 109909690 | FE23: 109909690 | FF23: 109909690 | FG23: 106612399 | FH23: 106612399 | FI23: 106612399 | FO23: =FI23 -> 106612399
